Workbook

Sheet Sheet1
A1: STT | B1: Mã sinh viên | C1: Tên sinh viên | D1: Mã lớp | E1: Điểm giữa kỳ | F1: Số buổi đi học có điểm danh | G1: Điểm điểm danh | H1: Điểm Quá trình | I1: Điểm cộng vào bài thi cuối kỳ | J1: Điểm bài thi cuối kỳ thật | K1: Điểm bài thi cuối kỳ + 0.5 | L1: Điểm tổng kết | M1: Kết quả | N1: Điểm chữ | O1: Thiếu | P1: Điểm cần cộng thêm (nếu có) | Q1: Điểm cuối | R1: Check (Điểm tổng kết) | S1: Điểm chữ sau khi nâng điểm | T1: Note
A2: Danh sách uốn nướt tè:
A3: 1 | B3: 1513460 | C3: Đoàn Việt Anh | D3: 60PM1 | E3: =VLOOKUP(B3,'Điểm giữa kỳ'!$B$2:$G$85,6, false) | F3: =VLOOKUP(B3,'Điểm danh'!$B$2:$M$47,12, FALSE) -> 0 | G3: =if(F3=7, F3/7*10, (F3+1)/7*10) -> 1.4285714 | H3: =ceiling(E3*6/10 + G3*4/10, 0.5) -> 1 | I3: =if(F3=7,0.5,"") | J3: =VLOOKUP(B3,'Tính Điểm thi cuối kỳ'!$B$2:$J$47,9, FALSE) | K3: =J3+I3 -> 0 | L3: =(H3*0.3) +(K3*0.7) -> 0.3 | M3: =IF((L3<4), "Tạch", "Đạt") -> Tạch | N3: =IF((L3<4),"F", if((L3<5),"D",IF((L3<5.5),"D+",IF((L3<6.5),"C",IF((L3<7),"C+",IF((L3<8),"B",IF((L3<8.5),"B+","A"))))))) -> F | O3: =IF((N3="F"),(4-L3),IF((N3="D"),(5-L3),IF((N3="D+"),(5.5-L3),IF((N3="C"),(6.5-L3),IF((N3="C+"),(7-L3),IF((N3="B"),(8-L3),IF((N3="B+"),(8.5-L3),"Đã bị điểm A -> Không <nâng> đỡ đc nữa"))))))) -> 3.7 | P3: =if((O3<=0.201),( O3/0.6),"") | Q3: =ceiling(if((P3>0),(K3+P3),K3),0.5) -> 0 | R3: =(H3*0.3)+(Q3*0.7) -> 0.3 | S3: =if((P3>0), IF((R3<4),"F", if((R3<5),"D",IF((R3<5.5),"D+",IF((R3<6.5),"C",IF((R3<7),"C+",IF((R3<8),"B",IF((R3<8.5),"B+","A"))))))), "") -> F | T3: BỎ HỌC, BỎ THI
A4: 2 | B4: 1503561 | C4: Nguyễn Tuấn Anh | D4: 61PM1 | E4: =VLOOKUP(B4,'Điểm giữa kỳ'!$B$2:$G$85,6, false) | F4: =VLOOKUP(B4,'Điểm danh'!$B$2:$M$47,12, FALSE) -> 0 | G4: =if(F4=7, F4/7*10, (F4+1)/7*10) -> 1.4285714 | H4: =ceiling(E4*6/10 + G4*4/10, 0.5) -> 1 | I4: =if(F4=7,0.5,"") | J4: =VLOOKUP(B4,'Tính Điểm thi cuối kỳ'!$B$2:$J$47,9, FALSE) | K4: =J4+I4 -> 0 | L4: =(H4*0.3) +(K4*0.7) -> 0.3 | M4: =IF((L4<4), "Tạch", "Đạt") -> Tạch | N4: =IF((L4<4),"F", if((L4<5),"D",IF((L4<5.5),"D+",IF((L4<6.5),"C",IF((L4<7),"C+",IF((L4<8),"B",IF((L4<8.5),"B+","A"))))))) -> F | O4: =IF((N4="F"),(4-L4),IF((N4="D"),(5-L4),IF((N4="D+"),(5.5-L4),IF((N4="C"),(6.5-L4),IF((N4="C+"),(7-L4),IF((N4="B"),(8-L4),IF((N4="B+"),(8.5-L4),"Đã bị điểm A -> Không <nâng> đỡ đc nữa"))))))) -> 3.7 | P4: =if((O4<=0.201),( O4/0.6),"") | Q4: =ceiling(if((P4>0),(K4+P4),K4),0.5) -> 0 | R4: =(H4*0.3)+(Q4*0.7) -> 0.3 | S4: =if((P4>0), IF((R4<4),"F", if((R4<5),"D",IF((R4<5.5),"D+",IF((R4<6.5),"C",IF((R4<7),"C+",IF((R4<8),"B",IF((R4<8.5),"B+","A"))))))), "") -> F | T4: BỎ HỌC, BỎ THI
A5: 3 | B5: 1543960 | C5: Trần Xuân Ba | D5: 60PM1 | E5: =VLOOKUP(B5,'Điểm giữa kỳ'!$B$2:$G$85,6, false) -> 7.5 | F5: =VLOOKUP(B5,'Điểm danh'!$B$2:$M$47,12, FALSE) -> 5.5 | G5: =if(F5=7, F5/7*10, (F5+1)/7*10) -> 9.2857143 | H5: =ceiling(E5*6/10 + G5*4/10, 0.5) -> 8.5 | I5: =if(F5=7,0.5,"") | J5: =VLOOKUP(B5,'Tính Điểm thi cuối kỳ'!$B$2:$J$47,9, FALSE) -> 5 | K5: =J5+I5 -> 5 | L5: =(H5*0.3) +(K5*0.7) -> 6.05 | M5: =IF((L5<4), "Tạch", "Đạt") -> Đạt | N5: =IF((L5<4),"F", if((L5<5),"D",IF((L5<5.5),"D+",IF((L5<6.5),"C",IF((L5<7),"C+",IF((L5<8),"B",IF((L5<8.5),"B+","A"))))))) -> C | O5: =IF((N5="F"),(4-L5),IF((N5="D"),(5-L5),IF((N5="D+"),(5.5-L5),IF((N5="C"),(6.5-L5),IF((N5="C+"),(7-L5),IF((N5="B"),(8-L5),IF((N5="B+"),(8.5-L5),"Đã bị điểm A -> Không <nâng> đỡ đc nữa"))))))) -> 0.45 | P5: =if((O5<=0.201),( O5/0.6),"") | Q5: =ceiling(if((P5>0),(K5+P5),K5),0.5) -> 5 | R5: =(H5*0.3)+(Q5*0.7) -> 6.05 | S5: =if((P5>0), IF((R5<4),"F", if((R5<5),"D",IF((R5<5.5),"D+",IF((R5<6.5),"C",IF((R5<7),"C+",IF((R5<8),"B",IF((R5<8.5),"B+","A"))))))), "") -> C | T5: =if((S5=N5),"","Đã được nâng điểm chữ")
A6: 4 | B6: 174860 | C6: Đoàn Quốc Bảo | D6: 60PM1 | E6: 4 | F6: =VLOOKUP(B6,'Điểm danh'!$B$2:$M$47,12, FALSE) -> 4 | G6: =if(F6=7, F6/7*10, (F6+1)/7*10) -> 7.1428571 | H6: =ceiling(E6*6/10 + G6*4/10, 0.5) -> 5.5 | I6: =if(F6=7,0.5,"") | J6: =VLOOKUP(B6,'Tính Điểm thi cuối kỳ'!$B$2:$J$47,9, FALSE) -> 5.5 | K6: =J6+I6 -> 5.5 | L6: =(H6*0.3) +(K6*0.7) -> 5.5 | M6: =IF((L6<4), "Tạch", "Đạt") -> Đạt | N6: =IF((L6<4),"F", if((L6<5),"D",IF((L6<5.5),"D+",IF((L6<6.5),"C",IF((L6<7),"C+",IF((L6<8),"B",IF((L6<8.5),"B+","A"))))))) -> C | O6: =IF((N6="F"),(4-L6),IF((N6="D"),(5-L6),IF((N6="D+"),(5.5-L6),IF((N6="C"),(6.5-L6),IF((N6="C+"),(7-L6),IF((N6="B"),(8-L6),IF((N6="B+"),(8.5-L6),"Đã bị điểm A -> Không <nâng> đỡ đc nữa"))))))) -> 1 | P6: =if((O6<=0.201),( O6/0.6),"") | Q6: =ceiling(if((P6>0),(K6+P6),K6),0.5) -> 5.5 | R6: =(H6*0.3)+(Q6*0.7) -> 5.5 | S6: =if((P6>0), IF((R6<4),"F", if((R6<5),"D",IF((R6<5.5),"D+",IF((R6<6.5),"C",IF((R6<7),"C+",IF((R6<8),"B",IF((R6<8.5),"B+","A"))))))), "") -> C
A7: 5 | B7: 9460 | C7: Nguyễn Mạnh Cường | D7: 60PM2 | E7: =VLOOKUP(B7,'Điểm giữa kỳ'!$B$2:$G$85,6, false) -> 7 | F7: =VLOOKUP(B7,'Điểm danh'!$B$2:$M$47,12, FALSE) -> 7 | G7: =if(F7=7, F7/7*10, (F7+1)/7*10) -> 10 | H7: =ceiling(E7*6/10 + G7*4/10, 0.5) -> 8.5 | I7: =if(F7=7,0.5,"") -> 0.5 | J7: =VLOOKUP(B7,'Tính Điểm thi cuối kỳ'!$B$2:$J$47,9, FALSE) -> 9 | K7: =J7+I7 -> 9.5 | L7: =(H7*0.3) +(K7*0.7) -> 9.2 | M7: =IF((L7<4), "Tạch", "Đạt") -> Đạt | N7: =IF((L7<4),"F", if((L7<5),"D",IF((L7<5.5),"D+",IF((L7<6.5),"C",IF((L7<7),"C+",IF((L7<8),"B",IF((L7<8.5),"B+","A"))))))) -> A | O7: =IF((N7="F"),(4-L7),IF((N7="D"),(5-L7),IF((N7="D+"),(5.5-L7),IF((N7="C"),(6.5-L7),IF((N7="C+"),(7-L7),IF((N7="B"),(8-L7),IF((N7="B+"),(8.5-L7),"Đã bị điểm A -> Không <nâng> đỡ đc nữa"))))))) -> Đã bị điểm A -> Không <nâng> đỡ đc nữa | P7: =if((O7<=0.201),( O7/0.6),"") | Q7: =ceiling(if((P7>0),(K7+P7),K7),0.5) -> 9.5 | R7: =(H7*0.3)+(Q7*0.7) -> 9.2 | S7: =if((P7>0), IF((R7<4),"F", if((R7<5),"D",IF((R7<5.5),"D+",IF((R7<6.5),"C",IF((R7<7),"C+",IF((R7<8),"B",IF((R7<8.5),"B+","A"))))))), "") -> A | T7: =if((S7=N7),"","Đã được nâng điểm chữ")
A8: 6 | B8: 1506260 | C8: Nguyễn Văn Đạt | D8: 60PM1 | E8: =VLOOKUP(B8,'Điểm giữa kỳ'!$B$2:$G$85,6, false) -> 8.5 | F8: =VLOOKUP(B8,'Điểm danh'!$B$2:$M$47,12, FALSE) -> 7 | G8: =if(F8=7, F8/7*10, (F8+1)/7*10) -> 10 | H8: =ceiling(E8*6/10 + G8*4/10, 0.5) -> 9.5 | I8: =if(F8=7,0.5,"") -> 0.5 | J8: =VLOOKUP(B8,'Tính Điểm thi cuối kỳ'!$B$2:$J$47,9, FALSE) -> 7.5 | K8: =J8+I8 -> 8 | L8: =(H8*0.3) +(K8*0.7) -> 8.45 | M8: =IF((L8<4), "Tạch", "Đạt") -> Đạt | N8: =IF((L8<4),"F", if((L8<5),"D",IF((L8<5.5),"D+",IF((L8<6.5),"C",IF((L8<7),"C+",IF((L8<8),"B",IF((L8<8.5),"B+","A"))))))) -> B+ | O8: =IF((N8="F"),(4-L8),IF((N8="D"),(5-L8),IF((N8="D+"),(5.5-L8),IF((N8="C"),(6.5-L8),IF((N8="C+"),(7-L8),IF((N8="B"),(8-L8),IF((N8="B+"),(8.5-L8),"Đã bị điểm A -> Không <nâng> đỡ đc nữa"))))))) -> 0.05 | P8: =if((O8<=0.201),( O8/0.6),"") -> 0.083333333 | Q8: =ceiling(if((P8>0),(K8+P8),K8),0.5) -> 8.5 | R8: =(H8*0.3)+(Q8*0.7) -> 8.8 | S8: =if((P8>0), IF((R8<4),"F", if((R8<5),"D",IF((R8<5.5),"D+",IF((R8<6.5),"C",IF((R8<7),"C+",IF((R8<8),"B",IF((R8<8.5),"B+","A"))))))), "") -> A | T8: =if((S8=N8),"","Đã được nâng điểm chữ") -> Đã được nâng điểm chữ
A9: 7 | B9: 1547360 | C9: Đậu Viết Đức | D9: 60PM1 | E9: =VLOOKUP(B9,'Điểm giữa kỳ'!$B$2:$G$85,6, false) -> 5.5 | F9: =VLOOKUP(B9,'Điểm danh'!$B$2:$M$47,12, FALSE) -> 7 | G9: =if(F9=7, F9/7*10, (F9+1)/7*10) -> 10 | H9: =ceiling(E9*6/10 + G9*4/10, 0.5) -> 7.5 | I9: =if(F9=7,0.5,"") -> 0.5 | J9: =VLOOKUP(B9,'Tính Điểm thi cuối kỳ'!$B$2:$J$47,9, FALSE) -> 7.5 | K9: =J9+I9 -> 8 | L9: =(H9*0.3) +(K9*0.7) -> 7.85 | M9: =IF((L9<4), "Tạch", "Đạt") -> Đạt | N9: =IF((L9<4),"F", if((L9<5),"D",IF((L9<5.5),"D+",IF((L9<6.5),"C",IF((L9<7),"C+",IF((L9<8),"B",IF((L9<8.5),"B+","A"))))))) -> B | O9: =IF((N9="F"),(4-L9),IF((N9="D"),(5-L9),IF((N9="D+"),(5.5-L9),IF((N9="C"),(6.5-L9),IF((N9="C+"),(7-L9),IF((N9="B"),(8-L9),IF((N9="B+"),(8.5-L9),"Đã bị điểm A -> Không <nâng> đỡ đc nữa"))))))) -> 0.15 | P9: =if((O9<=0.201),( O9/0.6),"") -> 0.25 | Q9: =ceiling(if((P9>0),(K9+P9),K9),0.5) -> 8.5 | R9: =(H9*0.3)+(Q9*0.7) -> 8.2 | S9: =if((P9>0), IF((R9<4),"F", if((R9<5),"D",IF((R9<5.5),"D+",IF((R9<6.5),"C",IF((R9<7),"C+",IF((R9<8),"B",IF((R9<8.5),"B+","A"))))))), "") -> B+ | T9: =if((S9=N9),"","Đã được nâng điểm chữ") -> Đã được nâng điểm chữ
A10: 8 | B10: 127160 | C10: Lê Đức Giáp | D10: 60PM1 | E10: =VLOOKUP(B10,'Điểm giữa kỳ'!$B$2:$G$85,6, false) -> 8 | F10: =VLOOKUP(B10,'Điểm danh'!$B$2:$M$47,12, FALSE) -> 3 | G10: =if(F10=7, F10/7*10, (F10+1)/7*10) -> 5.7142857 | H10: =ceiling(E10*6/10 + G10*4/10, 0.5) -> 7.5 | I10: =if(F10=7,0.5,"") | J10: 4 | K10: =J10+I10 -> 4 | L10: =(H10*0.3) +(K10*0.7) -> 5.05 | M10: =IF((L10<4), "Tạch", "Đạt") -> Đạt | N10: =IF((L10<4),"F", if((L10<5),"D",IF((L10<5.5),"D+",IF((L10<6.5),"C",IF((L10<7),"C+",IF((L10<8),"B",IF((L10<8.5),"B+","A"))))))) -> D+ | O10: =IF((N10="F"),(4-L10),IF((N10="D"),(5-L10),IF((N10="D+"),(5.5-L10),IF((N10="C"),(6.5-L10),IF((N10="C+"),(7-L10),IF((N10="B"),(8-L10),IF((N10="B+"),(8.5-L10),"Đã bị điểm A -> Không <nâng> đỡ đc nữa"))))))) -> 0.45 | P10: =if((O10<=0.201),( O10/0.6),"") | Q10: =ceiling(if((P10>0),(K10+P10),K10),0.5) -> 4 | R10: =(H10*0.3)+(Q10*0.7) -> 5.05 | S10: =if((P10>0), IF((R10<4),"F", if((R10<5),"D",IF((R10<5.5),"D+",IF((R10<6.5),"C",IF((R10<7),"C+",IF((R10<8),"B",IF((R10<8.5),"B+","A"))))))), "") -> D+ | T10: =if((S10=N10),"","Đã được nâng điểm chữ")
A11: 9 | B11: 1533860 | C11: Lê Trung Hiếu | D11: 60PM1 | E11: =VLOOKUP(B11,'Điểm giữa kỳ'!$B$2:$G$85,6, false) -> 5.5 | F11: =VLOOKUP(B11,'Điểm danh'!$B$2:$M$47,12, FALSE) -> 5.5 | G11: =if(F11=7, F11/7*10, (F11+1)/7*10) -> 9.2857143 | H11: =ceiling(E11*6/10 + G11*4/10, 0.5) -> 7.5 | I11: =if(F11=7,0.5,"") | J11: =VLOOKUP(B11,'Tính Điểm thi cuối kỳ'!$B$2:$J$47,9, FALSE) -> 2 | K11: =J11+I11 -> 2 | L11: =(H11*0.3) +(K11*0.7) -> 3.65 | M11: =IF((L11<4), "Tạch", "Đạt") -> Tạch | N11: =IF((L11<4),"F", if((L11<5),"D",IF((L11<5.5),"D+",IF((L11<6.5),"C",IF((L11<7),"C+",IF((L11<8),"B",IF((L11<8.5),"B+","A"))))))) -> F | O11: =IF((N11="F"),(4-L11),IF((N11="D"),(5-L11),IF((N11="D+"),(5.5-L11),IF((N11="C"),(6.5-L11),IF((N11="C+"),(7-L11),IF((N11="B"),(8-L11),IF((N11="B+"),(8.5-L11),"Đã bị điểm A -> Không <nâng> đỡ đc nữa"))))))) -> 0.35 | P11: =if((O11<=0.201),( O11/0.6),"") | Q11: =ceiling(if((P11>0),(K11+P11),K11),0.5) -> 2 | R11: =(H11*0.3)+(Q11*0.7) -> 3.65 | S11: =if((P11>0), IF((R11<4),"F", if((R11<5),"D",IF((R11<5.5),"D+",IF((R11<6.5),"C",IF((R11<7),"C+",IF((R11<8),"B",IF((R11<8.5),"B+","A"))))))), "") -> F | T11: =if((S11=N11),"","Đã được nâng điểm chữ")
A12: 10 | B12: 130260 | C12: Trần Văn Hiếu | D12: 60PM1 | E12: =VLOOKUP(B12,'Điểm giữa kỳ'!$B$2:$G$85,6, false) -> 6.5 | F12: =VLOOKUP(B12,'Điểm danh'!$B$2:$M$47,12, FALSE) -> 6 | G12: =if(F12=7, F12/7*10, (F12+1)/7*10) -> 10 | H12: =ceiling(E12*6/10 + G12*4/10, 0.5) -> 8 | I12: =if(F12=7,0.5,"") | J12: =VLOOKUP(B12,'Tính Điểm thi cuối kỳ'!$B$2:$J$47,9, FALSE) -> 6 | K12: =J12+I12 -> 6 | L12: =(H12*0.3) +(K12*0.7) -> 6.6 | M12: =IF((L12<4), "Tạch", "Đạt") -> Đạt | N12: =IF((L12<4),"F", if((L12<5),"D",IF((L12<5.5),"D+",IF((L12<6.5),"C",IF((L12<7),"C+",IF((L12<8),"B",IF((L12<8.5),"B+","A"))))))) -> C+ | O12: =IF((N12="F"),(4-L12),IF((N12="D"),(5-L12),IF((N12="D+"),(5.5-L12),IF((N12="C"),(6.5-L12),IF((N12="C+"),(7-L12),IF((N12="B"),(8-L12),IF((N12="B+"),(8.5-L12),"Đã bị điểm A -> Không <nâng> đỡ đc nữa"))))))) -> 0.4 | P12: =if((O12<=0.201),( O12/0.6),"") | Q12: =ceiling(if((P12>0),(K12+P12),K12),0.5) -> 6 | R12: =(H12*0.3)+(Q12*0.7) -> 6.6 | S12: =if((P12>0), IF((R12<4),"F", if((R12<5),"D",IF((R12<5.5),"D+",IF((R12<6.5),"C",IF((R12<7),"C+",IF((R12<8),"B",IF((R12<8.5),"B+","A"))))))), "") -> C+ | T12: =if((S12=N12),"","Đã được nâng điểm chữ")
A13: 11 | B13: 111060 | C13: Nguyễn Văn Hĩu | D13: 60PM1 | E13: =VLOOKUP(B13,'Điểm giữa kỳ'!$B$2:$G$85,6, false) -> 5 | F13: =VLOOKUP(B13,'Điểm danh'!$B$2:$M$47,12, FALSE) -> 7 | G13: =if(F13=7, F13/7*10, (F13+1)/7*10) -> 10 | H13: =ceiling(E13*6/10 + G13*4/10, 0.5) -> 7 | I13: =if(F13=7,0.5,"") -> 0.5 | J13: =VLOOKUP(B13,'Tính Điểm thi cuối kỳ'!$B$2:$J$47,9, FALSE) -> 5.5 | K13: =J13+I13 -> 6 | L13: =(H13*0.3) +(K13*0.7) -> 6.3 | M13: =IF((L13<4), "Tạch", "Đạt") -> Đạt | N13: =IF((L13<4),"F", if((L13<5),"D",IF((L13<5.5),"D+",IF((L13<6.5),"C",IF((L13<7),"C+",IF((L13<8),"B",IF((L13<8.5),"B+","A"))))))) -> C | O13: =IF((N13="F"),(4-L13),IF((N13="D"),(5-L13),IF((N13="D+"),(5.5-L13),IF((N13="C"),(6.5-L13),IF((N13="C+"),(7-L13),IF((N13="B"),(8-L13),IF((N13="B+"),(8.5-L13),"Đã bị điểm A -> Không <nâng> đỡ đc nữa"))))))) -> 0.2 | P13: =if((O13<=0.201),( O13/0.6),"") -> 0.33333333 | Q13: =ceiling(if((P13>0),(K13+P13),K13),0.5) -> 6.5 | R13: =(H13*0.3)+(Q13*0.7) -> 6.65 | S13: =if((P13>0), IF((R13<4),"F", if((R13<5),"D",IF((R13<5.5),"D+",IF((R13<6.5),"C",IF((R13<7),"C+",IF((R13<8),"B",IF((R13<8.5),"B+","A"))))))), "") -> C+ | T13: =if((S13=N13),"","Đã được nâng điểm chữ") -> Đã được nâng điểm chữ
A14: 12 | B14: 1518860 | C14: Nguyễn Hữu Hoàng | D14: 60PM1 | E14: =VLOOKUP(B14,'Điểm giữa kỳ'!$B$2:$G$85,6, false) -> 7.5 | F14: =VLOOKUP(B14,'Điểm danh'!$B$2:$M$47,12, FALSE) -> 7 | G14: =if(F14=7, F14/7*10, (F14+1)/7*10) -> 10 | H14: =ceiling(E14*6/10 + G14*4/10, 0.5) -> 8.5 | I14: =if(F14=7,0.5,"") -> 0.5 | J14: =VLOOKUP(B14,'Tính Điểm thi cuối kỳ'!$B$2:$J$47,9, FALSE) -> 4 | K14: =J14+I14 -> 4.5 | L14: =(H14*0.3) +(K14*0.7) -> 5.7 | M14: =IF((L14<4), "Tạch", "Đạt") -> Đạt | N14: =IF((L14<4),"F", if((L14<5),"D",IF((L14<5.5),"D+",IF((L14<6.5),"C",IF((L14<7),"C+",IF((L14<8),"B",IF((L14<8.5),"B+","A"))))))) -> C | O14: =IF((N14="F"),(4-L14),IF((N14="D"),(5-L14),IF((N14="D+"),(5.5-L14),IF((N14="C"),(6.5-L14),IF((N14="C+"),(7-L14),IF((N14="B"),(8-L14),IF((N14="B+"),(8.5-L14),"Đã bị điểm A -> Không <nâng> đỡ đc nữa"))))))) -> 0.8 | P14: =if((O14<=0.201),( O14/0.6),"") | Q14: =ceiling(if((P14>0),(K14+P14),K14),0.5) -> 4.5 | R14: =(H14*0.3)+(Q14*0.7) -> 5.7 | S14: =if((P14>0), IF((R14<4),"F", if((R14<5),"D",IF((R14<5.5),"D+",IF((R14<6.5),"C",IF((R14<7),"C+",IF((R14<8),"B",IF((R14<8.5),"B+","A"))))))), "") -> C | T14: =if((S14=N14),"","Đã được nâng điểm chữ")
A15: 13 | B15: 1506357 | C15: Vũ Minh Hoàng | D15: 57PM2 | E15: =VLOOKUP(B15,'Điểm giữa kỳ'!$B$2:$G$85,6, false) -> 6 | F15: =VLOOKUP(B15,'Điểm danh'!$B$2:$M$47,12, FALSE) -> 3.5 | G15: =if(F15=7, F15/7*10, (F15+1)/7*10) -> 6.4285714 | H15: =ceiling(E15*6/10 + G15*4/10, 0.5) -> 6.5 | I15: =if(F15=7,0.5,"") | J15: =VLOOKUP(B15,'Tính Điểm thi cuối kỳ'!$B$2:$J$47,9, FALSE) -> 3 | K15: =J15+I15 -> 3 | L15: =(H15*0.3) +(K15*0.7) -> 4.05 | M15: =IF((L15<4), "Tạch", "Đạt") -> Đạt | N15: =IF((L15<4),"F", if((L15<5),"D",IF((L15<5.5),"D+",IF((L15<6.5),"C",IF((L15<7),"C+",IF((L15<8),"B",IF((L15<8.5),"B+","A"))))))) -> D | O15: =IF((N15="F"),(4-L15),IF((N15="D"),(5-L15),IF((N15="D+"),(5.5-L15),IF((N15="C"),(6.5-L15),IF((N15="C+"),(7-L15),IF((N15="B"),(8-L15),IF((N15="B+"),(8.5-L15),"Đã bị điểm A -> Không <nâng> đỡ đc nữa"))))))) -> 0.95 | P15: =if((O15<=0.201),( O15/0.6),"") | Q15: =ceiling(if((P15>0),(K15+P15),K15),0.5) -> 3 | R15: =(H15*0.3)+(Q15*0.7) -> 4.05 | S15: =if((P15>0), IF((R15<4),"F", if((R15<5),"D",IF((R15<5.5),"D+",IF((R15<6.5),"C",IF((R15<7),"C+",IF((R15<8),"B",IF((R15<8.5),"B+","A"))))))), "") -> D | T15: =if((S15=N15),"","Đã được nâng điểm chữ")
A16: 14 | B16: 1535160 | C16: Khúc Gia Huy | D16: 60PM1 | E16: =VLOOKUP(B16,'Điểm giữa kỳ'!$B$2:$G$85,6, false) -> 7.5 | F16: =VLOOKUP(B16,'Điểm danh'!$B$2:$M$47,12, FALSE) -> 6 | G16: =if(F16=7, F16/7*10, (F16+1)/7*10) -> 10 | H16: =ceiling(E16*6/10 + G16*4/10, 0.5) -> 8.5 | I16: =if(F16=7,0.5,"") | J16: =VLOOKUP(B16,'Tính Điểm thi cuối kỳ'!$B$2:$J$47,9, FALSE) -> 4 | K16: =J16+I16 -> 4 | L16: =(H16*0.3) +(K16*0.7) -> 5.35 | M16: =IF((L16<4), "Tạch", "Đạt") -> Đạt | N16: =IF((L16<4),"F", if((L16<5),"D",IF((L16<5.5),"D+",IF((L16<6.5),"C",IF((L16<7),"C+",IF((L16<8),"B",IF((L16<8.5),"B+","A"))))))) -> D+ | O16: =IF((N16="F"),(4-L16),IF((N16="D"),(5-L16),IF((N16="D+"),(5.5-L16),IF((N16="C"),(6.5-L16),IF((N16="C+"),(7-L16),IF((N16="B"),(8-L16),IF((N16="B+"),(8.5-L16),"Đã bị điểm A -> Không <nâng> đỡ đc nữa"))))))) -> 0.15 | P16: =if((O16<=0.201),( O16/0.6),"") -> 0.25 | Q16: =ceiling(if((P16>0),(K16+P16),K16),0.5) -> 4.5 | R16: =(H16*0.3)+(Q16*0.7) -> 5.7 | S16: =if((P16>0), IF((R16<4),"F", if((R16<5),"D",IF((R16<5.5),"D+",IF((R16<6.5),"C",IF((R16<7),"C+",IF((R16<8),"B",IF((R16<8.5),"B+","A"))))))), "") -> C | T16: =if((S16=N16),"","Đã được nâng điểm chữ") -> Đã được nâng điểm chữ
A17: 15 | B17: 170060 | C17: Lê Minh Huy | D17: 60PM1 | E17: =VLOOKUP(B17,'Điểm giữa kỳ'!$B$2:$G$85,6, false) -> 7.5 | F17: =VLOOKUP(B17,'Điểm danh'!$B$2:$M$47,12, FALSE) -> 7 | G17: =if(F17=7, F17/7*10, (F17+1)/7*10) -> 10 | H17: =ceiling(E17*6/10 + G17*4/10, 0.5) -> 8.5 | I17: =if(F17=7,0.5,"") -> 0.5 | J17: =VLOOKUP(B17,'Tính Điểm thi cuối kỳ'!$B$2:$J$47,9, FALSE) -> 5.5 | K17: =J17+I17 -> 6 | L17: =(H17*0.3) +(K17*0.7) -> 6.75 | M17: =IF((L17<4), "Tạch", "Đạt") -> Đạt | N17: =IF((L17<4),"F", if((L17<5),"D",IF((L17<5.5),"D+",IF((L17<6.5),"C",IF((L17<7),"C+",IF((L17<8),"B",IF((L17<8.5),"B+","A"))))))) -> C+ | O17: =IF((N17="F"),(4-L17),IF((N17="D"),(5-L17),IF((N17="D+"),(5.5-L17),IF((N17="C"),(6.5-L17),IF((N17="C+"),(7-L17),IF((N17="B"),(8-L17),IF((N17="B+"),(8.5-L17),"Đã bị điểm A -> Không <nâng> đỡ đc nữa"))))))) -> 0.25 | P17: =if((O17<=0.201),( O17/0.6),"") | Q17: =ceiling(if((P17>0),(K17+P17),K17),0.5) -> 6 | R17: =(H17*0.3)+(Q17*0.7) -> 6.75 | S17: =if((P17>0), IF((R17<4),"F", if((R17<5),"D",IF((R17<5.5),"D+",IF((R17<6.5),"C",IF((R17<7),"C+",IF((R17<8),"B",IF((R17<8.5),"B+","A"))))))), "") -> C+ | T17: =if((S17=N17),"","Đã được nâng điểm chữ")
A18: 16 | B18: 1511460 | C18: Phạm Ngọc Huy | D18: 60PM1 | E18: =VLOOKUP(B18,'Điểm giữa kỳ'!$B$2:$G$85,6, false) -> 8 | F18: =VLOOKUP(B18,'Điểm danh'!$B$2:$M$47,12, FALSE) -> 6.5 | G18: 10 | H18: =ceiling(E18*6/10 + G18*4/10, 0.5) -> 9 | I18: =if(F18=7,0.5,"") | J18: =VLOOKUP(B18,'Tính Điểm thi cuối kỳ'!$B$2:$J$47,9, FALSE) -> 5.5 | K18: =J18+I18 -> 5.5 | L18: =(H18*0.3) +(K18*0.7) -> 6.55 | M18: =IF((L18<4), "Tạch", "Đạt") -> Đạt | N18: =IF((L18<4),"F", if((L18<5),"D",IF((L18<5.5),"D+",IF((L18<6.5),"C",IF((L18<7),"C+",IF((L18<8),"B",IF((L18<8.5),"B+","A"))))))) -> C+ | O18: =IF((N18="F"),(4-L18),IF((N18="D"),(5-L18),IF((N18="D+"),(5.5-L18),IF((N18="C"),(6.5-L18),IF((N18="C+"),(7-L18),IF((N18="B"),(8-L18),IF((N18="B+"),(8.5-L18),"Đã bị điểm A -> Không <nâng> đỡ đc nữa"))))))) -> 0.45 | P18: =if((O18<=0.201),( O18/0.6),"") | Q18: =ceiling(if((P18>0),(K18+P18),K18),0.5) -> 5.5 | R18: =(H18*0.3)+(Q18*0.7) -> 6.55 | S18: =if((P18>0), IF((R18<4),"F", if((R18<5),"D",IF((R18<5.5),"D+",IF((R18<6.5),"C",IF((R18<7),"C+",IF((R18<8),"B",IF((R18<8.5),"B+","A"))))))), "") -> C+ | T18: =if((S18=N18),"","Đã được nâng điểm chữ")
A19: 17 | B19: 1565360 | C19: Hoàng Việt Hưng | D19: 60PM1 | E19: =VLOOKUP(B19,'Điểm giữa kỳ'!$B$2:$G$85,6, false) | F19: =VLOOKUP(B19,'Điểm danh'!$B$2:$M$47,12, FALSE) -> 0 | G19: =if(F19=7, F19/7*10, (F19+1)/7*10) -> 1.4285714 | H19: =ceiling(E19*6/10 + G19*4/10, 0.5) -> 1 | I19: =if(F19=7,0.5,"") | J19: =VLOOKUP(B19,'Tính Điểm thi cuối kỳ'!$B$2:$J$47,9, FALSE) | K19: =J19+I19 -> 0 | L19: =(H19*0.3) +(K19*0.7) -> 0.3 | M19: =IF((L19<4), "Tạch", "Đạt") -> Tạch | N19: =IF((L19<4),"F", if((L19<5),"D",IF((L19<5.5),"D+",IF((L19<6.5),"C",IF((L19<7),"C+",IF((L19<8),"B",IF((L19<8.5),"B+","A"))))))) -> F | O19: =IF((N19="F"),(4-L19),IF((N19="D"),(5-L19),IF((N19="D+"),(5.5-L19),IF((N19="C"),(6.5-L19),IF((N19="C+"),(7-L19),IF((N19="B"),(8-L19),IF((N19="B+"),(8.5-L19),"Đã bị điểm A -> Không <nâng> đỡ đc nữa"))))))) -> 3.7 | P19: =if((O19<=0.201),( O19/0.6),"") | Q19: =ceiling(if((P19>0),(K19+P19),K19),0.5) -> 0 | R19: =(H19*0.3)+(Q19*0.7) -> 0.3 | S19: =if((P19>0), IF((R19<4),"F", if((R19<5),"D",IF((R19<5.5),"D+",IF((R19<6.5),"C",IF((R19<7),"C+",IF((R19<8),"B",IF((R19<8.5),"B+","A"))))))), "") -> F | T19: BỎ HỌC, BỎ THI
A20: 18 | B20: 1504559 | C20: Hà Bảo Khánh | D20: 59PM1 | E20: =VLOOKUP(B20,'Điểm giữa kỳ'!$B$2:$G$85,6, false) | F20: =VLOOKUP(B20,'Điểm danh'!$B$2:$M$47,12, FALSE) -> 2 | G20: =if(F20=7, F20/7*10, (F20+1)/7*10) -> 4.2857143 | H20: =ceiling(E20*6/10 + G20*4/10, 0.5) -> 2 | I20: =if(F20=7,0.5,"") | J20: =VLOOKUP(B20,'Tính Điểm thi cuối kỳ'!$B$2:$J$47,9, FALSE) | K20: =J20+I20 -> 0 | L20: =(H20*0.3) +(K20*0.7) -> 0.6 | M20: =IF((L20<4), "Tạch", "Đạt") -> Tạch | N20: =IF((L20<4),"F", if((L20<5),"D",IF((L20<5.5),"D+",IF((L20<6.5),"C",IF((L20<7),"C+",IF((L20<8),"B",IF((L20<8.5),"B+","A"))))))) -> F | O20: =IF((N20="F"),(4-L20),IF((N20="D"),(5-L20),IF((N20="D+"),(5.5-L20),IF((N20="C"),(6.5-L20),IF((N20="C+"),(7-L20),IF((N20="B"),(8-L20),IF((N20="B+"),(8.5-L20),"Đã bị điểm A -> Không <nâng> đỡ đc nữa"))))))) -> 3.4 | P20: =if((O20<=0.201),( O20/0.6),"") | Q20: =ceiling(if((P20>0),(K20+P20),K20),0.5) -> 0 | R20: =(H20*0.3)+(Q20*0.7) -> 0.6 | S20: =if((P20>0), IF((R20<4),"F", if((R20<5),"D",IF((R20<5.5),"D+",IF((R20<6.5),"C",IF((R20<7),"C+",IF((R20<8),"B",IF((R20<8.5),"B+","A"))))))), "") -> F | T20: BỎ HỌC, BỎ THI
A21: 19 | B21: 1519760 | C21: Nguyễn Kim Lâm | D21: 60PM1 | E21: =VLOOKUP(B21,'Điểm giữa kỳ'!$B$2:$G$85,6, false) -> 7.5 | F21: =VLOOKUP(B21,'Điểm danh'!$B$2:$M$47,12, FALSE) -> 7 | G21: =if(F21=7, F21/7*10, (F21+1)/7*10) -> 10 | H21: =ceiling(E21*6/10 + G21*4/10, 0.5) -> 8.5 | I21: =if(F21=7,0.5,"") -> 0.5 | J21: =VLOOKUP(B21,'Tính Điểm thi cuối kỳ'!$B$2:$J$47,9, FALSE) -> 6 | K21: =J21+I21 -> 6.5 | L21: =(H21*0.3) +(K21*0.7) -> 7.1 | M21: =IF((L21<4), "Tạch", "Đạt") -> Đạt | N21: =IF((L21<4),"F", if((L21<5),"D",IF((L21<5.5),"D+",IF((L21<6.5),"C",IF((L21<7),"C+",IF((L21<8),"B",IF((L21<8.5),"B+","A"))))))) -> B | O21: =IF((N21="F"),(4-L21),IF((N21="D"),(5-L21),IF((N21="D+"),(5.5-L21),IF((N21="C"),(6.5-L21),IF((N21="C+"),(7-L21),IF((N21="B"),(8-L21),IF((N21="B+"),(8.5-L21),"Đã bị điểm A -> Không <nâng> đỡ đc nữa"))))))) -> 0.9 | P21: =if((O21<=0.201),( O21/0.6),"") | Q21: =ceiling(if((P21>0),(K21+P21),K21),0.5) -> 6.5 | R21: =(H21*0.3)+(Q21*0.7) -> 7.1 | S21: =if((P21>0), IF((R21<4),"F", if((R21<5),"D",IF((R21<5.5),"D+",IF((R21<6.5),"C",IF((R21<7),"C+",IF((R21<8),"B",IF((R21<8.5),"B+","A"))))))), "") -> B | T21: =if((S21=N21),"","Đã được nâng điểm chữ")
A22: 20 | B22: 1539760 | C22: Nguyễn Văn Lâm | D22: 60PM1 | E22: =VLOOKUP(B22,'Điểm giữa kỳ'!$B$2:$G$85,6, false) -> 8 | F22: =VLOOKUP(B22,'Điểm danh'!$B$2:$M$47,12, FALSE) -> 7 | G22: =if(F22=7, F22/7*10, (F22+1)/7*10) -> 10 | H22: =ceiling(E22*6/10 + G22*4/10, 0.5) -> 9 | I22: =if(F22=7,0.5,"") -> 0.5 | J22: =VLOOKUP(B22,'Tính Điểm thi cuối kỳ'!$B$2:$J$47,9, FALSE) -> 5.5 | K22: =J22+I22 -> 6 | L22: =(H22*0.3) +(K22*0.7) -> 6.9 | M22: =IF((L22<4), "Tạch", "Đạt") -> Đạt | N22: =IF((L22<4),"F", if((L22<5),"D",IF((L22<5.5),"D+",IF((L22<6.5),"C",IF((L22<7),"C+",IF((L22<8),"B",IF((L22<8.5),"B+","A"))))))) -> C+ | O22: =IF((N22="F"),(4-L22),IF((N22="D"),(5-L22),IF((N22="D+"),(5.5-L22),IF((N22="C"),(6.5-L22),IF((N22="C+"),(7-L22),IF((N22="B"),(8-L22),IF((N22="B+"),(8.5-L22),"Đã bị điểm A -> Không <nâng> đỡ đc nữa"))))))) -> 0.1 | P22: =if((O22<=0.201),( O22/0.6),"") -> 0.16666667 | Q22: =ceiling(if((P22>0),(K22+P22),K22),0.5) -> 6.5 | R22: =(H22*0.3)+(Q22*0.7) -> 7.25 | S22: =if((P22>0), IF((R22<4),"F", if((R22<5),"D",IF((R22<5.5),"D+",IF((R22<6.5),"C",IF((R22<7),"C+",IF((R22<8),"B",IF((R22<8.5),"B+","A"))))))), "") -> B | T22: =if((S22=N22),"","Đã được nâng điểm chữ") -> Đã được nâng điểm chữ
A23: 21 | B23: 1512660 | C23: Lại Hoàng Lê | D23: 60PM1 | E23: =VLOOKUP(B23,'Điểm giữa kỳ'!$B$2:$G$85,6, false) + 0.5 -> 9.5 | F23: =VLOOKUP(B23,'Điểm danh'!$B$2:$M$47,12, FALSE) -> 7 | G23: =if(F23=7, F23/7*10, (F23+1)/7*10) -> 10 | H23: =ceiling(E23*6/10 + G23*4/10, 0.5) -> 10 | I23: =if(F23=7,0.5,"") -> 0.5 | J23: =VLOOKUP(B23,'Tính Điểm thi cuối kỳ'!$B$2:$J$47,9, FALSE) -> 9 | K23: =J23+I23 -> 9.5 | L23: =(H23*0.3) +(K23*0.7) -> 9.65 | M23: =IF((L23<4), "Tạch", "Đạt") -> Đạt | N23: =IF((L23<4),"F", if((L23<5),"D",IF((L23<5.5),"D+",IF((L23<6.5),"C",IF((L23<7),"C+",IF((L23<8),"B",IF((L23<8.5),"B+","A"))))))) -> A | O23: =IF((N23="F"),(4-L23),IF((N23="D"),(5-L23),IF((N23="D+"),(5.5-L23),IF((N23="C"),(6.5-L23),IF((N23="C+"),(7-L23),IF((N23="B"),(8-L23),IF((N23="B+"),(8.5-L23),"Đã bị điểm A -> Không <nâng> đỡ đc nữa"))))))) -> Đã bị điểm A -> Không <nâng> đỡ đc nữa | P23: =if((O23<=0.201),( O23/0.6),"") | Q23: =ceiling(if((P23>0),(K23+P23),K23),0.5) -> 9.5 | R23: =(H23*0.3)+(Q23*0.7) -> 9.65 | S23: =if((P23>0), IF((R23<4),"F", if((R23<5),"D",IF((R23<5.5),"D+",IF((R23<6.5),"C",IF((R23<7),"C+",IF((R23<8),"B",IF((R23<8.5),"B+","A"))))))), "") -> A | T23: =if((S23=N23),"","Đã được nâng điểm chữ")
A24: 22 | B24: 1536360 | C24: Đoàn Bảo Linh | D24: 60PM1 | E24: =VLOOKUP(B24,'Điểm giữa kỳ'!$B$2:$G$85,6, false) -> 6 | F24: =VLOOKUP(B24,'Điểm danh'!$B$2:$M$47,12, FALSE) -> 7 | G24: =if(F24=7, F24/7*10, (F24+1)/7*10) -> 10 | H24: =ceiling(E24*6/10 + G24*4/10, 0.5) -> 8 | I24: =if(F24=7,0.5,"") -> 0.5 | J24: =VLOOKUP(B24,'Tính Điểm thi cuối kỳ'!$B$2:$J$47,9, FALSE) -> 9 | K24: =J24+I24 -> 9.5 | L24: =(H24*0.3) +(K24*0.7) -> 9.05 | M24: =IF((L24<4), "Tạch", "Đạt") -> Đạt | N24: =IF((L24<4),"F", if((L24<5),"D",IF((L24<5.5),"D+",IF((L24<6.5),"C",IF((L24<7),"C+",IF((L24<8),"B",IF((L24<8.5),"B+","A"))))))) -> A | O24: =IF((N24="F"),(4-L24),IF((N24="D"),(5-L24),IF((N24="D+"),(5.5-L24),IF((N24="C"),(6.5-L24),IF((N24="C+"),(7-L24),IF((N24="B"),(8-L24),IF((N24="B+"),(8.5-L24),"Đã bị điểm A -> Không <nâng> đỡ đc nữa"))))))) -> Đã bị điểm A -> Không <nâng> đỡ đc nữa | P24: =if((O24<=0.201),( O24/0.6),"") | Q24: =ceiling(if((P24>0),(K24+P24),K24),0.5) -> 9.5 | R24: =(H24*0.3)+(Q24*0.7) -> 9.05 | S24: =if((P24>0), IF((R24<4),"F", if((R24<5),"D",IF((R24<5.5),"D+",IF((R24<6.5),"C",IF((R24<7),"C+",IF((R24<8),"B",IF((R24<8.5),"B+","A"))))))), "") -> A | T24: =if((S24=N24),"","Đã được nâng điểm chữ")
A25: 23 | B25: 1538660 | C25: Nguyễn Mỹ Linh | D25: 60PM1 | E25: =VLOOKUP(B25,'Điểm giữa kỳ'!$B$2:$G$85,6, false) -> 8 | F25: =VLOOKUP(B25,'Điểm danh'!$B$2:$M$47,12, FALSE) -> 7 | G25: =if(F25=7, F25/7*10, (F25+1)/7*10) -> 10 | H25: =ceiling(E25*6/10 + G25*4/10, 0.5) -> 9 | I25: =if(F25=7,0.5,"") -> 0.5 | J25: =VLOOKUP(B25,'Tính Điểm thi cuối kỳ'!$B$2:$J$47,9, FALSE) -> 6 | K25: =J25+I25 -> 6.5 | L25: =(H25*0.3) +(K25*0.7) -> 7.25 | M25: =IF((L25<4), "Tạch", "Đạt") -> Đạt | N25: =IF((L25<4),"F", if((L25<5),"D",IF((L25<5.5),"D+",IF((L25<6.5),"C",IF((L25<7),"C+",IF((L25<8),"B",IF((L25<8.5),"B+","A"))))))) -> B | O25: =IF((N25="F"),(4-L25),IF((N25="D"),(5-L25),IF((N25="D+"),(5.5-L25),IF((N25="C"),(6.5-L25),IF((N25="C+"),(7-L25),IF((N25="B"),(8-L25),IF((N25="B+"),(8.5-L25),"Đã bị điểm A -> Không <nâng> đỡ đc nữa"))))))) -> 0.75 | P25: =if((O25<=0.201),( O25/0.6),"") | Q25: =ceiling(if((P25>0),(K25+P25),K25),0.5) -> 6.5 | R25: =(H25*0.3)+(Q25*0.7) -> 7.25 | S25: =if((P25>0), IF((R25<4),"F", if((R25<5),"D",IF((R25<5.5),"D+",IF((R25<6.5),"C",IF((R25<7),"C+",IF((R25<8),"B",IF((R25<8.5),"B+","A"))))))), "") -> B | T25: =if((S25=N25),"","Đã được nâng điểm chữ")
A26: 24 | B26: 1520260 | C26: Nguyễn Thành Long | D26: 60PM1 | E26: =VLOOKUP(B26,'Điểm giữa kỳ'!$B$2:$G$85,6, false) -> 6 | F26: =VLOOKUP(B26,'Điểm danh'!$B$2:$M$47,12, FALSE) -> 7 | G26: =if(F26=7, F26/7*10, (F26+1)/7*10) -> 10 | H26: =ceiling(E26*6/10 + G26*4/10, 0.5) -> 8 | I26: =if(F26=7,0.5,"") -> 0.5 | J26: =VLOOKUP(B26,'Tính Điểm thi cuối kỳ'!$B$2:$J$47,9, FALSE) -> 5 | K26: =J26+I26 -> 5.5 | L26: =(H26*0.3) +(K26*0.7) -> 6.25 | M26: =IF((L26<4), "Tạch", "Đạt") -> Đạt | N26: =IF((L26<4),"F", if((L26<5),"D",IF((L26<5.5),"D+",IF((L26<6.5),"C",IF((L26<7),"C+",IF((L26<8),"B",IF((L26<8.5),"B+","A"))))))) -> C | O26: =IF((N26="F"),(4-L26),IF((N26="D"),(5-L26),IF((N26="D+"),(5.5-L26),IF((N26="C"),(6.5-L26),IF((N26="C+"),(7-L26),IF((N26="B"),(8-L26),IF((N26="B+"),(8.5-L26),"Đã bị điểm A -> Không <nâng> đỡ đc nữa"))))))) -> 0.25 | P26: =if((O26<=0.201),( O26/0.6),"") | Q26: =ceiling(if((P26>0),(K26+P26),K26),0.5) -> 5.5 | R26: =(H26*0.3)+(Q26*0.7) -> 6.25 | S26: =if((P26>0), IF((R26<4),"F", if((R26<5),"D",IF((R26<5.5),"D+",IF((R26<6.5),"C",IF((R26<7),"C+",IF((R26<8),"B",IF((R26<8.5),"B+","A"))))))), "") -> C | T26: =if((S26=N26),"","Đã được nâng điểm chữ")
A27: 25 | B27: 119160 | C27: Ngô Văn Luân | D27: 60PM1 | E27: =VLOOKUP(B27,'Điểm giữa kỳ'!$B$2:$G$85,6, false) -> 8.5 | F27: =VLOOKUP(B27,'Điểm danh'!$B$2:$M$47,12, FALSE) -> 7 | G27: =if(F27=7, F27/7*10, (F27+1)/7*10) -> 10 | H27: =ceiling(E27*6/10 + G27*4/10, 0.5) -> 9.5 | I27: =if(F27=7,0.5,"") -> 0.5 | J27: =VLOOKUP(B27,'Tính Điểm thi cuối kỳ'!$B$2:$J$47,9, FALSE) -> 5.5 | K27: =J27+I27 -> 6 | L27: =(H27*0.3) +(K27*0.7) -> 7.05 | M27: =IF((L27<4), "Tạch", "Đạt") -> Đạt | N27: =IF((L27<4),"F", if((L27<5),"D",IF((L27<5.5),"D+",IF((L27<6.5),"C",IF((L27<7),"C+",IF((L27<8),"B",IF((L27<8.5),"B+","A"))))))) -> B | O27: =IF((N27="F"),(4-L27),IF((N27="D"),(5-L27),IF((N27="D+"),(5.5-L27),IF((N27="C"),(6.5-L27),IF((N27="C+"),(7-L27),IF((N27="B"),(8-L27),IF((N27="B+"),(8.5-L27),"Đã bị điểm A -> Không <nâng> đỡ đc nữa"))))))) -> 0.95 | P27: =if((O27<=0.201),( O27/0.6),"") | Q27: =ceiling(if((P27>0),(K27+P27),K27),0.5) -> 6 | R27: =(H27*0.3)+(Q27*0.7) -> 7.05 | S27: =if((P27>0), IF((R27<4),"F", if((R27<5),"D",IF((R27<5.5),"D+",IF((R27<6.5),"C",IF((R27<7),"C+",IF((R27<8),"B",IF((R27<8.5),"B+","A"))))))), "") -> B | T27: =if((S27=N27),"","Đã được nâng điểm chữ")
A28: 26 | B28: 1531460 | C28: Đào Quang Minh | D28: 60PM1 | E28: =VLOOKUP(B28,'Điểm giữa kỳ'!$B$2:$G$85,6, false) -> 7.5 | F28: =VLOOKUP(B28,'Điểm danh'!$B$2:$M$47,12, FALSE) -> 7 | G28: =if(F28=7, F28/7*10, (F28+1)/7*10) -> 10 | H28: =ceiling(E28*6/10 + G28*4/10, 0.5) -> 8.5 | I28: =if(F28=7,0.5,"") -> 0.5 | J28: =VLOOKUP(B28,'Tính Điểm thi cuối kỳ'!$B$2:$J$47,9, FALSE) -> 4.5 | K28: =J28+I28 -> 5 | L28: =(H28*0.3) +(K28*0.7) -> 6.05 | M28: =IF((L28<4), "Tạch", "Đạt") -> Đạt | N28: =IF((L28<4),"F", if((L28<5),"D",IF((L28<5.5),"D+",IF((L28<6.5),"C",IF((L28<7),"C+",IF((L28<8),"B",IF((L28<8.5),"B+","A"))))))) -> C | O28: =IF((N28="F"),(4-L28),IF((N28="D"),(5-L28),IF((N28="D+"),(5.5-L28),IF((N28="C"),(6.5-L28),IF((N28="C+"),(7-L28),IF((N28="B"),(8-L28),IF((N28="B+"),(8.5-L28),"Đã bị điểm A -> Không <nâng> đỡ đc nữa"))))))) -> 0.45 | P28: =if((O28<=0.201),( O28/0.6),"") | Q28: =ceiling(if((P28>0),(K28+P28),K28),0.5) -> 5 | R28: =(H28*0.3)+(Q28*0.7) -> 6.05 | S28: =if((P28>0), IF((R28<4),"F", if((R28<5),"D",IF((R28<5.5),"D+",IF((R28<6.5),"C",IF((R28<7),"C+",IF((R28<8),"B",IF((R28<8.5),"B+","A"))))))), "") -> C | T28: =if((S28=N28),"","Đã được nâng điểm chữ")
A29: 27 | B29: 125960 | C29: Phạm Văn Minh | D29: 60PM1 | E29: =VLOOKUP(B29,'Điểm giữa kỳ'!$B$2:$G$85,6, false) -> 5 | F29: =VLOOKUP(B29,'Điểm danh'!$B$2:$M$47,12, FALSE) -> 5 | G29: =if(F29=7, F29/7*10, (F29+1)/7*10) -> 8.5714286 | H29: =ceiling(E29*6/10 + G29*4/10, 0.5) -> 6.5 | I29: =if(F29=7,0.5,"") | J29: =VLOOKUP(B29,'Tính Điểm thi cuối kỳ'!$B$2:$J$47,9, FALSE) -> 6 | K29: =J29+I29 -> 6 | L29: =(H29*0.3) +(K29*0.7) -> 6.15 | M29: =IF((L29<4), "Tạch", "Đạt") -> Đạt | N29: =IF((L29<4),"F", if((L29<5),"D",IF((L29<5.5),"D+",IF((L29<6.5),"C",IF((L29<7),"C+",IF((L29<8),"B",IF((L29<8.5),"B+","A"))))))) -> C | O29: =IF((N29="F"),(4-L29),IF((N29="D"),(5-L29),IF((N29="D+"),(5.5-L29),IF((N29="C"),(6.5-L29),IF((N29="C+"),(7-L29),IF((N29="B"),(8-L29),IF((N29="B+"),(8.5-L29),"Đã bị điểm A -> Không <nâng> đỡ đc nữa"))))))) -> 0.35 | P29: =if((O29<=0.201),( O29/0.6),"") | Q29: =ceiling(if((P29>0),(K29+P29),K29),0.5) -> 6 | R29: =(H29*0.3)+(Q29*0.7) -> 6.15 | S29: =if((P29>0), IF((R29<4),"F", if((R29<5),"D",IF((R29<5.5),"D+",IF((R29<6.5),"C",IF((R29<7),"C+",IF((R29<8),"B",IF((R29<8.5),"B+","A"))))))), "") -> C | T29: =if((S29=N29),"","Đã được nâng điểm chữ")
A30: 28 | B30: 1536260 | C30: Huỳnh Hoàng Nam | D30: 60PM1 | E30: =VLOOKUP(B30,'Điểm giữa kỳ'!$B$2:$G$85,6, false) | F30: =VLOOKUP(B30,'Điểm danh'!$B$2:$M$47,12, FALSE) -> 3 | G30: =if(F30=7, F30/7*10, (F30+1)/7*10) -> 5.7142857 | H30: =ceiling(E30*6/10 + G30*4/10, 0.5) -> 2.5 | I30: =if(F30=7,0.5,"") | J30: =VLOOKUP(B30,'Tính Điểm thi cuối kỳ'!$B$2:$J$47,9, FALSE) -> 1 | K30: =J30+I30 -> 1 | L30: =(H30*0.3) +(K30*0.7) -> 1.45 | M30: =IF((L30<4), "Tạch", "Đạt") -> Tạch | N30: =IF((L30<4),"F", if((L30<5),"D",IF((L30<5.5),"D+",IF((L30<6.5),"C",IF((L30<7),"C+",IF((L30<8),"B",IF((L30<8.5),"B+","A"))))))) -> F | O30: =IF((N30="F"),(4-L30),IF((N30="D"),(5-L30),IF((N30="D+"),(5.5-L30),IF((N30="C"),(6.5-L30),IF((N30="C+"),(7-L30),IF((N30="B"),(8-L30),IF((N30="B+"),(8.5-L30),"Đã bị điểm A -> Không <nâng> đỡ đc nữa"))))))) -> 2.55 | P30: =if((O30<=0.201),( O30/0.6),"") | Q30: =ceiling(if((P30>0),(K30+P30),K30),0.5) -> 1 | R30: =(H30*0.3)+(Q30*0.7) -> 1.45 | S30: =if((P30>0), IF((R30<4),"F", if((R30<5),"D",IF((R30<5.5),"D+",IF((R30<6.5),"C",IF((R30<7),"C+",IF((R30<8),"B",IF((R30<8.5),"B+","A"))))))), "") -> F | T30: BỎ THI GK
A31: 29 | B31: 1531360 | C31: Nguyễn Sơn Nam | D31: 60PM1 | E31: =VLOOKUP(B31,'Điểm giữa kỳ'!$B$2:$G$85,6, false) | F31: =VLOOKUP(B31,'Điểm danh'!$B$2:$M$47,12, FALSE) -> 0 | G31: =if(F31=7, F31/7*10, (F31+1)/7*10) -> 1.4285714 | H31: =ceiling(E31*6/10 + G31*4/10, 0.5) -> 1 | I31: =if(F31=7,0.5,"") | J31: =VLOOKUP(B31,'Tính Điểm thi cuối kỳ'!$B$2:$J$47,9, FALSE) | K31: =J31+I31 -> 0 | L31: =(H31*0.3) +(K31*0.7) -> 0.3 | M31: =IF((L31<4), "Tạch", "Đạt") -> Tạch | N31: =IF((L31<4),"F", if((L31<5),"D",IF((L31<5.5),"D+",IF((L31<6.5),"C",IF((L31<7),"C+",IF((L31<8),"B",IF((L31<8.5),"B+","A"))))))) -> F | O31: =IF((N31="F"),(4-L31),IF((N31="D"),(5-L31),IF((N31="D+"),(5.5-L31),IF((N31="C"),(6.5-L31),IF((N31="C+"),(7-L31),IF((N31="B"),(8-L31),IF((N31="B+"),(8.5-L31),"Đã bị điểm A -> Không <nâng> đỡ đc nữa"))))))) -> 3.7 | P31: =if((O31<=0.201),( O31/0.6),"") | Q31: =ceiling(if((P31>0),(K31+P31),K31),0.5) -> 0 | R31: =(H31*0.3)+(Q31*0.7) -> 0.3 | S31: =if((P31>0), IF((R31<4),"F", if((R31<5),"D",IF((R31<5.5),"D+",IF((R31<6.5),"C",IF((R31<7),"C+",IF((R31<8),"B",IF((R31<8.5),"B+","A"))))))), "") -> F | T31: BỎ HỌC, BỎ THI
A32: 30 | B32: 1540760 | C32: Mai Thị Kim Ngân | D32: 60PM1 | E32: =VLOOKUP(B32,'Điểm giữa kỳ'!$B$2:$G$85,6, false) -> 8.5 | F32: =VLOOKUP(B32,'Điểm danh'!$B$2:$M$47,12, FALSE) -> 7 | G32: =if(F32=7, F32/7*10, (F32+1)/7*10) -> 10 | H32: =ceiling(E32*6/10 + G32*4/10, 0.5) -> 9.5 | I32: =if(F32=7,0.5,"") -> 0.5 | J32: =VLOOKUP(B32,'Tính Điểm thi cuối kỳ'!$B$2:$J$47,9, FALSE) -> 7 | K32: =J32+I32 -> 7.5 | L32: =(H32*0.3) +(K32*0.7) -> 8.1 | M32: =IF((L32<4), "Tạch", "Đạt") -> Đạt | N32: =IF((L32<4),"F", if((L32<5),"D",IF((L32<5.5),"D+",IF((L32<6.5),"C",IF((L32<7),"C+",IF((L32<8),"B",IF((L32<8.5),"B+","A"))))))) -> B+ | O32: =IF((N32="F"),(4-L32),IF((N32="D"),(5-L32),IF((N32="D+"),(5.5-L32),IF((N32="C"),(6.5-L32),IF((N32="C+"),(7-L32),IF((N32="B"),(8-L32),IF((N32="B+"),(8.5-L32),"Đã bị điểm A -> Không <nâng> đỡ đc nữa"))))))) -> 0.4 | P32: =if((O32<=0.201),( O32/0.6),"") | Q32: =ceiling(if((P32>0),(K32+P32),K32),0.5) -> 7.5 | R32: =(H32*0.3)+(Q32*0.7) -> 8.1 | S32: =if((P32>0), IF((R32<4),"F", if((R32<5),"D",IF((R32<5.5),"D+",IF((R32<6.5),"C",IF((R32<7),"C+",IF((R32<8),"B",IF((R32<8.5),"B+","A"))))))), "") -> B+ | T32: =if((S32=N32),"","Đã được nâng điểm chữ")
A33: 31 | B33: 150160 | C33: Đỗ Văn Phiêu | D33: 60PM1 | E33: =VLOOKUP(B33,'Điểm giữa kỳ'!$B$2:$G$85,6, false) -> 4.5 | F33: =VLOOKUP(B33,'Điểm danh'!$B$2:$M$47,12, FALSE) -> 2.5 | G33: =if(F33=7, F33/7*10, (F33+1)/7*10) -> 5 | H33: =ceiling(E33*6/10 + G33*4/10, 0.5) -> 5 | I33: =if(F33=7,0.5,"") | J33: =VLOOKUP(B33,'Tính Điểm thi cuối kỳ'!$B$2:$J$47,9, FALSE) -> 4 | K33: =J33+I33 -> 4 | L33: =(H33*0.3) +(K33*0.7) -> 4.3 | M33: =IF((L33<4), "Tạch", "Đạt") -> Đạt | N33: =IF((L33<4),"F", if((L33<5),"D",IF((L33<5.5),"D+",IF((L33<6.5),"C",IF((L33<7),"C+",IF((L33<8),"B",IF((L33<8.5),"B+","A"))))))) -> D | O33: =IF((N33="F"),(4-L33),IF((N33="D"),(5-L33),IF((N33="D+"),(5.5-L33),IF((N33="C"),(6.5-L33),IF((N33="C+"),(7-L33),IF((N33="B"),(8-L33),IF((N33="B+"),(8.5-L33),"Đã bị điểm A -> Không <nâng> đỡ đc nữa"))))))) -> 0.7 | P33: =if((O33<=0.201),( O33/0.6),"") | Q33: =ceiling(if((P33>0),(K33+P33),K33),0.5) -> 4 | R33: =(H33*0.3)+(Q33*0.7) -> 4.3 | S33: =if((P33>0), IF((R33<4),"F", if((R33<5),"D",IF((R33<5.5),"D+",IF((R33<6.5),"C",IF((R33<7),"C+",IF((R33<8),"B",IF((R33<8.5),"B+","A"))))))), "") -> D | T33: =if((S33=N33),"","Đã được nâng điểm chữ")
A34: 32 | B34: 212360 | C34: Nguyễn Viết Quân | D34: 60PM1 | E34: =VLOOKUP(B34,'Điểm giữa kỳ'!$B$2:$G$85,6, false) -> 6 | F34: =VLOOKUP(B34,'Điểm danh'!$B$2:$M$47,12, FALSE) -> 7 | G34: =if(F34=7, F34/7*10, (F34+1)/7*10) -> 10 | H34: =ceiling(E34*6/10 + G34*4/10, 0.5) -> 8 | I34: =if(F34=7,0.5,"") -> 0.5 | J34: =VLOOKUP(B34,'Tính Điểm thi cuối kỳ'!$B$2:$J$47,9, FALSE) -> 8.5 | K34: =J34+I34 -> 9 | L34: =(H34*0.3) +(K34*0.7) -> 8.7 | M34: =IF((L34<4), "Tạch", "Đạt") -> Đạt | N34: =IF((L34<4),"F", if((L34<5),"D",IF((L34<5.5),"D+",IF((L34<6.5),"C",IF((L34<7),"C+",IF((L34<8),"B",IF((L34<8.5),"B+","A"))))))) -> A | O34: =IF((N34="F"),(4-L34),IF((N34="D"),(5-L34),IF((N34="D+"),(5.5-L34),IF((N34="C"),(6.5-L34),IF((N34="C+"),(7-L34),IF((N34="B"),(8-L34),IF((N34="B+"),(8.5-L34),"Đã bị điểm A -> Không <nâng> đỡ đc nữa"))))))) -> Đã bị điểm A -> Không <nâng> đỡ đc nữa | P34: =if((O34<=0.201),( O34/0.6),"") | Q34: =ceiling(if((P34>0),(K34+P34),K34),0.5) -> 9 | R34: =(H34*0.3)+(Q34*0.7) -> 8.7 | S34: =if((P34>0), IF((R34<4),"F", if((R34<5),"D",IF((R34<5.5),"D+",IF((R34<6.5),"C",IF((R34<7),"C+",IF((R34<8),"B",IF((R34<8.5),"B+","A"))))))), "") -> A | T34: =if((S34=N34),"","Đã được nâng điểm chữ")
A35: 33 | B35: 134760 | C35: Phạm Văn Tâm | D35: 60PM1 | E35: =VLOOKUP(B35,'Điểm giữa kỳ'!$B$2:$G$85,6, false) -> 5 | F35: =VLOOKUP(B35,'Điểm danh'!$B$2:$M$47,12, FALSE) -> 6 | G35: =if(F35=7, F35/7*10, (F35+1)/7*10) -> 10 | H35: =ceiling(E35*6/10 + G35*4/10, 0.5) -> 7 | I35: =if(F35=7,0.5,"") | J35: =VLOOKUP(B35,'Tính Điểm thi cuối kỳ'!$B$2:$J$47,9, FALSE) -> 7 | K35: =J35+I35 -> 7 | L35: =(H35*0.3) +(K35*0.7) -> 7 | M35: =IF((L35<4), "Tạch", "Đạt") -> Đạt | N35: =IF((L35<4),"F", if((L35<5),"D",IF((L35<5.5),"D+",IF((L35<6.5),"C",IF((L35<7),"C+",IF((L35<8),"B",IF((L35<8.5),"B+","A"))))))) -> B | O35: =IF((N35="F"),(4-L35),IF((N35="D"),(5-L35),IF((N35="D+"),(5.5-L35),IF((N35="C"),(6.5-L35),IF((N35="C+"),(7-L35),IF((N35="B"),(8-L35),IF((N35="B+"),(8.5-L35),"Đã bị điểm A -> Không <nâng> đỡ đc nữa"))))))) -> 1 | P35: =if((O35<=0.201),( O35/0.6),"") | Q35: =ceiling(if((P35>0),(K35+P35),K35),0.5) -> 7 | R35: =(H35*0.3)+(Q35*0.7) -> 7 | S35: =if((P35>0), IF((R35<4),"F", if((R35<5),"D",IF((R35<5.5),"D+",IF((R35<6.5),"C",IF((R35<7),"C+",IF((R35<8),"B",IF((R35<8.5),"B+","A"))))))), "") -> B | T35: =if((S35=N35),"","Đã được nâng điểm chữ")
A36: 34 | B36: 209460 | C36: Nguyễn Thanh Thản | D36: 60PM1 | E36: =VLOOKUP(B36,'Điểm giữa kỳ'!$B$2:$G$85,6, false) -> 4 | F36: =VLOOKUP(B36,'Điểm danh'!$B$2:$M$47,12, FALSE) -> 7 | G36: =if(F36=7, F36/7*10, (F36+1)/7*10) -> 10 | H36: =ceiling(E36*6/10 + G36*4/10, 0.5) -> 6.5 | I36: =if(F36=7,0.5,"") -> 0.5 | J36: =VLOOKUP(B36,'Tính Điểm thi cuối kỳ'!$B$2:$J$47,9, FALSE) -> 4.5 | K36: =J36+I36 -> 5 | L36: =(H36*0.3) +(K36*0.7) -> 5.45 | M36: =IF((L36<4), "Tạch", "Đạt") -> Đạt | N36: =IF((L36<4),"F", if((L36<5),"D",IF((L36<5.5),"D+",IF((L36<6.5),"C",IF((L36<7),"C+",IF((L36<8),"B",IF((L36<8.5),"B+","A"))))))) -> D+ | O36: =IF((N36="F"),(4-L36),IF((N36="D"),(5-L36),IF((N36="D+"),(5.5-L36),IF((N36="C"),(6.5-L36),IF((N36="C+"),(7-L36),IF((N36="B"),(8-L36),IF((N36="B+"),(8.5-L36),"Đã bị điểm A -> Không <nâng> đỡ đc nữa"))))))) -> 0.05 | P36: =if((O36<=0.201),( O36/0.6),"") -> 0.083333333 | Q36: =ceiling(if((P36>0),(K36+P36),K36),0.5) -> 5.5 | R36: =(H36*0.3)+(Q36*0.7) -> 5.8 | S36: =if((P36>0), IF((R36<4),"F", if((R36<5),"D",IF((R36<5.5),"D+",IF((R36<6.5),"C",IF((R36<7),"C+",IF((R36<8),"B",IF((R36<8.5),"B+","A"))))))), "") -> C | T36: =if((S36=N36),"","Đã được nâng điểm chữ") -> Đã được nâng điểm chữ
A37: 35 | B37: 92760 | C37: Nguyễn Quốc Thắng | D37: 60PM1 | E37: =VLOOKUP(B37,'Điểm giữa kỳ'!$B$2:$G$85,6, false) -> 3 | F37: =VLOOKUP(B37,'Điểm danh'!$B$2:$M$47,12, FALSE) -> 7 | G37: =if(F37=7, F37/7*10, (F37+1)/7*10) -> 10 | H37: =ceiling(E37*6/10 + G37*4/10, 0.5) -> 6 | I37: =if(F37=7,0.5,"") -> 0.5 | J37: =VLOOKUP(B37,'Tính Điểm thi cuối kỳ'!$B$2:$J$47,9, FALSE) -> 4 | K37: =J37+I37 -> 4.5 | L37: =(H37*0.3) +(K37*0.7) -> 4.95 | M37: =IF((L37<4), "Tạch", "Đạt") -> Đạt | N37: =IF((L37<4),"F", if((L37<5),"D",IF((L37<5.5),"D+",IF((L37<6.5),"C",IF((L37<7),"C+",IF((L37<8),"B",IF((L37<8.5),"B+","A"))))))) -> D | O37: =IF((N37="F"),(4-L37),IF((N37="D"),(5-L37),IF((N37="D+"),(5.5-L37),IF((N37="C"),(6.5-L37),IF((N37="C+"),(7-L37),IF((N37="B"),(8-L37),IF((N37="B+"),(8.5-L37),"Đã bị điểm A -> Không <nâng> đỡ đc nữa"))))))) -> 0.05 | P37: =if((O37<=0.201),( O37/0.6),"") -> 0.083333333 | Q37: =ceiling(if((P37>0),(K37+P37),K37),0.5) -> 5 | R37: =(H37*0.3)+(Q37*0.7) -> 5.3 | S37: =if((P37>0), IF((R37<4),"F", if((R37<5),"D",IF((R37<5.5),"D+",IF((R37<6.5),"C",IF((R37<7),"C+",IF((R37<8),"B",IF((R37<8.5),"B+","A"))))))), "") -> D+ | T37: =if((S37=N37),"","Đã được nâng điểm chữ") -> Đã được nâng điểm chữ
A38: 36 | B38: 1537160 | C38: Trần Hữu Tòng | D38: 60PM1 | E38: =VLOOKUP(B38,'Điểm giữa kỳ'!$B$2:$G$85,6, false) -> 6.5 | F38: =VLOOKUP(B38,'Điểm danh'!$B$2:$M$47,12, FALSE) -> 1 | G38: =if(F38=7, F38/7*10, (F38+1)/7*10) -> 2.8571429 | H38: =ceiling(E38*6/10 + G38*4/10, 0.5) -> 5.5 | I38: =if(F38=7,0.5,"") | J38: =VLOOKUP(B38,'Tính Điểm thi cuối kỳ'!$B$2:$J$47,9, FALSE) -> 6 | K38: =J38+I38 -> 6 | L38: =(H38*0.3) +(K38*0.7) -> 5.85 | M38: =IF((L38<4), "Tạch", "Đạt") -> Đạt | N38: =IF((L38<4),"F", if((L38<5),"D",IF((L38<5.5),"D+",IF((L38<6.5),"C",IF((L38<7),"C+",IF((L38<8),"B",IF((L38<8.5),"B+","A"))))))) -> C | O38: =IF((N38="F"),(4-L38),IF((N38="D"),(5-L38),IF((N38="D+"),(5.5-L38),IF((N38="C"),(6.5-L38),IF((N38="C+"),(7-L38),IF((N38="B"),(8-L38),IF((N38="B+"),(8.5-L38),"Đã bị điểm A -> Không <nâng> đỡ đc nữa"))))))) -> 0.65 | P38: =if((O38<=0.201),( O38/0.6),"") | Q38: =ceiling(if((P38>0),(K38+P38),K38),0.5) -> 6 | R38: =(H38*0.3)+(Q38*0.7) -> 5.85 | S38: =if((P38>0), IF((R38<4),"F", if((R38<5),"D",IF((R38<5.5),"D+",IF((R38<6.5),"C",IF((R38<7),"C+",IF((R38<8),"B",IF((R38<8.5),"B+","A"))))))), "") -> C | T38: =if((S38=N38),"","Đã được nâng điểm chữ")
A39: 37 | B39: 1509760 | C39: Đặng Trường Trúc | D39: 60PM1 | E39: =VLOOKUP(B39,'Điểm giữa kỳ'!$B$2:$G$85,6, false) -> 7.5 | F39: =VLOOKUP(B39,'Điểm danh'!$B$2:$M$47,12, FALSE) -> 6 | G39: =if(F39=7, F39/7*10, (F39+1)/7*10) -> 10 | H39: =ceiling(E39*6/10 + G39*4/10, 0.5) -> 8.5 | I39: =if(F39=7,0.5,"") | J39: =VLOOKUP(B39,'Tính Điểm thi cuối kỳ'!$B$2:$J$47,9, FALSE) -> 6 | K39: =J39+I39 -> 6 | L39: =(H39*0.3) +(K39*0.7) -> 6.75 | M39: =IF((L39<4), "Tạch", "Đạt") -> Đạt | N39: =IF((L39<4),"F", if((L39<5),"D",IF((L39<5.5),"D+",IF((L39<6.5),"C",IF((L39<7),"C+",IF((L39<8),"B",IF((L39<8.5),"B+","A"))))))) -> C+ | O39: =IF((N39="F"),(4-L39),IF((N39="D"),(5-L39),IF((N39="D+"),(5.5-L39),IF((N39="C"),(6.5-L39),IF((N39="C+"),(7-L39),IF((N39="B"),(8-L39),IF((N39="B+"),(8.5-L39),"Đã bị điểm A -> Không <nâng> đỡ đc nữa"))))))) -> 0.25 | P39: =if((O39<=0.201),( O39/0.6),"") | Q39: =ceiling(if((P39>0),(K39+P39),K39),0.5) -> 6 | R39: =(H39*0.3)+(Q39*0.7) -> 6.75 | S39: =if((P39>0), IF((R39<4),"F", if((R39<5),"D",IF((R39<5.5),"D+",IF((R39<6.5),"C",IF((R39<7),"C+",IF((R39<8),"B",IF((R39<8.5),"B+","A"))))))), "") -> C+ | T39: =if((S39=N39),"","Đã được nâng điểm chữ")
A40: 38 | B40: 1535760 | C40: Phạm Ngọc Trung | D40: 60PM1 | E40: =VLOOKUP(B40,'Điểm giữa kỳ'!$B$2:$G$85,6, false) -> 6 | F40: =VLOOKUP(B40,'Điểm danh'!$B$2:$M$47,12, FALSE) -> 7 | G40: =if(F40=7, F40/7*10, (F40+1)/7*10) -> 10 | H40: =ceiling(E40*6/10 + G40*4/10, 0.5) -> 8 | I40: =if(F40=7,0.5,"") -> 0.5 | J40: =VLOOKUP(B40,'Tính Điểm thi cuối kỳ'!$B$2:$J$47,9, FALSE) -> 5.5 | K40: =J40+I40 -> 6 | L40: =(H40*0.3) +(K40*0.7) -> 6.6 | M40: =IF((L40<4), "Tạch", "Đạt") -> Đạt | N40: =IF((L40<4),"F", if((L40<5),"D",IF((L40<5.5),"D+",IF((L40<6.5),"C",IF((L40<7),"C+",IF((L40<8),"B",IF((L40<8.5),"B+","A"))))))) -> C+ | O40: =IF((N40="F"),(4-L40),IF((N40="D"),(5-L40),IF((N40="D+"),(5.5-L40),IF((N40="C"),(6.5-L40),IF((N40="C+"),(7-L40),IF((N40="B"),(8-L40),IF((N40="B+"),(8.5-L40),"Đã bị điểm A -> Không <nâng> đỡ đc nữa"))))))) -> 0.4 | P40: =if((O40<=0.201),( O40/0.6),"") | Q40: =ceiling(if((P40>0),(K40+P40),K40),0.5) -> 6 | R40: =(H40*0.3)+(Q40*0.7) -> 6.6 | S40: =if((P40>0), IF((R40<4),"F", if((R40<5),"D",IF((R40<5.5),"D+",IF((R40<6.5),"C",IF((R40<7),"C+",IF((R40<8),"B",IF((R40<8.5),"B+","A"))))))), "") -> C+ | T40: =if((S40=N40),"","Đã được nâng điểm chữ")
...

Sheet Điểm giữa kỳ
A1: TT | B1: Số báo danh | C1: Họ tên | D1: Mã đề thi | E1: Lớp | F1: Điểm thô | G1: Điểm GK Quy đổi
A2: 1 | B2: 111060 | C2: Nguyễn Văn Hĩu | D2: CT_01 | E2: 60PM1 | F2: 10 | G2: 5
A3: 2 | B3: 112360 | C3: Trần Văn Hoạt | D3: CT_02 | E3: 60PM2 | F3: 15 | G3: 7.5
A4: 3 | B4: 117960 | C4: Phạm Văn Tình | D4: CT_03 | E4: 60PM2 | F4: 13 | G4: 6.5
A5: 4 | B5: 119160 | C5: Ngô Văn Luân | D5: CT_04 | E5: 60PM1 | F5: 17 | G5: 8.5
A6: 5 | B6: 122760 | C6: Phan Bá Tuyến | D6: CT_05 | E6: 60PM1 | F6: 15 | G6: 7.5
A7: 6 | B7: 125960 | C7: Phạm Văn Minh | D7: CT_06 | E7: 60PM1 | F7: 10 | G7: 5
A8: 7 | B8: 127160 | C8: Lê Đức Giáp | D8: CT_07 | E8: 60PM1 | F8: 16 | G8: 8
A9: 8 | B9: 130260 | C9: Trần Văn Hiếu | D9: CT_08 | E9: 60PM1 | F9: 13 | G9: 6.5
A10: 9 | B10: 134760 | C10: Phạm Văn Tâm | D10: CT_09 | E10: 60PM1 | F10: 10 | G10: 5
A11: 10 | B11: 147860 | C11: Phạm Thanh Dương | D11: CT_10 | E11: 60PM2 | F11: 14 | G11: 7
A12: 11 | B12: 150160 | C12: Đỗ Văn Phiêu | D12: CT_11 | E12: 60PM1 | F12: 9 | G12: 4.5
A13: 12 | B13: 1503561 | C13: Nguyễn Tuấn Anh | D13: CT_12 | E13: 61PM1
A14: 13 | B14: 1504360 | C14: Nguyễn Mạnh Hưng | D14: CT_13 | E14: 60PM2 | F14: 10 | G14: 5
A15: 14 | B15: 1504559 | C15: Hà Bảo Khánh | D15: CT_14 | E15: 59PM1
A16: 15 | B16: 1506060 | C16: Nguyễn Anh Tú | D16: CT_15 | E16: 60PM2 | F16: 12 | G16: 6
A17: 16 | B17: 1506257 | C17: Nguyễn Hải Hà | D17: CT_16 | E17: 57PM2
A18: 17 | B18: 1506260 | C18: Nguyễn Văn Đạt | D18: CT_17 | E18: 60PM1 | F18: 17 | G18: 8.5
A19: 18 | B19: 1506357 | C19: Vũ Minh Hoàng | D19: CT_18 | E19: 57PM2 | F19: 12 | G19: 6
A20: 19 | B20: 1509760 | C20: Đặng Trường Trúc | D20: CT_19 | E20: 60PM1 | F20: 15 | G20: 7.5
A21: 20 | B21: 1510560 | C21: Trần Văn Tuấn | D21: CT_22 | E21: 60PM1 | F21: 14 | G21: 7
A22: 21 | B22: 1511460 | C22: Phạm Ngọc Huy | D22: CT_23 | E22: 60PM1 | F22: 16 | G22: 8
A23: 22 | B23: 1511560 | C23: Nguyễn Hữu Thọ | D23: CT_24 | E23: 60PM2 | F23: 10 | G23: 5
A24: 23 | B24: 1512160 | C24: Cao Thành Trung | D24: CT_25 | E24: 60PM2 | F24: 15 | G24: 7.5
A25: 24 | B25: 1512660 | C25: Lại Hoàng Lê | D25: CT_26 | E25: 60PM1 | F25: 18 | G25: 9
A26: 25 | B26: 1513460 | C26: Đoàn Việt Anh | D26: CT_27 | E26: 60PM1
A27: 26 | B27: 1518860 | C27: Nguyễn Hữu Hoàng | D27: CT_28 | E27: 60PM1 | F27: 15 | G27: 7.5
A28: 27 | B28: 1519760 | C28: Nguyễn Kim Lâm | D28: CT_29 | E28: 60PM1 | F28: 15 | G28: 7.5
A29: 28 | B29: 1520260 | C29: Nguyễn Thành Long | D29: CT_33 | E29: 60PM1 | F29: 12 | G29: 6
A30: 29 | B30: 1521460 | C30: Đoàn Nhật Hưng | D30: CT_34 | E30: 60PM2
A31: 30 | B31: 1522860 | C31: Nguyễn Thị Hiền | D31: CT_35 | E31: 60PM2 | F31: 14 | G31: 7
A32: 31 | B32: 1523760 | C32: Đỗ Xuân Hưng | D32: CT_36 | E32: 60PM2 | F32: 14 | G32: 7
A33: 32 | B33: 1526460 | C33: Hoàng Thị Phương Hoa | D33: CT_37 | E33: 60PM2 | F33: 13 | G33: 6.5
A34: 33 | B34: 1529260 | C34: Nguyễn Thanh Luật | D34: CT_38 | E34: 60PM2 | F34: 13 | G34: 6.5
A35: 34 | B35: 1529460 | C35: Phạm Thanh Tùng | D35: CT_39 | E35: 60PM2 | F35: 15 | G35: 7.5
A36: 35 | B36: 1529660 | C36: Phan Thanh Mai | D36: CT_42 | E36: 60PM2 | F36: 9 | G36: 4.5
A37: 36 | B37: 1531360 | C37: Nguyễn Sơn Nam | D37: CT_43 | E37: 60PM1
A38: 37 | B38: 1531460 | C38: Đào Quang Minh | D38: CT_44 | E38: 60PM1 | F38: 15 | G38: 7.5
A39: 38 | B39: 1531660 | C39: Vũ Đức Thịnh | D39: CT_45 | E39: 60PM2 | F39: 11 | G39: 5.5
A40: 39 | B40: 1532660 | C40: Nguyễn Bảo Long | D40: CT_46 | E40: 60PM2 | F40: 16 | G40: 8
...

Sheet Bảng điểm chính thức
A1: STT | C1: Mã SV | D1: Họ và Tên | I1: Lớp Q.Lý | L1: ĐQT | O1: ĐKT | Q1: Ghi chú
A2: 1 | C2: 1513460 | D2: Đoàn Việt | F2: Anh | H2: 60PM1 | L2: =VLOOKUP(C2,Sheet1!$B$3:$H$44, 7, FALSE) -> 1 | O2: =VLOOKUP(C2, Sheet1!$B$3:$T$44, 16,FALSE) -> 0 | Q2: =VLOOKUP(C2, Sheet1!$B$3:$T$44, 19,FALSE) -> BỎ HỌC, BỎ THI
A3: 2 | C3: 1503561 | D3: Nguyễn Tuấn | F3: Anh | H3: 61PM1 | L3: =VLOOKUP(C3,Sheet1!$B$3:$H$44, 7, FALSE) -> 1 | O3: =VLOOKUP(C3, Sheet1!$B$3:$T$44, 16,FALSE) -> 0 | Q3: =VLOOKUP(C3, Sheet1!$B$3:$T$44, 19,FALSE) -> BỎ HỌC, BỎ THI
A4: 3 | C4: 1543960 | D4: Trần Xuân | F4: Ba | H4: 60PM1 | L4: =VLOOKUP(C4,Sheet1!$B$3:$H$44, 7, FALSE) -> 8.5 | O4: =VLOOKUP(C4, Sheet1!$B$3:$T$44, 16,FALSE) -> 5 | Q4: =VLOOKUP(C4, Sheet1!$B$3:$T$44, 19,FALSE)
A5: 4 | C5: 174860 | D5: Đoàn Quốc | F5: Bảo | H5: 60PM1 | L5: =VLOOKUP(C5,Sheet1!$B$3:$H$44, 7, FALSE) -> 5.5 | O5: =VLOOKUP(C5, Sheet1!$B$3:$T$44, 16,FALSE) -> 5.5 | Q5: =VLOOKUP(C5, Sheet1!$B$3:$T$44, 19,FALSE)
A6: 5 | C6: 9460 | D6: Nguyễn Mạnh | F6: Cường | H6: 60PM2 | L6: =VLOOKUP(C6,Sheet1!$B$3:$H$44, 7, FALSE) -> 8.5 | O6: =VLOOKUP(C6, Sheet1!$B$3:$T$44, 16,FALSE) -> 9.5 | Q6: =VLOOKUP(C6, Sheet1!$B$3:$T$44, 19,FALSE)
A7: 6 | C7: 1506260 | D7: Nguyễn Văn | F7: Đạt | H7: 60PM1 | L7: =VLOOKUP(C7,Sheet1!$B$3:$H$44, 7, FALSE) -> 9.5 | O7: =VLOOKUP(C7, Sheet1!$B$3:$T$44, 16,FALSE) -> 8.5 | Q7: =VLOOKUP(C7, Sheet1!$B$3:$T$44, 19,FALSE) -> Đã được nâng điểm chữ
A8: 7 | C8: 1547360 | D8: Đậu Viết | F8: Đức | H8: 60PM1 | L8: =VLOOKUP(C8,Sheet1!$B$3:$H$44, 7, FALSE) -> 7.5 | O8: =VLOOKUP(C8, Sheet1!$B$3:$T$44, 16,FALSE) -> 8.5 | Q8: =VLOOKUP(C8, Sheet1!$B$3:$T$44, 19,FALSE) -> Đã được nâng điểm chữ
A9: 8 | C9: 127160 | D9: Lê Đức | F9: Giáp | H9: 60PM1 | L9: =VLOOKUP(C9,Sheet1!$B$3:$H$44, 7, FALSE) -> 7.5 | O9: =VLOOKUP(C9, Sheet1!$B$3:$T$44, 16,FALSE) -> 4 | Q9: =VLOOKUP(C9, Sheet1!$B$3:$T$44, 19,FALSE)
A10: 9 | C10: 1533860 | D10: Lê Trung | F10: Hiếu | H10: 60PM1 | L10: =VLOOKUP(C10,Sheet1!$B$3:$H$44, 7, FALSE) -> 7.5 | O10: =VLOOKUP(C10, Sheet1!$B$3:$T$44, 16,FALSE) -> 2 | Q10: =VLOOKUP(C10, Sheet1!$B$3:$T$44, 19,FALSE)
A11: 10 | C11: 130260 | D11: Trần Văn | F11: Hiếu | H11: 60PM1 | L11: =VLOOKUP(C11,Sheet1!$B$3:$H$44, 7, FALSE) -> 8 | O11: =VLOOKUP(C11, Sheet1!$B$3:$T$44, 16,FALSE) -> 6 | Q11: =VLOOKUP(C11, Sheet1!$B$3:$T$44, 19,FALSE)
A12: 11 | C12: 111060 | D12: Nguyễn Văn | F12: Hĩu | H12: 60PM1 | L12: =VLOOKUP(C12,Sheet1!$B$3:$H$44, 7, FALSE) -> 7 | O12: =VLOOKUP(C12, Sheet1!$B$3:$T$44, 16,FALSE) -> 6.5 | Q12: =VLOOKUP(C12, Sheet1!$B$3:$T$44, 19,FALSE) -> Đã được nâng điểm chữ
A13: 12 | C13: 1518860 | D13: Nguyễn Hữu | F13: Hoàng | H13: 60PM1 | L13: =VLOOKUP(C13,Sheet1!$B$3:$H$44, 7, FALSE) -> 8.5 | O13: =VLOOKUP(C13, Sheet1!$B$3:$T$44, 16,FALSE) -> 4.5 | Q13: =VLOOKUP(C13, Sheet1!$B$3:$T$44, 19,FALSE)
... A43: 42 | C43: 1558460 | D43: Trương Hải | F43: Yến | H43: 60PM1 | L43: =VLOOKUP(C43,Sheet1!$B$3:$H$44, 7, FALSE) -> 7 | O43: =VLOOKUP(C43, Sheet1!$B$3:$T$44, 16,FALSE) -> 7 | Q43: =VLOOKUP(C43, Sheet1!$B$3:$T$44, 19,FALSE)

Sheet Tính Điểm thi cuối kỳ
A1: TT | B1: MSSV | C1: Họ và tên | G1: Lớp | J1: Điểm thực
A2: 1 | B2: 1513460 | C2: Đoàn Việt | E2: Anh | G2: 60PM1 | L2: =C2 & " " & E2 -> Đoàn Việt Anh
A3: 2 | B3: 1503561 | C3: Nguyễn Tuấn | E3: Anh | G3: 61PM1 | L3: =C3 & " " & E3 -> Nguyễn Tuấn Anh
A4: 3 | B4: 1543960 | C4: Trần Xuân | E4: Ba | G4: 60PM1 | J4: 5 | L4: =C4 & " " & E4 -> Trần Xuân Ba
A5: 4 | B5: 174860 | C5: Đoàn Quốc | E5: Bảo | G5: 60PM1 | J5: 5.5 | L5: =C5 & " " & E5 -> Đoàn Quốc Bảo
A6: 5 | B6: 9460 | C6: Nguyễn Mạnh | E6: Cường | G6: 60PM2 | J6: 9 | L6: =C6 & " " & E6 -> Nguyễn Mạnh Cường
A7: 6 | B7: 1506260 | C7: Nguyễn Văn | E7: Đạt | G7: 60PM1 | J7: 7.5 | L7: =C7 & " " & E7 -> Nguyễn Văn Đạt
A8: 7 | B8: 1547360 | C8: Đậu Viết | E8: Đức | G8: 60PM1 | J8: 7.5 | L8: =C8 & " " & E8 -> Đậu Viết Đức
A9: 8 | B9: 127160 | C9: Lê Đức | E9: Giáp | G9: 60PM1 | J9: 4.5 | L9: =C9 & " " & E9 -> Lê Đức Giáp
A10: 9 | B10: 1533860 | C10: Lê Trung | E10: Hiếu | G10: 60PM1 | J10: 2 | L10: =C10 & " " & E10 -> Lê Trung Hiếu
A11: 10 | B11: 130260 | C11: Trần Văn | E11: Hiếu | G11: 60PM1 | J11: 6 | L11: =C11 & " " & E11 -> Trần Văn Hiếu
A12: 11 | B12: 111060 | C12: Nguyễn Văn | E12: Hĩu | G12: 60PM1 | J12: 5.5 | L12: =C12 & " " & E12 -> Nguyễn Văn Hĩu
A13: 12 | B13: 1518860 | C13: Nguyễn Hữu | E13: Hoàng | G13: 60PM1 | J13: 4 | L13: =C13 & " " & E13 -> Nguyễn Hữu Hoàng
A14: 13 | B14: 1506357 | C14: Vũ Minh | E14: Hoàng | G14: 57PM2 | J14: 3 | L14: =C14 & " " & E14 -> Vũ Minh Hoàng
A15: 14 | B15: 1535160 | C15: Khúc Gia | E15: Huy | G15: 60PM1 | J15: 4 | L15: =C15 & " " & E15 -> Khúc Gia Huy
... A17: 16 | B17: 1511460 | C17: Phạm Ngọc | E17: Huy | G17: 60PM1 | J17: 5.5 | L17: =C17 & " " & E17 -> Phạm Ngọc Huy
A18: 17 | B18: 1565360 | C18: Hoàng Việt | E18: Hưng | G18: 60PM1 | L18: =C18 & " " & E18 -> Hoàng Việt Hưng
A19: 18 | B19: 1504559 | C19: Hà Bảo | E19: Khánh | G19: 59PM1 | L19: =C19 & " " & E19 -> Hà Bảo Khánh
A20: 19 | B20: 1519760 | C20: Nguyễn Kim | E20: Lâm | G20: 60PM1 | J20: 6 | L20: =C20 & " " & E20 -> Nguyễn Kim Lâm
A21: 20 | B21: 1539760 | C21: Nguyễn Văn | E21: Lâm | G21: 60PM1 | J21: 5.5 | L21: =C21 & " " & E21 -> Nguyễn Văn Lâm
A22: 21 | B22: 1512660 | C22: Lại Hoàng | E22: Lê | G22: 60PM1 | J22: 9 | L22: =C22 & " " & E22 -> Lại Hoàng Lê
A23: 22 | B23: 1536360 | C23: Đoàn Bảo | E23: Linh | G23: 60PM1 | J23: 9 | L23: =C23 & " " & E23 -> Đoàn Bảo Linh
A24: 23 | B24: 1538660 | C24: Nguyễn Mỹ | E24: Linh | G24: 60PM1 | J24: 6 | L24: =C24 & " " & E24 -> Nguyễn Mỹ Linh
A25: 24 | B25: 1520260 | C25: Nguyễn Thành | E25: Long | G25: 60PM1 | J25: 5 | L25: =C25 & " " & E25 -> Nguyễn Thành Long
A26: 25 | B26: 119160 | C26: Ngô Văn | E26: Luân | G26: 60PM1 | J26: 5.5 | L26: =C26 & " " & E26 -> Ngô Văn Luân
A27: 26 | B27: 1531460 | C27: Đào Quang | E27: Minh | G27: 60PM1 | J27: 4.5 | L27: =C27 & " " & E27 -> Đào Quang Minh
A28: 27 | B28: 125960 | C28: Phạm Văn | E28: Minh | G28: 60PM1 | J28: 6 | L28: =C28 & " " & E28 -> Phạm Văn Minh
A29: 28 | B29: 1536260 | C29: Huỳnh Hoàng | E29: Nam | G29: 60PM1 | J29: 1 | L29: =C29 & " " & E29 -> Huỳnh Hoàng Nam
A30: 29 | B30: 1531360 | C30: Nguyễn Sơn | E30: Nam | G30: 60PM1 | L30: =C30 & " " & E30 -> Nguyễn Sơn Nam
A31: 30 | B31: 1540760 | C31: Mai Thị Kim | E31: Ngân | G31: 60PM1 | J31: 7 | L31: =C31 & " " & E31 -> Mai Thị Kim Ngân
A32: 31 | B32: 150160 | C32: Đỗ Văn | E32: Phiêu | G32: 60PM1 | J32: 4 | L32: =C32 & " " & E32 -> Đỗ Văn Phiêu
A33: 32 | B33: 212360 | C33: Nguyễn Viết | E33: Quân | G33: 60PM1 | J33: 8.5 | L33: =C33 & " " & E33 -> Nguyễn Viết Quân
A34: 33 | B34: 134760 | C34: Phạm Văn | E34: Tâm | G34: 60PM1 | J34: 7 | L34: =C34 & " " & E34 -> Phạm Văn Tâm
A35: 34 | B35: 209460 | C35: Nguyễn Thanh | E35: Thản | G35: 60PM1 | J35: 4.5 | L35: =C35 & " " & E35 -> Nguyễn Thanh Thản
A36: 35 | B36: 92760 | C36: Nguyễn Quốc | E36: Thắng | G36: 60PM1 | J36: 4 | L36: =C36 & " " & E36 -> Nguyễn Quốc Thắng
A37: 36 | B37: 1537160 | C37: Trần Hữu | E37: Tòng | G37: 60PM1 | J37: 6 | L37: =C37 & " " & E37 -> Trần Hữu Tòng
A38: 37 | B38: 1509760 | C38: Đặng Trường | E38: Trúc | G38: 60PM1 | J38: 6 | L38: =C38 & " " & E38 -> Đặng Trường Trúc
A39: 38 | B39: 1535760 | C39: Phạm Ngọc | E39: Trung | G39: 60PM1 | J39: 5.5 | L39: =C39 & " " & E39 -> Phạm Ngọc Trung
A40: 39 | B40: 1534560 | C40: Đinh Minh | E40: Tuấn | G40: 60PM1 | J40: 5 | L40: =C40 & " " & E40 -> Đinh Minh Tuấn
A41: 40 | B41: 1510560 | C41: Trần Văn | E41: Tuấn | G41: 60PM1 | J41: 6.5 | L41: =C41 & " " & E41 -> Trần Văn Tuấn
...

Sheet Điểm danh
A1: STT | B1: Mã sinh viên | C1: Họ lót | D1: Tên | E1: Mã lớp | F1: B1 | G1: B2 | H1: B3 | I1: B4 | J1: B5 | K1: B6 | L1: B7 | M1: Số buổi đi học có điểm danh
A2: 1 | B2: 1513460 | C2: Đoàn Việt | D2: Anh | E2: 60PM1 | M2: =countif(F2:L2,"v") + countif(F2:L2,"p") * 0.5 - COUNTIF(F2:L2, "bv") * 2 -> 0
A3: 2 | B3: 1503561 | C3: Nguyễn Tuấn | D3: Anh | E3: 61PM1 | M3: =countif(F3:L3,"v") + countif(F3:L3,"p") * 0.5 - COUNTIF(F3:L3, "bv") * 2 -> 0
A4: 3 | B4: 1543960 | C4: Trần Xuân | D4: Ba | E4: 60PM1 | F4: v | G4: v | H4: p | I4: v | K4: v | L4: v | M4: =countif(F4:L4,"v") + countif(F4:L4,"p") * 0.5 - COUNTIF(F4:L4, "bv") * 2 -> 5.5
A5: 4 | B5: 174860 | C5: Đoàn Quốc | D5: Bảo | E5: 60PM1 | G5: p | H5: v | I5: p | K5: v | L5: v | M5: =countif(F5:L5,"v") + countif(F5:L5,"p") * 0.5 - COUNTIF(F5:L5, "bv") * 2 -> 4
A6: 5 | B6: 9460 | C6: Nguyễn Mạnh | D6: Cường | E6: 60PM2 | F6: v | G6: v | H6: v | I6: v | J6: v | K6: v | L6: v | M6: =countif(F6:L6,"v") + countif(F6:L6,"p") * 0.5 - COUNTIF(F6:L6, "bv") * 2 -> 7
A7: 6 | B7: 1506260 | C7: Nguyễn Văn | D7: Đạt | E7: 60PM1 | F7: v | G7: v | H7: v | I7: v | J7: v | K7: v | L7: v | M7: =countif(F7:L7,"v") + countif(F7:L7,"p") * 0.5 - COUNTIF(F7:L7, "bv") * 2 -> 7
A8: 7 | B8: 1547360 | C8: Đậu Viết | D8: Đức | E8: 60PM1 | F8: v | G8: v | H8: v | I8: v | J8: v | K8: v | L8: v | M8: =countif(F8:L8,"v") + countif(F8:L8,"p") * 0.5 - COUNTIF(F8:L8, "bv") * 2 -> 7
A9: 8 | B9: 127160 | C9: Lê Đức | D9: Giáp | E9: 60PM1 | F9: v | G9: v | J9: v | M9: =countif(F9:L9,"v") + countif(F9:L9,"p") * 0.5 - COUNTIF(F9:L9, "bv") * 2 -> 3
A10: 9 | B10: 1533860 | C10: Lê Trung | D10: Hiếu | E10: 60PM1 | F10: v | G10: v | I10: v | J10: p | K10: v | L10: v | M10: =countif(F10:L10,"v") + countif(F10:L10,"p") * 0.5 - COUNTIF(F10:L10, "bv") * 2 -> 5.5
A11: 10 | B11: 130260 | C11: Trần Văn | D11: Hiếu | E11: 60PM1 | F11: v | G11: v | H11: v | J11: v | K11: v | L11: v | M11: =countif(F11:L11,"v") + countif(F11:L11,"p") * 0.5 - COUNTIF(F11:L11, "bv") * 2 -> 6
A12: 11 | B12: 111060 | C12: Nguyễn Văn | D12: Hĩu | E12: 60PM1 | F12: v | G12: v | H12: v | I12: v | J12: v | K12: v | L12: v | M12: =countif(F12:L12,"v") + countif(F12:L12,"p") * 0.5 - COUNTIF(F12:L12, "bv") * 2 -> 7
A13: 12 | B13: 1518860 | C13: Nguyễn Hữu | D13: Hoàng | E13: 60PM1 | F13: v | G13: v | H13: v | I13: v | J13: v | K13: v | L13: v | M13: =countif(F13:L13,"v") + countif(F13:L13,"p") * 0.5 - COUNTIF(F13:L13, "bv") * 2 -> 7
A14: 13 | B14: 1506357 | C14: Vũ Minh | D14: Hoàng | E14: 57PM2 | F14: v | G14: v | H14: v | I14: p | M14: =countif(F14:L14,"v") + countif(F14:L14,"p") * 0.5 - COUNTIF(F14:L14, "bv") * 2 -> 3.5
A15: 14 | B15: 1535160 | C15: Khúc Gia | D15: Huy | E15: 60PM1 | F15: v | H15: v | I15: v | J15: v | K15: v | L15: v | M15: =countif(F15:L15,"v") + countif(F15:L15,"p") * 0.5 - COUNTIF(F15:L15, "bv") * 2 -> 6
A16: 15 | B16: 170060 | C16: Lê Minh | D16: Huy | E16: 60PM1 | F16: v | G16: v | H16: v | I16: v | J16: v | K16: v | L16: v | M16: =countif(F16:L16,"v") + countif(F16:L16,"p") * 0.5 - COUNTIF(F16:L16, "bv") * 2 -> 7
A17: 16 | B17: 1511460 | C17: Phạm Ngọc | D17: Huy | E17: 60PM1 | F17: v | G17: v | H17: v | I17: v | J17: p | K17: v | L17: v | M17: =countif(F17:L17,"v") + countif(F17:L17,"p") * 0.5 - COUNTIF(F17:L17, "bv") * 2 -> 6.5
A18: 17 | B18: 1565360 | C18: Hoàng Việt | D18: Hưng | E18: 60PM1 | M18: =countif(F18:L18,"v") + countif(F18:L18,"p") * 0.5 - COUNTIF(F18:L18, "bv") * 2 -> 0
A19: 18 | B19: 1504559 | C19: Hà Bảo | D19: Khánh | E19: 59PM1 | G19: v | H19: v | M19: =countif(F19:L19,"v") + countif(F19:L19,"p") * 0.5 - COUNTIF(F19:L19, "bv") * 2 -> 2
A20: 19 | B20: 1519760 | C20: Nguyễn Kim | D20: Lâm | E20: 60PM1 | F20: v | G20: v | H20: v | I20: v | J20: v | K20: v | L20: v | M20: =countif(F20:L20,"v") + countif(F20:L20,"p") * 0.5 - COUNTIF(F20:L20, "bv") * 2 -> 7
A21: 20 | B21: 1539760 | C21: Nguyễn Văn | D21: Lâm | E21: 60PM1 | F21: v | G21: v | H21: v | I21: v | J21: v | K21: v | L21: v | M21: =countif(F21:L21,"v") + countif(F21:L21,"p") * 0.5 - COUNTIF(F21:L21, "bv") * 2 -> 7
A22: 21 | B22: 1512660 | C22: Lại Hoàng | D22: Lê | E22: 60PM1 | F22: v | G22: v | H22: v | I22: v | J22: v | K22: v | L22: v | M22: =countif(F22:L22,"v") + countif(F22:L22,"p") * 0.5 - COUNTIF(F22:L22, "bv") * 2 -> 7
A23: 22 | B23: 1536360 | C23: Đoàn Bảo | D23: Linh | E23: 60PM1 | F23: v | G23: v | H23: v | I23: v | J23: v | K23: v | L23: v | M23: =countif(F23:L23,"v") + countif(F23:L23,"p") * 0.5 - COUNTIF(F23:L23, "bv") * 2 -> 7
