Workbook

Sheet S-boxes
A1: S1 | B1: 0 | C1: 1 | D1: 2 | E1: 3 | F1: 4 | G1: 5 | H1: 6 | I1: 7 | J1: 8 | K1: 9 | L1: 10 | M1: 11 | N1: 12 | O1: 13 | P1: 14 | Q1: 15
A2: 0 | B2: 14 | C2: 4 | D2: 13 | E2: 1 | F2: 2 | G2: 15 | H2: 11 | I2: 8 | J2: 3 | K2: 10 | L2: 6 | M2: 12 | N2: 5 | O2: 9 | P2: 0 | Q2: 7
A3: 1 | B3: 0 | C3: 15 | D3: 7 | E3: 4 | F3: 14 | G3: 2 | H3: 13 | I3: 1 | J3: 10 | K3: 6 | L3: 12 | M3: 11 | N3: 9 | O3: 5 | P3: 3 | Q3: 8
A4: 2 | B4: 4 | C4: 1 | D4: 14 | E4: 8 | F4: 13 | G4: 6 | H4: 2 | I4: 11 | J4: 15 | K4: 12 | L4: 9 | M4: 7 | N4: 3 | O4: 10 | P4: 5 | Q4: 0
A5: 3 | B5: 15 | C5: 12 | D5: 8 | E5: 2 | F5: 4 | G5: 9 | H5: 1 | I5: 7 | J5: 5 | K5: 11 | L5: 3 | M5: 14 | N5: 10 | O5: 0 | P5: 6 | Q5: 13
A8: S2 | B8: 0 | C8: 1 | D8: 2 | E8: 3 | F8: 4 | G8: 5 | H8: 6 | I8: 7 | J8: 8 | K8: 9 | L8: 10 | M8: 11 | N8: 12 | O8: 13 | P8: 14 | Q8: 15
A9: 0 | B9: 15 | C9: 1 | D9: 8 | E9: 14 | F9: 6 | G9: 11 | H9: 3 | I9: 4 | J9: 9 | K9: 7 | L9: 2 | M9: 13 | N9: 12 | O9: 0 | P9: 5 | Q9: 10
A10: 1 | B10: 3 | C10: 13 | D10: 4 | E10: 7 | F10: 15 | G10: 2 | H10: 8 | I10: 14 | J10: 12 | K10: 0 | L10: 1 | M10: 10 | N10: 6 | O10: 9 | P10: 11 | Q10: 5
A11: 2 | B11: 0 | C11: 14 | D11: 7 | E11: 11 | F11: 10 | G11: 4 | H11: 13 | I11: 1 | J11: 5 | K11: 8 | L11: 12 | M11: 6 | N11: 9 | O11: 3 | P11: 2 | Q11: 15
A12: 3 | B12: 13 | C12: 8 | D12: 10 | E12: 1 | F12: 3 | G12: 15 | H12: 4 | I12: 2 | J12: 11 | K12: 6 | L12: 7 | M12: 12 | N12: 0 | O12: 5 | P12: 14 | Q12: 9
A15: S3 | B15: 0 | C15: 1 | D15: 2 | E15: 3 | F15: 4 | G15: 5 | H15: 6 | I15: 7 | J15: 8 | K15: 9 | L15: 10 | M15: 11 | N15: 12 | O15: 13 | P15: 14 | Q15: 15
A16: 0 | B16: 10 | C16: 0 | D16: 9 | E16: 14 | F16: 6 | G16: 3 | H16: 15 | I16: 5 | J16: 1 | K16: 13 | L16: 12 | M16: 7 | N16: 11 | O16: 4 | P16: 2 | Q16: 8
A17: 1 | B17: 13 | C17: 7 | D17: 0 | E17: 9 | F17: 3 | G17: 4 | H17: 6 | I17: 10 | J17: 2 | K17: 8 | L17: 5 | M17: 14 | N17: 12 | O17: 11 | P17: 15 | Q17: 1
A18: 2 | B18: 13 | C18: 6 | D18: 4 | E18: 9 | F18: 8 | G18: 15 | H18: 3 | I18: 0 | J18: 11 | K18: 1 | L18: 2 | M18: 12 | N18: 5 | O18: 10 | P18: 14 | Q18: 7
A19: 3 | B19: 1 | C19: 10 | D19: 13 | E19: 0 | F19: 6 | G19: 9 | H19: 8 | I19: 7 | J19: 4 | K19: 15 | L19: 14 | M19: 3 | N19: 11 | O19: 5 | P19: 2 | Q19: 12
A22: S4 | B22: 0 | C22: 1 | D22: 2 | E22: 3 | F22: 4 | G22: 5 | H22: 6 | I22: 7 | J22: 8 | K22: 9 | L22: 10 | M22: 11 | N22: 12 | O22: 13 | P22: 14 | Q22: 15
A23: 0 | B23: 7 | C23: 13 | D23: 14 | E23: 3 | F23: 0 | G23: 6 | H23: 9 | I23: 10 | J23: 1 | K23: 2 | L23: 8 | M23: 5 | N23: 11 | O23: 12 | P23: 4 | Q23: 15
A24: 1 | B24: 13 | C24: 8 | D24: 11 | E24: 5 | F24: 6 | G24: 15 | H24: 0 | I24: 3 | J24: 4 | K24: 7 | L24: 2 | M24: 12 | N24: 1 | O24: 10 | P24: 14 | Q24: 9
A25: 2 | B25: 10 | C25: 6 | D25: 9 | E25: 0 | F25: 12 | G25: 11 | H25: 7 | I25: 13 | J25: 15 | K25: 1 | L25: 3 | M25: 14 | N25: 5 | O25: 2 | P25: 8 | Q25: 4
A26: 3 | B26: 3 | C26: 15 | D26: 0 | E26: 6 | F26: 10 | G26: 1 | H26: 13 | I26: 8 | J26: 9 | K26: 4 | L26: 5 | M26: 11 | N26: 12 | O26: 7 | P26: 2 | Q26: 14
A29: S5 | B29: 0 | C29: 1 | D29: 2 | E29: 3 | F29: 4 | G29: 5 | H29: 6 | I29: 7 | J29: 8 | K29: 9 | L29: 10 | M29: 11 | N29: 12 | O29: 13 | P29: 14 | Q29: 15
A30: 0 | B30: 2 | C30: 12 | D30: 4 | E30: 1 | F30: 7 | G30: 10 | H30: 11 | I30: 6 | J30: 8 | K30: 5 | L30: 3 | M30: 15 | N30: 13 | O30: 0 | P30: 14 | Q30: 9
A31: 1 | B31: 14 | C31: 11 | D31: 2 | E31: 12 | F31: 4 | G31: 7 | H31: 13 | I31: 1 | J31: 5 | K31: 0 | L31: 15 | M31: 10 | N31: 3 | O31: 9 | P31: 8 | Q31: 6
A32: 2 | B32: 4 | C32: 2 | D32: 1 | E32: 11 | F32: 10 | G32: 13 | H32: 7 | I32: 8 | J32: 15 | K32: 9 | L32: 12 | M32: 5 | N32: 6 | O32: 3 | P32: 0 | Q32: 14
A33: 3 | B33: 11 | C33: 8 | D33: 12 | E33: 7 | F33: 1 | G33: 14 | H33: 2 | I33: 13 | J33: 6 | K33: 15 | L33: 0 | M33: 9 | N33: 10 | O33: 4 | P33: 5 | Q33: 3
A36: S6 | B36: 0 | C36: 1 | D36: 2 | E36: 3 | F36: 4 | G36: 5 | H36: 6 | I36: 7 | J36: 8 | K36: 9 | L36: 10 | M36: 11 | N36: 12 | O36: 13 | P36: 14 | Q36: 15
A37: 0 | B37: 12 | C37: 1 | D37: 10 | E37: 15 | F37: 9 | G37: 2 | H37: 6 | I37: 8 | J37: 0 | K37: 13 | L37: 3 | M37: 4 | N37: 14 | O37: 7 | P37: 5 | Q37: 11
A38: 1 | B38: 10 | C38: 15 | D38: 4 | E38: 2 | F38: 7 | G38: 12 | H38: 9 | I38: 5 | J38: 6 | K38: 1 | L38: 13 | M38: 14 | N38: 0 | O38: 11 | P38: 3 | Q38: 8
A39: 2 | B39: 9 | C39: 14 | D39: 15 | E39: 5 | F39: 2 | G39: 8 | H39: 12 | I39: 3 | J39: 7 | K39: 0 | L39: 4 | M39: 10 | N39: 1 | O39: 13 | P39: 11 | Q39: 6
A40: 3 | B40: 4 | C40: 3 | D40: 2 | E40: 12 | F40: 9 | G40: 5 | H40: 15 | I40: 10 | J40: 11 | K40: 14 | L40: 1 | M40: 7 | N40: 6 | O40: 0 | P40: 8 | Q40: 13
A43: S7 | B43: 0 | C43: 1 | D43: 2 | E43: 3 | F43: 4 | G43: 5 | H43: 6 | I43: 7 | J43: 8 | K43: 9 | L43: 10 | M43: 11 | N43: 12 | O43: 13 | P43: 14 | Q43: 15
A44: 0 | B44: 4 | C44: 11 | D44: 2 | E44: 14 | F44: 15 | G44: 0 | H44: 8 | I44: 13 | J44: 3 | K44: 12 | L44: 9 | M44: 7 | N44: 5 | O44: 10 | P44: 6 | Q44: 1
A45: 1 | B45: 13 | C45: 0 | D45: 11 | E45: 7 | F45: 4 | G45: 9 | H45: 1 | I45: 10 | J45: 14 | K45: 3 | L45: 5 | M45: 12 | N45: 2 | O45: 15 | P45: 8 | Q45: 6
A46: 2 | B46: 1 | C46: 4 | D46: 11 | E46: 13 | F46: 12 | G46: 3 | H46: 7 | I46: 14 | J46: 10 | K46: 15 | L46: 6 | M46: 8 | N46: 0 | O46: 5 | P46: 9 | Q46: 2
A47: 3 | B47: 6 | C47: 11 | D47: 13 | E47: 8 | F47: 1 | G47: 4 | H47: 10 | I47: 7 | J47: 9 | K47: 5 | L47: 0 | M47: 15 | N47: 14 | O47: 2 | P47: 3 | Q47: 12
A50: S8 | B50: 0 | C50: 1 | D50: 2 | E50: 3 | F50: 4 | G50: 5 | H50: 6 | I50: 7 | J50: 8 | K50: 9 | L50: 10 | M50: 11 | N50: 12 | O50: 13 | P50: 14 | Q50: 15
A51: 0 | B51: 13 | C51: 2 | D51: 8 | E51: 4 | F51: 6 | G51: 15 | H51: 11 | I51: 1 | J51: 10 | K51: 9 | L51: 3 | M51: 14 | N51: 5 | O51: 0 | P51: 12 | Q51: 7
A52: 1 | B52: 1 | C52: 15 | D52: 13 | E52: 8 | F52: 10 | G52: 3 | H52: 7 | I52: 4 | J52: 12 | K52: 5 | L52: 6 | M52: 11 | N52: 0 | O52: 14 | P52: 9 | Q52: 2
A53: 2 | B53: 7 | C53: 11 | D53: 4 | E53: 1 | F53: 9 | G53: 12 | H53: 14 | I53: 2 | J53: 0 | K53: 6 | L53: 10 | M53: 13 | N53: 15 | O53: 3 | P53: 5 | Q53: 8
A54: 3 | B54: 2 | C54: 1 | D54: 14 | E54: 7 | F54: 4 | G54: 10 | H54: 8 | I54: 13 | J54: 15 | K54: 12 | L54: 9 | M54: 0 | N54: 3 | O54: 5 | P54: 6 | Q54: 11

Sheet Khóa k1-16
A2: Khóa K: | B2: 0133457799BBCDFF | D2: 0000000100110011010001010111011110011001101110111100110111111111
A3: Vị trí | B3: ký tự hexan | C3: binary | M3: =LEN(D3) -> 0
A4: 1 | B4: =MID($B$2,A4,1) -> 0 | C4: =HEX2BIN(B4,4) -> 0000 | D4: =C4&D5 -> 0000000100110011010001010111011110011001101110111100110111111111 | M4: =LEN(D4) -> 64
A5: 2 | B5: =MID($B$2,A5,1) -> 1 | C5: =HEX2BIN(B5,4) -> 0001 | D5: =C5&D6 -> 000100110011010001010111011110011001101110111100110111111111 | M5: =LEN(D5) -> 60
A6: 3 | B6: =MID($B$2,A6,1) -> 3 | C6: =HEX2BIN(B6,4) -> 0011 | D6: =C6&D7 -> 00110011010001010111011110011001101110111100110111111111 | M6: =LEN(D6) -> 56
A7: 4 | B7: =MID($B$2,A7,1) -> 3 | C7: =HEX2BIN(B7,4) -> 0011 | D7: =C7&D8 -> 0011010001010111011110011001101110111100110111111111 | M7: =LEN(D7) -> 52
A8: 5 | B8: =MID($B$2,A8,1) -> 4 | C8: =HEX2BIN(B8,4) -> 0100 | D8: =C8&D9 -> 010001010111011110011001101110111100110111111111 | M8: =LEN(D8) -> 48
A9: 6 | B9: =MID($B$2,A9,1) -> 5 | C9: =HEX2BIN(B9,4) -> 0101 | D9: =C9&D10 -> 01010111011110011001101110111100110111111111 | M9: =LEN(D9) -> 44
A10: 7 | B10: =MID($B$2,A10,1) -> 7 | C10: =HEX2BIN(B10,4) -> 0111 | D10: =C10&D11 -> 0111011110011001101110111100110111111111 | M10: =LEN(D10) -> 40
A11: 8 | B11: =MID($B$2,A11,1) -> 7 | C11: =HEX2BIN(B11,4) -> 0111 | D11: =C11&D12 -> 011110011001101110111100110111111111 | M11: =LEN(D11) -> 36
A12: 9 | B12: =MID($B$2,A12,1) -> 9 | C12: =HEX2BIN(B12,4) -> 1001 | D12: =C12&D13 -> 10011001101110111100110111111111 | M12: =LEN(D12) -> 32
A13: 10 | B13: =MID($B$2,A13,1) -> 9 | C13: =HEX2BIN(B13,4) -> 1001 | D13: =C13&D14 -> 1001101110111100110111111111 | M13: =LEN(D13) -> 28
A14: 11 | B14: =MID($B$2,A14,1) -> B | C14: =HEX2BIN(B14,4) -> 1011 | D14: =C14&D15 -> 101110111100110111111111 | M14: =LEN(D14) -> 24
A15: 12 | B15: =MID($B$2,A15,1) -> B | C15: =HEX2BIN(B15,4) -> 1011 | D15: =C15&D16 -> 10111100110111111111 | M15: =LEN(D15) -> 20
... A17: 14 | B17: =MID($B$2,A17,1) -> D | C17: =HEX2BIN(B17,4) -> 1101 | D17: =C17&D18 -> 110111111111 | M17: =LEN(D17) -> 12
A18: 15 | B18: =MID($B$2,A18,1) -> F | C18: =HEX2BIN(B18,4) -> 1111 | D18: =C18&C19 -> 11111111 | M18: =LEN(D18) -> 8
A19: 16 | B19: =MID($B$2,A19,1) -> F | C19: =HEX2BIN(B19,4) -> 1111 | M19: =LEN(D19) -> 0
A21: STT | B21: Pc-1 | C21: bit i
A22: 1 | B22: 57 | C22: =MID($D$2,B22,1) -> 1 | D22: =C22&D23 -> 11110000110011001010101010111010101011001100111100001010
A23: 2 | B23: 49 | C23: =MID($D$2,B23,1) -> 1 | D23: =C23&D24 -> 1110000110011001010101010111010101011001100111100001010
A24: 3 | B24: 41 | C24: =MID($D$2,B24,1) -> 1 | D24: =C24&D25 -> 110000110011001010101010111010101011001100111100001010
A25: 4 | B25: 33 | C25: =MID($D$2,B25,1) -> 1 | D25: =C25&D26 -> 10000110011001010101010111010101011001100111100001010
A26: 5 | B26: 25 | C26: =MID($D$2,B26,1) -> 0 | D26: =C26&D27 -> 0000110011001010101010111010101011001100111100001010
A27: 6 | B27: 17 | C27: =MID($D$2,B27,1) -> 0 | D27: =C27&D28 -> 000110011001010101010111010101011001100111100001010
A28: 7 | B28: 9 | C28: =MID($D$2,B28,1) -> 0 | D28: =C28&D29 -> 00110011001010101010111010101011001100111100001010
A29: 8 | B29: 1 | C29: =MID($D$2,B29,1) -> 0 | D29: =C29&D30 -> 0110011001010101010111010101011001100111100001010
A30: 9 | B30: 58 | C30: =MID($D$2,B30,1) -> 1 | D30: =C30&D31 -> 110011001010101010111010101011001100111100001010
A31: 10 | B31: 50 | C31: =MID($D$2,B31,1) -> 1 | D31: =C31&D32 -> 10011001010101010111010101011001100111100001010
A32: 11 | B32: 42 | C32: =MID($D$2,B32,1) -> 0 | D32: =C32&D33 -> 0011001010101010111010101011001100111100001010
A33: 12 | B33: 34 | C33: =MID($D$2,B33,1) -> 0 | D33: =C33&D34 -> 011001010101010111010101011001100111100001010
... A75: 54 | B75: 20 | C75: =MID($D$2,B75,1) -> 0 | D75: =C75&D76 -> 010
A76: 55 | B76: 12 | C76: =MID($D$2,B76,1) -> 1 | D76: =C76&C77 -> 10
A77: 56 | B77: 4 | C77: =MID($D$2,B77,1) -> 0
A79: Sau khi Pc-1 ta có k0 = | C79: =D22 -> 11110000110011001010101010111010101011001100111100001010
A81: Dịch bit | K81: Bảng dịch trái
A83: C0 | B83: =LEFT(C79,28) -> 1111000011001100101010101011 | F83: D0 | G83: =RIGHT(C79,28) -> 1010101011001100111100001010 | K83: 1 | L83: 1
A84: C1 | B84: =MID(B83, L83+1, LEN(B83)-L83) & LEFT(B83, L83) -> 1110000110011001010101010111 | F84: D1 | G84: =MID(G83, L83+1, LEN(G83)-L83) & LEFT(G83, L83) -> 0101010110011001111000010101 | K84: 2 | L84: 1
A85: C2 | B85: =MID(B84, L84+1, LEN(B84)-L84) & LEFT(B84, L84) -> 1100001100110010101010101111 | F85: D2 | G85: =MID(G84, L84+1, LEN(G84)-L84) & LEFT(G84, L84) -> 1010101100110011110000101010 | K85: 3 | L85: 2
A86: C3 | B86: =MID(B85, L85+1, LEN(B85)-L85) & LEFT(B85, L85) -> 0000110011001010101010111111 | F86: D3 | G86: =MID(G85, L85+1, LEN(G85)-L85) & LEFT(G85, L85) -> 1010110011001111000010101010 | K86: 4 | L86: 2
A87: C4 | B87: =MID(B86, L86+1, LEN(B86)-L86) & LEFT(B86, L86) -> 0011001100101010101011111100 | F87: D4 | G87: =MID(G86, L86+1, LEN(G86)-L86) & LEFT(G86, L86) -> 1011001100111100001010101010 | K87: 5 | L87: 2
...

Sheet E(Ri) XOR ki+1
A1: Bản rõ M | B1: Input M = | C1: 00123456789abcde | E1: 0000000000010010001101000101011001111000100110101011110011011110 | N1: IP(M) = | O1: =_xlfn.TEXTJOIN("", TRUE,C4:C67) -> 1001100011111110110011000000000011100000010101001111000010101010
A3: stt | B3: IP | C3: IP(M) | D3: Ma trận E | E3: IP^-1 | N3: L0 = | O3: =LEFT(O1,32) -> 10011000111111101100110000000000
A4: 1 | B4: 58 | C4: =MID($E$1,B4,1) -> 1 | D4: 32 | E4: 40 | N4: R0 = | O4: =RIGHT(O1,32) -> 11100000010101001111000010101010
A5: 2 | B5: 50 | C5: =MID($E$1,B5,1) -> 0 | D5: 1 | E5: 8
A6: 3 | B6: 42 | C6: =MID($E$1,B6,1) -> 0 | D6: 2 | E6: 48 | G6: Tính A = E(Ri) XOR ki+1
A7: 4 | B7: 34 | C7: =MID($E$1,B7,1) -> 1 | D7: 3 | E7: 16
A8: 5 | B8: 26 | C8: =MID($E$1,B8,1) -> 1 | D8: 4 | E8: 56 | G8: STT/i | H8: 0 | I8: 1 | J8: 2 | K8: 3 | L8: 4 | M8: 5 | N8: 6 | O8: 7 | P8: 8 | Q8: 9 | R8: 10 | S8: 11 | T8: 12 | U8: 13 | V8: 14 | W8: 15 | X8: 16
A9: 6 | B9: 18 | C9: =MID($E$1,B9,1) -> 0 | D9: 5 | E9: 24 | G9: 1 | H9: =MOD(VALUE(MID($O$4,D4,1)) + VALUE('Khóa k1-16'!B124),2) -> 0 | I9: =MOD(VALUE(MID(R0_L0!$C$75,'E(Ri) XOR ki+1'!D4,1))+VALUE('Khóa k1-16'!C124),2) -> 0 | J9: =MOD(VALUE(MID(R0_L0!$C$76,'E(Ri) XOR ki+1'!$D4,1))+VALUE('Khóa k1-16'!D124),2) -> 1 | K9: =MOD(VALUE(MID(R0_L0!$C$77,'E(Ri) XOR ki+1'!D4,1))+VALUE('Khóa k1-16'!E124),2) -> 0 | L9: =MOD(VALUE(MID(R0_L0!$C$78,'E(Ri) XOR ki+1'!D4,1))+VALUE('Khóa k1-16'!F124),2) -> 1 | M9: =MOD(VALUE(MID(R0_L0!$C$79,'E(Ri) XOR ki+1'!$D4,1))+VALUE('Khóa k1-16'!G124),2) -> 1 | N9: =MOD(VALUE(MID(R0_L0!$C$80,'E(Ri) XOR ki+1'!$D4,1))+VALUE('Khóa k1-16'!H124),2) -> 0 | O9: =MOD(VALUE(MID(R0_L0!$C$81,'E(Ri) XOR ki+1'!$D4,1))+VALUE('Khóa k1-16'!I124),2) -> 0 | P9: =MOD(VALUE(MID(R0_L0!$C$82,'E(Ri) XOR ki+1'!$D4,1))+VALUE('Khóa k1-16'!J124),2) -> 1 | Q9: =MOD(VALUE(MID(R0_L0!$C$83,'E(Ri) XOR ki+1'!$D4,1))+VALUE('Khóa k1-16'!K124),2) -> 1 | R9: =MOD(VALUE(MID(R0_L0!$C$84,'E(Ri) XOR ki+1'!$D4,1))+VALUE('Khóa k1-16'!L124),2) -> 0 | S9: =MOD(VALUE(MID(R0_L0!$C$85,'E(Ri) XOR ki+1'!$D4,1))+VALUE('Khóa k1-16'!M124),2) -> 0 | T9: =MOD(VALUE(MID(R0_L0!$C$86,'E(Ri) XOR ki+1'!$D4,1))+VALUE('Khóa k1-16'!N124),2) -> 0 | U9: =MOD(VALUE(MID(R0_L0!$C$87,'E(Ri) XOR ki+1'!$D4,1))+VALUE('Khóa k1-16'!O124),2) -> 0 | V9: =MOD(VALUE(MID(R0_L0!$C$88,'E(Ri) XOR ki+1'!$D4,1))+VALUE('Khóa k1-16'!P124),2) -> 0 | W9: =MOD(VALUE(MID(R0_L0!$C$89,'E(Ri) XOR ki+1'!$D4,1))+VALUE('Khóa k1-16'!Q124),2) -> 0 | X9: =MOD(VALUE(MID(R0_L0!$C$90,'E(Ri) XOR ki+1'!$D4,1))+VALUE('Khóa k1-16'!R124),2) -> 0
A10: 7 | B10: 10 | C10: =MID($E$1,B10,1) -> 0 | D10: 4 | E10: 64 | G10: 2 | H10: =MOD(VALUE(MID($O$4,D5,1)) + VALUE('Khóa k1-16'!B125),2) -> 1 | I10: =MOD(VALUE(MID(R0_L0!$C$75,'E(Ri) XOR ki+1'!D5,1))+VALUE('Khóa k1-16'!C125),2) -> 1 | J10: =MOD(VALUE(MID(R0_L0!$C$76,'E(Ri) XOR ki+1'!$D5,1))+VALUE('Khóa k1-16'!D125),2) -> 1 | K10: =MOD(VALUE(MID(R0_L0!$C$77,'E(Ri) XOR ki+1'!D5,1))+VALUE('Khóa k1-16'!E125),2) -> 0 | L10: =MOD(VALUE(MID(R0_L0!$C$78,'E(Ri) XOR ki+1'!D5,1))+VALUE('Khóa k1-16'!F125),2) -> 0 | M10: =MOD(VALUE(MID(R0_L0!$C$79,'E(Ri) XOR ki+1'!$D5,1))+VALUE('Khóa k1-16'!G125),2) -> 1 | N10: =MOD(VALUE(MID(R0_L0!$C$80,'E(Ri) XOR ki+1'!$D5,1))+VALUE('Khóa k1-16'!H125),2) -> 1 | O10: =MOD(VALUE(MID(R0_L0!$C$81,'E(Ri) XOR ki+1'!$D5,1))+VALUE('Khóa k1-16'!I125),2) -> 1 | P10: =MOD(VALUE(MID(R0_L0!$C$82,'E(Ri) XOR ki+1'!$D5,1))+VALUE('Khóa k1-16'!J125),2) -> 1 | Q10: =MOD(VALUE(MID(R0_L0!$C$83,'E(Ri) XOR ki+1'!$D5,1))+VALUE('Khóa k1-16'!K125),2) -> 1 | R10: =MOD(VALUE(MID(R0_L0!$C$84,'E(Ri) XOR ki+1'!$D5,1))+VALUE('Khóa k1-16'!L125),2) -> 1 | S10: =MOD(VALUE(MID(R0_L0!$C$85,'E(Ri) XOR ki+1'!$D5,1))+VALUE('Khóa k1-16'!M125),2) -> 1 | T10: =MOD(VALUE(MID(R0_L0!$C$86,'E(Ri) XOR ki+1'!$D5,1))+VALUE('Khóa k1-16'!N125),2) -> 1 | U10: =MOD(VALUE(MID(R0_L0!$C$87,'E(Ri) XOR ki+1'!$D5,1))+VALUE('Khóa k1-16'!O125),2) -> 1 | V10: =MOD(VALUE(MID(R0_L0!$C$88,'E(Ri) XOR ki+1'!$D5,1))+VALUE('Khóa k1-16'!P125),2) -> 1 | W10: =MOD(VALUE(MID(R0_L0!$C$89,'E(Ri) XOR ki+1'!$D5,1))+VALUE('Khóa k1-16'!Q125),2) -> 1 | X10: =MOD(VALUE(MID(R0_L0!$C$90,'E(Ri) XOR ki+1'!$D5,1))+VALUE('Khóa k1-16'!R125),2) -> 0
A11: 8 | B11: 2 | C11: =MID($E$1,B11,1) -> 0 | D11: 5 | E11: 32 | G11: 3 | H11: =MOD(VALUE(MID($O$4,D6,1)) + VALUE('Khóa k1-16'!B126),2) -> 1 | I11: =MOD(VALUE(MID(R0_L0!$C$75,'E(Ri) XOR ki+1'!D6,1))+VALUE('Khóa k1-16'!C126),2) -> 1 | J11: =MOD(VALUE(MID(R0_L0!$C$76,'E(Ri) XOR ki+1'!$D6,1))+VALUE('Khóa k1-16'!D126),2) -> 1 | K11: =MOD(VALUE(MID(R0_L0!$C$77,'E(Ri) XOR ki+1'!D6,1))+VALUE('Khóa k1-16'!E126),2) -> 0 | L11: =MOD(VALUE(MID(R0_L0!$C$78,'E(Ri) XOR ki+1'!D6,1))+VALUE('Khóa k1-16'!F126),2) -> 1 | M11: =MOD(VALUE(MID(R0_L0!$C$79,'E(Ri) XOR ki+1'!$D6,1))+VALUE('Khóa k1-16'!G126),2) -> 1 | N11: =MOD(VALUE(MID(R0_L0!$C$80,'E(Ri) XOR ki+1'!$D6,1))+VALUE('Khóa k1-16'!H126),2) -> 1 | O11: =MOD(VALUE(MID(R0_L0!$C$81,'E(Ri) XOR ki+1'!$D6,1))+VALUE('Khóa k1-16'!I126),2) -> 0 | P11: =MOD(VALUE(MID(R0_L0!$C$82,'E(Ri) XOR ki+1'!$D6,1))+VALUE('Khóa k1-16'!J126),2) -> 1 | Q11: =MOD(VALUE(MID(R0_L0!$C$83,'E(Ri) XOR ki+1'!$D6,1))+VALUE('Khóa k1-16'!K126),2) -> 1 | R11: =MOD(VALUE(MID(R0_L0!$C$84,'E(Ri) XOR ki+1'!$D6,1))+VALUE('Khóa k1-16'!L126),2) -> 1 | S11: =MOD(VALUE(MID(R0_L0!$C$85,'E(Ri) XOR ki+1'!$D6,1))+VALUE('Khóa k1-16'!M126),2) -> 0 | T11: =MOD(VALUE(MID(R0_L0!$C$86,'E(Ri) XOR ki+1'!$D6,1))+VALUE('Khóa k1-16'!N126),2) -> 1 | U11: =MOD(VALUE(MID(R0_L0!$C$87,'E(Ri) XOR ki+1'!$D6,1))+VALUE('Khóa k1-16'!O126),2) -> 0 | V11: =MOD(VALUE(MID(R0_L0!$C$88,'E(Ri) XOR ki+1'!$D6,1))+VALUE('Khóa k1-16'!P126),2) -> 1 | W11: =MOD(VALUE(MID(R0_L0!$C$89,'E(Ri) XOR ki+1'!$D6,1))+VALUE('Khóa k1-16'!Q126),2) -> 1 | X11: =MOD(VALUE(MID(R0_L0!$C$90,'E(Ri) XOR ki+1'!$D6,1))+VALUE('Khóa k1-16'!R126),2) -> 1
A12: 9 | B12: 60 | C12: =MID($E$1,B12,1) -> 1 | D12: 6 | E12: 39 | G12: 4 | H12: =MOD(VALUE(MID($O$4,D7,1)) + VALUE('Khóa k1-16'!B127),2) -> 0 | I12: =MOD(VALUE(MID(R0_L0!$C$75,'E(Ri) XOR ki+1'!D7,1))+VALUE('Khóa k1-16'!C127),2) -> 0 | J12: =MOD(VALUE(MID(R0_L0!$C$76,'E(Ri) XOR ki+1'!$D7,1))+VALUE('Khóa k1-16'!D127),2) -> 0 | K12: =MOD(VALUE(MID(R0_L0!$C$77,'E(Ri) XOR ki+1'!D7,1))+VALUE('Khóa k1-16'!E127),2) -> 1 | L12: =MOD(VALUE(MID(R0_L0!$C$78,'E(Ri) XOR ki+1'!D7,1))+VALUE('Khóa k1-16'!F127),2) -> 1 | M12: =MOD(VALUE(MID(R0_L0!$C$79,'E(Ri) XOR ki+1'!$D7,1))+VALUE('Khóa k1-16'!G127),2) -> 0 | N12: =MOD(VALUE(MID(R0_L0!$C$80,'E(Ri) XOR ki+1'!$D7,1))+VALUE('Khóa k1-16'!H127),2) -> 1 | O12: =MOD(VALUE(MID(R0_L0!$C$81,'E(Ri) XOR ki+1'!$D7,1))+VALUE('Khóa k1-16'!I127),2) -> 1 | P12: =MOD(VALUE(MID(R0_L0!$C$82,'E(Ri) XOR ki+1'!$D7,1))+VALUE('Khóa k1-16'!J127),2) -> 0 | Q12: =MOD(VALUE(MID(R0_L0!$C$83,'E(Ri) XOR ki+1'!$D7,1))+VALUE('Khóa k1-16'!K127),2) -> 0 | R12: =MOD(VALUE(MID(R0_L0!$C$84,'E(Ri) XOR ki+1'!$D7,1))+VALUE('Khóa k1-16'!L127),2) -> 0 | S12: =MOD(VALUE(MID(R0_L0!$C$85,'E(Ri) XOR ki+1'!$D7,1))+VALUE('Khóa k1-16'!M127),2) -> 1 | T12: =MOD(VALUE(MID(R0_L0!$C$86,'E(Ri) XOR ki+1'!$D7,1))+VALUE('Khóa k1-16'!N127),2) -> 0 | U12: =MOD(VALUE(MID(R0_L0!$C$87,'E(Ri) XOR ki+1'!$D7,1))+VALUE('Khóa k1-16'!O127),2) -> 0 | V12: =MOD(VALUE(MID(R0_L0!$C$88,'E(Ri) XOR ki+1'!$D7,1))+VALUE('Khóa k1-16'!P127),2) -> 1 | W12: =MOD(VALUE(MID(R0_L0!$C$89,'E(Ri) XOR ki+1'!$D7,1))+VALUE('Khóa k1-16'!Q127),2) -> 1 | X12: =MOD(VALUE(MID(R0_L0!$C$90,'E(Ri) XOR ki+1'!$D7,1))+VALUE('Khóa k1-16'!R127),2) -> 0
A13: 10 | B13: 52 | C13: =MID($E$1,B13,1) -> 1 | D13: 7 | E13: 7 | G13: 5 | H13: =MOD(VALUE(MID($O$4,D8,1)) + VALUE('Khóa k1-16'!B128),2) -> 1 | I13: =MOD(VALUE(MID(R0_L0!$C$75,'E(Ri) XOR ki+1'!D8,1))+VALUE('Khóa k1-16'!C128),2) -> 1 | J13: =MOD(VALUE(MID(R0_L0!$C$76,'E(Ri) XOR ki+1'!$D8,1))+VALUE('Khóa k1-16'!D128),2) -> 0 | K13: =MOD(VALUE(MID(R0_L0!$C$77,'E(Ri) XOR ki+1'!D8,1))+VALUE('Khóa k1-16'!E128),2) -> 1 | L13: =MOD(VALUE(MID(R0_L0!$C$78,'E(Ri) XOR ki+1'!D8,1))+VALUE('Khóa k1-16'!F128),2) -> 0 | M13: =MOD(VALUE(MID(R0_L0!$C$79,'E(Ri) XOR ki+1'!$D8,1))+VALUE('Khóa k1-16'!G128),2) -> 0 | N13: =MOD(VALUE(MID(R0_L0!$C$80,'E(Ri) XOR ki+1'!$D8,1))+VALUE('Khóa k1-16'!H128),2) -> 0 | O13: =MOD(VALUE(MID(R0_L0!$C$81,'E(Ri) XOR ki+1'!$D8,1))+VALUE('Khóa k1-16'!I128),2) -> 0 | P13: =MOD(VALUE(MID(R0_L0!$C$82,'E(Ri) XOR ki+1'!$D8,1))+VALUE('Khóa k1-16'!J128),2) -> 1 | Q13: =MOD(VALUE(MID(R0_L0!$C$83,'E(Ri) XOR ki+1'!$D8,1))+VALUE('Khóa k1-16'!K128),2) -> 1 | R13: =MOD(VALUE(MID(R0_L0!$C$84,'E(Ri) XOR ki+1'!$D8,1))+VALUE('Khóa k1-16'!L128),2) -> 0 | S13: =MOD(VALUE(MID(R0_L0!$C$85,'E(Ri) XOR ki+1'!$D8,1))+VALUE('Khóa k1-16'!M128),2) -> 0 | T13: =MOD(VALUE(MID(R0_L0!$C$86,'E(Ri) XOR ki+1'!$D8,1))+VALUE('Khóa k1-16'!N128),2) -> 1 | U13: =MOD(VALUE(MID(R0_L0!$C$87,'E(Ri) XOR ki+1'!$D8,1))+VALUE('Khóa k1-16'!O128),2) -> 1 | V13: =MOD(VALUE(MID(R0_L0!$C$88,'E(Ri) XOR ki+1'!$D8,1))+VALUE('Khóa k1-16'!P128),2) -> 0 | W13: =MOD(VALUE(MID(R0_L0!$C$89,'E(Ri) XOR ki+1'!$D8,1))+VALUE('Khóa k1-16'!Q128),2) -> 1 | X13: =MOD(VALUE(MID(R0_L0!$C$90,'E(Ri) XOR ki+1'!$D8,1))+VALUE('Khóa k1-16'!R128),2) -> 1
A14: 11 | B14: 44 | C14: =MID($E$1,B14,1) -> 1 | D14: 8 | E14: 47 | G14: 6 | H14: =MOD(VALUE(MID($O$4,D9,1)) + VALUE('Khóa k1-16'!B129),2) -> 0 | I14: =MOD(VALUE(MID(R0_L0!$C$75,'E(Ri) XOR ki+1'!D9,1))+VALUE('Khóa k1-16'!C129),2) -> 1 | J14: =MOD(VALUE(MID(R0_L0!$C$76,'E(Ri) XOR ki+1'!$D9,1))+VALUE('Khóa k1-16'!D129),2) -> 0 | K14: =MOD(VALUE(MID(R0_L0!$C$77,'E(Ri) XOR ki+1'!D9,1))+VALUE('Khóa k1-16'!E129),2) -> 0 | L14: =MOD(VALUE(MID(R0_L0!$C$78,'E(Ri) XOR ki+1'!D9,1))+VALUE('Khóa k1-16'!F129),2) -> 0 | M14: =MOD(VALUE(MID(R0_L0!$C$79,'E(Ri) XOR ki+1'!$D9,1))+VALUE('Khóa k1-16'!G129),2) -> 1 | N14: =MOD(VALUE(MID(R0_L0!$C$80,'E(Ri) XOR ki+1'!$D9,1))+VALUE('Khóa k1-16'!H129),2) -> 1 | O14: =MOD(VALUE(MID(R0_L0!$C$81,'E(Ri) XOR ki+1'!$D9,1))+VALUE('Khóa k1-16'!I129),2) -> 1 | P14: =MOD(VALUE(MID(R0_L0!$C$82,'E(Ri) XOR ki+1'!$D9,1))+VALUE('Khóa k1-16'!J129),2) -> 1 | Q14: =MOD(VALUE(MID(R0_L0!$C$83,'E(Ri) XOR ki+1'!$D9,1))+VALUE('Khóa k1-16'!K129),2) -> 1 | R14: =MOD(VALUE(MID(R0_L0!$C$84,'E(Ri) XOR ki+1'!$D9,1))+VALUE('Khóa k1-16'!L129),2) -> 1 | S14: =MOD(VALUE(MID(R0_L0!$C$85,'E(Ri) XOR ki+1'!$D9,1))+VALUE('Khóa k1-16'!M129),2) -> 0 | T14: =MOD(VALUE(MID(R0_L0!$C$86,'E(Ri) XOR ki+1'!$D9,1))+VALUE('Khóa k1-16'!N129),2) -> 0 | U14: =MOD(VALUE(MID(R0_L0!$C$87,'E(Ri) XOR ki+1'!$D9,1))+VALUE('Khóa k1-16'!O129),2) -> 0 | V14: =MOD(VALUE(MID(R0_L0!$C$88,'E(Ri) XOR ki+1'!$D9,1))+VALUE('Khóa k1-16'!P129),2) -> 0 | W14: =MOD(VALUE(MID(R0_L0!$C$89,'E(Ri) XOR ki+1'!$D9,1))+VALUE('Khóa k1-16'!Q129),2) -> 1 | X14: =MOD(VALUE(MID(R0_L0!$C$90,'E(Ri) XOR ki+1'!$D9,1))+VALUE('Khóa k1-16'!R129),2) -> 0
A15: 12 | B15: 36 | C15: =MID($E$1,B15,1) -> 1 | D15: 9 | E15: 15 | G15: 7 | H15: =MOD(VALUE(MID($O$4,D10,1)) + VALUE('Khóa k1-16'!B130),2) -> 1 | I15: =MOD(VALUE(MID(R0_L0!$C$75,'E(Ri) XOR ki+1'!D10,1))+VALUE('Khóa k1-16'!C130),2) -> 0 | J15: =MOD(VALUE(MID(R0_L0!$C$76,'E(Ri) XOR ki+1'!$D10,1))+VALUE('Khóa k1-16'!D130),2) -> 0 | K15: =MOD(VALUE(MID(R0_L0!$C$77,'E(Ri) XOR ki+1'!D10,1))+VALUE('Khóa k1-16'!E130),2) -> 0 | L15: =MOD(VALUE(MID(R0_L0!$C$78,'E(Ri) XOR ki+1'!D10,1))+VALUE('Khóa k1-16'!F130),2) -> 1 | M15: =MOD(VALUE(MID(R0_L0!$C$79,'E(Ri) XOR ki+1'!$D10,1))+VALUE('Khóa k1-16'!G130),2) -> 1 | N15: =MOD(VALUE(MID(R0_L0!$C$80,'E(Ri) XOR ki+1'!$D10,1))+VALUE('Khóa k1-16'!H130),2) -> 1 | O15: =MOD(VALUE(MID(R0_L0!$C$81,'E(Ri) XOR ki+1'!$D10,1))+VALUE('Khóa k1-16'!I130),2) -> 1 | P15: =MOD(VALUE(MID(R0_L0!$C$82,'E(Ri) XOR ki+1'!$D10,1))+VALUE('Khóa k1-16'!J130),2) -> 1 | Q15: =MOD(VALUE(MID(R0_L0!$C$83,'E(Ri) XOR ki+1'!$D10,1))+VALUE('Khóa k1-16'!K130),2) -> 1 | R15: =MOD(VALUE(MID(R0_L0!$C$84,'E(Ri) XOR ki+1'!$D10,1))+VALUE('Khóa k1-16'!L130),2) -> 0 | S15: =MOD(VALUE(MID(R0_L0!$C$85,'E(Ri) XOR ki+1'!$D10,1))+VALUE('Khóa k1-16'!M130),2) -> 0 | T15: =MOD(VALUE(MID(R0_L0!$C$86,'E(Ri) XOR ki+1'!$D10,1))+VALUE('Khóa k1-16'!N130),2) -> 1 | U15: =MOD(VALUE(MID(R0_L0!$C$87,'E(Ri) XOR ki+1'!$D10,1))+VALUE('Khóa k1-16'!O130),2) -> 0 | V15: =MOD(VALUE(MID(R0_L0!$C$88,'E(Ri) XOR ki+1'!$D10,1))+VALUE('Khóa k1-16'!P130),2) -> 0 | W15: =MOD(VALUE(MID(R0_L0!$C$89,'E(Ri) XOR ki+1'!$D10,1))+VALUE('Khóa k1-16'!Q130),2) -> 1 | X15: =MOD(VALUE(MID(R0_L0!$C$90,'E(Ri) XOR ki+1'!$D10,1))+VALUE('Khóa k1-16'!R130),2) -> 1
A16: 13 | B16: 28 | C16: =MID($E$1,B16,1) -> 1 | D16: 8 | E16: 55 | G16: 8 | H16: =MOD(VALUE(MID($O$4,D11,1)) + VALUE('Khóa k1-16'!B131),2) -> 1 | I16: =MOD(VALUE(MID(R0_L0!$C$75,'E(Ri) XOR ki+1'!D11,1))+VALUE('Khóa k1-16'!C131),2) -> 0 | J16: =MOD(VALUE(MID(R0_L0!$C$76,'E(Ri) XOR ki+1'!$D11,1))+VALUE('Khóa k1-16'!D131),2) -> 0 | K16: =MOD(VALUE(MID(R0_L0!$C$77,'E(Ri) XOR ki+1'!D11,1))+VALUE('Khóa k1-16'!E131),2) -> 0 | L16: =MOD(VALUE(MID(R0_L0!$C$78,'E(Ri) XOR ki+1'!D11,1))+VALUE('Khóa k1-16'!F131),2) -> 1 | M16: =MOD(VALUE(MID(R0_L0!$C$79,'E(Ri) XOR ki+1'!$D11,1))+VALUE('Khóa k1-16'!G131),2) -> 0 | N16: =MOD(VALUE(MID(R0_L0!$C$80,'E(Ri) XOR ki+1'!$D11,1))+VALUE('Khóa k1-16'!H131),2) -> 0 | O16: =MOD(VALUE(MID(R0_L0!$C$81,'E(Ri) XOR ki+1'!$D11,1))+VALUE('Khóa k1-16'!I131),2) -> 1 | P16: =MOD(VALUE(MID(R0_L0!$C$82,'E(Ri) XOR ki+1'!$D11,1))+VALUE('Khóa k1-16'!J131),2) -> 1 | Q16: =MOD(VALUE(MID(R0_L0!$C$83,'E(Ri) XOR ki+1'!$D11,1))+VALUE('Khóa k1-16'!K131),2) -> 0 | R16: =MOD(VALUE(MID(R0_L0!$C$84,'E(Ri) XOR ki+1'!$D11,1))+VALUE('Khóa k1-16'!L131),2) -> 0 | S16: =MOD(VALUE(MID(R0_L0!$C$85,'E(Ri) XOR ki+1'!$D11,1))+VALUE('Khóa k1-16'!M131),2) -> 1 | T16: =MOD(VALUE(MID(R0_L0!$C$86,'E(Ri) XOR ki+1'!$D11,1))+VALUE('Khóa k1-16'!N131),2) -> 0 | U16: =MOD(VALUE(MID(R0_L0!$C$87,'E(Ri) XOR ki+1'!$D11,1))+VALUE('Khóa k1-16'!O131),2) -> 0 | V16: =MOD(VALUE(MID(R0_L0!$C$88,'E(Ri) XOR ki+1'!$D11,1))+VALUE('Khóa k1-16'!P131),2) -> 0 | W16: =MOD(VALUE(MID(R0_L0!$C$89,'E(Ri) XOR ki+1'!$D11,1))+VALUE('Khóa k1-16'!Q131),2) -> 0 | X16: =MOD(VALUE(MID(R0_L0!$C$90,'E(Ri) XOR ki+1'!$D11,1))+VALUE('Khóa k1-16'!R131),2) -> 0
A17: 14 | B17: 20 | C17: =MID($E$1,B17,1) -> 1 | D17: 9 | E17: 23 | G17: 9 | H17: =MOD(VALUE(MID($O$4,D12,1)) + VALUE('Khóa k1-16'!B132),2) -> 0 | I17: =MOD(VALUE(MID(R0_L0!$C$75,'E(Ri) XOR ki+1'!D12,1))+VALUE('Khóa k1-16'!C132),2) -> 0 | J17: =MOD(VALUE(MID(R0_L0!$C$76,'E(Ri) XOR ki+1'!$D12,1))+VALUE('Khóa k1-16'!D132),2) -> 1 | K17: =MOD(VALUE(MID(R0_L0!$C$77,'E(Ri) XOR ki+1'!D12,1))+VALUE('Khóa k1-16'!E132),2) -> 0 | L17: =MOD(VALUE(MID(R0_L0!$C$78,'E(Ri) XOR ki+1'!D12,1))+VALUE('Khóa k1-16'!F132),2) -> 0 | M17: =MOD(VALUE(MID(R0_L0!$C$79,'E(Ri) XOR ki+1'!$D12,1))+VALUE('Khóa k1-16'!G132),2) -> 0 | N17: =MOD(VALUE(MID(R0_L0!$C$80,'E(Ri) XOR ki+1'!$D12,1))+VALUE('Khóa k1-16'!H132),2) -> 1 | O17: =MOD(VALUE(MID(R0_L0!$C$81,'E(Ri) XOR ki+1'!$D12,1))+VALUE('Khóa k1-16'!I132),2) -> 1 | P17: =MOD(VALUE(MID(R0_L0!$C$82,'E(Ri) XOR ki+1'!$D12,1))+VALUE('Khóa k1-16'!J132),2) -> 0 | Q17: =MOD(VALUE(MID(R0_L0!$C$83,'E(Ri) XOR ki+1'!$D12,1))+VALUE('Khóa k1-16'!K132),2) -> 1 | R17: =MOD(VALUE(MID(R0_L0!$C$84,'E(Ri) XOR ki+1'!$D12,1))+VALUE('Khóa k1-16'!L132),2) -> 0 | S17: =MOD(VALUE(MID(R0_L0!$C$85,'E(Ri) XOR ki+1'!$D12,1))+VALUE('Khóa k1-16'!M132),2) -> 1 | T17: =MOD(VALUE(MID(R0_L0!$C$86,'E(Ri) XOR ki+1'!$D12,1))+VALUE('Khóa k1-16'!N132),2) -> 1 | U17: =MOD(VALUE(MID(R0_L0!$C$87,'E(Ri) XOR ki+1'!$D12,1))+VALUE('Khóa k1-16'!O132),2) -> 1 | V17: =MOD(VALUE(MID(R0_L0!$C$88,'E(Ri) XOR ki+1'!$D12,1))+VALUE('Khóa k1-16'!P132),2) -> 0 | W17: =MOD(VALUE(MID(R0_L0!$C$89,'E(Ri) XOR ki+1'!$D12,1))+VALUE('Khóa k1-16'!Q132),2) -> 1 | X17: =MOD(VALUE(MID(R0_L0!$C$90,'E(Ri) XOR ki+1'!$D12,1))+VALUE('Khóa k1-16'!R132),2) -> 1
A18: 15 | B18: 12 | C18: =MID($E$1,B18,1) -> 1 | D18: 10 | E18: 63 | G18: 10 | H18: =MOD(VALUE(MID($O$4,D13,1)) + VALUE('Khóa k1-16'!B133),2) -> 0 | I18: =MOD(VALUE(MID(R0_L0!$C$75,'E(Ri) XOR ki+1'!D13,1))+VALUE('Khóa k1-16'!C133),2) -> 1 | J18: =MOD(VALUE(MID(R0_L0!$C$76,'E(Ri) XOR ki+1'!$D13,1))+VALUE('Khóa k1-16'!D133),2) -> 1 | K18: =MOD(VALUE(MID(R0_L0!$C$77,'E(Ri) XOR ki+1'!D13,1))+VALUE('Khóa k1-16'!E133),2) -> 0 | L18: =MOD(VALUE(MID(R0_L0!$C$78,'E(Ri) XOR ki+1'!D13,1))+VALUE('Khóa k1-16'!F133),2) -> 1 | M18: =MOD(VALUE(MID(R0_L0!$C$79,'E(Ri) XOR ki+1'!$D13,1))+VALUE('Khóa k1-16'!G133),2) -> 0 | N18: =MOD(VALUE(MID(R0_L0!$C$80,'E(Ri) XOR ki+1'!$D13,1))+VALUE('Khóa k1-16'!H133),2) -> 1 | O18: =MOD(VALUE(MID(R0_L0!$C$81,'E(Ri) XOR ki+1'!$D13,1))+VALUE('Khóa k1-16'!I133),2) -> 1 | P18: =MOD(VALUE(MID(R0_L0!$C$82,'E(Ri) XOR ki+1'!$D13,1))+VALUE('Khóa k1-16'!J133),2) -> 0 | Q18: =MOD(VALUE(MID(R0_L0!$C$83,'E(Ri) XOR ki+1'!$D13,1))+VALUE('Khóa k1-16'!K133),2) -> 1 | R18: =MOD(VALUE(MID(R0_L0!$C$84,'E(Ri) XOR ki+1'!$D13,1))+VALUE('Khóa k1-16'!L133),2) -> 0 | S18: =MOD(VALUE(MID(R0_L0!$C$85,'E(Ri) XOR ki+1'!$D13,1))+VALUE('Khóa k1-16'!M133),2) -> 1 | T18: =MOD(VALUE(MID(R0_L0!$C$86,'E(Ri) XOR ki+1'!$D13,1))+VALUE('Khóa k1-16'!N133),2) -> 0 | U18: =MOD(VALUE(MID(R0_L0!$C$87,'E(Ri) XOR ki+1'!$D13,1))+VALUE('Khóa k1-16'!O133),2) -> 0 | V18: =MOD(VALUE(MID(R0_L0!$C$88,'E(Ri) XOR ki+1'!$D13,1))+VALUE('Khóa k1-16'!P133),2) -> 1 | W18: =MOD(VALUE(MID(R0_L0!$C$89,'E(Ri) XOR ki+1'!$D13,1))+VALUE('Khóa k1-16'!Q133),2) -> 1 | X18: =MOD(VALUE(MID(R0_L0!$C$90,'E(Ri) XOR ki+1'!$D13,1))+VALUE('Khóa k1-16'!R133),2) -> 0
A19: 16 | B19: 4 | C19: =MID($E$1,B19,1) -> 0 | D19: 11 | E19: 31 | G19: 11 | H19: =MOD(VALUE(MID($O$4,D14,1)) + VALUE('Khóa k1-16'!B134),2) -> 0 | I19: =MOD(VALUE(MID(R0_L0!$C$75,'E(Ri) XOR ki+1'!D14,1))+VALUE('Khóa k1-16'!C134),2) -> 0 | J19: =MOD(VALUE(MID(R0_L0!$C$76,'E(Ri) XOR ki+1'!$D14,1))+VALUE('Khóa k1-16'!D134),2) -> 1 | K19: =MOD(VALUE(MID(R0_L0!$C$77,'E(Ri) XOR ki+1'!D14,1))+VALUE('Khóa k1-16'!E134),2) -> 0 | L19: =MOD(VALUE(MID(R0_L0!$C$78,'E(Ri) XOR ki+1'!D14,1))+VALUE('Khóa k1-16'!F134),2) -> 1 | M19: =MOD(VALUE(MID(R0_L0!$C$79,'E(Ri) XOR ki+1'!$D14,1))+VALUE('Khóa k1-16'!G134),2) -> 0 | N19: =MOD(VALUE(MID(R0_L0!$C$80,'E(Ri) XOR ki+1'!$D14,1))+VALUE('Khóa k1-16'!H134),2) -> 1 | O19: =MOD(VALUE(MID(R0_L0!$C$81,'E(Ri) XOR ki+1'!$D14,1))+VALUE('Khóa k1-16'!I134),2) -> 1 | P19: =MOD(VALUE(MID(R0_L0!$C$82,'E(Ri) XOR ki+1'!$D14,1))+VALUE('Khóa k1-16'!J134),2) -> 1 | Q19: =MOD(VALUE(MID(R0_L0!$C$83,'E(Ri) XOR ki+1'!$D14,1))+VALUE('Khóa k1-16'!K134),2) -> 1 | R19: =MOD(VALUE(MID(R0_L0!$C$84,'E(Ri) XOR ki+1'!$D14,1))+VALUE('Khóa k1-16'!L134),2) -> 0 | S19: =MOD(VALUE(MID(R0_L0!$C$85,'E(Ri) XOR ki+1'!$D14,1))+VALUE('Khóa k1-16'!M134),2) -> 1 | T19: =MOD(VALUE(MID(R0_L0!$C$86,'E(Ri) XOR ki+1'!$D14,1))+VALUE('Khóa k1-16'!N134),2) -> 0 | U19: =MOD(VALUE(MID(R0_L0!$C$87,'E(Ri) XOR ki+1'!$D14,1))+VALUE('Khóa k1-16'!O134),2) -> 1 | V19: =MOD(VALUE(MID(R0_L0!$C$88,'E(Ri) XOR ki+1'!$D14,1))+VALUE('Khóa k1-16'!P134),2) -> 1 | W19: =MOD(VALUE(MID(R0_L0!$C$89,'E(Ri) XOR ki+1'!$D14,1))+VALUE('Khóa k1-16'!Q134),2) -> 1 | X19: =MOD(VALUE(MID(R0_L0!$C$90,'E(Ri) XOR ki+1'!$D14,1))+VALUE('Khóa k1-16'!R134),2) -> 0
A20: 17 | B20: 62 | C20: =MID($E$1,B20,1) -> 1 | D20: 12 | E20: 38 | G20: 12 | H20: =MOD(VALUE(MID($O$4,D15,1)) + VALUE('Khóa k1-16'!B135),2) -> 0 | I20: =MOD(VALUE(MID(R0_L0!$C$75,'E(Ri) XOR ki+1'!D15,1))+VALUE('Khóa k1-16'!C135),2) -> 0 | J20: =MOD(VALUE(MID(R0_L0!$C$76,'E(Ri) XOR ki+1'!$D15,1))+VALUE('Khóa k1-16'!D135),2) -> 1 | K20: =MOD(VALUE(MID(R0_L0!$C$77,'E(Ri) XOR ki+1'!D15,1))+VALUE('Khóa k1-16'!E135),2) -> 0 | L20: =MOD(VALUE(MID(R0_L0!$C$78,'E(Ri) XOR ki+1'!D15,1))+VALUE('Khóa k1-16'!F135),2) -> 0 | M20: =MOD(VALUE(MID(R0_L0!$C$79,'E(Ri) XOR ki+1'!$D15,1))+VALUE('Khóa k1-16'!G135),2) -> 0 | N20: =MOD(VALUE(MID(R0_L0!$C$80,'E(Ri) XOR ki+1'!$D15,1))+VALUE('Khóa k1-16'!H135),2) -> 1 | O20: =MOD(VALUE(MID(R0_L0!$C$81,'E(Ri) XOR ki+1'!$D15,1))+VALUE('Khóa k1-16'!I135),2) -> 0 | P20: =MOD(VALUE(MID(R0_L0!$C$82,'E(Ri) XOR ki+1'!$D15,1))+VALUE('Khóa k1-16'!J135),2) -> 1 | Q20: =MOD(VALUE(MID(R0_L0!$C$83,'E(Ri) XOR ki+1'!$D15,1))+VALUE('Khóa k1-16'!K135),2) -> 1 | R20: =MOD(VALUE(MID(R0_L0!$C$84,'E(Ri) XOR ki+1'!$D15,1))+VALUE('Khóa k1-16'!L135),2) -> 1 | S20: =MOD(VALUE(MID(R0_L0!$C$85,'E(Ri) XOR ki+1'!$D15,1))+VALUE('Khóa k1-16'!M135),2) -> 0 | T20: =MOD(VALUE(MID(R0_L0!$C$86,'E(Ri) XOR ki+1'!$D15,1))+VALUE('Khóa k1-16'!N135),2) -> 0 | U20: =MOD(VALUE(MID(R0_L0!$C$87,'E(Ri) XOR ki+1'!$D15,1))+VALUE('Khóa k1-16'!O135),2) -> 0 | V20: =MOD(VALUE(MID(R0_L0!$C$88,'E(Ri) XOR ki+1'!$D15,1))+VALUE('Khóa k1-16'!P135),2) -> 0 | W20: =MOD(VALUE(MID(R0_L0!$C$89,'E(Ri) XOR ki+1'!$D15,1))+VALUE('Khóa k1-16'!Q135),2) -> 1 | X20: =MOD(VALUE(MID(R0_L0!$C$90,'E(Ri) XOR ki+1'!$D15,1))+VALUE('Khóa k1-16'!R135),2) -> 0
... A51: 48 | B51: 3 | C51: =MID($E$1,B51,1) -> 0 | D51: 1 | E51: 27 | G51: 43 | H51: =MOD(VALUE(MID($O$4,D46,1)) + VALUE('Khóa k1-16'!B166),2) -> 1 | I51: =MOD(VALUE(MID(R0_L0!$C$75,'E(Ri) XOR ki+1'!D46,1))+VALUE('Khóa k1-16'!C166),2) -> 0 | J51: =MOD(VALUE(MID(R0_L0!$C$76,'E(Ri) XOR ki+1'!$D46,1))+VALUE('Khóa k1-16'!D166),2) -> 0 | K51: =MOD(VALUE(MID(R0_L0!$C$77,'E(Ri) XOR ki+1'!D46,1))+VALUE('Khóa k1-16'!E166),2) -> 0 | L51: =MOD(VALUE(MID(R0_L0!$C$78,'E(Ri) XOR ki+1'!D46,1))+VALUE('Khóa k1-16'!F166),2) -> 1 | M51: =MOD(VALUE(MID(R0_L0!$C$79,'E(Ri) XOR ki+1'!$D46,1))+VALUE('Khóa k1-16'!G166),2) -> 1 | N51: =MOD(VALUE(MID(R0_L0!$C$80,'E(Ri) XOR ki+1'!$D46,1))+VALUE('Khóa k1-16'!H166),2) -> 1 | O51: =MOD(VALUE(MID(R0_L0!$C$81,'E(Ri) XOR ki+1'!$D46,1))+VALUE('Khóa k1-16'!I166),2) -> 1 | P51: =MOD(VALUE(MID(R0_L0!$C$82,'E(Ri) XOR ki+1'!$D46,1))+VALUE('Khóa k1-16'!J166),2) -> 1 | Q51: =MOD(VALUE(MID(R0_L0!$C$83,'E(Ri) XOR ki+1'!$D46,1))+VALUE('Khóa k1-16'!K166),2) -> 1 | R51: =MOD(VALUE(MID(R0_L0!$C$84,'E(Ri) XOR ki+1'!$D46,1))+VALUE('Khóa k1-16'!L166),2) -> 1 | S51: =MOD(VALUE(MID(R0_L0!$C$85,'E(Ri) XOR ki+1'!$D46,1))+VALUE('Khóa k1-16'!M166),2) -> 0 | T51: =MOD(VALUE(MID(R0_L0!$C$86,'E(Ri) XOR ki+1'!$D46,1))+VALUE('Khóa k1-16'!N166),2) -> 1 | U51: =MOD(VALUE(MID(R0_L0!$C$87,'E(Ri) XOR ki+1'!$D46,1))+VALUE('Khóa k1-16'!O166),2) -> 0 | V51: =MOD(VALUE(MID(R0_L0!$C$88,'E(Ri) XOR ki+1'!$D46,1))+VALUE('Khóa k1-16'!P166),2) -> 1 | W51: =MOD(VALUE(MID(R0_L0!$C$89,'E(Ri) XOR ki+1'!$D46,1))+VALUE('Khóa k1-16'!Q166),2) -> 0 | X51: =MOD(VALUE(MID(R0_L0!$C$90,'E(Ri) XOR ki+1'!$D46,1))+VALUE('Khóa k1-16'!R166),2) -> 0
A52: 49 | B52: 61 | C52: =MID($E$1,B52,1) -> 1 | E52: 34 | G52: 44 | H52: =MOD(VALUE(MID($O$4,D47,1)) + VALUE('Khóa k1-16'!B167),2) -> 1 | I52: =MOD(VALUE(MID(R0_L0!$C$75,'E(Ri) XOR ki+1'!D47,1))+VALUE('Khóa k1-16'!C167),2) -> 1 | J52: =MOD(VALUE(MID(R0_L0!$C$76,'E(Ri) XOR ki+1'!$D47,1))+VALUE('Khóa k1-16'!D167),2) -> 1 | K52: =MOD(VALUE(MID(R0_L0!$C$77,'E(Ri) XOR ki+1'!D47,1))+VALUE('Khóa k1-16'!E167),2) -> 0 | L52: =MOD(VALUE(MID(R0_L0!$C$78,'E(Ri) XOR ki+1'!D47,1))+VALUE('Khóa k1-16'!F167),2) -> 0 | M52: =MOD(VALUE(MID(R0_L0!$C$79,'E(Ri) XOR ki+1'!$D47,1))+VALUE('Khóa k1-16'!G167),2) -> 0 | N52: =MOD(VALUE(MID(R0_L0!$C$80,'E(Ri) XOR ki+1'!$D47,1))+VALUE('Khóa k1-16'!H167),2) -> 0 | O52: =MOD(VALUE(MID(R0_L0!$C$81,'E(Ri) XOR ki+1'!$D47,1))+VALUE('Khóa k1-16'!I167),2) -> 0 | P52: =MOD(VALUE(MID(R0_L0!$C$82,'E(Ri) XOR ki+1'!$D47,1))+VALUE('Khóa k1-16'!J167),2) -> 0 | Q52: =MOD(VALUE(MID(R0_L0!$C$83,'E(Ri) XOR ki+1'!$D47,1))+VALUE('Khóa k1-16'!K167),2) -> 1 | R52: =MOD(VALUE(MID(R0_L0!$C$84,'E(Ri) XOR ki+1'!$D47,1))+VALUE('Khóa k1-16'!L167),2) -> 0 | S52: =MOD(VALUE(MID(R0_L0!$C$85,'E(Ri) XOR ki+1'!$D47,1))+VALUE('Khóa k1-16'!M167),2) -> 1 | T52: =MOD(VALUE(MID(R0_L0!$C$86,'E(Ri) XOR ki+1'!$D47,1))+VALUE('Khóa k1-16'!N167),2) -> 0 | U52: =MOD(VALUE(MID(R0_L0!$C$87,'E(Ri) XOR ki+1'!$D47,1))+VALUE('Khóa k1-16'!O167),2) -> 0 | V52: =MOD(VALUE(MID(R0_L0!$C$88,'E(Ri) XOR ki+1'!$D47,1))+VALUE('Khóa k1-16'!P167),2) -> 1 | W52: =MOD(VALUE(MID(R0_L0!$C$89,'E(Ri) XOR ki+1'!$D47,1))+VALUE('Khóa k1-16'!Q167),2) -> 1 | X52: =MOD(VALUE(MID(R0_L0!$C$90,'E(Ri) XOR ki+1'!$D47,1))+VALUE('Khóa k1-16'!R167),2) -> 1
A53: 50 | B53: 53 | C53: =MID($E$1,B53,1) -> 1 | E53: 2 | G53: 45 | H53: =MOD(VALUE(MID($O$4,D48,1)) + VALUE('Khóa k1-16'!B168),2) -> 0 | I53: =MOD(VALUE(MID(R0_L0!$C$75,'E(Ri) XOR ki+1'!D48,1))+VALUE('Khóa k1-16'!C168),2) -> 0 | J53: =MOD(VALUE(MID(R0_L0!$C$76,'E(Ri) XOR ki+1'!$D48,1))+VALUE('Khóa k1-16'!D168),2) -> 0 | K53: =MOD(VALUE(MID(R0_L0!$C$77,'E(Ri) XOR ki+1'!D48,1))+VALUE('Khóa k1-16'!E168),2) -> 0 | L53: =MOD(VALUE(MID(R0_L0!$C$78,'E(Ri) XOR ki+1'!D48,1))+VALUE('Khóa k1-16'!F168),2) -> 0 | M53: =MOD(VALUE(MID(R0_L0!$C$79,'E(Ri) XOR ki+1'!$D48,1))+VALUE('Khóa k1-16'!G168),2) -> 1 | N53: =MOD(VALUE(MID(R0_L0!$C$80,'E(Ri) XOR ki+1'!$D48,1))+VALUE('Khóa k1-16'!H168),2) -> 1 | O53: =MOD(VALUE(MID(R0_L0!$C$81,'E(Ri) XOR ki+1'!$D48,1))+VALUE('Khóa k1-16'!I168),2) -> 1 | P53: =MOD(VALUE(MID(R0_L0!$C$82,'E(Ri) XOR ki+1'!$D48,1))+VALUE('Khóa k1-16'!J168),2) -> 0 | Q53: =MOD(VALUE(MID(R0_L0!$C$83,'E(Ri) XOR ki+1'!$D48,1))+VALUE('Khóa k1-16'!K168),2) -> 1 | R53: =MOD(VALUE(MID(R0_L0!$C$84,'E(Ri) XOR ki+1'!$D48,1))+VALUE('Khóa k1-16'!L168),2) -> 1 | S53: =MOD(VALUE(MID(R0_L0!$C$85,'E(Ri) XOR ki+1'!$D48,1))+VALUE('Khóa k1-16'!M168),2) -> 0 | T53: =MOD(VALUE(MID(R0_L0!$C$86,'E(Ri) XOR ki+1'!$D48,1))+VALUE('Khóa k1-16'!N168),2) -> 0 | U53: =MOD(VALUE(MID(R0_L0!$C$87,'E(Ri) XOR ki+1'!$D48,1))+VALUE('Khóa k1-16'!O168),2) -> 0 | V53: =MOD(VALUE(MID(R0_L0!$C$88,'E(Ri) XOR ki+1'!$D48,1))+VALUE('Khóa k1-16'!P168),2) -> 1 | W53: =MOD(VALUE(MID(R0_L0!$C$89,'E(Ri) XOR ki+1'!$D48,1))+VALUE('Khóa k1-16'!Q168),2) -> 1 | X53: =MOD(VALUE(MID(R0_L0!$C$90,'E(Ri) XOR ki+1'!$D48,1))+VALUE('Khóa k1-16'!R168),2) -> 0
A54: 51 | B54: 45 | C54: =MID($E$1,B54,1) -> 1 | E54: 42 | G54: 46 | H54: =MOD(VALUE(MID($O$4,D49,1)) + VALUE('Khóa k1-16'!B169),2) -> 0 | I54: =MOD(VALUE(MID(R0_L0!$C$75,'E(Ri) XOR ki+1'!D49,1))+VALUE('Khóa k1-16'!C169),2) -> 0 | J54: =MOD(VALUE(MID(R0_L0!$C$76,'E(Ri) XOR ki+1'!$D49,1))+VALUE('Khóa k1-16'!D169),2) -> 0 | K54: =MOD(VALUE(MID(R0_L0!$C$77,'E(Ri) XOR ki+1'!D49,1))+VALUE('Khóa k1-16'!E169),2) -> 1 | L54: =MOD(VALUE(MID(R0_L0!$C$78,'E(Ri) XOR ki+1'!D49,1))+VALUE('Khóa k1-16'!F169),2) -> 1 | M54: =MOD(VALUE(MID(R0_L0!$C$79,'E(Ri) XOR ki+1'!$D49,1))+VALUE('Khóa k1-16'!G169),2) -> 1 | N54: =MOD(VALUE(MID(R0_L0!$C$80,'E(Ri) XOR ki+1'!$D49,1))+VALUE('Khóa k1-16'!H169),2) -> 0 | O54: =MOD(VALUE(MID(R0_L0!$C$81,'E(Ri) XOR ki+1'!$D49,1))+VALUE('Khóa k1-16'!I169),2) -> 1 | P54: =MOD(VALUE(MID(R0_L0!$C$82,'E(Ri) XOR ki+1'!$D49,1))+VALUE('Khóa k1-16'!J169),2) -> 1 | Q54: =MOD(VALUE(MID(R0_L0!$C$83,'E(Ri) XOR ki+1'!$D49,1))+VALUE('Khóa k1-16'!K169),2) -> 0 | R54: =MOD(VALUE(MID(R0_L0!$C$84,'E(Ri) XOR ki+1'!$D49,1))+VALUE('Khóa k1-16'!L169),2) -> 0 | S54: =MOD(VALUE(MID(R0_L0!$C$85,'E(Ri) XOR ki+1'!$D49,1))+VALUE('Khóa k1-16'!M169),2) -> 1 | T54: =MOD(VALUE(MID(R0_L0!$C$86,'E(Ri) XOR ki+1'!$D49,1))+VALUE('Khóa k1-16'!N169),2) -> 0 | U54: =MOD(VALUE(MID(R0_L0!$C$87,'E(Ri) XOR ki+1'!$D49,1))+VALUE('Khóa k1-16'!O169),2) -> 0 | V54: =MOD(VALUE(MID(R0_L0!$C$88,'E(Ri) XOR ki+1'!$D49,1))+VALUE('Khóa k1-16'!P169),2) -> 0 | W54: =MOD(VALUE(MID(R0_L0!$C$89,'E(Ri) XOR ki+1'!$D49,1))+VALUE('Khóa k1-16'!Q169),2) -> 1 | X54: =MOD(VALUE(MID(R0_L0!$C$90,'E(Ri) XOR ki+1'!$D49,1))+VALUE('Khóa k1-16'!R169),2) -> 1
A55: 52 | B55: 37 | C55: =MID($E$1,B55,1) -> 1 | E55: 10 | G55: 47 | H55: =MOD(VALUE(MID($O$4,D50,1)) + VALUE('Khóa k1-16'!B170),2) -> 0 | I55: =MOD(VALUE(MID(R0_L0!$C$75,'E(Ri) XOR ki+1'!D50,1))+VALUE('Khóa k1-16'!C170),2) -> 1 | J55: =MOD(VALUE(MID(R0_L0!$C$76,'E(Ri) XOR ki+1'!$D50,1))+VALUE('Khóa k1-16'!D170),2) -> 0 | K55: =MOD(VALUE(MID(R0_L0!$C$77,'E(Ri) XOR ki+1'!D50,1))+VALUE('Khóa k1-16'!E170),2) -> 1 | L55: =MOD(VALUE(MID(R0_L0!$C$78,'E(Ri) XOR ki+1'!D50,1))+VALUE('Khóa k1-16'!F170),2) -> 0 | M55: =MOD(VALUE(MID(R0_L0!$C$79,'E(Ri) XOR ki+1'!$D50,1))+VALUE('Khóa k1-16'!G170),2) -> 1 | N55: =MOD(VALUE(MID(R0_L0!$C$80,'E(Ri) XOR ki+1'!$D50,1))+VALUE('Khóa k1-16'!H170),2) -> 1 | O55: =MOD(VALUE(MID(R0_L0!$C$81,'E(Ri) XOR ki+1'!$D50,1))+VALUE('Khóa k1-16'!I170),2) -> 1 | P55: =MOD(VALUE(MID(R0_L0!$C$82,'E(Ri) XOR ki+1'!$D50,1))+VALUE('Khóa k1-16'!J170),2) -> 0 | Q55: =MOD(VALUE(MID(R0_L0!$C$83,'E(Ri) XOR ki+1'!$D50,1))+VALUE('Khóa k1-16'!K170),2) -> 1 | R55: =MOD(VALUE(MID(R0_L0!$C$84,'E(Ri) XOR ki+1'!$D50,1))+VALUE('Khóa k1-16'!L170),2) -> 1 | S55: =MOD(VALUE(MID(R0_L0!$C$85,'E(Ri) XOR ki+1'!$D50,1))+VALUE('Khóa k1-16'!M170),2) -> 0 | T55: =MOD(VALUE(MID(R0_L0!$C$86,'E(Ri) XOR ki+1'!$D50,1))+VALUE('Khóa k1-16'!N170),2) -> 1 | U55: =MOD(VALUE(MID(R0_L0!$C$87,'E(Ri) XOR ki+1'!$D50,1))+VALUE('Khóa k1-16'!O170),2) -> 0 | V55: =MOD(VALUE(MID(R0_L0!$C$88,'E(Ri) XOR ki+1'!$D50,1))+VALUE('Khóa k1-16'!P170),2) -> 1 | W55: =MOD(VALUE(MID(R0_L0!$C$89,'E(Ri) XOR ki+1'!$D50,1))+VALUE('Khóa k1-16'!Q170),2) -> 0 | X55: =MOD(VALUE(MID(R0_L0!$C$90,'E(Ri) XOR ki+1'!$D50,1))+VALUE('Khóa k1-16'!R170),2) -> 0
A56: 53 | B56: 29 | C56: =MID($E$1,B56,1) -> 0 | E56: 50 | G56: 48 | H56: =MOD(VALUE(MID($O$4,D51,1)) + VALUE('Khóa k1-16'!B171),2) -> 0 | I56: =MOD(VALUE(MID(R0_L0!$C$75,'E(Ri) XOR ki+1'!D51,1))+VALUE('Khóa k1-16'!C171),2) -> 0 | J56: =MOD(VALUE(MID(R0_L0!$C$76,'E(Ri) XOR ki+1'!$D51,1))+VALUE('Khóa k1-16'!D171),2) -> 0 | K56: =MOD(VALUE(MID(R0_L0!$C$77,'E(Ri) XOR ki+1'!D51,1))+VALUE('Khóa k1-16'!E171),2) -> 0 | L56: =MOD(VALUE(MID(R0_L0!$C$78,'E(Ri) XOR ki+1'!D51,1))+VALUE('Khóa k1-16'!F171),2) -> 1 | M56: =MOD(VALUE(MID(R0_L0!$C$79,'E(Ri) XOR ki+1'!$D51,1))+VALUE('Khóa k1-16'!G171),2) -> 1 | N56: =MOD(VALUE(MID(R0_L0!$C$80,'E(Ri) XOR ki+1'!$D51,1))+VALUE('Khóa k1-16'!H171),2) -> 0 | O56: =MOD(VALUE(MID(R0_L0!$C$81,'E(Ri) XOR ki+1'!$D51,1))+VALUE('Khóa k1-16'!I171),2) -> 1 | P56: =MOD(VALUE(MID(R0_L0!$C$82,'E(Ri) XOR ki+1'!$D51,1))+VALUE('Khóa k1-16'!J171),2) -> 1 | Q56: =MOD(VALUE(MID(R0_L0!$C$83,'E(Ri) XOR ki+1'!$D51,1))+VALUE('Khóa k1-16'!K171),2) -> 1 | R56: =MOD(VALUE(MID(R0_L0!$C$84,'E(Ri) XOR ki+1'!$D51,1))+VALUE('Khóa k1-16'!L171),2) -> 1 | S56: =MOD(VALUE(MID(R0_L0!$C$85,'E(Ri) XOR ki+1'!$D51,1))+VALUE('Khóa k1-16'!M171),2) -> 1 | T56: =MOD(VALUE(MID(R0_L0!$C$86,'E(Ri) XOR ki+1'!$D51,1))+VALUE('Khóa k1-16'!N171),2) -> 0 | U56: =MOD(VALUE(MID(R0_L0!$C$87,'E(Ri) XOR ki+1'!$D51,1))+VALUE('Khóa k1-16'!O171),2) -> 1 | V56: =MOD(VALUE(MID(R0_L0!$C$88,'E(Ri) XOR ki+1'!$D51,1))+VALUE('Khóa k1-16'!P171),2) -> 0 | W56: =MOD(VALUE(MID(R0_L0!$C$89,'E(Ri) XOR ki+1'!$D51,1))+VALUE('Khóa k1-16'!Q171),2) -> 0 | X56: =MOD(VALUE(MID(R0_L0!$C$90,'E(Ri) XOR ki+1'!$D51,1))+VALUE('Khóa k1-16'!R171),2) -> 0
A57: 54 | B57: 21 | C57: =MID($E$1,B57,1) -> 0 | E57: 18
A58: 55 | B58: 13 | C58: =MID($E$1,B58,1) -> 0 | E58: 58
A59: 56 | B59: 5 | C59: =MID($E$1,B59,1) -> 0 | E59: 26 | G59: Chia thành các kí tự 6 bit
A60: 57 | B60: 63 | C60: =MID($E$1,B60,1) -> 1 | E60: 33
A61: 58 | B61: 55 | C61: =MID($E$1,B61,1) -> 0 | E61: 1 | G61: i | H61: 1 | I61: 2 | J61: 3 | K61: 4 | L61: 5 | M61: 6 | N61: 7 | O61: 8 | P61: 9 | Q61: 10 | R61: 11 | S61: 12 | T61: 13 | U61: 14 | V61: 15 | W61: 16
A62: 59 | B62: 47 | C62: =MID($E$1,B62,1) -> 1 | E62: 41 | G62: 1 | H62: =MID(_xlfn.TEXTJOIN("",TRUE,H$9:H$56), 1 + 6*($G62-1), 6) -> 011010 | I62: =MID(_xlfn.TEXTJOIN("",TRUE,I$9:I$56), 1 + 6*($G62-1), 6) -> 011011 | J62: =MID(_xlfn.TEXTJOIN("",TRUE,J$9:J$56), 1 + 6*($G62-1), 6) -> 111000 | K62: =MID(_xlfn.TEXTJOIN("",TRUE,K$9:K$56), 1 + 6*($G62-1), 6) -> 000110 | L62: =MID(_xlfn.TEXTJOIN("",TRUE,L$9:L$56), 1 + 6*($G62-1), 6) -> 101100 | M62: =MID(_xlfn.TEXTJOIN("",TRUE,M$9:M$56), 1 + 6*($G62-1), 6) -> 111001 | N62: =MID(_xlfn.TEXTJOIN("",TRUE,N$9:N$56), 1 + 6*($G62-1), 6) -> 011101 | O62: =MID(_xlfn.TEXTJOIN("",TRUE,O$9:O$56), 1 + 6*($G62-1), 6) -> 010101 | ... W62: =MID(_xlfn.TEXTJOIN("",TRUE,W$9:W$56), 1 + 6*($G62-1), 6) -> 011111
A63: 60 | B63: 39 | C63: =MID($E$1,B63,1) -> 0 | E63: 9 | G63: 2 | H63: =MID(_xlfn.TEXTJOIN("",TRUE,H$9:H$56), 1 + 6*($G63-1), 6) -> 110000 | I63: =MID(_xlfn.TEXTJOIN("",TRUE,I$9:I$56), 1 + 6*($G63-1), 6) -> 000100 | J63: =MID(_xlfn.TEXTJOIN("",TRUE,J$9:J$56), 1 + 6*($G63-1), 6) -> 001111 | K63: =MID(_xlfn.TEXTJOIN("",TRUE,K$9:K$56), 1 + 6*($G63-1), 6) -> 000000 | L63: =MID(_xlfn.TEXTJOIN("",TRUE,L$9:L$56), 1 + 6*($G63-1), 6) -> 110110 | M63: =MID(_xlfn.TEXTJOIN("",TRUE,M$9:M$56), 1 + 6*($G63-1), 6) -> 100000 | N63: =MID(_xlfn.TEXTJOIN("",TRUE,N$9:N$56), 1 + 6*($G63-1), 6) -> 101111 | O63: =MID(_xlfn.TEXTJOIN("",TRUE,O$9:O$56), 1 + 6*($G63-1), 6) -> 111110 | ... W63: =MID(_xlfn.TEXTJOIN("",TRUE,W$9:W$56), 1 + 6*($G63-1), 6) -> 101111
A64: 61 | B64: 31 | C64: =MID($E$1,B64,1) -> 1 | E64: 49 | G64: 3 | H64: =MID(_xlfn.TEXTJOIN("",TRUE,H$9:H$56), 1 + 6*($G64-1), 6) -> 000001 | I64: =MID(_xlfn.TEXTJOIN("",TRUE,I$9:I$56), 1 + 6*($G64-1), 6) -> 011110 | J64: =MID(_xlfn.TEXTJOIN("",TRUE,J$9:J$56), 1 + 6*($G64-1), 6) -> 110001 | K64: =MID(_xlfn.TEXTJOIN("",TRUE,K$9:K$56), 1 + 6*($G64-1), 6) -> 010101 | L64: =MID(_xlfn.TEXTJOIN("",TRUE,L$9:L$56), 1 + 6*($G64-1), 6) -> 111010 | M64: =MID(_xlfn.TEXTJOIN("",TRUE,M$9:M$56), 1 + 6*($G64-1), 6) -> 110000 | N64: =MID(_xlfn.TEXTJOIN("",TRUE,N$9:N$56), 1 + 6*($G64-1), 6) -> 100000 | O64: =MID(_xlfn.TEXTJOIN("",TRUE,O$9:O$56), 1 + 6*($G64-1), 6) -> 001110 | ... W64: =MID(_xlfn.TEXTJOIN("",TRUE,W$9:W$56), 1 + 6*($G64-1), 6) -> 111100
A65: 62 | B65: 23 | C65: =MID($E$1,B65,1) -> 0 | E65: 17 | G65: 4 | H65: =MID(_xlfn.TEXTJOIN("",TRUE,H$9:H$56), 1 + 6*($G65-1), 6) -> 000110 | I65: =MID(_xlfn.TEXTJOIN("",TRUE,I$9:I$56), 1 + 6*($G65-1), 6) -> 000110 | J65: =MID(_xlfn.TEXTJOIN("",TRUE,J$9:J$56), 1 + 6*($G65-1), 6) -> 110010 | K65: =MID(_xlfn.TEXTJOIN("",TRUE,K$9:K$56), 1 + 6*($G65-1), 6) -> 111011 | L65: =MID(_xlfn.TEXTJOIN("",TRUE,L$9:L$56), 1 + 6*($G65-1), 6) -> 101101 | M65: =MID(_xlfn.TEXTJOIN("",TRUE,M$9:M$56), 1 + 6*($G65-1), 6) -> 010011 | N65: =MID(_xlfn.TEXTJOIN("",TRUE,N$9:N$56), 1 + 6*($G65-1), 6) -> 010101 | O65: =MID(_xlfn.TEXTJOIN("",TRUE,O$9:O$56), 1 + 6*($G65-1), 6) -> 010101 | ... W65: =MID(_xlfn.TEXTJOIN("",TRUE,W$9:W$56), 1 + 6*($G65-1), 6) -> 000110
A66: 63 | B66: 15 | C66: =MID($E$1,B66,1) -> 1 | E66: 57 | G66: 5 | H66: =MID(_xlfn.TEXTJOIN("",TRUE,H$9:H$56), 1 + 6*($G66-1), 6) -> 101000 | I66: =MID(_xlfn.TEXTJOIN("",TRUE,I$9:I$56), 1 + 6*($G66-1), 6) -> 111100 | J66: =MID(_xlfn.TEXTJOIN("",TRUE,J$9:J$56), 1 + 6*($G66-1), 6) -> 100010 | K66: =MID(_xlfn.TEXTJOIN("",TRUE,K$9:K$56), 1 + 6*($G66-1), 6) -> 111010 | L66: =MID(_xlfn.TEXTJOIN("",TRUE,L$9:L$56), 1 + 6*($G66-1), 6) -> 100010 | M66: =MID(_xlfn.TEXTJOIN("",TRUE,M$9:M$56), 1 + 6*($G66-1), 6) -> 011000 | N66: =MID(_xlfn.TEXTJOIN("",TRUE,N$9:N$56), 1 + 6*($G66-1), 6) -> 000000 | O66: =MID(_xlfn.TEXTJOIN("",TRUE,O$9:O$56), 1 + 6*($G66-1), 6) -> 001000 | ... W66: =MID(_xlfn.TEXTJOIN("",TRUE,W$9:W$56), 1 + 6*($G66-1), 6) -> 110100
A67: 64 | B67: 7 | C67: =MID($E$1,B67,1) -> 0 | E67: 25 | G67: 6 | H67: =MID(_xlfn.TEXTJOIN("",TRUE,H$9:H$56), 1 + 6*($G67-1), 6) -> 010101 | I67: =MID(_xlfn.TEXTJOIN("",TRUE,I$9:I$56), 1 + 6*($G67-1), 6) -> 000101 | J67: =MID(_xlfn.TEXTJOIN("",TRUE,J$9:J$56), 1 + 6*($G67-1), 6) -> 110001 | K67: =MID(_xlfn.TEXTJOIN("",TRUE,K$9:K$56), 1 + 6*($G67-1), 6) -> 001110 | L67: =MID(_xlfn.TEXTJOIN("",TRUE,L$9:L$56), 1 + 6*($G67-1), 6) -> 100100 | M67: =MID(_xlfn.TEXTJOIN("",TRUE,M$9:M$56), 1 + 6*($G67-1), 6) -> 110101 | N67: =MID(_xlfn.TEXTJOIN("",TRUE,N$9:N$56), 1 + 6*($G67-1), 6) -> 000010 | O67: =MID(_xlfn.TEXTJOIN("",TRUE,O$9:O$56), 1 + 6*($G67-1), 6) -> 110000 | ... W67: =MID(_xlfn.TEXTJOIN("",TRUE,W$9:W$56), 1 + 6*($G67-1), 6) -> 110000
G68: 7 | H68: =MID(_xlfn.TEXTJOIN("",TRUE,H$9:H$56), 1 + 6*($G68-1), 6) -> 110011 | I68: =MID(_xlfn.TEXTJOIN("",TRUE,I$9:I$56), 1 + 6*($G68-1), 6) -> 011010 | J68: =MID(_xlfn.TEXTJOIN("",TRUE,J$9:J$56), 1 + 6*($G68-1), 6) -> 000111 | K68: =MID(_xlfn.TEXTJOIN("",TRUE,K$9:K$56), 1 + 6*($G68-1), 6) -> 111000 | L68: =MID(_xlfn.TEXTJOIN("",TRUE,L$9:L$56), 1 + 6*($G68-1), 6) -> 111001 | M68: =MID(_xlfn.TEXTJOIN("",TRUE,M$9:M$56), 1 + 6*($G68-1), 6) -> 001011 | N68: =MID(_xlfn.TEXTJOIN("",TRUE,N$9:N$56), 1 + 6*($G68-1), 6) -> 010101 | O68: =MID(_xlfn.TEXTJOIN("",TRUE,O$9:O$56), 1 + 6*($G68-1), 6) -> 110100 | ... W68: =MID(_xlfn.TEXTJOIN("",TRUE,W$9:W$56), 1 + 6*($G68-1), 6) -> 110111
G69: 8 | H69: =MID(_xlfn.TEXTJOIN("",TRUE,H$9:H$56), 1 + 6*($G69-1), 6) -> 110000 | I69: =MID(_xlfn.TEXTJOIN("",TRUE,I$9:I$56), 1 + 6*($G69-1), 6) -> 010010 | J69: =MID(_xlfn.TEXTJOIN("",TRUE,J$9:J$56), 1 + 6*($G69-1), 6) -> 010000 | K69: =MID(_xlfn.TEXTJOIN("",TRUE,K$9:K$56), 1 + 6*($G69-1), 6) -> 000110 | L69: =MID(_xlfn.TEXTJOIN("",TRUE,L$9:L$56), 1 + 6*($G69-1), 6) -> 100101 | M69: =MID(_xlfn.TEXTJOIN("",TRUE,M$9:M$56), 1 + 6*($G69-1), 6) -> 101111 | N69: =MID(_xlfn.TEXTJOIN("",TRUE,N$9:N$56), 1 + 6*($G69-1), 6) -> 101010 | O69: =MID(_xlfn.TEXTJOIN("",TRUE,O$9:O$56), 1 + 6*($G69-1), 6) -> 101111 | ... W69: =MID(_xlfn.TEXTJOIN("",TRUE,W$9:W$56), 1 + 6*($G69-1), 6) -> 011100
G71: Sau khi đi qua S_BOX thì kết quả là
G73: i | H73: 1 | I73: 2 | J73: 3 | K73: 4 | L73: 5 | M73: 6 | N73: 7 | O73: 8 | P73: 9 | Q73: 10 | R73: 11 | S73: 12 | T73: 13 | U73: 14 | V73: 15 | W73: 16
...

Sheet R0_L0
A1: IP(M) = | B1: ='E(Ri) XOR ki+1'!O1 -> 1001100011111110110011000000000011100000010101001111000010101010
A3: L0 = | B3: =LEFT(B1,32) -> 10011000111111101100110000000000 | G3: R0 = | H3: =RIGHT(B1,32) -> 11100000010101001111000010101010
A5: STT | B5: L0 | C5: L1 | D5: L2 | E5: L3 | F5: L4 | G5: L5 | H5: L6 | I5: L7 | J5: L8 | K5: L9 | L5: L10 | M5: L11 | N5: L12 | O5: L13 | P5: L14 | Q5: L15 | R5: L16
A6: 1 | B6: =MID($B$3,ROW(A1),1) -> 1 | C6: =B41 -> 1 | D6: =C41 -> 0 | E6: =D41 -> 0 | F6: =E41 -> 1 | G6: =F41 -> 1 | H6: =G41 -> 0 | I6: =H41 -> 0 | J6: =I41 -> 0 | ... R6: =Q41 -> 0
A7: 2 | B7: =MID($B$3,ROW(A2),1) -> 0 | C7: =B42 -> 1 | D7: =C42 -> 0 | E7: =D42 -> 1 | F7: =E42 -> 1 | G7: =F42 -> 0 | H7: =G42 -> 0 | I7: =H42 -> 0 | J7: =I42 -> 1 | ... R7: =Q42 -> 1
A8: 3 | B8: =MID($B$3,ROW(A3),1) -> 0 | C8: =B43 -> 1 | D8: =C43 -> 0 | E8: =D43 -> 1 | F8: =E43 -> 0 | G8: =F43 -> 0 | H8: =G43 -> 0 | I8: =H43 -> 1 | J8: =I43 -> 0 | ... R8: =Q43 -> 1
A9: 4 | B9: =MID($B$3,ROW(A4),1) -> 1 | C9: =B44 -> 0 | D9: =C44 -> 0 | E9: =D44 -> 0 | F9: =E44 -> 1 | G9: =F44 -> 1 | H9: =G44 -> 0 | I9: =H44 -> 1 | J9: =I44 -> 0 | ... R9: =Q44 -> 0
A10: 5 | B10: =MID($B$3,ROW(A5),1) -> 1 | C10: =B45 -> 0 | D10: =C45 -> 1 | E10: =D45 -> 1 | F10: =E45 -> 0 | G10: =F45 -> 1 | H10: =G45 -> 1 | I10: =H45 -> 0 | J10: =I45 -> 0 | ... R10: =Q45 -> 1
A11: 6 | B11: =MID($B$3,ROW(A6),1) -> 0 | C11: =B46 -> 0 | D11: =C46 -> 1 | E11: =D46 -> 0 | F11: =E46 -> 1 | G11: =F46 -> 1 | H11: =G46 -> 1 | I11: =H46 -> 0 | J11: =I46 -> 0 | ... R11: =Q46 -> 1
A12: 7 | B12: =MID($B$3,ROW(A7),1) -> 0 | C12: =B47 -> 0 | D12: =C47 -> 1 | E12: =D47 -> 0 | F12: =E47 -> 0 | G12: =F47 -> 0 | H12: =G47 -> 0 | I12: =H47 -> 1 | J12: =I47 -> 1 | ... R12: =Q47 -> 1
A13: 8 | B13: =MID($B$3,ROW(A8),1) -> 0 | C13: =B48 -> 0 | D13: =C48 -> 1 | E13: =D48 -> 0 | F13: =E48 -> 1 | G13: =F48 -> 0 | H13: =G48 -> 1 | I13: =H48 -> 1 | J13: =I48 -> 1 | ... R13: =Q48 -> 0
A14: 9 | B14: =MID($B$3,ROW(A9),1) -> 1 | C14: =B49 -> 0 | D14: =C49 -> 0 | E14: =D49 -> 0 | F14: =E49 -> 0 | G14: =F49 -> 0 | H14: =G49 -> 0 | I14: =H49 -> 1 | J14: =I49 -> 0 | ... R14: =Q49 -> 0
A15: 10 | B15: =MID($B$3,ROW(A10),1) -> 1 | C15: =B50 -> 1 | D15: =C50 -> 0 | E15: =D50 -> 0 | F15: =E50 -> 0 | G15: =F50 -> 1 | H15: =G50 -> 0 | I15: =H50 -> 0 | J15: =I50 -> 1 | ... R15: =Q50 -> 1
A16: 11 | B16: =MID($B$3,ROW(A11),1) -> 1 | C16: =B51 -> 0 | D16: =C51 -> 1 | E16: =D51 -> 0 | F16: =E51 -> 0 | G16: =F51 -> 0 | H16: =G51 -> 1 | I16: =H51 -> 0 | J16: =I51 -> 1 | ... R16: =Q51 -> 0
A17: 12 | B17: =MID($B$3,ROW(A12),1) -> 1 | C17: =B52 -> 1 | D17: =C52 -> 0 | E17: =D52 -> 1 | F17: =E52 -> 1 | G17: =F52 -> 1 | H17: =G52 -> 0 | I17: =H52 -> 1 | J17: =I52 -> 1 | ... R17: =Q52 -> 0
... A37: 32 | B37: =MID($B$3,ROW(A32),1) -> 0 | C37: =B72 -> 0 | D37: =C72 -> 0 | E37: =D72 -> 1 | F37: =E72 -> 0 | G37: =F72 -> 1 | H37: =G72 -> 1 | I37: =H72 -> 0 | J37: =I72 -> 1 | ... R37: =Q72 -> 1
A40: STT | B40: R0 | C40: R1 | D40: R2 | E40: R3 | F40: R4 | G40: R5 | H40: R6 | I40: R7 | J40: R8 | K40: R9 | L40: R10 | M40: R11 | N40: R12 | O40: R13 | P40: R14 | Q40: R15 | R40: R16
A41: 1 | B41: =MID($H$3, ROW(A1),1) -> 1 | C41: =MOD(B6 + MID('E(Ri) XOR ki+1'!$H$85, ROW(R0_L0!A1),1),2) -> 0 | D41: =MOD(C6+MID('E(Ri) XOR ki+1'!$H$86,ROW(R0_L0!$A1),1),2) -> 0 | E41: =MOD(D6+MID('E(Ri) XOR ki+1'!$H$87,ROW(R0_L0!A1),1),2) -> 1 | F41: =MOD(E6+MID('E(Ri) XOR ki+1'!$H$88,ROW(R0_L0!A1),1),2) -> 1 | G41: =MOD(F6+MID('E(Ri) XOR ki+1'!$H$89,ROW(R0_L0!$A1),1),2) -> 0 | H41: =MOD(G6+MID('E(Ri) XOR ki+1'!$H$90,ROW(R0_L0!$A1),1),2) -> 0 | I41: =MOD(H6+MID('E(Ri) XOR ki+1'!$H$91,ROW(R0_L0!$A1),1),2) -> 0 | J41: =MOD(I6+MID('E(Ri) XOR ki+1'!$H$92,ROW(R0_L0!$A1),1),2) -> 0 | K41: =MOD(J6+MID('E(Ri) XOR ki+1'!$H$93,ROW(R0_L0!$A1),1),2) -> 1 | L41: =MOD(K6+MID('E(Ri) XOR ki+1'!$H$94,ROW(R0_L0!$A1),1),2) -> 1 | M41: =MOD(L6+MID('E(Ri) XOR ki+1'!$H$95,ROW(R0_L0!$A1),1),2) -> 0 | N41: =MOD(M6+MID('E(Ri) XOR ki+1'!$H$96,ROW(R0_L0!$A1),1),2) -> 1 | O41: =MOD(N6+MID('E(Ri) XOR ki+1'!$H$97,ROW(R0_L0!$A1),1),2) -> 0 | P41: =MOD(O6+MID('E(Ri) XOR ki+1'!$H$98,ROW(R0_L0!$A1),1),2) -> 1 | Q41: =MOD(P6+MID('E(Ri) XOR ki+1'!$H$99,ROW(R0_L0!$A1),1),2) -> 0 | R41: =MOD(Q6+MID('E(Ri) XOR ki+1'!$H$100,ROW(R0_L0!$A1),1),2) -> 0
A42: 2 | B42: =MID($H$3, ROW(A2),1) -> 1 | C42: =MOD(B7 + MID('E(Ri) XOR ki+1'!$H$85, ROW(R0_L0!A2),1),2) -> 0 | D42: =MOD(C7+MID('E(Ri) XOR ki+1'!$H$86,ROW(R0_L0!$A2),1),2) -> 1 | E42: =MOD(D7+MID('E(Ri) XOR ki+1'!$H$87,ROW(R0_L0!A2),1),2) -> 1 | F42: =MOD(E7+MID('E(Ri) XOR ki+1'!$H$88,ROW(R0_L0!A2),1),2) -> 0 | G42: =MOD(F7+MID('E(Ri) XOR ki+1'!$H$89,ROW(R0_L0!$A2),1),2) -> 0 | H42: =MOD(G7+MID('E(Ri) XOR ki+1'!$H$90,ROW(R0_L0!$A2),1),2) -> 0 | I42: =MOD(H7+MID('E(Ri) XOR ki+1'!$H$91,ROW(R0_L0!$A2),1),2) -> 1 | J42: =MOD(I7+MID('E(Ri) XOR ki+1'!$H$92,ROW(R0_L0!$A2),1),2) -> 1 | K42: =MOD(J7+MID('E(Ri) XOR ki+1'!$H$93,ROW(R0_L0!$A2),1),2) -> 0 | L42: =MOD(K7+MID('E(Ri) XOR ki+1'!$H$94,ROW(R0_L0!$A2),1),2) -> 0 | M42: =MOD(L7+MID('E(Ri) XOR ki+1'!$H$95,ROW(R0_L0!$A2),1),2) -> 1 | N42: =MOD(M7+MID('E(Ri) XOR ki+1'!$H$96,ROW(R0_L0!$A2),1),2) -> 1 | O42: =MOD(N7+MID('E(Ri) XOR ki+1'!$H$97,ROW(R0_L0!$A2),1),2) -> 0 | P42: =MOD(O7+MID('E(Ri) XOR ki+1'!$H$98,ROW(R0_L0!$A2),1),2) -> 0 | Q42: =MOD(P7+MID('E(Ri) XOR ki+1'!$H$99,ROW(R0_L0!$A2),1),2) -> 1 | R42: =MOD(Q7+MID('E(Ri) XOR ki+1'!$H$100,ROW(R0_L0!$A2),1),2) -> 1
A43: 3 | B43: =MID($H$3, ROW(A3),1) -> 1 | C43: =MOD(B8 + MID('E(Ri) XOR ki+1'!$H$85, ROW(R0_L0!A3),1),2) -> 0 | D43: =MOD(C8+MID('E(Ri) XOR ki+1'!$H$86,ROW(R0_L0!$A3),1),2) -> 1 | E43: =MOD(D8+MID('E(Ri) XOR ki+1'!$H$87,ROW(R0_L0!A3),1),2) -> 0 | F43: =MOD(E8+MID('E(Ri) XOR ki+1'!$H$88,ROW(R0_L0!A3),1),2) -> 0 | G43: =MOD(F8+MID('E(Ri) XOR ki+1'!$H$89,ROW(R0_L0!$A3),1),2) -> 0 | H43: =MOD(G8+MID('E(Ri) XOR ki+1'!$H$90,ROW(R0_L0!$A3),1),2) -> 1 | I43: =MOD(H8+MID('E(Ri) XOR ki+1'!$H$91,ROW(R0_L0!$A3),1),2) -> 0 | J43: =MOD(I8+MID('E(Ri) XOR ki+1'!$H$92,ROW(R0_L0!$A3),1),2) -> 0 | K43: =MOD(J8+MID('E(Ri) XOR ki+1'!$H$93,ROW(R0_L0!$A3),1),2) -> 1 | L43: =MOD(K8+MID('E(Ri) XOR ki+1'!$H$94,ROW(R0_L0!$A3),1),2) -> 0 | M43: =MOD(L8+MID('E(Ri) XOR ki+1'!$H$95,ROW(R0_L0!$A3),1),2) -> 0 | N43: =MOD(M8+MID('E(Ri) XOR ki+1'!$H$96,ROW(R0_L0!$A3),1),2) -> 1 | O43: =MOD(N8+MID('E(Ri) XOR ki+1'!$H$97,ROW(R0_L0!$A3),1),2) -> 1 | P43: =MOD(O8+MID('E(Ri) XOR ki+1'!$H$98,ROW(R0_L0!$A3),1),2) -> 0 | Q43: =MOD(P8+MID('E(Ri) XOR ki+1'!$H$99,ROW(R0_L0!$A3),1),2) -> 1 | R43: =MOD(Q8+MID('E(Ri) XOR ki+1'!$H$100,ROW(R0_L0!$A3),1),2) -> 0
A44: 4 | B44: =MID($H$3, ROW(A4),1) -> 0 | C44: =MOD(B9 + MID('E(Ri) XOR ki+1'!$H$85, ROW(R0_L0!A4),1),2) -> 0 | D44: =MOD(C9+MID('E(Ri) XOR ki+1'!$H$86,ROW(R0_L0!$A4),1),2) -> 0 | E44: =MOD(D9+MID('E(Ri) XOR ki+1'!$H$87,ROW(R0_L0!A4),1),2) -> 1 | F44: =MOD(E9+MID('E(Ri) XOR ki+1'!$H$88,ROW(R0_L0!A4),1),2) -> 1 | G44: =MOD(F9+MID('E(Ri) XOR ki+1'!$H$89,ROW(R0_L0!$A4),1),2) -> 0 | H44: =MOD(G9+MID('E(Ri) XOR ki+1'!$H$90,ROW(R0_L0!$A4),1),2) -> 1 | I44: =MOD(H9+MID('E(Ri) XOR ki+1'!$H$91,ROW(R0_L0!$A4),1),2) -> 0 | J44: =MOD(I9+MID('E(Ri) XOR ki+1'!$H$92,ROW(R0_L0!$A4),1),2) -> 1 | K44: =MOD(J9+MID('E(Ri) XOR ki+1'!$H$93,ROW(R0_L0!$A4),1),2) -> 1 | L44: =MOD(K9+MID('E(Ri) XOR ki+1'!$H$94,ROW(R0_L0!$A4),1),2) -> 0 | M44: =MOD(L9+MID('E(Ri) XOR ki+1'!$H$95,ROW(R0_L0!$A4),1),2) -> 0 | N44: =MOD(M9+MID('E(Ri) XOR ki+1'!$H$96,ROW(R0_L0!$A4),1),2) -> 1 | O44: =MOD(N9+MID('E(Ri) XOR ki+1'!$H$97,ROW(R0_L0!$A4),1),2) -> 1 | P44: =MOD(O9+MID('E(Ri) XOR ki+1'!$H$98,ROW(R0_L0!$A4),1),2) -> 1 | Q44: =MOD(P9+MID('E(Ri) XOR ki+1'!$H$99,ROW(R0_L0!$A4),1),2) -> 0 | R44: =MOD(Q9+MID('E(Ri) XOR ki+1'!$H$100,ROW(R0_L0!$A4),1),2) -> 1
A45: 5 | B45: =MID($H$3, ROW(A5),1) -> 0 | C45: =MOD(B10 + MID('E(Ri) XOR ki+1'!$H$85, ROW(R0_L0!A5),1),2) -> 1 | D45: =MOD(C10+MID('E(Ri) XOR ki+1'!$H$86,ROW(R0_L0!$A5),1),2) -> 1 | E45: =MOD(D10+MID('E(Ri) XOR ki+1'!$H$87,ROW(R0_L0!A5),1),2) -> 0 | F45: =MOD(E10+MID('E(Ri) XOR ki+1'!$H$88,ROW(R0_L0!A5),1),2) -> 1 | G45: =MOD(F10+MID('E(Ri) XOR ki+1'!$H$89,ROW(R0_L0!$A5),1),2) -> 1 | H45: =MOD(G10+MID('E(Ri) XOR ki+1'!$H$90,ROW(R0_L0!$A5),1),2) -> 0 | I45: =MOD(H10+MID('E(Ri) XOR ki+1'!$H$91,ROW(R0_L0!$A5),1),2) -> 0 | J45: =MOD(I10+MID('E(Ri) XOR ki+1'!$H$92,ROW(R0_L0!$A5),1),2) -> 1 | K45: =MOD(J10+MID('E(Ri) XOR ki+1'!$H$93,ROW(R0_L0!$A5),1),2) -> 1 | L45: =MOD(K10+MID('E(Ri) XOR ki+1'!$H$94,ROW(R0_L0!$A5),1),2) -> 1 | M45: =MOD(L10+MID('E(Ri) XOR ki+1'!$H$95,ROW(R0_L0!$A5),1),2) -> 0 | N45: =MOD(M10+MID('E(Ri) XOR ki+1'!$H$96,ROW(R0_L0!$A5),1),2) -> 1 | O45: =MOD(N10+MID('E(Ri) XOR ki+1'!$H$97,ROW(R0_L0!$A5),1),2) -> 1 | P45: =MOD(O10+MID('E(Ri) XOR ki+1'!$H$98,ROW(R0_L0!$A5),1),2) -> 1 | Q45: =MOD(P10+MID('E(Ri) XOR ki+1'!$H$99,ROW(R0_L0!$A5),1),2) -> 1 | R45: =MOD(Q10+MID('E(Ri) XOR ki+1'!$H$100,ROW(R0_L0!$A5),1),2) -> 0
A46: 6 | B46: =MID($H$3, ROW(A6),1) -> 0 | C46: =MOD(B11 + MID('E(Ri) XOR ki+1'!$H$85, ROW(R0_L0!A6),1),2) -> 1 | D46: =MOD(C11+MID('E(Ri) XOR ki+1'!$H$86,ROW(R0_L0!$A6),1),2) -> 0 | E46: =MOD(D11+MID('E(Ri) XOR ki+1'!$H$87,ROW(R0_L0!A6),1),2) -> 1 | F46: =MOD(E11+MID('E(Ri) XOR ki+1'!$H$88,ROW(R0_L0!A6),1),2) -> 1 | G46: =MOD(F11+MID('E(Ri) XOR ki+1'!$H$89,ROW(R0_L0!$A6),1),2) -> 1 | H46: =MOD(G11+MID('E(Ri) XOR ki+1'!$H$90,ROW(R0_L0!$A6),1),2) -> 0 | I46: =MOD(H11+MID('E(Ri) XOR ki+1'!$H$91,ROW(R0_L0!$A6),1),2) -> 0 | J46: =MOD(I11+MID('E(Ri) XOR ki+1'!$H$92,ROW(R0_L0!$A6),1),2) -> 1 | K46: =MOD(J11+MID('E(Ri) XOR ki+1'!$H$93,ROW(R0_L0!$A6),1),2) -> 0 | L46: =MOD(K11+MID('E(Ri) XOR ki+1'!$H$94,ROW(R0_L0!$A6),1),2) -> 0 | M46: =MOD(L11+MID('E(Ri) XOR ki+1'!$H$95,ROW(R0_L0!$A6),1),2) -> 1 | N46: =MOD(M11+MID('E(Ri) XOR ki+1'!$H$96,ROW(R0_L0!$A6),1),2) -> 0 | O46: =MOD(N11+MID('E(Ri) XOR ki+1'!$H$97,ROW(R0_L0!$A6),1),2) -> 1 | P46: =MOD(O11+MID('E(Ri) XOR ki+1'!$H$98,ROW(R0_L0!$A6),1),2) -> 1 | Q46: =MOD(P11+MID('E(Ri) XOR ki+1'!$H$99,ROW(R0_L0!$A6),1),2) -> 1 | R46: =MOD(Q11+MID('E(Ri) XOR ki+1'!$H$100,ROW(R0_L0!$A6),1),2) -> 1
A47: 7 | B47: =MID($H$3, ROW(A7),1) -> 0 | C47: =MOD(B12 + MID('E(Ri) XOR ki+1'!$H$85, ROW(R0_L0!A7),1),2) -> 1 | D47: =MOD(C12+MID('E(Ri) XOR ki+1'!$H$86,ROW(R0_L0!$A7),1),2) -> 0 | E47: =MOD(D12+MID('E(Ri) XOR ki+1'!$H$87,ROW(R0_L0!A7),1),2) -> 0 | F47: =MOD(E12+MID('E(Ri) XOR ki+1'!$H$88,ROW(R0_L0!A7),1),2) -> 0 | G47: =MOD(F12+MID('E(Ri) XOR ki+1'!$H$89,ROW(R0_L0!$A7),1),2) -> 0 | H47: =MOD(G12+MID('E(Ri) XOR ki+1'!$H$90,ROW(R0_L0!$A7),1),2) -> 1 | I47: =MOD(H12+MID('E(Ri) XOR ki+1'!$H$91,ROW(R0_L0!$A7),1),2) -> 1 | J47: =MOD(I12+MID('E(Ri) XOR ki+1'!$H$92,ROW(R0_L0!$A7),1),2) -> 1 | K47: =MOD(J12+MID('E(Ri) XOR ki+1'!$H$93,ROW(R0_L0!$A7),1),2) -> 0 | L47: =MOD(K12+MID('E(Ri) XOR ki+1'!$H$94,ROW(R0_L0!$A7),1),2) -> 1 | M47: =MOD(L12+MID('E(Ri) XOR ki+1'!$H$95,ROW(R0_L0!$A7),1),2) -> 0 | N47: =MOD(M12+MID('E(Ri) XOR ki+1'!$H$96,ROW(R0_L0!$A7),1),2) -> 1 | O47: =MOD(N12+MID('E(Ri) XOR ki+1'!$H$97,ROW(R0_L0!$A7),1),2) -> 1 | P47: =MOD(O12+MID('E(Ri) XOR ki+1'!$H$98,ROW(R0_L0!$A7),1),2) -> 1 | Q47: =MOD(P12+MID('E(Ri) XOR ki+1'!$H$99,ROW(R0_L0!$A7),1),2) -> 1 | R47: =MOD(Q12+MID('E(Ri) XOR ki+1'!$H$100,ROW(R0_L0!$A7),1),2) -> 0
