Workbook

Sheet Input
A1: Khóa K = | B1: 0133457799bbcdff | E1: <- Thay đổi | H1: K1 | I1: ='K1 & K2'!D15 -> 000110110000001011101111110110110100100110100101 | O1: ='K1 & K2'!P12 & 'K1 & K2'!P13 & 'K1 & K2'!P14 & 'K1 & K2'!P15 & 'K1 & K2'!P16 & 'K1 & K2'!P17 -> 1B02EFDB49A5
A2: Bản rõ = | B2: 00123456789abcde | E2: <- Thay đổi | H2: K2 | I2: ='K1 & K2'!D133 -> 011010011010111011011001001001011110101001100110 | O2: ='K1 & K2'!$C$136&'K1 & K2'!$C$137&'K1 & K2'!$C$138&'K1 & K2'!$C$139&'K1 & K2'!$C$140&'K1 & K2'!$C$141 -> 69AED925EA66
H3: K3 | I3: ='K3'!$D$61 -> 010101011111110010001010101101001010110011010010 | O3: {=INDIRECT("'"&H3&"'!C64") & INDIRECT("'"&H3&"'!C65") & INDIRECT("'"&H3&"'!C66") & INDIRECT("'"&H3&"'!C67") & INDIRECT("'"&H3&"'!C68") & INDIRECT("'"&H3&"'!C69")} -> 55FC8AB4ACD2
A4: Mã hóa = | B4: ='L16,R16'!B92 -> 0001101010111111111101101001110101011010100100111110100000001011 | H4: K4 | I4: ='K4'!$D$61 -> 011100101010110111010010101011011000011001010111 | O4: {=INDIRECT("'"&H4&"'!C64") & INDIRECT("'"&H4&"'!C65") & INDIRECT("'"&H4&"'!C66") & INDIRECT("'"&H4&"'!C67") & INDIRECT("'"&H4&"'!C68") & INDIRECT("'"&H4&"'!C69")} -> 72ADD2AD8657
B5: ='L16,R16'!C95&'L16,R16'!C96&'L16,R16'!C97&'L16,R16'!C98&'L16,R16'!C99&'L16,R16'!C100&'L16,R16'!C101&'L16,R16'!C102 -> 1ABFF69D5A93E80B | H5: K5 | I5: ='K5'!$D$61 -> 011111001110110000000111000111111110011011000010 | O5: {=INDIRECT("'"&H5&"'!C64") & INDIRECT("'"&H5&"'!C65") & INDIRECT("'"&H5&"'!C66") & INDIRECT("'"&H5&"'!C67") & INDIRECT("'"&H5&"'!C68") & INDIRECT("'"&H5&"'!C69")} -> 7CEC071FE6C2
H6: K6 | I6: ='K6'!$D$61 -> 011000111010010100011110001111001100010101000101 | O6: {=INDIRECT("'"&H6&"'!C64") & INDIRECT("'"&H6&"'!C65") & INDIRECT("'"&H6&"'!C66") & INDIRECT("'"&H6&"'!C67") & INDIRECT("'"&H6&"'!C68") & INDIRECT("'"&H6&"'!C69")} -> 63A51E3CC545
H7: K7 | I7: ='K7'!$D$61 -> 011011001000010010110111100010101110010011000110 | O7: {=INDIRECT("'"&H7&"'!C64") & INDIRECT("'"&H7&"'!C65") & INDIRECT("'"&H7&"'!C66") & INDIRECT("'"&H7&"'!C67") & INDIRECT("'"&H7&"'!C68") & INDIRECT("'"&H7&"'!C69")} -> 6C84B78AE4C6
H8: K8 | I8: ='K8'!$D$61 -> 111101111000100000111010111011001110011110000001 | O8: {=INDIRECT("'"&H8&"'!C64") & INDIRECT("'"&H8&"'!C65") & INDIRECT("'"&H8&"'!C66") & INDIRECT("'"&H8&"'!C67") & INDIRECT("'"&H8&"'!C68") & INDIRECT("'"&H8&"'!C69")} -> F7883AECE781
H9: K9 | I9: ='K9'!$D$61 -> 110000001101101111101011001001111011100000111001 | O9: {=INDIRECT("'"&H9&"'!C64") & INDIRECT("'"&H9&"'!C65") & INDIRECT("'"&H9&"'!C66") & INDIRECT("'"&H9&"'!C67") & INDIRECT("'"&H9&"'!C68") & INDIRECT("'"&H9&"'!C69")} -> C0DBEB27B839
H10: K10 | I10: ='K10'!$D$61 -> 101100011111001101000111011000110001110101110110 | O10: {=INDIRECT("'"&H10&"'!C64") & INDIRECT("'"&H10&"'!C65") & INDIRECT("'"&H10&"'!C66") & INDIRECT("'"&H10&"'!C67") & INDIRECT("'"&H10&"'!C68") & INDIRECT("'"&H10&"'!C69")} -> B1F347631D76
H11: K11 | I11: ='K11'!$D$61 -> 001000010101111111000011000011011000100110111110 | O11: {=INDIRECT("'"&H11&"'!C64") & INDIRECT("'"&H11&"'!C65") & INDIRECT("'"&H11&"'!C66") & INDIRECT("'"&H11&"'!C67") & INDIRECT("'"&H11&"'!C68") & INDIRECT("'"&H11&"'!C69")} -> 215FC30D89BE
H12: K12 | I12: ='K12'!$D$61 -> 011100010111000111110101010001010101110011010101 | O12: {=INDIRECT("'"&H12&"'!C64") & INDIRECT("'"&H12&"'!C65") & INDIRECT("'"&H12&"'!C66") & INDIRECT("'"&H12&"'!C67") & INDIRECT("'"&H12&"'!C68") & INDIRECT("'"&H12&"'!C69")} -> 7171F5455CD5
H13: K13 | I13: ='K13'!$D$61 -> 100101011100010111010001010010111000000011111101 | O13: {=INDIRECT("'"&H13&"'!C64") & INDIRECT("'"&H13&"'!C65") & INDIRECT("'"&H13&"'!C66") & INDIRECT("'"&H13&"'!C67") & INDIRECT("'"&H13&"'!C68") & INDIRECT("'"&H13&"'!C69")} -> 95C5D14B80FD
H14: K14 | I14: ='K14'!$D$61 -> 010101110100001110110111100000111101110110001101 | O14: {=INDIRECT("'"&H14&"'!C64") & INDIRECT("'"&H14&"'!C65") & INDIRECT("'"&H14&"'!C66") & INDIRECT("'"&H14&"'!C67") & INDIRECT("'"&H14&"'!C68") & INDIRECT("'"&H14&"'!C69")} -> 5743B783DD8D
H15: K15 | I15: ='K15'!$D$61 -> 101111111001000110000101000010100001011110110101 | O15: {=INDIRECT("'"&H15&"'!C64") & INDIRECT("'"&H15&"'!C65") & INDIRECT("'"&H15&"'!C66") & INDIRECT("'"&H15&"'!C67") & INDIRECT("'"&H15&"'!C68") & INDIRECT("'"&H15&"'!C69")} -> BF91850A17B5
H16: K16 | I16: ='K16'!$D$61 -> 110010110011110100001011101111000111000001110010 | O16: {=INDIRECT("'"&H16&"'!C64") & INDIRECT("'"&H16&"'!C65") & INDIRECT("'"&H16&"'!C66") & INDIRECT("'"&H16&"'!C67") & INDIRECT("'"&H16&"'!C68") & INDIRECT("'"&H16&"'!C69")} -> CB3D0BBC7072
H18: f(R0,K1) | I18: ='f(R0,K1)'!B129 -> 10010111110100010110000110011010 | O18: {=INDIRECT("'"&H18&"'!C132") & INDIRECT("'"&H18&"'!C133") & INDIRECT("'"&H18&"'!C134") & INDIRECT("'"&H18&"'!C135")} -> 97D1619A
H19: f(R1,K2) | I19: {=INDIRECT("'" & H19 & "'!B145")} -> 10001000010010001000110100001011 | O19: {=INDIRECT("'"&H19&"'!C148") & INDIRECT("'"&H19&"'!C149") & INDIRECT("'"&H19&"'!C150") & INDIRECT("'"&H19&"'!C151")} -> 88488D0B
H20: f(R2,K3) | I20: {=INDIRECT("'" & H20 & "'!B145")} -> 11011010001110110010011010010010 | O20: {=INDIRECT("'"&H20&"'!C148") & INDIRECT("'"&H20&"'!C149") & INDIRECT("'"&H20&"'!C150") & INDIRECT("'"&H20&"'!C151")} -> DA3B2692
H21: f(R3,K4) | I21: {=INDIRECT("'" & H21 & "'!B145")} -> 11110100010010010101000010110010 | O21: {=INDIRECT("'"&H21&"'!C148") & INDIRECT("'"&H21&"'!C149") & INDIRECT("'"&H21&"'!C150") & INDIRECT("'"&H21&"'!C151")} -> F44950B2
H22: f(R4,K5) | I22: {=INDIRECT("'" & H22 & "'!B145")} -> 11011000001100100011011111111101 | O22: {=INDIRECT("'"&H22&"'!C148") & INDIRECT("'"&H22&"'!C149") & INDIRECT("'"&H22&"'!C150") & INDIRECT("'"&H22&"'!C151")} -> D83237FD
H23: f(R5,K6) | I23: {=INDIRECT("'" & H23 & "'!B145")} -> 10101111110001000011101100100101 | O23: {=INDIRECT("'"&H23&"'!C148") & INDIRECT("'"&H23&"'!C149") & INDIRECT("'"&H23&"'!C150") & INDIRECT("'"&H23&"'!C151")} -> AFC43B25
H24: f(R6,K7) | I24: {=INDIRECT("'" & H24 & "'!B145")} -> 01001110010100010010001110100010 | O24: {=INDIRECT("'"&H24&"'!C148") & INDIRECT("'"&H24&"'!C149") & INDIRECT("'"&H24&"'!C150") & INDIRECT("'"&H24&"'!C151")} -> 4E5123A2
H25: f(R7,K8) | I25: {=INDIRECT("'" & H25 & "'!B145")} -> 01101100111111011110110010111000 | O25: {=INDIRECT("'"&H25&"'!C148") & INDIRECT("'"&H25&"'!C149") & INDIRECT("'"&H25&"'!C150") & INDIRECT("'"&H25&"'!C151")} -> 6CFDECB8
H26: f(R8,K9) | I26: {=INDIRECT("'" & H26 & "'!B145")} -> 11111011000001100000000010110001 | O26: {=INDIRECT("'"&H26&"'!C148") & INDIRECT("'"&H26&"'!C149") & INDIRECT("'"&H26&"'!C150") & INDIRECT("'"&H26&"'!C151")} -> FB0600B1
H27: f(R9,K10) | I27: {=INDIRECT("'" & H27 & "'!B145")} -> 11010101000101010000100011100100 | O27: {=INDIRECT("'"&H27&"'!C148") & INDIRECT("'"&H27&"'!C149") & INDIRECT("'"&H27&"'!C150") & INDIRECT("'"&H27&"'!C151")} -> D51508E4
H28: f(R10,K11) | I28: {=INDIRECT("'" & H28 & "'!B145")} -> 11111100111101100111000101000110 | O28: {=INDIRECT("'"&H28&"'!C148") & INDIRECT("'"&H28&"'!C149") & INDIRECT("'"&H28&"'!C150") & INDIRECT("'"&H28&"'!C151")} -> FCF67146
H29: f(R11,K12) | I29: {=INDIRECT("'" & H29 & "'!B145")} -> 01110000010011111010001110100101 | O29: {=INDIRECT("'"&H29&"'!C148") & INDIRECT("'"&H29&"'!C149") & INDIRECT("'"&H29&"'!C150") & INDIRECT("'"&H29&"'!C151")} -> 704FA3A5
H30: f(R12,K13) | I30: {=INDIRECT("'" & H30 & "'!B145")} -> 01111011111111100010100000000110 | O30: {=INDIRECT("'"&H30&"'!C148") & INDIRECT("'"&H30&"'!C149") & INDIRECT("'"&H30&"'!C150") & INDIRECT("'"&H30&"'!C151")} -> 7BFE2806
... H33: f(R15,K16) | I33: {=INDIRECT("'" & H33 & "'!B145")} -> 11001011111101010010010100101101 | O33: {=INDIRECT("'"&H33&"'!C148") & INDIRECT("'"&H33&"'!C149") & INDIRECT("'"&H33&"'!C150") & INDIRECT("'"&H33&"'!C151")} -> CBF5252D

Sheet Constanst
A1: PC1 | D1: PC2 | G1: IP | J1: E | W1: P | Z1: IP-1
A2: STT | B2: Vị trí | D2: STT | E2: Vị trí | G2: STT | H2: Vị trí | J2: STT | K2: Vị trí | M2: Chỉ số | N2: S1 | O2: S2 | P2: S3 | Q2: S4 | R2: S5 | S2: S6 | T2: S7 | U2: S8 | W2: STT | X2: Vị trí | Z2: STT | AA2: Vị trí
A3: 1 | B3: 57 | D3: 1 | E3: 14 | G3: 1 | H3: 58 | J3: 1 | K3: 32 | M3: 0 | N3: 14 | O3: 15 | P3: 10 | Q3: 7 | R3: 2 | S3: 12 | T3: 4 | U3: 13 | W3: 1 | X3: 16 | Z3: 1 | AA3: 40
A4: 2 | B4: 49 | D4: 2 | E4: 17 | G4: 2 | H4: 50 | J4: 2 | K4: 1 | M4: 1 | N4: 4 | O4: 1 | P4: 0 | Q4: 13 | R4: 12 | S4: 1 | T4: 11 | U4: 2 | W4: 2 | X4: 7 | Z4: 2 | AA4: 8
A5: 3 | B5: 41 | D5: 3 | E5: 11 | G5: 3 | H5: 42 | J5: 3 | K5: 2 | M5: 2 | N5: 13 | O5: 8 | P5: 9 | Q5: 14 | R5: 4 | S5: 10 | T5: 2 | U5: 8 | W5: 3 | X5: 20 | Z5: 3 | AA5: 48
A6: 4 | B6: 33 | D6: 4 | E6: 24 | G6: 4 | H6: 34 | J6: 4 | K6: 3 | M6: 3 | N6: 1 | O6: 14 | P6: 14 | Q6: 3 | R6: 1 | S6: 15 | T6: 14 | U6: 4 | W6: 4 | X6: 21 | Z6: 4 | AA6: 16
A7: 5 | B7: 25 | D7: 5 | E7: 1 | G7: 5 | H7: 26 | J7: 5 | K7: 4 | M7: 4 | N7: 2 | O7: 6 | P7: 6 | Q7: 0 | R7: 7 | S7: 9 | T7: 15 | U7: 6 | W7: 5 | X7: 29 | Z7: 5 | AA7: 56
A8: 6 | B8: 17 | D8: 6 | E8: 5 | G8: 6 | H8: 18 | J8: 6 | K8: 5 | M8: 5 | N8: 15 | O8: 11 | P8: 3 | Q8: 6 | R8: 10 | S8: 2 | T8: 0 | U8: 15 | W8: 6 | X8: 12 | Z8: 6 | AA8: 24
A9: 7 | B9: 9 | D9: 7 | E9: 3 | G9: 7 | H9: 10 | J9: 7 | K9: 4 | M9: 6 | N9: 11 | O9: 3 | P9: 15 | Q9: 9 | R9: 11 | S9: 6 | T9: 8 | U9: 11 | W9: 7 | X9: 28 | Z9: 7 | AA9: 64
A10: 8 | B10: 1 | D10: 8 | E10: 28 | G10: 8 | H10: 2 | J10: 8 | K10: 5 | M10: 7 | N10: 8 | O10: 4 | P10: 5 | Q10: 10 | R10: 6 | S10: 8 | T10: 13 | U10: 1 | W10: 8 | X10: 17 | Z10: 8 | AA10: 32
A11: 9 | B11: 58 | D11: 9 | E11: 15 | G11: 9 | H11: 60 | J11: 9 | K11: 6 | M11: 8 | N11: 3 | O11: 9 | P11: 1 | Q11: 1 | R11: 8 | S11: 0 | T11: 3 | U11: 10 | W11: 9 | X11: 1 | Z11: 9 | AA11: 39
A12: 10 | B12: 50 | D12: 10 | E12: 6 | G12: 10 | H12: 52 | J12: 10 | K12: 7 | M12: 9 | N12: 10 | O12: 7 | P12: 13 | Q12: 2 | R12: 5 | S12: 13 | T12: 12 | U12: 9 | W12: 10 | X12: 15 | Z12: 10 | AA12: 7
A13: 11 | B13: 42 | D13: 11 | E13: 21 | G13: 11 | H13: 44 | J13: 11 | K13: 8 | M13: 10 | N13: 6 | O13: 2 | P13: 12 | Q13: 8 | R13: 3 | S13: 3 | T13: 9 | U13: 3 | W13: 11 | X13: 23 | Z13: 11 | AA13: 47
A14: 12 | B14: 34 | D14: 12 | E14: 10 | G14: 12 | H14: 36 | J14: 12 | K14: 9 | M14: 11 | N14: 12 | O14: 13 | P14: 7 | Q14: 5 | R14: 15 | S14: 4 | T14: 7 | U14: 14 | W14: 12 | X14: 26 | Z14: 12 | AA14: 15
... A34: 32 | B34: 39 | D34: 32 | E34: 40 | G34: 32 | H34: 8 | J34: 32 | K34: 21 | M34: 31 | N34: 8 | O34: 5 | P34: 1 | Q34: 9 | R34: 6 | S34: 8 | T34: 6 | U34: 2 | W34: 32 | X34: 25 | Z34: 32 | AA34: 29
A35: 33 | B35: 31 | D35: 33 | E35: 51 | G35: 33 | H35: 57 | J35: 33 | K35: 22 | M35: 32 | N35: 4 | O35: 0 | P35: 13 | Q35: 10 | R35: 4 | S35: 9 | T35: 1 | U35: 7 | Z35: 33 | AA35: 36
A36: 34 | B36: 23 | D36: 34 | E36: 45 | G36: 34 | H36: 49 | J36: 34 | K36: 23 | M36: 33 | N36: 1 | O36: 14 | P36: 6 | Q36: 6 | R36: 2 | S36: 14 | T36: 4 | U36: 11 | Z36: 34 | AA36: 4
A37: 35 | B37: 15 | D37: 35 | E37: 33 | G37: 35 | H37: 41 | J37: 35 | K37: 24 | M37: 34 | N37: 14 | O37: 7 | P37: 4 | Q37: 9 | R37: 1 | S37: 15 | T37: 11 | U37: 4 | Z37: 35 | AA37: 44
A38: 36 | B38: 7 | D38: 36 | E38: 48 | G38: 36 | H38: 33 | J38: 36 | K38: 25 | M38: 35 | N38: 8 | O38: 11 | P38: 9 | Q38: 0 | R38: 11 | S38: 5 | T38: 13 | U38: 1 | Z38: 36 | AA38: 12
A39: 37 | B39: 62 | D39: 37 | E39: 44 | G39: 37 | H39: 25 | J39: 37 | K39: 24 | M39: 36 | N39: 13 | O39: 10 | P39: 8 | Q39: 12 | R39: 10 | S39: 2 | T39: 12 | U39: 9 | Z39: 37 | AA39: 52
A40: 38 | B40: 54 | D40: 38 | E40: 49 | G40: 38 | H40: 17 | J40: 38 | K40: 25 | M40: 37 | N40: 6 | O40: 4 | P40: 15 | Q40: 11 | R40: 13 | S40: 8 | T40: 3 | U40: 12 | Z40: 38 | AA40: 20
A41: 39 | B41: 46 | D41: 39 | E41: 39 | G41: 39 | H41: 9 | J41: 39 | K41: 26 | M41: 38 | N41: 2 | O41: 13 | P41: 3 | Q41: 7 | R41: 7 | S41: 12 | T41: 7 | U41: 14 | Z41: 39 | AA41: 60
A42: 40 | B42: 38 | D42: 40 | E42: 56 | G42: 40 | H42: 1 | J42: 40 | K42: 27 | M42: 39 | N42: 11 | O42: 1 | P42: 0 | Q42: 13 | R42: 8 | S42: 3 | T42: 14 | U42: 2 | Z42: 40 | AA42: 28
A43: 41 | B43: 30 | D43: 41 | E43: 34 | G43: 41 | H43: 59 | J43: 41 | K43: 28 | M43: 40 | N43: 15 | O43: 5 | P43: 11 | Q43: 15 | R43: 15 | S43: 7 | T43: 10 | U43: 0 | Z43: 41 | AA43: 35
A44: 42 | B44: 22 | D44: 42 | E44: 53 | G44: 42 | H44: 51 | J44: 42 | K44: 29 | M44: 41 | N44: 12 | O44: 8 | P44: 1 | Q44: 1 | R44: 9 | S44: 0 | T44: 15 | U44: 6 | Z44: 42 | AA44: 3
A45: 43 | B45: 14 | D45: 43 | E45: 46 | G45: 43 | H45: 43 | J45: 43 | K45: 28 | M45: 42 | N45: 9 | O45: 12 | P45: 2 | Q45: 3 | R45: 12 | S45: 4 | T45: 6 | U45: 10 | Z45: 43 | AA45: 43
A46: 44 | B46: 6 | D46: 44 | E46: 42 | G46: 44 | H46: 35 | J46: 44 | K46: 29 | M46: 43 | N46: 7 | O46: 6 | P46: 12 | Q46: 14 | R46: 5 | S46: 10 | T46: 8 | U46: 13 | Z46: 44 | AA46: 11
... A50: 48 | B50: 37 | D50: 48 | E50: 32 | G50: 48 | H50: 3 | J50: 48 | K50: 1 | M50: 47 | N50: 0 | O50: 15 | P50: 7 | Q50: 4 | R50: 14 | S50: 6 | T50: 2 | U50: 8 | Z50: 48 | AA50: 27
A51: 49 | B51: 29 | G51: 49 | H51: 61 | M51: 48 | N51: 15 | O51: 13 | P51: 1 | Q51: 3 | R51: 11 | S51: 4 | T51: 6 | U51: 2 | Z51: 49 | AA51: 34
A52: 50 | B52: 21 | G52: 50 | H52: 53 | M52: 49 | N52: 12 | O52: 8 | P52: 10 | Q52: 15 | R52: 8 | S52: 3 | T52: 11 | U52: 1 | Z52: 50 | AA52: 2
A53: 51 | B53: 13 | G53: 51 | H53: 45 | M53: 50 | N53: 8 | O53: 10 | P53: 13 | Q53: 0 | R53: 12 | S53: 2 | T53: 13 | U53: 14 | Z53: 51 | AA53: 42
A54: 52 | B54: 5 | G54: 52 | H54: 37 | M54: 51 | N54: 2 | O54: 1 | P54: 0 | Q54: 6 | R54: 7 | S54: 12 | T54: 8 | U54: 7 | Z54: 52 | AA54: 10
A55: 53 | B55: 28 | G55: 53 | H55: 29 | M55: 52 | N55: 4 | O55: 3 | P55: 6 | Q55: 10 | R55: 1 | S55: 9 | T55: 1 | U55: 4 | Z55: 53 | AA55: 50
A56: 54 | B56: 20 | G56: 54 | H56: 21 | M56: 53 | N56: 9 | O56: 15 | P56: 9 | Q56: 1 | R56: 14 | S56: 5 | T56: 4 | U56: 10 | Z56: 54 | AA56: 18
A57: 55 | B57: 12 | G57: 55 | H57: 13 | M57: 54 | N57: 1 | O57: 4 | P57: 8 | Q57: 13 | R57: 2 | S57: 15 | T57: 10 | U57: 8 | Z57: 55 | AA57: 58
A58: 56 | B58: 4 | G58: 56 | H58: 5 | M58: 55 | N58: 7 | O58: 2 | P58: 7 | Q58: 8 | R58: 13 | S58: 10 | T58: 7 | U58: 13 | Z58: 56 | AA58: 26
G59: 57 | H59: 63 | M59: 56 | N59: 5 | O59: 11 | P59: 4 | Q59: 9 | R59: 6 | S59: 11 | T59: 9 | U59: 15 | Z59: 57 | AA59: 33
G60: 58 | H60: 55 | M60: 57 | N60: 11 | O60: 6 | P60: 15 | Q60: 4 | R60: 15 | S60: 14 | T60: 5 | U60: 12 | Z60: 58 | AA60: 1
G61: 59 | H61: 47 | M61: 58 | N61: 3 | O61: 7 | P61: 14 | Q61: 5 | R61: 0 | S61: 1 | T61: 0 | U61: 9 | Z61: 59 | AA61: 41
G62: 60 | H62: 39 | M62: 59 | N62: 14 | O62: 12 | P62: 3 | Q62: 11 | R62: 9 | S62: 7 | T62: 15 | U62: 0 | Z62: 60 | AA62: 9
...

Sheet PC1
A1: Khoa K = | B1: =Input!B1 -> 0133457799bbcdff | L1: Bản rõ | M1: =Input!B2 -> 00123456789abcde
A2: vi tri | B2: ki tu hexan | C2: binary | L2: vi tri | M2: ki tu hexan | N2: binary
A3: 1 | B3: =MID($B$1,A3,1) -> 0 | C3: =HEX2BIN(B3,4) -> 0000 | D3: =C3&D4 -> 0000000100110011010001010111011110011001101110111100110111111111 | L3: 1 | M3: =MID($M$1,L3,1) -> 0 | N3: =HEX2BIN(M3,4) -> 0000 | O3: =N3&O4 -> 0000000000010010001101000101011001111000100110101011110011011110
A4: 2 | B4: =MID($B$1,A4,1) -> 1 | C4: =HEX2BIN(B4,4) -> 0001 | D4: =C4&D5 -> 000100110011010001010111011110011001101110111100110111111111 | L4: 2 | M4: =MID($M$1,L4,1) -> 0 | N4: =HEX2BIN(M4,4) -> 0000 | O4: =N4&O5 -> 000000010010001101000101011001111000100110101011110011011110
A5: 3 | B5: =MID($B$1,A5,1) -> 3 | C5: =HEX2BIN(B5,4) -> 0011 | D5: =C5&D6 -> 00110011010001010111011110011001101110111100110111111111 | L5: 3 | M5: =MID($M$1,L5,1) -> 1 | N5: =HEX2BIN(M5,4) -> 0001 | O5: =N5&O6 -> 00010010001101000101011001111000100110101011110011011110
A6: 4 | B6: =MID($B$1,A6,1) -> 3 | C6: =HEX2BIN(B6,4) -> 0011 | D6: =C6&D7 -> 0011010001010111011110011001101110111100110111111111 | L6: 4 | M6: =MID($M$1,L6,1) -> 2 | N6: =HEX2BIN(M6,4) -> 0010 | O6: =N6&O7 -> 0010001101000101011001111000100110101011110011011110
A7: 5 | B7: =MID($B$1,A7,1) -> 4 | C7: =HEX2BIN(B7,4) -> 0100 | D7: =C7&D8 -> 010001010111011110011001101110111100110111111111 | L7: 5 | M7: =MID($M$1,L7,1) -> 3 | N7: =HEX2BIN(M7,4) -> 0011 | O7: =N7&O8 -> 001101000101011001111000100110101011110011011110
A8: 6 | B8: =MID($B$1,A8,1) -> 5 | C8: =HEX2BIN(B8,4) -> 0101 | D8: =C8&D9 -> 01010111011110011001101110111100110111111111 | L8: 6 | M8: =MID($M$1,L8,1) -> 4 | N8: =HEX2BIN(M8,4) -> 0100 | O8: =N8&O9 -> 01000101011001111000100110101011110011011110
A9: 7 | B9: =MID($B$1,A9,1) -> 7 | C9: =HEX2BIN(B9,4) -> 0111 | D9: =C9&D10 -> 0111011110011001101110111100110111111111 | L9: 7 | M9: =MID($M$1,L9,1) -> 5 | N9: =HEX2BIN(M9,4) -> 0101 | O9: =N9&O10 -> 0101011001111000100110101011110011011110
A10: 8 | B10: =MID($B$1,A10,1) -> 7 | C10: =HEX2BIN(B10,4) -> 0111 | D10: =C10&D11 -> 011110011001101110111100110111111111 | L10: 8 | M10: =MID($M$1,L10,1) -> 6 | N10: =HEX2BIN(M10,4) -> 0110 | O10: =N10&O11 -> 011001111000100110101011110011011110
A11: 9 | B11: =MID($B$1,A11,1) -> 9 | C11: =HEX2BIN(B11,4) -> 1001 | D11: =C11&D12 -> 10011001101110111100110111111111 | L11: 9 | M11: =MID($M$1,L11,1) -> 7 | N11: =HEX2BIN(M11,4) -> 0111 | O11: =N11&O12 -> 01111000100110101011110011011110
A12: 10 | B12: =MID($B$1,A12,1) -> 9 | C12: =HEX2BIN(B12,4) -> 1001 | D12: =C12&D13 -> 1001101110111100110111111111 | L12: 10 | M12: =MID($M$1,L12,1) -> 8 | N12: =HEX2BIN(M12,4) -> 1000 | O12: =N12&O13 -> 1000100110101011110011011110
A13: 11 | B13: =MID($B$1,A13,1) -> b | C13: =HEX2BIN(B13,4) -> 1011 | D13: =C13&D14 -> 101110111100110111111111 | L13: 11 | M13: =MID($M$1,L13,1) -> 9 | N13: =HEX2BIN(M13,4) -> 1001 | O13: =N13&O14 -> 100110101011110011011110
A14: 12 | B14: =MID($B$1,A14,1) -> b | C14: =HEX2BIN(B14,4) -> 1011 | D14: =C14&D15 -> 10111100110111111111 | L14: 12 | M14: =MID($M$1,L14,1) -> a | N14: =HEX2BIN(M14,4) -> 1010 | O14: =N14&O15 -> 10101011110011011110
... A16: 14 | B16: =MID($B$1,A16,1) -> d | C16: =HEX2BIN(B16,4) -> 1101 | D16: =C16&D17 -> 110111111111 | L16: 14 | M16: =MID($M$1,L16,1) -> c | N16: =HEX2BIN(M16,4) -> 1100 | O16: =N16&O17 -> 110011011110
A17: 15 | B17: =MID($B$1,A17,1) -> f | C17: =HEX2BIN(B17,4) -> 1111 | D17: =C17&C18 -> 11111111 | L17: 15 | M17: =MID($M$1,L17,1) -> d | N17: =HEX2BIN(M17,4) -> 1101 | O17: =N17&N18 -> 11011110
A18: 16 | B18: =MID($B$1,A18,1) -> f | C18: =HEX2BIN(B18,4) -> 1111 | L18: 16 | M18: =MID($M$1,L18,1) -> e | N18: =HEX2BIN(M18,4) -> 1110
A20: PC1 | B20: =B22 -> 11110000110011001010101010111010101011001100111100001010 | H20: byte | I20: byte | J20: hexan
A21: bit i | H21: 1 | I21: =MID($B$20,(H21-1)*8+1, 8) -> 11110000 | J21: =BIN2HEX(I21,2) -> F0
A22: =MID($D$3, Constanst!B3, 1) -> 1 | B22: =A22&B23 -> 11110000110011001010101010111010101011001100111100001010 | H22: 2 | I22: =MID($B$20,(H22-1)*8+1, 8) -> 11001100 | J22: =BIN2HEX(I22,2) -> CC
A23: =MID($D$3, Constanst!B4, 1) -> 1 | B23: =A23&B24 -> 1110000110011001010101010111010101011001100111100001010 | H23: 3 | I23: =MID($B$20,(H23-1)*8+1, 8) -> 10101010 | J23: =BIN2HEX(I23,2) -> AA
A24: =MID($D$3, Constanst!B5, 1) -> 1 | B24: =A24&B25 -> 110000110011001010101010111010101011001100111100001010 | H24: 4 | I24: =MID($B$20,(H24-1)*8+1, 8) -> 10111010 | J24: =BIN2HEX(I24,2) -> BA
A25: =MID($D$3, Constanst!B6, 1) -> 1 | B25: =A25&B26 -> 10000110011001010101010111010101011001100111100001010 | H25: 5 | I25: =MID($B$20,(H25-1)*8+1, 8) -> 10101100 | J25: =BIN2HEX(I25,2) -> AC
A26: =MID($D$3, Constanst!B7, 1) -> 0 | B26: =A26&B27 -> 0000110011001010101010111010101011001100111100001010 | H26: 6 | I26: =MID($B$20,(H26-1)*8+1, 8) -> 11001111 | J26: =BIN2HEX(I26,2) -> CF
A27: =MID($D$3, Constanst!B8, 1) -> 0 | B27: =A27&B28 -> 000110011001010101010111010101011001100111100001010 | H27: 7 | I27: =MID($B$20,(H27-1)*8+1, 8) -> 00001010 | J27: =BIN2HEX(I27,2) -> 0A
A28: =MID($D$3, Constanst!B9, 1) -> 0 | B28: =A28&B29 -> 00110011001010101010111010101011001100111100001010
A29: =MID($D$3, Constanst!B10, 1) -> 0 | B29: =A29&B30 -> 0110011001010101010111010101011001100111100001010
A30: =MID($D$3, Constanst!B11, 1) -> 1 | B30: =A30&B31 -> 110011001010101010111010101011001100111100001010
A31: =MID($D$3, Constanst!B12, 1) -> 1 | B31: =A31&B32 -> 10011001010101010111010101011001100111100001010
A32: =MID($D$3, Constanst!B13, 1) -> 0 | B32: =A32&B33 -> 0011001010101010111010101011001100111100001010
A33: =MID($D$3, Constanst!B14, 1) -> 0 | B33: =A33&B34 -> 011001010101010111010101011001100111100001010
A34: =MID($D$3, Constanst!B15, 1) -> 1 | B34: =A34&B35 -> 11001010101010111010101011001100111100001010
A35: =MID($D$3, Constanst!B16, 1) -> 1 | B35: =A35&B36 -> 1001010101010111010101011001100111100001010
A36: =MID($D$3, Constanst!B17, 1) -> 0 | B36: =A36&B37 -> 001010101010111010101011001100111100001010
A37: =MID($D$3, Constanst!B18, 1) -> 0 | B37: =A37&B38 -> 01010101010111010101011001100111100001010
A38: =MID($D$3, Constanst!B19, 1) -> 1 | B38: =A38&B39 -> 1010101010111010101011001100111100001010
A39: =MID($D$3, Constanst!B20, 1) -> 0 | B39: =A39&B40 -> 010101010111010101011001100111100001010
... A75: =MID($D$3, Constanst!B56, 1) -> 0 | B75: =A75&B76 -> 010
A76: =MID($D$3, Constanst!B57, 1) -> 1 | B76: =A76&A77 -> 10
A77: =MID($D$3, Constanst!B58, 1) -> 0

Sheet IP(M)
A2: byte | B2: byte | C2: hexan
A3: 1 | B3: =MID('f(R0,K1)'!$D$1,(A3-1)*8+1, 8) -> 00011011 | C3: =BIN2HEX(B3,2) -> 1B
A4: 2 | B4: =MID('f(R0,K1)'!$D$1,(A4-1)*8+1, 8) -> 00000010 | C4: =BIN2HEX(B4,2) -> 02
A5: 3 | B5: =MID('f(R0,K1)'!$D$1,(A5-1)*8+1, 8) -> 11101111 | C5: =BIN2HEX(B5,2) -> EF
A6: 4 | B6: =MID('f(R0,K1)'!$D$1,(A6-1)*8+1, 8) -> 11011011 | C6: =BIN2HEX(B6,2) -> DB
A7: 5 | B7: =MID('f(R0,K1)'!$D$1,(A7-1)*8+1, 8) -> 01001001 | C7: =BIN2HEX(B7,2) -> 49
A8: 6 | B8: =MID('f(R0,K1)'!$D$1,(A8-1)*8+1, 8) -> 10100101 | C8: =BIN2HEX(B8,2) -> A5
A10: input= | B10: =Input!B2 -> 00123456789abcde | D10: ='PC1'!O3 -> 0000000000010010001101000101011001111000100110101011110011011110
A12: vi tri | B12: ki tu hexan | C12: binary
A13: 1 | B13: =MID($B$10,A13,1) -> 0 | C13: =HEX2BIN(B13,4) -> 0000 | D13: =C13&D14 -> 0000000000010010001101000101011001111000100110101011110011011110
A14: 2 | B14: =MID($B$10,A14,1) -> 0 | C14: =HEX2BIN(B14,4) -> 0000 | D14: =C14&D15 -> 000000010010001101000101011001111000100110101011110011011110
A15: 3 | B15: =MID($B$10,A15,1) -> 1 | C15: =HEX2BIN(B15,4) -> 0001 | D15: =C15&D16 -> 00010010001101000101011001111000100110101011110011011110
A16: 4 | B16: =MID($B$10,A16,1) -> 2 | C16: =HEX2BIN(B16,4) -> 0010 | D16: =C16&D17 -> 0010001101000101011001111000100110101011110011011110
A17: 5 | B17: =MID($B$10,A17,1) -> 3 | C17: =HEX2BIN(B17,4) -> 0011 | D17: =C17&D18 -> 001101000101011001111000100110101011110011011110
A18: 6 | B18: =MID($B$10,A18,1) -> 4 | C18: =HEX2BIN(B18,4) -> 0100 | D18: =C18&D19 -> 01000101011001111000100110101011110011011110
A19: 7 | B19: =MID($B$10,A19,1) -> 5 | C19: =HEX2BIN(B19,4) -> 0101 | D19: =C19&D20 -> 0101011001111000100110101011110011011110
A20: 8 | B20: =MID($B$10,A20,1) -> 6 | C20: =HEX2BIN(B20,4) -> 0110 | D20: =C20&D21 -> 011001111000100110101011110011011110
A21: 9 | B21: =MID($B$10,A21,1) -> 7 | C21: =HEX2BIN(B21,4) -> 0111 | D21: =C21&D22 -> 01111000100110101011110011011110
A22: 10 | B22: =MID($B$10,A22,1) -> 8 | C22: =HEX2BIN(B22,4) -> 1000 | D22: =C22&D23 -> 1000100110101011110011011110
A23: 11 | B23: =MID($B$10,A23,1) -> 9 | C23: =HEX2BIN(B23,4) -> 1001 | D23: =C23&D24 -> 100110101011110011011110
A24: 12 | B24: =MID($B$10,A24,1) -> a | C24: =HEX2BIN(B24,4) -> 1010 | D24: =C24&D25 -> 10101011110011011110
... A26: 14 | B26: =MID($B$10,A26,1) -> c | C26: =HEX2BIN(B26,4) -> 1100 | D26: =C26&D27 -> 110011011110
A27: 15 | B27: =MID($B$10,A27,1) -> d | C27: =HEX2BIN(B27,4) -> 1101 | D27: =C27&C28 -> 11011110
A28: 16 | B28: =MID($B$10,A28,1) -> e | C28: =HEX2BIN(B28,4) -> 1110
A30: bit
A31: =MID($D$10,Constanst!H3,1) -> 1 | B31: =A31&B32 -> 1001100011111110110011000000000011100000010101001111000010101010
A32: =MID($D$10,Constanst!H4,1) -> 0 | B32: =A32&B33 -> 001100011111110110011000000000011100000010101001111000010101010
A33: =MID($D$10,Constanst!H5,1) -> 0 | B33: =A33&B34 -> 01100011111110110011000000000011100000010101001111000010101010
A34: =MID($D$10,Constanst!H6,1) -> 1 | B34: =A34&B35 -> 1100011111110110011000000000011100000010101001111000010101010
A35: =MID($D$10,Constanst!H7,1) -> 1 | B35: =A35&B36 -> 100011111110110011000000000011100000010101001111000010101010
A36: =MID($D$10,Constanst!H8,1) -> 0 | B36: =A36&B37 -> 00011111110110011000000000011100000010101001111000010101010
A37: =MID($D$10,Constanst!H9,1) -> 0 | B37: =A37&B38 -> 0011111110110011000000000011100000010101001111000010101010
A38: =MID($D$10,Constanst!H10,1) -> 0 | B38: =A38&B39 -> 011111110110011000000000011100000010101001111000010101010
A39: =MID($D$10,Constanst!H11,1) -> 1 | B39: =A39&B40 -> 11111110110011000000000011100000010101001111000010101010
A40: =MID($D$10,Constanst!H12,1) -> 1 | B40: =A40&B41 -> 1111110110011000000000011100000010101001111000010101010
A41: =MID($D$10,Constanst!H13,1) -> 1 | B41: =A41&B42 -> 111110110011000000000011100000010101001111000010101010
A42: =MID($D$10,Constanst!H14,1) -> 1 | B42: =A42&B43 -> 11110110011000000000011100000010101001111000010101010
... A92: =MID($D$10,Constanst!H64,1) -> 0 | B92: =A92&B93 -> 010
A93: =MID($D$10,Constanst!H65,1) -> 1 | B93: =A93&A94 -> 10
A94: =MID($D$10,Constanst!H66,1) -> 0
...

Sheet f(R0,K1)
A1: K1= | D1: =Input!I1 -> 000110110000001011101111110110110100100110100101
F4: Nửa trái | G4: L0= | H4: =LEFT('IP(M)'!C96, 32) -> 10011000111111101100110000000000
F5: Nửa phải | G5: R0= | H5: =RIGHT('IP(M)'!C96, 32) -> 11100000010101001111000010101010
A7: Mở rộng R0 => E(R0) | D7: =B9 -> 011100000000001010101001011110100001010101010101
A8: bit
A9: =MID($H$5,Constanst!K3,1) -> 0 | B9: =A9&B10 -> 011100000000001010101001011110100001010101010101
A10: =MID($H$5,Constanst!K4,1) -> 1 | B10: =A10&B11 -> 11100000000001010101001011110100001010101010101
A11: =MID($H$5,Constanst!K5,1) -> 1 | B11: =A11&B12 -> 1100000000001010101001011110100001010101010101
A12: =MID($H$5,Constanst!K6,1) -> 1 | B12: =A12&B13 -> 100000000001010101001011110100001010101010101
A13: =MID($H$5,Constanst!K7,1) -> 0 | B13: =A13&B14 -> 00000000001010101001011110100001010101010101
A14: =MID($H$5,Constanst!K8,1) -> 0 | B14: =A14&B15 -> 0000000001010101001011110100001010101010101
A15: =MID($H$5,Constanst!K9,1) -> 0 | B15: =A15&B16 -> 000000001010101001011110100001010101010101
A16: =MID($H$5,Constanst!K10,1) -> 0 | B16: =A16&B17 -> 00000001010101001011110100001010101010101
A17: =MID($H$5,Constanst!K11,1) -> 0 | B17: =A17&B18 -> 0000001010101001011110100001010101010101
A18: =MID($H$5,Constanst!K12,1) -> 0 | B18: =A18&B19 -> 000001010101001011110100001010101010101
A19: =MID($H$5,Constanst!K13,1) -> 0 | B19: =A19&B20 -> 00001010101001011110100001010101010101
A20: =MID($H$5,Constanst!K14,1) -> 0 | B20: =A20&B21 -> 0001010101001011110100001010101010101
... A54: =MID($H$5,Constanst!K48,1) -> 1 | B54: =A54&B55 -> 101
A55: =MID($H$5,Constanst!K49,1) -> 0 | B55: =A55&A56 -> 01
A56: =MID($H$5,Constanst!K50,1) -> 1
A58: Thực hiện phép XOR A = E(R0) XOR K1
A59: byte | B59: byte | C59: hexan | D59: decimal | G59: byte | H59: byte | I59: hexan | J59: decimal
A60: 1 | B60: =MID($D$1,(A60-1)*8+1, 8) -> 00011011 | C60: =BIN2HEX(B60,2) -> 1B | D60: =BIN2DEC(B60) -> 27 | G60: 1 | H60: =MID($D$7,(G60-1)*8+1, 8) -> 01110000 | I60: =BIN2HEX(H60,2) -> 70 | J60: =BIN2DEC(H60) -> 112
A61: 2 | B61: =MID($D$1,(A61-1)*8+1, 8) -> 00000010 | C61: =BIN2HEX(B61,2) -> 02 | D61: =BIN2DEC(B61) -> 2 | G61: 2 | H61: =MID($D$7,(G61-1)*8+1, 8) -> 00000010 | I61: =BIN2HEX(H61,2) -> 02 | J61: =BIN2DEC(H61) -> 2
A62: 3 | B62: =MID($D$1,(A62-1)*8+1, 8) -> 11101111 | C62: =BIN2HEX(B62,2) -> EF | D62: =BIN2DEC(B62) -> 239 | G62: 3 | H62: =MID($D$7,(G62-1)*8+1, 8) -> 10101001 | I62: =BIN2HEX(H62,2) -> A9 | J62: =BIN2DEC(H62) -> 169
A63: 4 | B63: =MID($D$1,(A63-1)*8+1, 8) -> 11011011 | C63: =BIN2HEX(B63,2) -> DB | D63: =BIN2DEC(B63) -> 219 | G63: 4 | H63: =MID($D$7,(G63-1)*8+1, 8) -> 01111010 | I63: =BIN2HEX(H63,2) -> 7A | J63: =BIN2DEC(H63) -> 122
A64: 5 | B64: =MID($D$1,(A64-1)*8+1, 8) -> 01001001 | C64: =BIN2HEX(B64,2) -> 49 | D64: =BIN2DEC(B64) -> 73 | G64: 5 | H64: =MID($D$7,(G64-1)*8+1, 8) -> 00010101 | I64: =BIN2HEX(H64,2) -> 15 | J64: =BIN2DEC(H64) -> 21
A65: 6 | B65: =MID($D$1,(A65-1)*8+1, 8) -> 10100101 | C65: =BIN2HEX(B65,2) -> A5 | D65: =BIN2DEC(B65) -> 165 | G65: 6 | H65: =MID($D$7,(G65-1)*8+1, 8) -> 01010101 | I65: =BIN2HEX(H65,2) -> 55 | J65: =BIN2DEC(H65) -> 85
B67: Khóa K1 | H67: E(R0)
A69: Byte | B69: XOR(ER0, K1) | C69: Binary | D69: hexan
A70: 1 | B70: =BITXOR(D60,J60) -> 107 | C70: =DEC2BIN(B70,8) -> 01101011 | D70: =BIN2HEX(C70,2) -> 6B
A71: 2 | B71: =BITXOR(D61,J61) -> 0 | C71: =DEC2BIN(B71,8) -> 00000000 | D71: =BIN2HEX(C71,2) -> 00
A72: 3 | B72: =BITXOR(D62,J62) -> 70 | C72: =DEC2BIN(B72,8) -> 01000110 | D72: =BIN2HEX(C72,2) -> 46
A73: 4 | B73: =BITXOR(D63,J63) -> 161 | C73: =DEC2BIN(B73,8) -> 10100001 | D73: =BIN2HEX(C73,2) -> A1
A74: 5 | B74: =BITXOR(D64,J64) -> 92 | C74: =DEC2BIN(B74,8) -> 01011100 | D74: =BIN2HEX(C74,2) -> 5C
A75: 6 | B75: =BITXOR(D65,J65) -> 240 | C75: =DEC2BIN(B75,8) -> 11110000 | D75: =BIN2HEX(C75,2) -> F0
B77: A = ER0 XOR K1 = | D77: =C70&C71&C72&C73&C74&C75 -> 011010110000000001000110101000010101110011110000
A79: Thực hiện phép thế | E79: Hàng = bit đầu + bit cuối
E80: Cột = 4 bit giữa
A81: cặp 6 bit | C81: hàng | D81: cột | F81: Chỉ số mảng | G81: Tra bảng S
...

Sheet f(R1,K2)
A2: =L6 -> K2 | D2: =Input!I2 -> 011010011010111011011001001001011110101001100110
A3: F=P(B)= | B3: {=INDIRECT("'f(" & L5 & "," & L7 & ")'!B129")} -> 10010111110100010110000110011010
A4: =L4 -> L0 | B4: {=INDIRECT("'f(" & L5 & "," & L7 & ")'!H4")} -> 10011000111111101100110000000000 | L4: L0 | M4: L1
A5: =L5 -> R0 | B5: {=INDIRECT("'f(" & L5 & "," & L7 & ")'!H5")} -> 11100000010101001111000010101010 | L5: R0 | M5: R1
L6: K2
A7: F | G7: =L4 -> L0 | L7: K1
A8: byte | B8: byte | C8: hexan | D8: dec | G8: byte | H8: byte | I8: hexan | J8: dec
A9: 1 | B9: =MID($B$3,(A9-1)*8+1, 8) -> 10010111 | C9: =BIN2HEX(B9,2) -> 97 | D9: =HEX2DEC(C9) -> 151 | G9: 1 | H9: =MID($B$4,(G9-1)*8+1, 8) -> 10011000 | I9: =BIN2HEX(H9,2) -> 98 | J9: =HEX2DEC(I9) -> 152
A10: 2 | B10: =MID($B$3,(A10-1)*8+1, 8) -> 11010001 | C10: =BIN2HEX(B10,2) -> D1 | D10: =HEX2DEC(C10) -> 209 | G10: 2 | H10: =MID($B$4,(G10-1)*8+1, 8) -> 11111110 | I10: =BIN2HEX(H10,2) -> FE | J10: =HEX2DEC(I10) -> 254
A11: 3 | B11: =MID($B$3,(A11-1)*8+1, 8) -> 01100001 | C11: =BIN2HEX(B11,2) -> 61 | D11: =HEX2DEC(C11) -> 97 | G11: 3 | H11: =MID($B$4,(G11-1)*8+1, 8) -> 11001100 | I11: =BIN2HEX(H11,2) -> CC | J11: =HEX2DEC(I11) -> 204
A12: 4 | B12: =MID($B$3,(A12-1)*8+1, 8) -> 10011010 | C12: =BIN2HEX(B12,2) -> 9A | D12: =HEX2DEC(C12) -> 154 | G12: 4 | H12: =MID($B$4,(G12-1)*8+1, 8) -> 00000000 | I12: =BIN2HEX(H12,2) -> 00 | J12: =HEX2DEC(I12) -> 0
A14: =M5&" = F XOR "&L4&" =" -> R1 = F XOR L0 = | C14: =F17&F18&F19&F20 -> 00001111001011111010110110011010
C16: byte | D16: XOR | E16: HEX | F16: Bin
C17: 1 | D17: =BITXOR(J9,D9) -> 15 | E17: =DEC2HEX(D17,2) -> 0F | F17: =HEX2BIN(E17,8) -> 00001111
C18: 2 | D18: =BITXOR(J10,D10) -> 47 | E18: =DEC2HEX(D18,2) -> 2F | F18: =HEX2BIN(E18,8) -> 00101111
C19: 3 | D19: =BITXOR(J11,D11) -> 173 | E19: =DEC2HEX(D19,2) -> AD | F19: =HEX2BIN(E19,8) -> 10101101
C20: 4 | D20: =BITXOR(J12,D12) -> 154 | E20: =DEC2HEX(D20,2) -> 9A | F20: =HEX2BIN(E20,8) -> 10011010
A22: =M4&" = "&L5&" =" -> L1 = R0 = | C22: =B5 -> 11100000010101001111000010101010
A24: ="Mở rộng "&M5&" => E("&M5&")" -> Mở rộng R1 => E(R1) | D24: =B26 -> 000001011110100101011111110101011011110011110100
A25: bit
A26: =MID($C$14,Constanst!K3,1) -> 0 | B26: =A26&B27 -> 000001011110100101011111110101011011110011110100
A27: =MID($C$14,Constanst!K4,1) -> 0 | B27: =A27&B28 -> 00001011110100101011111110101011011110011110100
A28: =MID($C$14,Constanst!K5,1) -> 0 | B28: =A28&B29 -> 0001011110100101011111110101011011110011110100
A29: =MID($C$14,Constanst!K6,1) -> 0 | B29: =A29&B30 -> 001011110100101011111110101011011110011110100
A30: =MID($C$14,Constanst!K7,1) -> 0 | B30: =A30&B31 -> 01011110100101011111110101011011110011110100
A31: =MID($C$14,Constanst!K8,1) -> 1 | B31: =A31&B32 -> 1011110100101011111110101011011110011110100
A32: =MID($C$14,Constanst!K9,1) -> 0 | B32: =A32&B33 -> 011110100101011111110101011011110011110100
A33: =MID($C$14,Constanst!K10,1) -> 1 | B33: =A33&B34 -> 11110100101011111110101011011110011110100
A34: =MID($C$14,Constanst!K11,1) -> 1 | B34: =A34&B35 -> 1110100101011111110101011011110011110100
A35: =MID($C$14,Constanst!K12,1) -> 1 | B35: =A35&B36 -> 110100101011111110101011011110011110100
A36: =MID($C$14,Constanst!K13,1) -> 1 | B36: =A36&B37 -> 10100101011111110101011011110011110100
A37: =MID($C$14,Constanst!K14,1) -> 0 | B37: =A37&B38 -> 0100101011111110101011011110011110100
... A71: =MID($C$14,Constanst!K48,1) -> 1 | B71: =A71&B72 -> 100
A72: =MID($C$14,Constanst!K49,1) -> 0 | B72: =A72&A73 -> 00
A73: =MID($C$14,Constanst!K50,1) -> 0
A75: ="Thực hiện phép XOR A = E("&M5&") XOR "&L6 -> Thực hiện phép XOR A = E(R1) XOR K2
A76: ="Khóa " & L6 -> Khóa K2 | G76: ="E("&M5&")" -> E(R1)
A77: byte | B77: byte | C77: hexan | D77: decimal | G77: byte | H77: byte | I77: hexan | J77: decimal
A78: 1 | B78: =MID($D$2,(A78-1)*8+1, 8) -> 01101001 | C78: =BIN2HEX(B78,2) -> 69 | D78: =BIN2DEC(B78) -> 105 | G78: 1 | H78: =MID($D$24,(G78-1)*8+1, 8) -> 00000101 | I78: =BIN2HEX(H78,2) -> 05 | J78: =BIN2DEC(H78) -> 5
A79: 2 | B79: =MID($D$2,(A79-1)*8+1, 8) -> 10101110 | C79: =BIN2HEX(B79,2) -> AE | D79: =BIN2DEC(B79) -> 174 | G79: 2 | H79: =MID($D$24,(G79-1)*8+1, 8) -> 11101001 | I79: =BIN2HEX(H79,2) -> E9 | J79: =BIN2DEC(H79) -> 233
...

Sheet f(R2,K3)
A2: =L6 -> K3 | D2: =Input!I3 -> 010101011111110010001010101101001010110011010010
A3: F=P(B)= | B3: {=INDIRECT("'f(" & L5 & "," & L7 & ")'!B145")} -> 10001000010010001000110100001011
A4: =L4 -> L1 | B4: {=INDIRECT("'f(" & L5 & "," & L7 & ")'!C22")} -> 11100000010101001111000010101010 | L4: L1 | M4: L2
A5: =L5 -> R1 | B5: {=INDIRECT("'f(" & L5 & "," & L7 & ")'!C14")} -> 00001111001011111010110110011010 | L5: R1 | M5: R2
L6: K3
A7: F | G7: =L4 -> L1 | L7: K2
A8: byte | B8: byte | C8: hexan | D8: dec | G8: byte | H8: byte | I8: hexan | J8: dec
A9: 1 | B9: =MID($B$3,(A9-1)*8+1, 8) -> 10001000 | C9: =BIN2HEX(B9,2) -> 88 | D9: =HEX2DEC(C9) -> 136 | G9: 1 | H9: =MID($B$4,(G9-1)*8+1, 8) -> 11100000 | I9: =BIN2HEX(H9,2) -> E0 | J9: =HEX2DEC(I9) -> 224
A10: 2 | B10: =MID($B$3,(A10-1)*8+1, 8) -> 01001000 | C10: =BIN2HEX(B10,2) -> 48 | D10: =HEX2DEC(C10) -> 72 | G10: 2 | H10: =MID($B$4,(G10-1)*8+1, 8) -> 01010100 | I10: =BIN2HEX(H10,2) -> 54 | J10: =HEX2DEC(I10) -> 84
A11: 3 | B11: =MID($B$3,(A11-1)*8+1, 8) -> 10001101 | C11: =BIN2HEX(B11,2) -> 8D | D11: =HEX2DEC(C11) -> 141 | G11: 3 | H11: =MID($B$4,(G11-1)*8+1, 8) -> 11110000 | I11: =BIN2HEX(H11,2) -> F0 | J11: =HEX2DEC(I11) -> 240
A12: 4 | B12: =MID($B$3,(A12-1)*8+1, 8) -> 00001011 | C12: =BIN2HEX(B12,2) -> 0B | D12: =HEX2DEC(C12) -> 11 | G12: 4 | H12: =MID($B$4,(G12-1)*8+1, 8) -> 10101010 | I12: =BIN2HEX(H12,2) -> AA | J12: =HEX2DEC(I12) -> 170
A14: =M5&" = F XOR "&L4&" =" -> R2 = F XOR L1 = | C14: =F17&F18&F19&F20 -> 01101000000111000111110110100001
C16: byte | D16: XOR | E16: HEX | F16: Bin
C17: 1 | D17: =BITXOR(J9,D9) -> 104 | E17: =DEC2HEX(D17,2) -> 68 | F17: =HEX2BIN(E17,8) -> 01101000
C18: 2 | D18: =BITXOR(J10,D10) -> 28 | E18: =DEC2HEX(D18,2) -> 1C | F18: =HEX2BIN(E18,8) -> 00011100
C19: 3 | D19: =BITXOR(J11,D11) -> 125 | E19: =DEC2HEX(D19,2) -> 7D | F19: =HEX2BIN(E19,8) -> 01111101
C20: 4 | D20: =BITXOR(J12,D12) -> 161 | E20: =DEC2HEX(D20,2) -> A1 | F20: =HEX2BIN(E20,8) -> 10100001
A22: =M4&" = "&L5&" =" -> L2 = R1 = | C22: =B5 -> 00001111001011111010110110011010
A24: ="Mở rộng "&M5&" => E("&M5&")" -> Mở rộng R2 => E(R2) | D24: =B26 -> 101101010000000011111000001111111011110100000010
A25: bit
A26: =MID($C$14,Constanst!K3,1) -> 1 | B26: =A26&B27 -> 101101010000000011111000001111111011110100000010
A27: =MID($C$14,Constanst!K4,1) -> 0 | B27: =A27&B28 -> 01101010000000011111000001111111011110100000010
A28: =MID($C$14,Constanst!K5,1) -> 1 | B28: =A28&B29 -> 1101010000000011111000001111111011110100000010
A29: =MID($C$14,Constanst!K6,1) -> 1 | B29: =A29&B30 -> 101010000000011111000001111111011110100000010
A30: =MID($C$14,Constanst!K7,1) -> 0 | B30: =A30&B31 -> 01010000000011111000001111111011110100000010
A31: =MID($C$14,Constanst!K8,1) -> 1 | B31: =A31&B32 -> 1010000000011111000001111111011110100000010
A32: =MID($C$14,Constanst!K9,1) -> 0 | B32: =A32&B33 -> 010000000011111000001111111011110100000010
A33: =MID($C$14,Constanst!K10,1) -> 1 | B33: =A33&B34 -> 10000000011111000001111111011110100000010
A34: =MID($C$14,Constanst!K11,1) -> 0 | B34: =A34&B35 -> 0000000011111000001111111011110100000010
A35: =MID($C$14,Constanst!K12,1) -> 0 | B35: =A35&B36 -> 000000011111000001111111011110100000010
A36: =MID($C$14,Constanst!K13,1) -> 0 | B36: =A36&B37 -> 00000011111000001111111011110100000010
A37: =MID($C$14,Constanst!K14,1) -> 0 | B37: =A37&B38 -> 0000011111000001111111011110100000010
... A71: =MID($C$14,Constanst!K48,1) -> 0 | B71: =A71&B72 -> 010
A72: =MID($C$14,Constanst!K49,1) -> 1 | B72: =A72&A73 -> 10
A73: =MID($C$14,Constanst!K50,1) -> 0
A75: ="Thực hiện phép XOR A = E("&M5&") XOR "&L6 -> Thực hiện phép XOR A = E(R2) XOR K3
A76: ="Khóa " & L6 -> Khóa K3 | G76: ="E("&M5&")" -> E(R2)
A77: byte | B77: byte | C77: hexan | D77: decimal | G77: byte | H77: byte | I77: hexan | J77: decimal
A78: 1 | B78: =MID($D$2,(A78-1)*8+1, 8) -> 01010101 | C78: =BIN2HEX(B78,2) -> 55 | D78: =BIN2DEC(B78) -> 85 | G78: 1 | H78: =MID($D$24,(G78-1)*8+1, 8) -> 10110101 | I78: =BIN2HEX(H78,2) -> B5 | J78: =BIN2DEC(H78) -> 181
A79: 2 | B79: =MID($D$2,(A79-1)*8+1, 8) -> 11111100 | C79: =BIN2HEX(B79,2) -> FC | D79: =BIN2DEC(B79) -> 252 | G79: 2 | H79: =MID($D$24,(G79-1)*8+1, 8) -> 00000000 | I79: =BIN2HEX(H79,2) -> 00 | J79: =BIN2DEC(H79) -> 0
...

Sheet f(R3,K4)
A2: =L6 -> K4 | D2: =Input!I4 -> 011100101010110111010010101011011000011001010111
A3: F=P(B)= | B3: {=INDIRECT("'f(" & L5 & "," & L7 & ")'!B145")} -> 11011010001110110010011010010010
A4: =L4 -> L2 | B4: {=INDIRECT("'f(" & L5 & "," & L7 & ")'!C22")} -> 00001111001011111010110110011010 | L4: L2 | M4: L3
A5: =L5 -> R2 | B5: {=INDIRECT("'f(" & L5 & "," & L7 & ")'!C14")} -> 01101000000111000111110110100001 | L5: R2 | M5: R3
L6: K4
A7: F | G7: =L4 -> L2 | L7: K3
A8: byte | B8: byte | C8: hexan | D8: dec | G8: byte | H8: byte | I8: hexan | J8: dec
A9: 1 | B9: =MID($B$3,(A9-1)*8+1, 8) -> 11011010 | C9: =BIN2HEX(B9,2) -> DA | D9: =HEX2DEC(C9) -> 218 | G9: 1 | H9: =MID($B$4,(G9-1)*8+1, 8) -> 00001111 | I9: =BIN2HEX(H9,2) -> 0F | J9: =HEX2DEC(I9) -> 15
A10: 2 | B10: =MID($B$3,(A10-1)*8+1, 8) -> 00111011 | C10: =BIN2HEX(B10,2) -> 3B | D10: =HEX2DEC(C10) -> 59 | G10: 2 | H10: =MID($B$4,(G10-1)*8+1, 8) -> 00101111 | I10: =BIN2HEX(H10,2) -> 2F | J10: =HEX2DEC(I10) -> 47
A11: 3 | B11: =MID($B$3,(A11-1)*8+1, 8) -> 00100110 | C11: =BIN2HEX(B11,2) -> 26 | D11: =HEX2DEC(C11) -> 38 | G11: 3 | H11: =MID($B$4,(G11-1)*8+1, 8) -> 10101101 | I11: =BIN2HEX(H11,2) -> AD | J11: =HEX2DEC(I11) -> 173
A12: 4 | B12: =MID($B$3,(A12-1)*8+1, 8) -> 10010010 | C12: =BIN2HEX(B12,2) -> 92 | D12: =HEX2DEC(C12) -> 146 | G12: 4 | H12: =MID($B$4,(G12-1)*8+1, 8) -> 10011010 | I12: =BIN2HEX(H12,2) -> 9A | J12: =HEX2DEC(I12) -> 154
A14: =M5&" = F XOR "&L4&" =" -> R3 = F XOR L2 = | C14: =F17&F18&F19&F20 -> 11010101000101001000101100001000
C16: byte | D16: XOR | E16: HEX | F16: Bin
C17: 1 | D17: =BITXOR(J9,D9) -> 213 | E17: =DEC2HEX(D17,2) -> D5 | F17: =HEX2BIN(E17,8) -> 11010101
C18: 2 | D18: =BITXOR(J10,D10) -> 20 | E18: =DEC2HEX(D18,2) -> 14 | F18: =HEX2BIN(E18,8) -> 00010100
C19: 3 | D19: =BITXOR(J11,D11) -> 139 | E19: =DEC2HEX(D19,2) -> 8B | F19: =HEX2BIN(E19,8) -> 10001011
C20: 4 | D20: =BITXOR(J12,D12) -> 8 | E20: =DEC2HEX(D20,2) -> 08 | F20: =HEX2BIN(E20,8) -> 00001000
A22: =M4&" = "&L5&" =" -> L3 = R2 = | C22: =B5 -> 01101000000111000111110110100001
A24: ="Mở rộng "&M5&" => E("&M5&")" -> Mở rộng R3 => E(R3) | D24: =B26 -> 011010101010100010101001010001010110100001010001
A25: bit
A26: =MID($C$14,Constanst!K3,1) -> 0 | B26: =A26&B27 -> 011010101010100010101001010001010110100001010001
A27: =MID($C$14,Constanst!K4,1) -> 1 | B27: =A27&B28 -> 11010101010100010101001010001010110100001010001
A28: =MID($C$14,Constanst!K5,1) -> 1 | B28: =A28&B29 -> 1010101010100010101001010001010110100001010001
A29: =MID($C$14,Constanst!K6,1) -> 0 | B29: =A29&B30 -> 010101010100010101001010001010110100001010001
A30: =MID($C$14,Constanst!K7,1) -> 1 | B30: =A30&B31 -> 10101010100010101001010001010110100001010001
A31: =MID($C$14,Constanst!K8,1) -> 0 | B31: =A31&B32 -> 0101010100010101001010001010110100001010001
A32: =MID($C$14,Constanst!K9,1) -> 1 | B32: =A32&B33 -> 101010100010101001010001010110100001010001
A33: =MID($C$14,Constanst!K10,1) -> 0 | B33: =A33&B34 -> 01010100010101001010001010110100001010001
A34: =MID($C$14,Constanst!K11,1) -> 1 | B34: =A34&B35 -> 1010100010101001010001010110100001010001
A35: =MID($C$14,Constanst!K12,1) -> 0 | B35: =A35&B36 -> 010100010101001010001010110100001010001
A36: =MID($C$14,Constanst!K13,1) -> 1 | B36: =A36&B37 -> 10100010101001010001010110100001010001
A37: =MID($C$14,Constanst!K14,1) -> 0 | B37: =A37&B38 -> 0100010101001010001010110100001010001
... A71: =MID($C$14,Constanst!K48,1) -> 0 | B71: =A71&B72 -> 001
A72: =MID($C$14,Constanst!K49,1) -> 0 | B72: =A72&A73 -> 01
A73: =MID($C$14,Constanst!K50,1) -> 1
A75: ="Thực hiện phép XOR A = E("&M5&") XOR "&L6 -> Thực hiện phép XOR A = E(R3) XOR K4
A76: ="Khóa " & L6 -> Khóa K4 | G76: ="E("&M5&")" -> E(R3)
A77: byte | B77: byte | C77: hexan | D77: decimal | G77: byte | H77: byte | I77: hexan | J77: decimal
A78: 1 | B78: =MID($D$2,(A78-1)*8+1, 8) -> 01110010 | C78: =BIN2HEX(B78,2) -> 72 | D78: =BIN2DEC(B78) -> 114 | G78: 1 | H78: =MID($D$24,(G78-1)*8+1, 8) -> 01101010 | I78: =BIN2HEX(H78,2) -> 6A | J78: =BIN2DEC(H78) -> 106
A79: 2 | B79: =MID($D$2,(A79-1)*8+1, 8) -> 10101101 | C79: =BIN2HEX(B79,2) -> AD | D79: =BIN2DEC(B79) -> 173 | G79: 2 | H79: =MID($D$24,(G79-1)*8+1, 8) -> 10101000 | I79: =BIN2HEX(H79,2) -> A8 | J79: =BIN2DEC(H79) -> 168
...

Sheet f(R4,K5)
A2: =L6 -> K5 | D2: =Input!I5 -> 011111001110110000000111000111111110011011000010
A3: F=P(B)= | B3: {=INDIRECT("'f(" & L5 & "," & L7 & ")'!B145")} -> 11110100010010010101000010110010
A4: =L4 -> L3 | B4: {=INDIRECT("'f(" & L5 & "," & L7 & ")'!C22")} -> 01101000000111000111110110100001 | L4: L3 | M4: L4
A5: =L5 -> R3 | B5: {=INDIRECT("'f(" & L5 & "," & L7 & ")'!C14")} -> 11010101000101001000101100001000 | L5: R3 | M5: R4
L6: K5
A7: F | G7: =L4 -> L3 | L7: K4
A8: byte | B8: byte | C8: hexan | D8: dec | G8: byte | H8: byte | I8: hexan | J8: dec
A9: 1 | B9: =MID($B$3,(A9-1)*8+1, 8) -> 11110100 | C9: =BIN2HEX(B9,2) -> F4 | D9: =HEX2DEC(C9) -> 244 | G9: 1 | H9: =MID($B$4,(G9-1)*8+1, 8) -> 01101000 | I9: =BIN2HEX(H9,2) -> 68 | J9: =HEX2DEC(I9) -> 104
A10: 2 | B10: =MID($B$3,(A10-1)*8+1, 8) -> 01001001 | C10: =BIN2HEX(B10,2) -> 49 | D10: =HEX2DEC(C10) -> 73 | G10: 2 | H10: =MID($B$4,(G10-1)*8+1, 8) -> 00011100 | I10: =BIN2HEX(H10,2) -> 1C | J10: =HEX2DEC(I10) -> 28
A11: 3 | B11: =MID($B$3,(A11-1)*8+1, 8) -> 01010000 | C11: =BIN2HEX(B11,2) -> 50 | D11: =HEX2DEC(C11) -> 80 | G11: 3 | H11: =MID($B$4,(G11-1)*8+1, 8) -> 01111101 | I11: =BIN2HEX(H11,2) -> 7D | J11: =HEX2DEC(I11) -> 125
A12: 4 | B12: =MID($B$3,(A12-1)*8+1, 8) -> 10110010 | C12: =BIN2HEX(B12,2) -> B2 | D12: =HEX2DEC(C12) -> 178 | G12: 4 | H12: =MID($B$4,(G12-1)*8+1, 8) -> 10100001 | I12: =BIN2HEX(H12,2) -> A1 | J12: =HEX2DEC(I12) -> 161
A14: =M5&" = F XOR "&L4&" =" -> R4 = F XOR L3 = | C14: =F17&F18&F19&F20 -> 10011100010101010010110100010011
C16: byte | D16: XOR | E16: HEX | F16: Bin
C17: 1 | D17: =BITXOR(J9,D9) -> 156 | E17: =DEC2HEX(D17,2) -> 9C | F17: =HEX2BIN(E17,8) -> 10011100
C18: 2 | D18: =BITXOR(J10,D10) -> 85 | E18: =DEC2HEX(D18,2) -> 55 | F18: =HEX2BIN(E18,8) -> 01010101
C19: 3 | D19: =BITXOR(J11,D11) -> 45 | E19: =DEC2HEX(D19,2) -> 2D | F19: =HEX2BIN(E19,8) -> 00101101
C20: 4 | D20: =BITXOR(J12,D12) -> 19 | E20: =DEC2HEX(D20,2) -> 13 | F20: =HEX2BIN(E20,8) -> 00010011
A22: =M4&" = "&L5&" =" -> L4 = R3 = | C22: =B5 -> 11010101000101001000101100001000
A24: ="Mở rộng "&M5&" => E("&M5&")" -> Mở rộng R4 => E(R4) | D24: =B26 -> 110011111000001010101010100101011010100010100111
A25: bit
A26: =MID($C$14,Constanst!K3,1) -> 1 | B26: =A26&B27 -> 110011111000001010101010100101011010100010100111
A27: =MID($C$14,Constanst!K4,1) -> 1 | B27: =A27&B28 -> 10011111000001010101010100101011010100010100111
A28: =MID($C$14,Constanst!K5,1) -> 0 | B28: =A28&B29 -> 0011111000001010101010100101011010100010100111
A29: =MID($C$14,Constanst!K6,1) -> 0 | B29: =A29&B30 -> 011111000001010101010100101011010100010100111
A30: =MID($C$14,Constanst!K7,1) -> 1 | B30: =A30&B31 -> 11111000001010101010100101011010100010100111
A31: =MID($C$14,Constanst!K8,1) -> 1 | B31: =A31&B32 -> 1111000001010101010100101011010100010100111
A32: =MID($C$14,Constanst!K9,1) -> 1 | B32: =A32&B33 -> 111000001010101010100101011010100010100111
A33: =MID($C$14,Constanst!K10,1) -> 1 | B33: =A33&B34 -> 11000001010101010100101011010100010100111
A34: =MID($C$14,Constanst!K11,1) -> 1 | B34: =A34&B35 -> 1000001010101010100101011010100010100111
A35: =MID($C$14,Constanst!K12,1) -> 0 | B35: =A35&B36 -> 000001010101010100101011010100010100111
A36: =MID($C$14,Constanst!K13,1) -> 0 | B36: =A36&B37 -> 00001010101010100101011010100010100111
A37: =MID($C$14,Constanst!K14,1) -> 0 | B37: =A37&B38 -> 0001010101010100101011010100010100111
... A71: =MID($C$14,Constanst!K48,1) -> 1 | B71: =A71&B72 -> 111
A72: =MID($C$14,Constanst!K49,1) -> 1 | B72: =A72&A73 -> 11
A73: =MID($C$14,Constanst!K50,1) -> 1
A75: ="Thực hiện phép XOR A = E("&M5&") XOR "&L6 -> Thực hiện phép XOR A = E(R4) XOR K5
A76: ="Khóa " & L6 -> Khóa K5 | G76: ="E("&M5&")" -> E(R4)
A77: byte | B77: byte | C77: hexan | D77: decimal | G77: byte | H77: byte | I77: hexan | J77: decimal
A78: 1 | B78: =MID($D$2,(A78-1)*8+1, 8) -> 01111100 | C78: =BIN2HEX(B78,2) -> 7C | D78: =BIN2DEC(B78) -> 124 | G78: 1 | H78: =MID($D$24,(G78-1)*8+1, 8) -> 11001111 | I78: =BIN2HEX(H78,2) -> CF | J78: =BIN2DEC(H78) -> 207
A79: 2 | B79: =MID($D$2,(A79-1)*8+1, 8) -> 11101100 | C79: =BIN2HEX(B79,2) -> EC | D79: =BIN2DEC(B79) -> 236 | G79: 2 | H79: =MID($D$24,(G79-1)*8+1, 8) -> 10000010 | I79: =BIN2HEX(H79,2) -> 82 | J79: =BIN2DEC(H79) -> 130
...

Sheet f(R5,K6)
A2: =L6 -> K6 | D2: =Input!I6 -> 011000111010010100011110001111001100010101000101
A3: F=P(B)= | B3: {=INDIRECT("'f(" & L5 & "," & L7 & ")'!B145")} -> 11011000001100100011011111111101
A4: =L4 -> L4 | B4: {=INDIRECT("'f(" & L5 & "," & L7 & ")'!C22")} -> 11010101000101001000101100001000 | L4: L4 | M4: L5
A5: =L5 -> R4 | B5: {=INDIRECT("'f(" & L5 & "," & L7 & ")'!C14")} -> 10011100010101010010110100010011 | L5: R4 | M5: R5
L6: K6
A7: F | G7: =L4 -> L4 | L7: K5
A8: byte | B8: byte | C8: hexan | D8: dec | G8: byte | H8: byte | I8: hexan | J8: dec
A9: 1 | B9: =MID($B$3,(A9-1)*8+1, 8) -> 11011000 | C9: =BIN2HEX(B9,2) -> D8 | D9: =HEX2DEC(C9) -> 216 | G9: 1 | H9: =MID($B$4,(G9-1)*8+1, 8) -> 11010101 | I9: =BIN2HEX(H9,2) -> D5 | J9: =HEX2DEC(I9) -> 213
A10: 2 | B10: =MID($B$3,(A10-1)*8+1, 8) -> 00110010 | C10: =BIN2HEX(B10,2) -> 32 | D10: =HEX2DEC(C10) -> 50 | G10: 2 | H10: =MID($B$4,(G10-1)*8+1, 8) -> 00010100 | I10: =BIN2HEX(H10,2) -> 14 | J10: =HEX2DEC(I10) -> 20
A11: 3 | B11: =MID($B$3,(A11-1)*8+1, 8) -> 00110111 | C11: =BIN2HEX(B11,2) -> 37 | D11: =HEX2DEC(C11) -> 55 | G11: 3 | H11: =MID($B$4,(G11-1)*8+1, 8) -> 10001011 | I11: =BIN2HEX(H11,2) -> 8B | J11: =HEX2DEC(I11) -> 139
A12: 4 | B12: =MID($B$3,(A12-1)*8+1, 8) -> 11111101 | C12: =BIN2HEX(B12,2) -> FD | D12: =HEX2DEC(C12) -> 253 | G12: 4 | H12: =MID($B$4,(G12-1)*8+1, 8) -> 00001000 | I12: =BIN2HEX(H12,2) -> 08 | J12: =HEX2DEC(I12) -> 8
A14: =M5&" = F XOR "&L4&" =" -> R5 = F XOR L4 = | C14: =F17&F18&F19&F20 -> 00001101001001101011110011110101
C16: byte | D16: XOR | E16: HEX | F16: Bin
C17: 1 | D17: =BITXOR(J9,D9) -> 13 | E17: =DEC2HEX(D17,2) -> 0D | F17: =HEX2BIN(E17,8) -> 00001101
C18: 2 | D18: =BITXOR(J10,D10) -> 38 | E18: =DEC2HEX(D18,2) -> 26 | F18: =HEX2BIN(E18,8) -> 00100110
C19: 3 | D19: =BITXOR(J11,D11) -> 188 | E19: =DEC2HEX(D19,2) -> BC | F19: =HEX2BIN(E19,8) -> 10111100
C20: 4 | D20: =BITXOR(J12,D12) -> 245 | E20: =DEC2HEX(D20,2) -> F5 | F20: =HEX2BIN(E20,8) -> 11110101
A22: =M4&" = "&L5&" =" -> L5 = R4 = | C22: =B5 -> 10011100010101010010110100010011
A24: ="Mở rộng "&M5&" => E("&M5&")" -> Mở rộng R5 => E(R5) | D24: =B26 -> 100001011010100100001101010111111001011110101010
A25: bit
A26: =MID($C$14,Constanst!K3,1) -> 1 | B26: =A26&B27 -> 100001011010100100001101010111111001011110101010
A27: =MID($C$14,Constanst!K4,1) -> 0 | B27: =A27&B28 -> 00001011010100100001101010111111001011110101010
A28: =MID($C$14,Constanst!K5,1) -> 0 | B28: =A28&B29 -> 0001011010100100001101010111111001011110101010
A29: =MID($C$14,Constanst!K6,1) -> 0 | B29: =A29&B30 -> 001011010100100001101010111111001011110101010
A30: =MID($C$14,Constanst!K7,1) -> 0 | B30: =A30&B31 -> 01011010100100001101010111111001011110101010
A31: =MID($C$14,Constanst!K8,1) -> 1 | B31: =A31&B32 -> 1011010100100001101010111111001011110101010
A32: =MID($C$14,Constanst!K9,1) -> 0 | B32: =A32&B33 -> 011010100100001101010111111001011110101010
A33: =MID($C$14,Constanst!K10,1) -> 1 | B33: =A33&B34 -> 11010100100001101010111111001011110101010
A34: =MID($C$14,Constanst!K11,1) -> 1 | B34: =A34&B35 -> 1010100100001101010111111001011110101010
A35: =MID($C$14,Constanst!K12,1) -> 0 | B35: =A35&B36 -> 010100100001101010111111001011110101010
A36: =MID($C$14,Constanst!K13,1) -> 1 | B36: =A36&B37 -> 10100100001101010111111001011110101010
A37: =MID($C$14,Constanst!K14,1) -> 0 | B37: =A37&B38 -> 0100100001101010111111001011110101010
... A71: =MID($C$14,Constanst!K48,1) -> 0 | B71: =A71&B72 -> 010
A72: =MID($C$14,Constanst!K49,1) -> 1 | B72: =A72&A73 -> 10
A73: =MID($C$14,Constanst!K50,1) -> 0
A75: ="Thực hiện phép XOR A = E("&M5&") XOR "&L6 -> Thực hiện phép XOR A = E(R5) XOR K6
A76: ="Khóa " & L6 -> Khóa K6 | G76: ="E("&M5&")" -> E(R5)
A77: byte | B77: byte | C77: hexan | D77: decimal | G77: byte | H77: byte | I77: hexan | J77: decimal
A78: 1 | B78: =MID($D$2,(A78-1)*8+1, 8) -> 01100011 | C78: =BIN2HEX(B78,2) -> 63 | D78: =BIN2DEC(B78) -> 99 | G78: 1 | H78: =MID($D$24,(G78-1)*8+1, 8) -> 10000101 | I78: =BIN2HEX(H78,2) -> 85 | J78: =BIN2DEC(H78) -> 133
A79: 2 | B79: =MID($D$2,(A79-1)*8+1, 8) -> 10100101 | C79: =BIN2HEX(B79,2) -> A5 | D79: =BIN2DEC(B79) -> 165 | G79: 2 | H79: =MID($D$24,(G79-1)*8+1, 8) -> 10101001 | I79: =BIN2HEX(H79,2) -> A9 | J79: =BIN2DEC(H79) -> 169
...

Sheet f(R6,K7)
A2: =L6 -> K7 | D2: =Input!I7 -> 011011001000010010110111100010101110010011000110
A3: F=P(B)= | B3: {=INDIRECT("'f(" & L5 & "," & L7 & ")'!B145")} -> 10101111110001000011101100100101
A4: =L4 -> L5 | B4: {=INDIRECT("'f(" & L5 & "," & L7 & ")'!C22")} -> 10011100010101010010110100010011 | L4: L5 | M4: L6
A5: =L5 -> R5 | B5: {=INDIRECT("'f(" & L5 & "," & L7 & ")'!C14")} -> 00001101001001101011110011110101 | L5: R5 | M5: R6
L6: K7
A7: F | G7: =L4 -> L5 | L7: K6
A8: byte | B8: byte | C8: hexan | D8: dec | G8: byte | H8: byte | I8: hexan | J8: dec
A9: 1 | B9: =MID($B$3,(A9-1)*8+1, 8) -> 10101111 | C9: =BIN2HEX(B9,2) -> AF | D9: =HEX2DEC(C9) -> 175 | G9: 1 | H9: =MID($B$4,(G9-1)*8+1, 8) -> 10011100 | I9: =BIN2HEX(H9,2) -> 9C | J9: =HEX2DEC(I9) -> 156
A10: 2 | B10: =MID($B$3,(A10-1)*8+1, 8) -> 11000100 | C10: =BIN2HEX(B10,2) -> C4 | D10: =HEX2DEC(C10) -> 196 | G10: 2 | H10: =MID($B$4,(G10-1)*8+1, 8) -> 01010101 | I10: =BIN2HEX(H10,2) -> 55 | J10: =HEX2DEC(I10) -> 85
A11: 3 | B11: =MID($B$3,(A11-1)*8+1, 8) -> 00111011 | C11: =BIN2HEX(B11,2) -> 3B | D11: =HEX2DEC(C11) -> 59 | G11: 3 | H11: =MID($B$4,(G11-1)*8+1, 8) -> 00101101 | I11: =BIN2HEX(H11,2) -> 2D | J11: =HEX2DEC(I11) -> 45
A12: 4 | B12: =MID($B$3,(A12-1)*8+1, 8) -> 00100101 | C12: =BIN2HEX(B12,2) -> 25 | D12: =HEX2DEC(C12) -> 37 | G12: 4 | H12: =MID($B$4,(G12-1)*8+1, 8) -> 00010011 | I12: =BIN2HEX(H12,2) -> 13 | J12: =HEX2DEC(I12) -> 19
A14: =M5&" = F XOR "&L4&" =" -> R6 = F XOR L5 = | C14: =F17&F18&F19&F20 -> 00110011100100010001011000110110
C16: byte | D16: XOR | E16: HEX | F16: Bin
C17: 1 | D17: =BITXOR(J9,D9) -> 51 | E17: =DEC2HEX(D17,2) -> 33 | F17: =HEX2BIN(E17,8) -> 00110011
C18: 2 | D18: =BITXOR(J10,D10) -> 145 | E18: =DEC2HEX(D18,2) -> 91 | F18: =HEX2BIN(E18,8) -> 10010001
C19: 3 | D19: =BITXOR(J11,D11) -> 22 | E19: =DEC2HEX(D19,2) -> 16 | F19: =HEX2BIN(E19,8) -> 00010110
C20: 4 | D20: =BITXOR(J12,D12) -> 54 | E20: =DEC2HEX(D20,2) -> 36 | F20: =HEX2BIN(E20,8) -> 00110110
A22: =M4&" = "&L5&" =" -> L6 = R5 = | C22: =B5 -> 00001101001001101011110011110101
A24: ="Mở rộng "&M5&" => E("&M5&")" -> Mở rộng R6 => E(R6) | D24: =B26 -> 000110100111110010100010100010101100000110101100
A25: bit
A26: =MID($C$14,Constanst!K3,1) -> 0 | B26: =A26&B27 -> 000110100111110010100010100010101100000110101100
A27: =MID($C$14,Constanst!K4,1) -> 0 | B27: =A27&B28 -> 00110100111110010100010100010101100000110101100
A28: =MID($C$14,Constanst!K5,1) -> 0 | B28: =A28&B29 -> 0110100111110010100010100010101100000110101100
A29: =MID($C$14,Constanst!K6,1) -> 1 | B29: =A29&B30 -> 110100111110010100010100010101100000110101100
A30: =MID($C$14,Constanst!K7,1) -> 1 | B30: =A30&B31 -> 10100111110010100010100010101100000110101100
A31: =MID($C$14,Constanst!K8,1) -> 0 | B31: =A31&B32 -> 0100111110010100010100010101100000110101100
A32: =MID($C$14,Constanst!K9,1) -> 1 | B32: =A32&B33 -> 100111110010100010100010101100000110101100
A33: =MID($C$14,Constanst!K10,1) -> 0 | B33: =A33&B34 -> 00111110010100010100010101100000110101100
A34: =MID($C$14,Constanst!K11,1) -> 0 | B34: =A34&B35 -> 0111110010100010100010101100000110101100
A35: =MID($C$14,Constanst!K12,1) -> 1 | B35: =A35&B36 -> 111110010100010100010101100000110101100
A36: =MID($C$14,Constanst!K13,1) -> 1 | B36: =A36&B37 -> 11110010100010100010101100000110101100
A37: =MID($C$14,Constanst!K14,1) -> 1 | B37: =A37&B38 -> 1110010100010100010101100000110101100
... A71: =MID($C$14,Constanst!K48,1) -> 1 | B71: =A71&B72 -> 100
A72: =MID($C$14,Constanst!K49,1) -> 0 | B72: =A72&A73 -> 00
A73: =MID($C$14,Constanst!K50,1) -> 0
A75: ="Thực hiện phép XOR A = E("&M5&") XOR "&L6 -> Thực hiện phép XOR A = E(R6) XOR K7
A76: ="Khóa " & L6 -> Khóa K7 | G76: ="E("&M5&")" -> E(R6)
A77: byte | B77: byte | C77: hexan | D77: decimal | G77: byte | H77: byte | I77: hexan | J77: decimal
A78: 1 | B78: =MID($D$2,(A78-1)*8+1, 8) -> 01101100 | C78: =BIN2HEX(B78,2) -> 6C | D78: =BIN2DEC(B78) -> 108 | G78: 1 | H78: =MID($D$24,(G78-1)*8+1, 8) -> 00011010 | I78: =BIN2HEX(H78,2) -> 1A | J78: =BIN2DEC(H78) -> 26
A79: 2 | B79: =MID($D$2,(A79-1)*8+1, 8) -> 10000100 | C79: =BIN2HEX(B79,2) -> 84 | D79: =BIN2DEC(B79) -> 132 | G79: 2 | H79: =MID($D$24,(G79-1)*8+1, 8) -> 01111100 | I79: =BIN2HEX(H79,2) -> 7C | J79: =BIN2DEC(H79) -> 124
...

Sheet f(R7,K8)
A2: =L6 -> K8 | D2: =Input!I8 -> 111101111000100000111010111011001110011110000001
A3: F=P(B)= | B3: {=INDIRECT("'f(" & L5 & "," & L7 & ")'!B145")} -> 01001110010100010010001110100010
A4: =L4 -> L6 | B4: {=INDIRECT("'f(" & L5 & "," & L7 & ")'!C22")} -> 00001101001001101011110011110101 | L4: L6 | M4: L7
A5: =L5 -> R6 | B5: {=INDIRECT("'f(" & L5 & "," & L7 & ")'!C14")} -> 00110011100100010001011000110110 | L5: R6 | M5: R7
L6: K8
A7: F | G7: =L4 -> L6 | L7: K7
A8: byte | B8: byte | C8: hexan | D8: dec | G8: byte | H8: byte | I8: hexan | J8: dec
A9: 1 | B9: =MID($B$3,(A9-1)*8+1, 8) -> 01001110 | C9: =BIN2HEX(B9,2) -> 4E | D9: =HEX2DEC(C9) -> 78 | G9: 1 | H9: =MID($B$4,(G9-1)*8+1, 8) -> 00001101 | I9: =BIN2HEX(H9,2) -> 0D | J9: =HEX2DEC(I9) -> 13
A10: 2 | B10: =MID($B$3,(A10-1)*8+1, 8) -> 01010001 | C10: =BIN2HEX(B10,2) -> 51 | D10: =HEX2DEC(C10) -> 81 | G10: 2 | H10: =MID($B$4,(G10-1)*8+1, 8) -> 00100110 | I10: =BIN2HEX(H10,2) -> 26 | J10: =HEX2DEC(I10) -> 38
A11: 3 | B11: =MID($B$3,(A11-1)*8+1, 8) -> 00100011 | C11: =BIN2HEX(B11,2) -> 23 | D11: =HEX2DEC(C11) -> 35 | G11: 3 | H11: =MID($B$4,(G11-1)*8+1, 8) -> 10111100 | I11: =BIN2HEX(H11,2) -> BC | J11: =HEX2DEC(I11) -> 188
A12: 4 | B12: =MID($B$3,(A12-1)*8+1, 8) -> 10100010 | C12: =BIN2HEX(B12,2) -> A2 | D12: =HEX2DEC(C12) -> 162 | G12: 4 | H12: =MID($B$4,(G12-1)*8+1, 8) -> 11110101 | I12: =BIN2HEX(H12,2) -> F5 | J12: =HEX2DEC(I12) -> 245
A14: =M5&" = F XOR "&L4&" =" -> R7 = F XOR L6 = | C14: =F17&F18&F19&F20 -> 01000011011101111001111101010111
C16: byte | D16: XOR | E16: HEX | F16: Bin
C17: 1 | D17: =BITXOR(J9,D9) -> 67 | E17: =DEC2HEX(D17,2) -> 43 | F17: =HEX2BIN(E17,8) -> 01000011
C18: 2 | D18: =BITXOR(J10,D10) -> 119 | E18: =DEC2HEX(D18,2) -> 77 | F18: =HEX2BIN(E18,8) -> 01110111
C19: 3 | D19: =BITXOR(J11,D11) -> 159 | E19: =DEC2HEX(D19,2) -> 9F | F19: =HEX2BIN(E19,8) -> 10011111
C20: 4 | D20: =BITXOR(J12,D12) -> 87 | E20: =DEC2HEX(D20,2) -> 57 | F20: =HEX2BIN(E20,8) -> 01010111
A22: =M4&" = "&L5&" =" -> L7 = R6 = | C22: =B5 -> 00110011100100010001011000110110
A24: ="Mở rộng "&M5&" => E("&M5&")" -> Mở rộng R7 => E(R7) | D24: =B26 -> 101000000110101110101111110011111110101010101110
A25: bit
A26: =MID($C$14,Constanst!K3,1) -> 1 | B26: =A26&B27 -> 101000000110101110101111110011111110101010101110
A27: =MID($C$14,Constanst!K4,1) -> 0 | B27: =A27&B28 -> 01000000110101110101111110011111110101010101110
A28: =MID($C$14,Constanst!K5,1) -> 1 | B28: =A28&B29 -> 1000000110101110101111110011111110101010101110
A29: =MID($C$14,Constanst!K6,1) -> 0 | B29: =A29&B30 -> 000000110101110101111110011111110101010101110
A30: =MID($C$14,Constanst!K7,1) -> 0 | B30: =A30&B31 -> 00000110101110101111110011111110101010101110
A31: =MID($C$14,Constanst!K8,1) -> 0 | B31: =A31&B32 -> 0000110101110101111110011111110101010101110
A32: =MID($C$14,Constanst!K9,1) -> 0 | B32: =A32&B33 -> 000110101110101111110011111110101010101110
A33: =MID($C$14,Constanst!K10,1) -> 0 | B33: =A33&B34 -> 00110101110101111110011111110101010101110
A34: =MID($C$14,Constanst!K11,1) -> 0 | B34: =A34&B35 -> 0110101110101111110011111110101010101110
A35: =MID($C$14,Constanst!K12,1) -> 1 | B35: =A35&B36 -> 110101110101111110011111110101010101110
A36: =MID($C$14,Constanst!K13,1) -> 1 | B36: =A36&B37 -> 10101110101111110011111110101010101110
A37: =MID($C$14,Constanst!K14,1) -> 0 | B37: =A37&B38 -> 0101110101111110011111110101010101110
... A71: =MID($C$14,Constanst!K48,1) -> 1 | B71: =A71&B72 -> 110
A72: =MID($C$14,Constanst!K49,1) -> 1 | B72: =A72&A73 -> 10
A73: =MID($C$14,Constanst!K50,1) -> 0
A75: ="Thực hiện phép XOR A = E("&M5&") XOR "&L6 -> Thực hiện phép XOR A = E(R7) XOR K8
A76: ="Khóa " & L6 -> Khóa K8 | G76: ="E("&M5&")" -> E(R7)
A77: byte | B77: byte | C77: hexan | D77: decimal | G77: byte | H77: byte | I77: hexan | J77: decimal
A78: 1 | B78: =MID($D$2,(A78-1)*8+1, 8) -> 11110111 | C78: =BIN2HEX(B78,2) -> F7 | D78: =BIN2DEC(B78) -> 247 | G78: 1 | H78: =MID($D$24,(G78-1)*8+1, 8) -> 10100000 | I78: =BIN2HEX(H78,2) -> A0 | J78: =BIN2DEC(H78) -> 160
A79: 2 | B79: =MID($D$2,(A79-1)*8+1, 8) -> 10001000 | C79: =BIN2HEX(B79,2) -> 88 | D79: =BIN2DEC(B79) -> 136 | G79: 2 | H79: =MID($D$24,(G79-1)*8+1, 8) -> 01101011 | I79: =BIN2HEX(H79,2) -> 6B | J79: =BIN2DEC(H79) -> 107
...

Sheet f(R8,K9)
A2: =L6 -> K9 | D2: =Input!I9 -> 110000001101101111101011001001111011100000111001
A3: F=P(B)= | B3: {=INDIRECT("'f(" & L5 & "," & L7 & ")'!B145")} -> 01101100111111011110110010111000
A4: =L4 -> L7 | B4: {=INDIRECT("'f(" & L5 & "," & L7 & ")'!C22")} -> 00110011100100010001011000110110 | L4: L7 | M4: L8
A5: =L5 -> R7 | B5: {=INDIRECT("'f(" & L5 & "," & L7 & ")'!C14")} -> 01000011011101111001111101010111 | L5: R7 | M5: R8
L6: K9
A7: F | G7: =L4 -> L7 | L7: K8
A8: byte | B8: byte | C8: hexan | D8: dec | G8: byte | H8: byte | I8: hexan | J8: dec
A9: 1 | B9: =MID($B$3,(A9-1)*8+1, 8) -> 01101100 | C9: =BIN2HEX(B9,2) -> 6C | D9: =HEX2DEC(C9) -> 108 | G9: 1 | H9: =MID($B$4,(G9-1)*8+1, 8) -> 00110011 | I9: =BIN2HEX(H9,2) -> 33 | J9: =HEX2DEC(I9) -> 51
A10: 2 | B10: =MID($B$3,(A10-1)*8+1, 8) -> 11111101 | C10: =BIN2HEX(B10,2) -> FD | D10: =HEX2DEC(C10) -> 253 | G10: 2 | H10: =MID($B$4,(G10-1)*8+1, 8) -> 10010001 | I10: =BIN2HEX(H10,2) -> 91 | J10: =HEX2DEC(I10) -> 145
