Workbook

Sheet Sbox
A1: s1 | B1: 0 | C1: 1 | D1: 2 | E1: 3 | F1: 4 | G1: 5 | H1: 6 | I1: 7 | J1: 8 | K1: 9 | L1: 10 | M1: 11 | N1: 12 | O1: 13 | P1: 14 | Q1: 15 | S1: s5 | T1: 0 | U1: 1 | V1: 2 | W1: 3 | X1: 4 | Y1: 5 | Z1: 6 | AA1: 7 | AB1: 8 | AC1: 9 | AD1: 10 | AE1: 11 | AF1: 12 | AG1: 13 | AH1: 14 | AI1: 15
A2: 0 | B2: 14 | C2: 4 | D2: 13 | E2: 1 | F2: 2 | G2: 15 | H2: 11 | I2: 8 | J2: 3 | K2: 10 | L2: 6 | M2: 12 | N2: 5 | O2: 9 | P2: 0 | Q2: 7 | S2: 0 | T2: 2 | U2: 12 | V2: 4 | W2: 1 | X2: 7 | Y2: 10 | Z2: 11 | AA2: 6 | AB2: 8 | AC2: 5 | AD2: 3 | AE2: 15 | AF2: 13 | AG2: 0 | AH2: 14 | AI2: 9
A3: 1 | B3: 0 | C3: 15 | D3: 7 | E3: 4 | F3: 14 | G3: 2 | H3: 13 | I3: 1 | J3: 10 | K3: 6 | L3: 12 | M3: 11 | N3: 9 | O3: 5 | P3: 3 | Q3: 8 | S3: 1 | T3: 14 | U3: 11 | V3: 2 | W3: 12 | X3: 4 | Y3: 7 | Z3: 13 | AA3: 1 | AB3: 5 | AC3: 0 | AD3: 15 | AE3: 10 | AF3: 3 | AG3: 9 | AH3: 8 | AI3: 6
A4: 2 | B4: 4 | C4: 1 | D4: 14 | E4: 8 | F4: 13 | G4: 6 | H4: 2 | I4: 11 | J4: 15 | K4: 12 | L4: 9 | M4: 7 | N4: 3 | O4: 10 | P4: 5 | Q4: 0 | S4: 2 | T4: 4 | U4: 2 | V4: 1 | W4: 11 | X4: 10 | Y4: 13 | Z4: 7 | AA4: 8 | AB4: 15 | AC4: 9 | AD4: 12 | AE4: 5 | AF4: 6 | AG4: 3 | AH4: 0 | AI4: 14
A5: 3 | B5: 15 | C5: 12 | D5: 8 | E5: 2 | F5: 4 | G5: 9 | H5: 1 | I5: 7 | J5: 5 | K5: 11 | L5: 3 | M5: 14 | N5: 10 | O5: 0 | P5: 6 | Q5: 13 | S5: 3 | T5: 11 | U5: 8 | V5: 12 | W5: 7 | X5: 1 | Y5: 14 | Z5: 2 | AA5: 13 | AB5: 6 | AC5: 15 | AD5: 0 | AE5: 9 | AF5: 10 | AG5: 4 | AH5: 5 | AI5: 3
A8: s2 | B8: 0 | C8: 1 | D8: 2 | E8: 3 | F8: 4 | G8: 5 | H8: 6 | I8: 7 | J8: 8 | K8: 9 | L8: 10 | M8: 11 | N8: 12 | O8: 13 | P8: 14 | Q8: 15 | S8: s6 | T8: 0 | U8: 1 | V8: 2 | W8: 3 | X8: 4 | Y8: 5 | Z8: 6 | AA8: 7 | AB8: 8 | AC8: 9 | AD8: 10 | AE8: 11 | AF8: 12 | AG8: 13 | AH8: 14 | AI8: 15
A9: 0 | B9: 15 | C9: 1 | D9: 8 | E9: 14 | F9: 6 | G9: 11 | H9: 3 | I9: 4 | J9: 9 | K9: 7 | L9: 2 | M9: 13 | N9: 12 | O9: 0 | P9: 5 | Q9: 10 | S9: 0 | T9: 12 | U9: 1 | V9: 10 | W9: 15 | X9: 9 | Y9: 2 | Z9: 6 | AA9: 8 | AB9: 0 | AC9: 13 | AD9: 3 | AE9: 4 | AF9: 14 | AG9: 7 | AH9: 5 | AI9: 11
A10: 1 | B10: 3 | C10: 13 | D10: 4 | E10: 7 | F10: 15 | G10: 2 | H10: 8 | I10: 14 | J10: 12 | K10: 0 | L10: 1 | M10: 10 | N10: 6 | O10: 9 | P10: 11 | Q10: 5 | S10: 1 | T10: 10 | U10: 15 | V10: 4 | W10: 2 | X10: 7 | Y10: 12 | Z10: 9 | AA10: 5 | AB10: 6 | AC10: 1 | AD10: 13 | AE10: 14 | AF10: 0 | AG10: 11 | AH10: 3 | AI10: 8
A11: 2 | B11: 0 | C11: 14 | D11: 7 | E11: 11 | F11: 10 | G11: 4 | H11: 13 | I11: 1 | J11: 5 | K11: 8 | L11: 12 | M11: 6 | N11: 9 | O11: 3 | P11: 2 | Q11: 15 | S11: 2 | T11: 9 | U11: 14 | V11: 15 | W11: 5 | X11: 2 | Y11: 8 | Z11: 12 | AA11: 3 | AB11: 7 | AC11: 0 | AD11: 4 | AE11: 10 | AF11: 1 | AG11: 13 | AH11: 11 | AI11: 6
A12: 3 | B12: 13 | C12: 8 | D12: 10 | E12: 1 | F12: 3 | G12: 15 | H12: 4 | I12: 2 | J12: 11 | K12: 6 | L12: 7 | M12: 12 | N12: 0 | O12: 5 | P12: 14 | Q12: 9 | S12: 3 | T12: 4 | U12: 3 | V12: 2 | W12: 12 | X12: 9 | Y12: 5 | Z12: 15 | AA12: 10 | AB12: 11 | AC12: 14 | AD12: 1 | AE12: 7 | AF12: 6 | AG12: 0 | AH12: 8 | AI12: 13
A15: s3 | B15: 0 | C15: 1 | D15: 2 | E15: 3 | F15: 4 | G15: 5 | H15: 6 | I15: 7 | J15: 8 | K15: 9 | L15: 10 | M15: 11 | N15: 12 | O15: 13 | P15: 14 | Q15: 15 | S15: s7 | T15: 0 | U15: 1 | V15: 2 | W15: 3 | X15: 4 | Y15: 5 | Z15: 6 | AA15: 7 | AB15: 8 | AC15: 9 | AD15: 10 | AE15: 11 | AF15: 12 | AG15: 13 | AH15: 14 | AI15: 15
A16: 0 | B16: 10 | C16: 0 | D16: 9 | E16: 14 | F16: 6 | G16: 3 | H16: 15 | I16: 5 | J16: 1 | K16: 13 | L16: 12 | M16: 7 | N16: 11 | O16: 4 | P16: 2 | Q16: 8 | S16: 0 | T16: 4 | U16: 11 | V16: 2 | W16: 14 | X16: 15 | Y16: 0 | Z16: 8 | AA16: 13 | AB16: 3 | AC16: 12 | AD16: 9 | AE16: 7 | AF16: 5 | AG16: 10 | AH16: 6 | AI16: 1
A17: 1 | B17: 13 | C17: 7 | D17: 0 | E17: 9 | F17: 3 | G17: 4 | H17: 6 | I17: 10 | J17: 2 | K17: 8 | L17: 5 | M17: 14 | N17: 12 | O17: 11 | P17: 15 | Q17: 1 | S17: 1 | T17: 13 | U17: 0 | V17: 11 | W17: 7 | X17: 4 | Y17: 9 | Z17: 1 | AA17: 10 | AB17: 14 | AC17: 3 | AD17: 5 | AE17: 12 | AF17: 2 | AG17: 15 | AH17: 8 | AI17: 6
A18: 2 | B18: 13 | C18: 6 | D18: 4 | E18: 9 | F18: 8 | G18: 15 | H18: 3 | I18: 0 | J18: 11 | K18: 1 | L18: 2 | M18: 12 | N18: 5 | O18: 10 | P18: 14 | Q18: 7 | S18: 2 | T18: 1 | U18: 4 | V18: 11 | W18: 13 | X18: 12 | Y18: 3 | Z18: 7 | AA18: 14 | AB18: 10 | AC18: 15 | AD18: 6 | AE18: 8 | AF18: 0 | AG18: 5 | AH18: 9 | AI18: 2
A19: 3 | B19: 1 | C19: 10 | D19: 13 | E19: 0 | F19: 6 | G19: 9 | H19: 8 | I19: 7 | J19: 4 | K19: 15 | L19: 14 | M19: 3 | N19: 11 | O19: 5 | P19: 2 | Q19: 12 | S19: 3 | T19: 6 | U19: 11 | V19: 13 | W19: 8 | X19: 1 | Y19: 4 | Z19: 10 | AA19: 7 | AB19: 9 | AC19: 5 | AD19: 0 | AE19: 15 | AF19: 14 | AG19: 2 | AH19: 3 | AI19: 12
A22: s4 | B22: 0 | C22: 1 | D22: 2 | E22: 3 | F22: 4 | G22: 5 | H22: 6 | I22: 7 | J22: 8 | K22: 9 | L22: 10 | M22: 11 | N22: 12 | O22: 13 | P22: 14 | Q22: 15 | S22: s8 | T22: 0 | U22: 1 | V22: 2 | W22: 3 | X22: 4 | Y22: 5 | Z22: 6 | AA22: 7 | AB22: 8 | AC22: 9 | AD22: 10 | AE22: 11 | AF22: 12 | AG22: 13 | AH22: 14 | AI22: 15
A23: 0 | B23: 7 | C23: 13 | D23: 14 | E23: 3 | F23: 0 | G23: 6 | H23: 9 | I23: 10 | J23: 1 | K23: 2 | L23: 8 | M23: 5 | N23: 11 | O23: 12 | P23: 4 | Q23: 15 | S23: 0 | T23: 13 | U23: 2 | V23: 8 | W23: 4 | X23: 6 | Y23: 15 | Z23: 11 | AA23: 1 | AB23: 10 | AC23: 9 | AD23: 3 | AE23: 14 | AF23: 5 | AG23: 0 | AH23: 12 | AI23: 7
A24: 1 | B24: 13 | C24: 8 | D24: 11 | E24: 5 | F24: 6 | G24: 15 | H24: 0 | I24: 3 | J24: 4 | K24: 7 | L24: 2 | M24: 12 | N24: 1 | O24: 10 | P24: 14 | Q24: 9 | S24: 1 | T24: 1 | U24: 15 | V24: 13 | W24: 8 | X24: 10 | Y24: 3 | Z24: 7 | AA24: 4 | AB24: 12 | AC24: 5 | AD24: 6 | AE24: 11 | AF24: 0 | AG24: 14 | AH24: 9 | AI24: 2
A25: 2 | B25: 10 | C25: 6 | D25: 9 | E25: 0 | F25: 12 | G25: 11 | H25: 7 | I25: 13 | J25: 15 | K25: 1 | L25: 3 | M25: 14 | N25: 5 | O25: 2 | P25: 8 | Q25: 4 | S25: 2 | T25: 7 | U25: 11 | V25: 4 | W25: 1 | X25: 9 | Y25: 12 | Z25: 14 | AA25: 2 | AB25: 0 | AC25: 6 | AD25: 10 | AE25: 13 | AF25: 15 | AG25: 3 | AH25: 5 | AI25: 8
A26: 3 | B26: 3 | C26: 15 | D26: 0 | E26: 6 | F26: 10 | G26: 1 | H26: 13 | I26: 8 | J26: 9 | K26: 4 | L26: 5 | M26: 11 | N26: 12 | O26: 7 | P26: 2 | Q26: 14 | S26: 3 | T26: 2 | U26: 1 | V26: 14 | W26: 7 | X26: 4 | Y26: 10 | Z26: 8 | AA26: 13 | AB26: 15 | AC26: 12 | AD26: 9 | AE26: 0 | AF26: 3 | AG26: 5 | AH26: 6 | AI26: 11

Sheet k1-16
A2: Khóa K: | B2: 0133457799BBCDFF | D2: 0000000100110011010001010111011110011001101110111100110111111111
A3: vị trí | B3: ký tự hexan | C3: binary | M3: =LEN(D3) -> 0
A4: 1 | B4: =MID($B$2,A4,1) -> 0 | C4: =HEX2BIN(B4,4) -> 0000 | D4: =C4&D5 -> 0000000100110011010001010111011110011001101110111100110111111111 | M4: =LEN(D4) -> 64
A5: 2 | B5: =MID($B$2,A5,1) -> 1 | C5: =HEX2BIN(B5,4) -> 0001 | D5: =C5&D6 -> 000100110011010001010111011110011001101110111100110111111111 | M5: =LEN(D5) -> 60
A6: 3 | B6: =MID($B$2,A6,1) -> 3 | C6: =HEX2BIN(B6,4) -> 0011 | D6: =C6&D7 -> 00110011010001010111011110011001101110111100110111111111 | M6: =LEN(D6) -> 56
A7: 4 | B7: =MID($B$2,A7,1) -> 3 | C7: =HEX2BIN(B7,4) -> 0011 | D7: =C7&D8 -> 0011010001010111011110011001101110111100110111111111 | M7: =LEN(D7) -> 52
A8: 5 | B8: =MID($B$2,A8,1) -> 4 | C8: =HEX2BIN(B8,4) -> 0100 | D8: =C8&D9 -> 010001010111011110011001101110111100110111111111 | M8: =LEN(D8) -> 48
A9: 6 | B9: =MID($B$2,A9,1) -> 5 | C9: =HEX2BIN(B9,4) -> 0101 | D9: =C9&D10 -> 01010111011110011001101110111100110111111111 | M9: =LEN(D9) -> 44
A10: 7 | B10: =MID($B$2,A10,1) -> 7 | C10: =HEX2BIN(B10,4) -> 0111 | D10: =C10&D11 -> 0111011110011001101110111100110111111111 | M10: =LEN(D10) -> 40
A11: 8 | B11: =MID($B$2,A11,1) -> 7 | C11: =HEX2BIN(B11,4) -> 0111 | D11: =C11&D12 -> 011110011001101110111100110111111111 | M11: =LEN(D11) -> 36
A12: 9 | B12: =MID($B$2,A12,1) -> 9 | C12: =HEX2BIN(B12,4) -> 1001 | D12: =C12&D13 -> 10011001101110111100110111111111 | M12: =LEN(D12) -> 32
A13: 10 | B13: =MID($B$2,A13,1) -> 9 | C13: =HEX2BIN(B13,4) -> 1001 | D13: =C13&D14 -> 1001101110111100110111111111 | M13: =LEN(D13) -> 28
A14: 11 | B14: =MID($B$2,A14,1) -> B | C14: =HEX2BIN(B14,4) -> 1011 | D14: =C14&D15 -> 101110111100110111111111 | M14: =LEN(D14) -> 24
A15: 12 | B15: =MID($B$2,A15,1) -> B | C15: =HEX2BIN(B15,4) -> 1011 | D15: =C15&D16 -> 10111100110111111111 | M15: =LEN(D15) -> 20
... A17: 14 | B17: =MID($B$2,A17,1) -> D | C17: =HEX2BIN(B17,4) -> 1101 | D17: =C17&D18 -> 110111111111 | M17: =LEN(D17) -> 12
A18: 15 | B18: =MID($B$2,A18,1) -> F | C18: =HEX2BIN(B18,4) -> 1111 | D18: =C18&C19 -> 11111111 | M18: =LEN(D18) -> 8
A19: 16 | B19: =MID($B$2,A19,1) -> F | C19: =HEX2BIN(B19,4) -> 1111 | M19: =LEN(D19) -> 0
A21: stt | B21: Pc-1 | C21: bit i
A22: 1 | B22: 57 | C22: =MID($D$2,B22,1) -> 1 | D22: =C22&D23 -> 11110000110011001010101010111010101011001100111100001010
A23: 2 | B23: 49 | C23: =MID($D$2,B23,1) -> 1 | D23: =C23&D24 -> 1110000110011001010101010111010101011001100111100001010
A24: 3 | B24: 41 | C24: =MID($D$2,B24,1) -> 1 | D24: =C24&D25 -> 110000110011001010101010111010101011001100111100001010
A25: 4 | B25: 33 | C25: =MID($D$2,B25,1) -> 1 | D25: =C25&D26 -> 10000110011001010101010111010101011001100111100001010
A26: 5 | B26: 25 | C26: =MID($D$2,B26,1) -> 0 | D26: =C26&D27 -> 0000110011001010101010111010101011001100111100001010
A27: 6 | B27: 17 | C27: =MID($D$2,B27,1) -> 0 | D27: =C27&D28 -> 000110011001010101010111010101011001100111100001010
A28: 7 | B28: 9 | C28: =MID($D$2,B28,1) -> 0 | D28: =C28&D29 -> 00110011001010101010111010101011001100111100001010
A29: 8 | B29: 1 | C29: =MID($D$2,B29,1) -> 0 | D29: =C29&D30 -> 0110011001010101010111010101011001100111100001010
A30: 9 | B30: 58 | C30: =MID($D$2,B30,1) -> 1 | D30: =C30&D31 -> 110011001010101010111010101011001100111100001010
A31: 10 | B31: 50 | C31: =MID($D$2,B31,1) -> 1 | D31: =C31&D32 -> 10011001010101010111010101011001100111100001010
A32: 11 | B32: 42 | C32: =MID($D$2,B32,1) -> 0 | D32: =C32&D33 -> 0011001010101010111010101011001100111100001010
A33: 12 | B33: 34 | C33: =MID($D$2,B33,1) -> 0 | D33: =C33&D34 -> 011001010101010111010101011001100111100001010
... A75: 54 | B75: 20 | C75: =MID($D$2,B75,1) -> 0 | D75: =C75&D76 -> 010
A76: 55 | B76: 12 | C76: =MID($D$2,B76,1) -> 1 | D76: =C76&C77 -> 10
A77: 56 | B77: 4 | C77: =MID($D$2,B77,1) -> 0
A79: Sau khi Pc-1 ta có k0 = | C79: =D22 -> 11110000110011001010101010111010101011001100111100001010
A81: * Dịch bit | K81: Bảng dịch trái | O81: * Khoá K sau khi dịch bit
A83: C0 | B83: =LEFT(C79,28) -> 1111000011001100101010101011 | F83: D0 | G83: =RIGHT(C79,28) -> 1010101011001100111100001010 | K83: 1 | L83: 1 | O83: 1 | P83: =B84&G84 -> 11100001100110010101010101110101010110011001111000010101
A84: C1 | B84: =MID(B83, L83+1, LEN(B83)-L83) & LEFT(B83, L83) -> 1110000110011001010101010111 | F84: D1 | G84: =MID(G83, L83+1, LEN(G83)-L83) & LEFT(G83, L83) -> 0101010110011001111000010101 | K84: 2 | L84: 1 | O84: 2 | P84: =B85&G85 -> 11000011001100101010101011111010101100110011110000101010
A85: C2 | B85: =MID(B84, L84+1, LEN(B84)-L84) & LEFT(B84, L84) -> 1100001100110010101010101111 | F85: D2 | G85: =MID(G84, L84+1, LEN(G84)-L84) & LEFT(G84, L84) -> 1010101100110011110000101010 | K85: 3 | L85: 2 | O85: 3 | P85: =B86&G86 -> 00001100110010101010101111111010110011001111000010101010
A86: C3 | B86: =MID(B85, L85+1, LEN(B85)-L85) & LEFT(B85, L85) -> 0000110011001010101010111111 | F86: D3 | G86: =MID(G85, L85+1, LEN(G85)-L85) & LEFT(G85, L85) -> 1010110011001111000010101010 | K86: 4 | L86: 2 | O86: 4 | P86: =B87&G87 -> 00110011001010101010111111001011001100111100001010101010
A87: C4 | B87: =MID(B86, L86+1, LEN(B86)-L86) & LEFT(B86, L86) -> 0011001100101010101011111100 | F87: D4 | G87: =MID(G86, L86+1, LEN(G86)-L86) & LEFT(G86, L86) -> 1011001100111100001010101010 | K87: 5 | L87: 2 | O87: 5 | P87: =B88&G88 -> 11001100101010101011111100001100110011110000101010101010
...

Sheet F(RxorK)
A1: Bản rõ M | B1: Input M = | C1: 00123456789abcde | E1: 0000000000010010001101000101011001111000100110101011110011011110 | N1: IP(M) = | O1: =_xlfn.TEXTJOIN("", TRUE,C4:C67) -> 1001100011111110110011000000000011100000010101001111000010101010
A3: stt | B3: IP | C3: IP(M) | D3: Ma trận E | E3: IP^-1 | N3: R0 = | O3: =LEFT(O1,32) -> 10011000111111101100110000000000
A4: 1 | B4: 58 | C4: =MID($E$1,B4,1) -> 1 | D4: 32 | E4: 40 | N4: R1 = | O4: =RIGHT(O1,32) -> 11100000010101001111000010101010
A5: 2 | B5: 50 | C5: =MID($E$1,B5,1) -> 0 | D5: 1 | E5: 8
A6: 3 | B6: 42 | C6: =MID($E$1,B6,1) -> 0 | D6: 2 | E6: 48 | G6: Tính A = E(Ri) XOR ki+1
A7: 4 | B7: 34 | C7: =MID($E$1,B7,1) -> 1 | D7: 3 | E7: 16
A8: 5 | B8: 26 | C8: =MID($E$1,B8,1) -> 1 | D8: 4 | E8: 56 | G8: STT/i | H8: 0 | I8: 1 | J8: 2 | K8: 3 | L8: 4 | M8: 5 | N8: 6 | O8: 7 | P8: 8 | Q8: 9 | R8: 10 | S8: 11 | T8: 12 | U8: 13 | V8: 14 | W8: 15 | X8: 16
A9: 6 | B9: 18 | C9: =MID($E$1,B9,1) -> 0 | D9: 5 | E9: 24 | G9: 1 | H9: =MOD(VALUE(MID($O$4,D4,1)) + VALUE('k1-16'!B108),2) -> 0 | I9: =MOD(VALUE(MID(r0_l0!$C$43,'F(RxorK)'!D4,1))+VALUE('k1-16'!C108),2) -> 0 | J9: =MOD(VALUE(MID(r0_l0!$C$44,'F(RxorK)'!$D4,1))+VALUE('k1-16'!D108),2) -> 1 | K9: =MOD(VALUE(MID(r0_l0!$C$45,'F(RxorK)'!D4,1))+VALUE('k1-16'!E108),2) -> 0 | L9: =MOD(VALUE(MID(r0_l0!$C$46,'F(RxorK)'!D4,1))+VALUE('k1-16'!F108),2) -> 1 | M9: =MOD(VALUE(MID(r0_l0!$C$47,'F(RxorK)'!$D4,1))+VALUE('k1-16'!G108),2) -> 1 | N9: =MOD(VALUE(MID(r0_l0!$C$48,'F(RxorK)'!$D4,1))+VALUE('k1-16'!H108),2) -> 0 | O9: =MOD(VALUE(MID(r0_l0!$C$49,'F(RxorK)'!$D4,1))+VALUE('k1-16'!I108),2) -> 0 | P9: =MOD(VALUE(MID(r0_l0!$C$50,'F(RxorK)'!$D4,1))+VALUE('k1-16'!J108),2) -> 1 | Q9: =MOD(VALUE(MID(r0_l0!$C$51,'F(RxorK)'!$D4,1))+VALUE('k1-16'!K108),2) -> 1 | R9: =MOD(VALUE(MID(r0_l0!$C$52,'F(RxorK)'!$D4,1))+VALUE('k1-16'!L108),2) -> 0 | S9: =MOD(VALUE(MID(r0_l0!$C$53,'F(RxorK)'!$D4,1))+VALUE('k1-16'!M108),2) -> 0 | T9: =MOD(VALUE(MID(r0_l0!$C$54,'F(RxorK)'!$D4,1))+VALUE('k1-16'!N108),2) -> 0 | U9: =MOD(VALUE(MID(r0_l0!$C$55,'F(RxorK)'!$D4,1))+VALUE('k1-16'!O108),2) -> 0 | V9: =MOD(VALUE(MID(r0_l0!$C$56,'F(RxorK)'!$D4,1))+VALUE('k1-16'!P108),2) -> 0 | W9: =MOD(VALUE(MID(r0_l0!$C$57,'F(RxorK)'!$D4,1))+VALUE('k1-16'!Q108),2) -> 0 | X9: =MOD(VALUE(MID(r0_l0!$C$58,'F(RxorK)'!$D4,1))+VALUE('k1-16'!R108),2) -> 0
A10: 7 | B10: 10 | C10: =MID($E$1,B10,1) -> 0 | D10: 4 | E10: 64 | G10: 2 | H10: =MOD(VALUE(MID($O$4,D5,1)) + VALUE('k1-16'!B109),2) -> 1 | I10: =MOD(VALUE(MID(r0_l0!$C$43,'F(RxorK)'!D5,1))+VALUE('k1-16'!C109),2) -> 1 | J10: =MOD(VALUE(MID(r0_l0!$C$44,'F(RxorK)'!$D5,1))+VALUE('k1-16'!D109),2) -> 1 | K10: =MOD(VALUE(MID(r0_l0!$C$45,'F(RxorK)'!D5,1))+VALUE('k1-16'!E109),2) -> 0 | L10: =MOD(VALUE(MID(r0_l0!$C$46,'F(RxorK)'!D5,1))+VALUE('k1-16'!F109),2) -> 0 | M10: =MOD(VALUE(MID(r0_l0!$C$47,'F(RxorK)'!$D5,1))+VALUE('k1-16'!G109),2) -> 1 | N10: =MOD(VALUE(MID(r0_l0!$C$48,'F(RxorK)'!$D5,1))+VALUE('k1-16'!H109),2) -> 1 | O10: =MOD(VALUE(MID(r0_l0!$C$49,'F(RxorK)'!$D5,1))+VALUE('k1-16'!I109),2) -> 1 | P10: =MOD(VALUE(MID(r0_l0!$C$50,'F(RxorK)'!$D5,1))+VALUE('k1-16'!J109),2) -> 1 | Q10: =MOD(VALUE(MID(r0_l0!$C$51,'F(RxorK)'!$D5,1))+VALUE('k1-16'!K109),2) -> 1 | R10: =MOD(VALUE(MID(r0_l0!$C$52,'F(RxorK)'!$D5,1))+VALUE('k1-16'!L109),2) -> 1 | S10: =MOD(VALUE(MID(r0_l0!$C$53,'F(RxorK)'!$D5,1))+VALUE('k1-16'!M109),2) -> 1 | T10: =MOD(VALUE(MID(r0_l0!$C$54,'F(RxorK)'!$D5,1))+VALUE('k1-16'!N109),2) -> 1 | U10: =MOD(VALUE(MID(r0_l0!$C$55,'F(RxorK)'!$D5,1))+VALUE('k1-16'!O109),2) -> 1 | V10: =MOD(VALUE(MID(r0_l0!$C$56,'F(RxorK)'!$D5,1))+VALUE('k1-16'!P109),2) -> 1 | W10: =MOD(VALUE(MID(r0_l0!$C$57,'F(RxorK)'!$D5,1))+VALUE('k1-16'!Q109),2) -> 1 | X10: =MOD(VALUE(MID(r0_l0!$C$58,'F(RxorK)'!$D5,1))+VALUE('k1-16'!R109),2) -> 0
A11: 8 | B11: 2 | C11: =MID($E$1,B11,1) -> 0 | D11: 5 | E11: 32 | G11: 3 | H11: =MOD(VALUE(MID($O$4,D6,1)) + VALUE('k1-16'!B110),2) -> 1 | I11: =MOD(VALUE(MID(r0_l0!$C$43,'F(RxorK)'!D6,1))+VALUE('k1-16'!C110),2) -> 1 | J11: =MOD(VALUE(MID(r0_l0!$C$44,'F(RxorK)'!$D6,1))+VALUE('k1-16'!D110),2) -> 1 | K11: =MOD(VALUE(MID(r0_l0!$C$45,'F(RxorK)'!D6,1))+VALUE('k1-16'!E110),2) -> 0 | L11: =MOD(VALUE(MID(r0_l0!$C$46,'F(RxorK)'!D6,1))+VALUE('k1-16'!F110),2) -> 1 | M11: =MOD(VALUE(MID(r0_l0!$C$47,'F(RxorK)'!$D6,1))+VALUE('k1-16'!G110),2) -> 1 | N11: =MOD(VALUE(MID(r0_l0!$C$48,'F(RxorK)'!$D6,1))+VALUE('k1-16'!H110),2) -> 1 | O11: =MOD(VALUE(MID(r0_l0!$C$49,'F(RxorK)'!$D6,1))+VALUE('k1-16'!I110),2) -> 0 | P11: =MOD(VALUE(MID(r0_l0!$C$50,'F(RxorK)'!$D6,1))+VALUE('k1-16'!J110),2) -> 1 | Q11: =MOD(VALUE(MID(r0_l0!$C$51,'F(RxorK)'!$D6,1))+VALUE('k1-16'!K110),2) -> 1 | R11: =MOD(VALUE(MID(r0_l0!$C$52,'F(RxorK)'!$D6,1))+VALUE('k1-16'!L110),2) -> 1 | S11: =MOD(VALUE(MID(r0_l0!$C$53,'F(RxorK)'!$D6,1))+VALUE('k1-16'!M110),2) -> 0 | T11: =MOD(VALUE(MID(r0_l0!$C$54,'F(RxorK)'!$D6,1))+VALUE('k1-16'!N110),2) -> 1 | U11: =MOD(VALUE(MID(r0_l0!$C$55,'F(RxorK)'!$D6,1))+VALUE('k1-16'!O110),2) -> 0 | V11: =MOD(VALUE(MID(r0_l0!$C$56,'F(RxorK)'!$D6,1))+VALUE('k1-16'!P110),2) -> 1 | W11: =MOD(VALUE(MID(r0_l0!$C$57,'F(RxorK)'!$D6,1))+VALUE('k1-16'!Q110),2) -> 1 | X11: =MOD(VALUE(MID(r0_l0!$C$58,'F(RxorK)'!$D6,1))+VALUE('k1-16'!R110),2) -> 1
A12: 9 | B12: 60 | C12: =MID($E$1,B12,1) -> 1 | D12: 6 | E12: 39 | G12: 4 | H12: =MOD(VALUE(MID($O$4,D7,1)) + VALUE('k1-16'!B111),2) -> 0 | I12: =MOD(VALUE(MID(r0_l0!$C$43,'F(RxorK)'!D7,1))+VALUE('k1-16'!C111),2) -> 0 | J12: =MOD(VALUE(MID(r0_l0!$C$44,'F(RxorK)'!$D7,1))+VALUE('k1-16'!D111),2) -> 0 | K12: =MOD(VALUE(MID(r0_l0!$C$45,'F(RxorK)'!D7,1))+VALUE('k1-16'!E111),2) -> 1 | L12: =MOD(VALUE(MID(r0_l0!$C$46,'F(RxorK)'!D7,1))+VALUE('k1-16'!F111),2) -> 1 | M12: =MOD(VALUE(MID(r0_l0!$C$47,'F(RxorK)'!$D7,1))+VALUE('k1-16'!G111),2) -> 0 | N12: =MOD(VALUE(MID(r0_l0!$C$48,'F(RxorK)'!$D7,1))+VALUE('k1-16'!H111),2) -> 1 | O12: =MOD(VALUE(MID(r0_l0!$C$49,'F(RxorK)'!$D7,1))+VALUE('k1-16'!I111),2) -> 1 | P12: =MOD(VALUE(MID(r0_l0!$C$50,'F(RxorK)'!$D7,1))+VALUE('k1-16'!J111),2) -> 0 | Q12: =MOD(VALUE(MID(r0_l0!$C$51,'F(RxorK)'!$D7,1))+VALUE('k1-16'!K111),2) -> 0 | R12: =MOD(VALUE(MID(r0_l0!$C$52,'F(RxorK)'!$D7,1))+VALUE('k1-16'!L111),2) -> 0 | S12: =MOD(VALUE(MID(r0_l0!$C$53,'F(RxorK)'!$D7,1))+VALUE('k1-16'!M111),2) -> 1 | T12: =MOD(VALUE(MID(r0_l0!$C$54,'F(RxorK)'!$D7,1))+VALUE('k1-16'!N111),2) -> 0 | U12: =MOD(VALUE(MID(r0_l0!$C$55,'F(RxorK)'!$D7,1))+VALUE('k1-16'!O111),2) -> 0 | V12: =MOD(VALUE(MID(r0_l0!$C$56,'F(RxorK)'!$D7,1))+VALUE('k1-16'!P111),2) -> 1 | W12: =MOD(VALUE(MID(r0_l0!$C$57,'F(RxorK)'!$D7,1))+VALUE('k1-16'!Q111),2) -> 1 | X12: =MOD(VALUE(MID(r0_l0!$C$58,'F(RxorK)'!$D7,1))+VALUE('k1-16'!R111),2) -> 0
A13: 10 | B13: 52 | C13: =MID($E$1,B13,1) -> 1 | D13: 7 | E13: 7 | G13: 5 | H13: =MOD(VALUE(MID($O$4,D8,1)) + VALUE('k1-16'!B112),2) -> 1 | I13: =MOD(VALUE(MID(r0_l0!$C$43,'F(RxorK)'!D8,1))+VALUE('k1-16'!C112),2) -> 1 | J13: =MOD(VALUE(MID(r0_l0!$C$44,'F(RxorK)'!$D8,1))+VALUE('k1-16'!D112),2) -> 0 | K13: =MOD(VALUE(MID(r0_l0!$C$45,'F(RxorK)'!D8,1))+VALUE('k1-16'!E112),2) -> 1 | L13: =MOD(VALUE(MID(r0_l0!$C$46,'F(RxorK)'!D8,1))+VALUE('k1-16'!F112),2) -> 0 | M13: =MOD(VALUE(MID(r0_l0!$C$47,'F(RxorK)'!$D8,1))+VALUE('k1-16'!G112),2) -> 0 | N13: =MOD(VALUE(MID(r0_l0!$C$48,'F(RxorK)'!$D8,1))+VALUE('k1-16'!H112),2) -> 0 | O13: =MOD(VALUE(MID(r0_l0!$C$49,'F(RxorK)'!$D8,1))+VALUE('k1-16'!I112),2) -> 0 | P13: =MOD(VALUE(MID(r0_l0!$C$50,'F(RxorK)'!$D8,1))+VALUE('k1-16'!J112),2) -> 1 | Q13: =MOD(VALUE(MID(r0_l0!$C$51,'F(RxorK)'!$D8,1))+VALUE('k1-16'!K112),2) -> 1 | R13: =MOD(VALUE(MID(r0_l0!$C$52,'F(RxorK)'!$D8,1))+VALUE('k1-16'!L112),2) -> 0 | S13: =MOD(VALUE(MID(r0_l0!$C$53,'F(RxorK)'!$D8,1))+VALUE('k1-16'!M112),2) -> 0 | T13: =MOD(VALUE(MID(r0_l0!$C$54,'F(RxorK)'!$D8,1))+VALUE('k1-16'!N112),2) -> 1 | U13: =MOD(VALUE(MID(r0_l0!$C$55,'F(RxorK)'!$D8,1))+VALUE('k1-16'!O112),2) -> 1 | V13: =MOD(VALUE(MID(r0_l0!$C$56,'F(RxorK)'!$D8,1))+VALUE('k1-16'!P112),2) -> 0 | W13: =MOD(VALUE(MID(r0_l0!$C$57,'F(RxorK)'!$D8,1))+VALUE('k1-16'!Q112),2) -> 1 | X13: =MOD(VALUE(MID(r0_l0!$C$58,'F(RxorK)'!$D8,1))+VALUE('k1-16'!R112),2) -> 1
A14: 11 | B14: 44 | C14: =MID($E$1,B14,1) -> 1 | D14: 8 | E14: 47 | G14: 6 | H14: =MOD(VALUE(MID($O$4,D9,1)) + VALUE('k1-16'!B113),2) -> 0 | I14: =MOD(VALUE(MID(r0_l0!$C$43,'F(RxorK)'!D9,1))+VALUE('k1-16'!C113),2) -> 1 | J14: =MOD(VALUE(MID(r0_l0!$C$44,'F(RxorK)'!$D9,1))+VALUE('k1-16'!D113),2) -> 0 | K14: =MOD(VALUE(MID(r0_l0!$C$45,'F(RxorK)'!D9,1))+VALUE('k1-16'!E113),2) -> 0 | L14: =MOD(VALUE(MID(r0_l0!$C$46,'F(RxorK)'!D9,1))+VALUE('k1-16'!F113),2) -> 0 | M14: =MOD(VALUE(MID(r0_l0!$C$47,'F(RxorK)'!$D9,1))+VALUE('k1-16'!G113),2) -> 1 | N14: =MOD(VALUE(MID(r0_l0!$C$48,'F(RxorK)'!$D9,1))+VALUE('k1-16'!H113),2) -> 1 | O14: =MOD(VALUE(MID(r0_l0!$C$49,'F(RxorK)'!$D9,1))+VALUE('k1-16'!I113),2) -> 1 | P14: =MOD(VALUE(MID(r0_l0!$C$50,'F(RxorK)'!$D9,1))+VALUE('k1-16'!J113),2) -> 1 | Q14: =MOD(VALUE(MID(r0_l0!$C$51,'F(RxorK)'!$D9,1))+VALUE('k1-16'!K113),2) -> 1 | R14: =MOD(VALUE(MID(r0_l0!$C$52,'F(RxorK)'!$D9,1))+VALUE('k1-16'!L113),2) -> 1 | S14: =MOD(VALUE(MID(r0_l0!$C$53,'F(RxorK)'!$D9,1))+VALUE('k1-16'!M113),2) -> 0 | T14: =MOD(VALUE(MID(r0_l0!$C$54,'F(RxorK)'!$D9,1))+VALUE('k1-16'!N113),2) -> 0 | U14: =MOD(VALUE(MID(r0_l0!$C$55,'F(RxorK)'!$D9,1))+VALUE('k1-16'!O113),2) -> 0 | V14: =MOD(VALUE(MID(r0_l0!$C$56,'F(RxorK)'!$D9,1))+VALUE('k1-16'!P113),2) -> 0 | W14: =MOD(VALUE(MID(r0_l0!$C$57,'F(RxorK)'!$D9,1))+VALUE('k1-16'!Q113),2) -> 1 | X14: =MOD(VALUE(MID(r0_l0!$C$58,'F(RxorK)'!$D9,1))+VALUE('k1-16'!R113),2) -> 0
A15: 12 | B15: 36 | C15: =MID($E$1,B15,1) -> 1 | D15: 9 | E15: 15 | G15: 7 | H15: =MOD(VALUE(MID($O$4,D10,1)) + VALUE('k1-16'!B114),2) -> 1 | I15: =MOD(VALUE(MID(r0_l0!$C$43,'F(RxorK)'!D10,1))+VALUE('k1-16'!C114),2) -> 0 | J15: =MOD(VALUE(MID(r0_l0!$C$44,'F(RxorK)'!$D10,1))+VALUE('k1-16'!D114),2) -> 0 | K15: =MOD(VALUE(MID(r0_l0!$C$45,'F(RxorK)'!D10,1))+VALUE('k1-16'!E114),2) -> 0 | L15: =MOD(VALUE(MID(r0_l0!$C$46,'F(RxorK)'!D10,1))+VALUE('k1-16'!F114),2) -> 1 | M15: =MOD(VALUE(MID(r0_l0!$C$47,'F(RxorK)'!$D10,1))+VALUE('k1-16'!G114),2) -> 1 | N15: =MOD(VALUE(MID(r0_l0!$C$48,'F(RxorK)'!$D10,1))+VALUE('k1-16'!H114),2) -> 1 | O15: =MOD(VALUE(MID(r0_l0!$C$49,'F(RxorK)'!$D10,1))+VALUE('k1-16'!I114),2) -> 1 | P15: =MOD(VALUE(MID(r0_l0!$C$50,'F(RxorK)'!$D10,1))+VALUE('k1-16'!J114),2) -> 1 | Q15: =MOD(VALUE(MID(r0_l0!$C$51,'F(RxorK)'!$D10,1))+VALUE('k1-16'!K114),2) -> 1 | R15: =MOD(VALUE(MID(r0_l0!$C$52,'F(RxorK)'!$D10,1))+VALUE('k1-16'!L114),2) -> 0 | S15: =MOD(VALUE(MID(r0_l0!$C$53,'F(RxorK)'!$D10,1))+VALUE('k1-16'!M114),2) -> 0 | T15: =MOD(VALUE(MID(r0_l0!$C$54,'F(RxorK)'!$D10,1))+VALUE('k1-16'!N114),2) -> 1 | U15: =MOD(VALUE(MID(r0_l0!$C$55,'F(RxorK)'!$D10,1))+VALUE('k1-16'!O114),2) -> 0 | V15: =MOD(VALUE(MID(r0_l0!$C$56,'F(RxorK)'!$D10,1))+VALUE('k1-16'!P114),2) -> 0 | W15: =MOD(VALUE(MID(r0_l0!$C$57,'F(RxorK)'!$D10,1))+VALUE('k1-16'!Q114),2) -> 1 | X15: =MOD(VALUE(MID(r0_l0!$C$58,'F(RxorK)'!$D10,1))+VALUE('k1-16'!R114),2) -> 1
A16: 13 | B16: 28 | C16: =MID($E$1,B16,1) -> 1 | D16: 8 | E16: 55 | G16: 8 | H16: =MOD(VALUE(MID($O$4,D11,1)) + VALUE('k1-16'!B115),2) -> 1 | I16: =MOD(VALUE(MID(r0_l0!$C$43,'F(RxorK)'!D11,1))+VALUE('k1-16'!C115),2) -> 0 | J16: =MOD(VALUE(MID(r0_l0!$C$44,'F(RxorK)'!$D11,1))+VALUE('k1-16'!D115),2) -> 0 | K16: =MOD(VALUE(MID(r0_l0!$C$45,'F(RxorK)'!D11,1))+VALUE('k1-16'!E115),2) -> 0 | L16: =MOD(VALUE(MID(r0_l0!$C$46,'F(RxorK)'!D11,1))+VALUE('k1-16'!F115),2) -> 1 | M16: =MOD(VALUE(MID(r0_l0!$C$47,'F(RxorK)'!$D11,1))+VALUE('k1-16'!G115),2) -> 0 | N16: =MOD(VALUE(MID(r0_l0!$C$48,'F(RxorK)'!$D11,1))+VALUE('k1-16'!H115),2) -> 0 | O16: =MOD(VALUE(MID(r0_l0!$C$49,'F(RxorK)'!$D11,1))+VALUE('k1-16'!I115),2) -> 1 | P16: =MOD(VALUE(MID(r0_l0!$C$50,'F(RxorK)'!$D11,1))+VALUE('k1-16'!J115),2) -> 1 | Q16: =MOD(VALUE(MID(r0_l0!$C$51,'F(RxorK)'!$D11,1))+VALUE('k1-16'!K115),2) -> 0 | R16: =MOD(VALUE(MID(r0_l0!$C$52,'F(RxorK)'!$D11,1))+VALUE('k1-16'!L115),2) -> 0 | S16: =MOD(VALUE(MID(r0_l0!$C$53,'F(RxorK)'!$D11,1))+VALUE('k1-16'!M115),2) -> 1 | T16: =MOD(VALUE(MID(r0_l0!$C$54,'F(RxorK)'!$D11,1))+VALUE('k1-16'!N115),2) -> 0 | U16: =MOD(VALUE(MID(r0_l0!$C$55,'F(RxorK)'!$D11,1))+VALUE('k1-16'!O115),2) -> 0 | V16: =MOD(VALUE(MID(r0_l0!$C$56,'F(RxorK)'!$D11,1))+VALUE('k1-16'!P115),2) -> 0 | W16: =MOD(VALUE(MID(r0_l0!$C$57,'F(RxorK)'!$D11,1))+VALUE('k1-16'!Q115),2) -> 0 | X16: =MOD(VALUE(MID(r0_l0!$C$58,'F(RxorK)'!$D11,1))+VALUE('k1-16'!R115),2) -> 0
A17: 14 | B17: 20 | C17: =MID($E$1,B17,1) -> 1 | D17: 9 | E17: 23 | G17: 9 | H17: =MOD(VALUE(MID($O$4,D12,1)) + VALUE('k1-16'!B116),2) -> 0 | I17: =MOD(VALUE(MID(r0_l0!$C$43,'F(RxorK)'!D12,1))+VALUE('k1-16'!C116),2) -> 0 | J17: =MOD(VALUE(MID(r0_l0!$C$44,'F(RxorK)'!$D12,1))+VALUE('k1-16'!D116),2) -> 1 | K17: =MOD(VALUE(MID(r0_l0!$C$45,'F(RxorK)'!D12,1))+VALUE('k1-16'!E116),2) -> 0 | L17: =MOD(VALUE(MID(r0_l0!$C$46,'F(RxorK)'!D12,1))+VALUE('k1-16'!F116),2) -> 0 | M17: =MOD(VALUE(MID(r0_l0!$C$47,'F(RxorK)'!$D12,1))+VALUE('k1-16'!G116),2) -> 0 | N17: =MOD(VALUE(MID(r0_l0!$C$48,'F(RxorK)'!$D12,1))+VALUE('k1-16'!H116),2) -> 1 | O17: =MOD(VALUE(MID(r0_l0!$C$49,'F(RxorK)'!$D12,1))+VALUE('k1-16'!I116),2) -> 1 | P17: =MOD(VALUE(MID(r0_l0!$C$50,'F(RxorK)'!$D12,1))+VALUE('k1-16'!J116),2) -> 0 | Q17: =MOD(VALUE(MID(r0_l0!$C$51,'F(RxorK)'!$D12,1))+VALUE('k1-16'!K116),2) -> 1 | R17: =MOD(VALUE(MID(r0_l0!$C$52,'F(RxorK)'!$D12,1))+VALUE('k1-16'!L116),2) -> 0 | S17: =MOD(VALUE(MID(r0_l0!$C$53,'F(RxorK)'!$D12,1))+VALUE('k1-16'!M116),2) -> 1 | T17: =MOD(VALUE(MID(r0_l0!$C$54,'F(RxorK)'!$D12,1))+VALUE('k1-16'!N116),2) -> 1 | U17: =MOD(VALUE(MID(r0_l0!$C$55,'F(RxorK)'!$D12,1))+VALUE('k1-16'!O116),2) -> 1 | V17: =MOD(VALUE(MID(r0_l0!$C$56,'F(RxorK)'!$D12,1))+VALUE('k1-16'!P116),2) -> 0 | W17: =MOD(VALUE(MID(r0_l0!$C$57,'F(RxorK)'!$D12,1))+VALUE('k1-16'!Q116),2) -> 1 | X17: =MOD(VALUE(MID(r0_l0!$C$58,'F(RxorK)'!$D12,1))+VALUE('k1-16'!R116),2) -> 1
A18: 15 | B18: 12 | C18: =MID($E$1,B18,1) -> 1 | D18: 10 | E18: 63 | G18: 10 | H18: =MOD(VALUE(MID($O$4,D13,1)) + VALUE('k1-16'!B117),2) -> 0 | I18: =MOD(VALUE(MID(r0_l0!$C$43,'F(RxorK)'!D13,1))+VALUE('k1-16'!C117),2) -> 1 | J18: =MOD(VALUE(MID(r0_l0!$C$44,'F(RxorK)'!$D13,1))+VALUE('k1-16'!D117),2) -> 1 | K18: =MOD(VALUE(MID(r0_l0!$C$45,'F(RxorK)'!D13,1))+VALUE('k1-16'!E117),2) -> 0 | L18: =MOD(VALUE(MID(r0_l0!$C$46,'F(RxorK)'!D13,1))+VALUE('k1-16'!F117),2) -> 1 | M18: =MOD(VALUE(MID(r0_l0!$C$47,'F(RxorK)'!$D13,1))+VALUE('k1-16'!G117),2) -> 0 | N18: =MOD(VALUE(MID(r0_l0!$C$48,'F(RxorK)'!$D13,1))+VALUE('k1-16'!H117),2) -> 1 | O18: =MOD(VALUE(MID(r0_l0!$C$49,'F(RxorK)'!$D13,1))+VALUE('k1-16'!I117),2) -> 1 | P18: =MOD(VALUE(MID(r0_l0!$C$50,'F(RxorK)'!$D13,1))+VALUE('k1-16'!J117),2) -> 0 | Q18: =MOD(VALUE(MID(r0_l0!$C$51,'F(RxorK)'!$D13,1))+VALUE('k1-16'!K117),2) -> 1 | R18: =MOD(VALUE(MID(r0_l0!$C$52,'F(RxorK)'!$D13,1))+VALUE('k1-16'!L117),2) -> 0 | S18: =MOD(VALUE(MID(r0_l0!$C$53,'F(RxorK)'!$D13,1))+VALUE('k1-16'!M117),2) -> 1 | T18: =MOD(VALUE(MID(r0_l0!$C$54,'F(RxorK)'!$D13,1))+VALUE('k1-16'!N117),2) -> 0 | U18: =MOD(VALUE(MID(r0_l0!$C$55,'F(RxorK)'!$D13,1))+VALUE('k1-16'!O117),2) -> 0 | V18: =MOD(VALUE(MID(r0_l0!$C$56,'F(RxorK)'!$D13,1))+VALUE('k1-16'!P117),2) -> 1 | W18: =MOD(VALUE(MID(r0_l0!$C$57,'F(RxorK)'!$D13,1))+VALUE('k1-16'!Q117),2) -> 1 | X18: =MOD(VALUE(MID(r0_l0!$C$58,'F(RxorK)'!$D13,1))+VALUE('k1-16'!R117),2) -> 0
A19: 16 | B19: 4 | C19: =MID($E$1,B19,1) -> 0 | D19: 11 | E19: 31 | G19: 11 | H19: =MOD(VALUE(MID($O$4,D14,1)) + VALUE('k1-16'!B118),2) -> 0 | I19: =MOD(VALUE(MID(r0_l0!$C$43,'F(RxorK)'!D14,1))+VALUE('k1-16'!C118),2) -> 0 | J19: =MOD(VALUE(MID(r0_l0!$C$44,'F(RxorK)'!$D14,1))+VALUE('k1-16'!D118),2) -> 1 | K19: =MOD(VALUE(MID(r0_l0!$C$45,'F(RxorK)'!D14,1))+VALUE('k1-16'!E118),2) -> 0 | L19: =MOD(VALUE(MID(r0_l0!$C$46,'F(RxorK)'!D14,1))+VALUE('k1-16'!F118),2) -> 1 | M19: =MOD(VALUE(MID(r0_l0!$C$47,'F(RxorK)'!$D14,1))+VALUE('k1-16'!G118),2) -> 0 | N19: =MOD(VALUE(MID(r0_l0!$C$48,'F(RxorK)'!$D14,1))+VALUE('k1-16'!H118),2) -> 1 | O19: =MOD(VALUE(MID(r0_l0!$C$49,'F(RxorK)'!$D14,1))+VALUE('k1-16'!I118),2) -> 1 | P19: =MOD(VALUE(MID(r0_l0!$C$50,'F(RxorK)'!$D14,1))+VALUE('k1-16'!J118),2) -> 1 | Q19: =MOD(VALUE(MID(r0_l0!$C$51,'F(RxorK)'!$D14,1))+VALUE('k1-16'!K118),2) -> 1 | R19: =MOD(VALUE(MID(r0_l0!$C$52,'F(RxorK)'!$D14,1))+VALUE('k1-16'!L118),2) -> 0 | S19: =MOD(VALUE(MID(r0_l0!$C$53,'F(RxorK)'!$D14,1))+VALUE('k1-16'!M118),2) -> 1 | T19: =MOD(VALUE(MID(r0_l0!$C$54,'F(RxorK)'!$D14,1))+VALUE('k1-16'!N118),2) -> 0 | U19: =MOD(VALUE(MID(r0_l0!$C$55,'F(RxorK)'!$D14,1))+VALUE('k1-16'!O118),2) -> 1 | V19: =MOD(VALUE(MID(r0_l0!$C$56,'F(RxorK)'!$D14,1))+VALUE('k1-16'!P118),2) -> 1 | W19: =MOD(VALUE(MID(r0_l0!$C$57,'F(RxorK)'!$D14,1))+VALUE('k1-16'!Q118),2) -> 1 | X19: =MOD(VALUE(MID(r0_l0!$C$58,'F(RxorK)'!$D14,1))+VALUE('k1-16'!R118),2) -> 0
A20: 17 | B20: 62 | C20: =MID($E$1,B20,1) -> 1 | D20: 12 | E20: 38 | G20: 12 | H20: =MOD(VALUE(MID($O$4,D15,1)) + VALUE('k1-16'!B119),2) -> 0 | I20: =MOD(VALUE(MID(r0_l0!$C$43,'F(RxorK)'!D15,1))+VALUE('k1-16'!C119),2) -> 0 | J20: =MOD(VALUE(MID(r0_l0!$C$44,'F(RxorK)'!$D15,1))+VALUE('k1-16'!D119),2) -> 1 | K20: =MOD(VALUE(MID(r0_l0!$C$45,'F(RxorK)'!D15,1))+VALUE('k1-16'!E119),2) -> 0 | L20: =MOD(VALUE(MID(r0_l0!$C$46,'F(RxorK)'!D15,1))+VALUE('k1-16'!F119),2) -> 0 | M20: =MOD(VALUE(MID(r0_l0!$C$47,'F(RxorK)'!$D15,1))+VALUE('k1-16'!G119),2) -> 0 | N20: =MOD(VALUE(MID(r0_l0!$C$48,'F(RxorK)'!$D15,1))+VALUE('k1-16'!H119),2) -> 1 | O20: =MOD(VALUE(MID(r0_l0!$C$49,'F(RxorK)'!$D15,1))+VALUE('k1-16'!I119),2) -> 0 | P20: =MOD(VALUE(MID(r0_l0!$C$50,'F(RxorK)'!$D15,1))+VALUE('k1-16'!J119),2) -> 1 | Q20: =MOD(VALUE(MID(r0_l0!$C$51,'F(RxorK)'!$D15,1))+VALUE('k1-16'!K119),2) -> 1 | R20: =MOD(VALUE(MID(r0_l0!$C$52,'F(RxorK)'!$D15,1))+VALUE('k1-16'!L119),2) -> 1 | S20: =MOD(VALUE(MID(r0_l0!$C$53,'F(RxorK)'!$D15,1))+VALUE('k1-16'!M119),2) -> 0 | T20: =MOD(VALUE(MID(r0_l0!$C$54,'F(RxorK)'!$D15,1))+VALUE('k1-16'!N119),2) -> 0 | U20: =MOD(VALUE(MID(r0_l0!$C$55,'F(RxorK)'!$D15,1))+VALUE('k1-16'!O119),2) -> 0 | V20: =MOD(VALUE(MID(r0_l0!$C$56,'F(RxorK)'!$D15,1))+VALUE('k1-16'!P119),2) -> 0 | W20: =MOD(VALUE(MID(r0_l0!$C$57,'F(RxorK)'!$D15,1))+VALUE('k1-16'!Q119),2) -> 1 | X20: =MOD(VALUE(MID(r0_l0!$C$58,'F(RxorK)'!$D15,1))+VALUE('k1-16'!R119),2) -> 0
... A51: 48 | B51: 3 | C51: =MID($E$1,B51,1) -> 0 | D51: 1 | E51: 27 | G51: 43 | H51: =MOD(VALUE(MID($O$4,D46,1)) + VALUE('k1-16'!B150),2) -> 1 | I51: =MOD(VALUE(MID(r0_l0!$C$43,'F(RxorK)'!D46,1))+VALUE('k1-16'!C150),2) -> 0 | J51: =MOD(VALUE(MID(r0_l0!$C$44,'F(RxorK)'!$D46,1))+VALUE('k1-16'!D150),2) -> 0 | K51: =MOD(VALUE(MID(r0_l0!$C$45,'F(RxorK)'!D46,1))+VALUE('k1-16'!E150),2) -> 0 | L51: =MOD(VALUE(MID(r0_l0!$C$46,'F(RxorK)'!D46,1))+VALUE('k1-16'!F150),2) -> 1 | M51: =MOD(VALUE(MID(r0_l0!$C$47,'F(RxorK)'!$D46,1))+VALUE('k1-16'!G150),2) -> 1 | N51: =MOD(VALUE(MID(r0_l0!$C$48,'F(RxorK)'!$D46,1))+VALUE('k1-16'!H150),2) -> 1 | O51: =MOD(VALUE(MID(r0_l0!$C$49,'F(RxorK)'!$D46,1))+VALUE('k1-16'!I150),2) -> 1 | P51: =MOD(VALUE(MID(r0_l0!$C$50,'F(RxorK)'!$D46,1))+VALUE('k1-16'!J150),2) -> 1 | Q51: =MOD(VALUE(MID(r0_l0!$C$51,'F(RxorK)'!$D46,1))+VALUE('k1-16'!K150),2) -> 1 | R51: =MOD(VALUE(MID(r0_l0!$C$52,'F(RxorK)'!$D46,1))+VALUE('k1-16'!L150),2) -> 1 | S51: =MOD(VALUE(MID(r0_l0!$C$53,'F(RxorK)'!$D46,1))+VALUE('k1-16'!M150),2) -> 0 | T51: =MOD(VALUE(MID(r0_l0!$C$54,'F(RxorK)'!$D46,1))+VALUE('k1-16'!N150),2) -> 1 | U51: =MOD(VALUE(MID(r0_l0!$C$55,'F(RxorK)'!$D46,1))+VALUE('k1-16'!O150),2) -> 0 | V51: =MOD(VALUE(MID(r0_l0!$C$56,'F(RxorK)'!$D46,1))+VALUE('k1-16'!P150),2) -> 1 | W51: =MOD(VALUE(MID(r0_l0!$C$57,'F(RxorK)'!$D46,1))+VALUE('k1-16'!Q150),2) -> 0 | X51: =MOD(VALUE(MID(r0_l0!$C$58,'F(RxorK)'!$D46,1))+VALUE('k1-16'!R150),2) -> 0
A52: 49 | B52: 61 | C52: =MID($E$1,B52,1) -> 1 | E52: 34 | G52: 44 | H52: =MOD(VALUE(MID($O$4,D47,1)) + VALUE('k1-16'!B151),2) -> 1 | I52: =MOD(VALUE(MID(r0_l0!$C$43,'F(RxorK)'!D47,1))+VALUE('k1-16'!C151),2) -> 1 | J52: =MOD(VALUE(MID(r0_l0!$C$44,'F(RxorK)'!$D47,1))+VALUE('k1-16'!D151),2) -> 1 | K52: =MOD(VALUE(MID(r0_l0!$C$45,'F(RxorK)'!D47,1))+VALUE('k1-16'!E151),2) -> 0 | L52: =MOD(VALUE(MID(r0_l0!$C$46,'F(RxorK)'!D47,1))+VALUE('k1-16'!F151),2) -> 0 | M52: =MOD(VALUE(MID(r0_l0!$C$47,'F(RxorK)'!$D47,1))+VALUE('k1-16'!G151),2) -> 0 | N52: =MOD(VALUE(MID(r0_l0!$C$48,'F(RxorK)'!$D47,1))+VALUE('k1-16'!H151),2) -> 0 | O52: =MOD(VALUE(MID(r0_l0!$C$49,'F(RxorK)'!$D47,1))+VALUE('k1-16'!I151),2) -> 0 | P52: =MOD(VALUE(MID(r0_l0!$C$50,'F(RxorK)'!$D47,1))+VALUE('k1-16'!J151),2) -> 0 | Q52: =MOD(VALUE(MID(r0_l0!$C$51,'F(RxorK)'!$D47,1))+VALUE('k1-16'!K151),2) -> 1 | R52: =MOD(VALUE(MID(r0_l0!$C$52,'F(RxorK)'!$D47,1))+VALUE('k1-16'!L151),2) -> 0 | S52: =MOD(VALUE(MID(r0_l0!$C$53,'F(RxorK)'!$D47,1))+VALUE('k1-16'!M151),2) -> 1 | T52: =MOD(VALUE(MID(r0_l0!$C$54,'F(RxorK)'!$D47,1))+VALUE('k1-16'!N151),2) -> 0 | U52: =MOD(VALUE(MID(r0_l0!$C$55,'F(RxorK)'!$D47,1))+VALUE('k1-16'!O151),2) -> 0 | V52: =MOD(VALUE(MID(r0_l0!$C$56,'F(RxorK)'!$D47,1))+VALUE('k1-16'!P151),2) -> 1 | W52: =MOD(VALUE(MID(r0_l0!$C$57,'F(RxorK)'!$D47,1))+VALUE('k1-16'!Q151),2) -> 1 | X52: =MOD(VALUE(MID(r0_l0!$C$58,'F(RxorK)'!$D47,1))+VALUE('k1-16'!R151),2) -> 1
A53: 50 | B53: 53 | C53: =MID($E$1,B53,1) -> 1 | E53: 2 | G53: 45 | H53: =MOD(VALUE(MID($O$4,D48,1)) + VALUE('k1-16'!B152),2) -> 0 | I53: =MOD(VALUE(MID(r0_l0!$C$43,'F(RxorK)'!D48,1))+VALUE('k1-16'!C152),2) -> 0 | J53: =MOD(VALUE(MID(r0_l0!$C$44,'F(RxorK)'!$D48,1))+VALUE('k1-16'!D152),2) -> 0 | K53: =MOD(VALUE(MID(r0_l0!$C$45,'F(RxorK)'!D48,1))+VALUE('k1-16'!E152),2) -> 0 | L53: =MOD(VALUE(MID(r0_l0!$C$46,'F(RxorK)'!D48,1))+VALUE('k1-16'!F152),2) -> 0 | M53: =MOD(VALUE(MID(r0_l0!$C$47,'F(RxorK)'!$D48,1))+VALUE('k1-16'!G152),2) -> 1 | N53: =MOD(VALUE(MID(r0_l0!$C$48,'F(RxorK)'!$D48,1))+VALUE('k1-16'!H152),2) -> 1 | O53: =MOD(VALUE(MID(r0_l0!$C$49,'F(RxorK)'!$D48,1))+VALUE('k1-16'!I152),2) -> 1 | P53: =MOD(VALUE(MID(r0_l0!$C$50,'F(RxorK)'!$D48,1))+VALUE('k1-16'!J152),2) -> 0 | Q53: =MOD(VALUE(MID(r0_l0!$C$51,'F(RxorK)'!$D48,1))+VALUE('k1-16'!K152),2) -> 1 | R53: =MOD(VALUE(MID(r0_l0!$C$52,'F(RxorK)'!$D48,1))+VALUE('k1-16'!L152),2) -> 1 | S53: =MOD(VALUE(MID(r0_l0!$C$53,'F(RxorK)'!$D48,1))+VALUE('k1-16'!M152),2) -> 0 | T53: =MOD(VALUE(MID(r0_l0!$C$54,'F(RxorK)'!$D48,1))+VALUE('k1-16'!N152),2) -> 0 | U53: =MOD(VALUE(MID(r0_l0!$C$55,'F(RxorK)'!$D48,1))+VALUE('k1-16'!O152),2) -> 0 | V53: =MOD(VALUE(MID(r0_l0!$C$56,'F(RxorK)'!$D48,1))+VALUE('k1-16'!P152),2) -> 1 | W53: =MOD(VALUE(MID(r0_l0!$C$57,'F(RxorK)'!$D48,1))+VALUE('k1-16'!Q152),2) -> 1 | X53: =MOD(VALUE(MID(r0_l0!$C$58,'F(RxorK)'!$D48,1))+VALUE('k1-16'!R152),2) -> 0
A54: 51 | B54: 45 | C54: =MID($E$1,B54,1) -> 1 | E54: 42 | G54: 46 | H54: =MOD(VALUE(MID($O$4,D49,1)) + VALUE('k1-16'!B153),2) -> 0 | I54: =MOD(VALUE(MID(r0_l0!$C$43,'F(RxorK)'!D49,1))+VALUE('k1-16'!C153),2) -> 0 | J54: =MOD(VALUE(MID(r0_l0!$C$44,'F(RxorK)'!$D49,1))+VALUE('k1-16'!D153),2) -> 0 | K54: =MOD(VALUE(MID(r0_l0!$C$45,'F(RxorK)'!D49,1))+VALUE('k1-16'!E153),2) -> 1 | L54: =MOD(VALUE(MID(r0_l0!$C$46,'F(RxorK)'!D49,1))+VALUE('k1-16'!F153),2) -> 1 | M54: =MOD(VALUE(MID(r0_l0!$C$47,'F(RxorK)'!$D49,1))+VALUE('k1-16'!G153),2) -> 1 | N54: =MOD(VALUE(MID(r0_l0!$C$48,'F(RxorK)'!$D49,1))+VALUE('k1-16'!H153),2) -> 0 | O54: =MOD(VALUE(MID(r0_l0!$C$49,'F(RxorK)'!$D49,1))+VALUE('k1-16'!I153),2) -> 1 | P54: =MOD(VALUE(MID(r0_l0!$C$50,'F(RxorK)'!$D49,1))+VALUE('k1-16'!J153),2) -> 1 | Q54: =MOD(VALUE(MID(r0_l0!$C$51,'F(RxorK)'!$D49,1))+VALUE('k1-16'!K153),2) -> 0 | R54: =MOD(VALUE(MID(r0_l0!$C$52,'F(RxorK)'!$D49,1))+VALUE('k1-16'!L153),2) -> 0 | S54: =MOD(VALUE(MID(r0_l0!$C$53,'F(RxorK)'!$D49,1))+VALUE('k1-16'!M153),2) -> 1 | T54: =MOD(VALUE(MID(r0_l0!$C$54,'F(RxorK)'!$D49,1))+VALUE('k1-16'!N153),2) -> 0 | U54: =MOD(VALUE(MID(r0_l0!$C$55,'F(RxorK)'!$D49,1))+VALUE('k1-16'!O153),2) -> 0 | V54: =MOD(VALUE(MID(r0_l0!$C$56,'F(RxorK)'!$D49,1))+VALUE('k1-16'!P153),2) -> 0 | W54: =MOD(VALUE(MID(r0_l0!$C$57,'F(RxorK)'!$D49,1))+VALUE('k1-16'!Q153),2) -> 1 | X54: =MOD(VALUE(MID(r0_l0!$C$58,'F(RxorK)'!$D49,1))+VALUE('k1-16'!R153),2) -> 1
A55: 52 | B55: 37 | C55: =MID($E$1,B55,1) -> 1 | E55: 10 | G55: 47 | H55: =MOD(VALUE(MID($O$4,D50,1)) + VALUE('k1-16'!B154),2) -> 0 | I55: =MOD(VALUE(MID(r0_l0!$C$43,'F(RxorK)'!D50,1))+VALUE('k1-16'!C154),2) -> 1 | J55: =MOD(VALUE(MID(r0_l0!$C$44,'F(RxorK)'!$D50,1))+VALUE('k1-16'!D154),2) -> 0 | K55: =MOD(VALUE(MID(r0_l0!$C$45,'F(RxorK)'!D50,1))+VALUE('k1-16'!E154),2) -> 1 | L55: =MOD(VALUE(MID(r0_l0!$C$46,'F(RxorK)'!D50,1))+VALUE('k1-16'!F154),2) -> 0 | M55: =MOD(VALUE(MID(r0_l0!$C$47,'F(RxorK)'!$D50,1))+VALUE('k1-16'!G154),2) -> 1 | N55: =MOD(VALUE(MID(r0_l0!$C$48,'F(RxorK)'!$D50,1))+VALUE('k1-16'!H154),2) -> 1 | O55: =MOD(VALUE(MID(r0_l0!$C$49,'F(RxorK)'!$D50,1))+VALUE('k1-16'!I154),2) -> 1 | P55: =MOD(VALUE(MID(r0_l0!$C$50,'F(RxorK)'!$D50,1))+VALUE('k1-16'!J154),2) -> 0 | Q55: =MOD(VALUE(MID(r0_l0!$C$51,'F(RxorK)'!$D50,1))+VALUE('k1-16'!K154),2) -> 1 | R55: =MOD(VALUE(MID(r0_l0!$C$52,'F(RxorK)'!$D50,1))+VALUE('k1-16'!L154),2) -> 1 | S55: =MOD(VALUE(MID(r0_l0!$C$53,'F(RxorK)'!$D50,1))+VALUE('k1-16'!M154),2) -> 0 | T55: =MOD(VALUE(MID(r0_l0!$C$54,'F(RxorK)'!$D50,1))+VALUE('k1-16'!N154),2) -> 1 | U55: =MOD(VALUE(MID(r0_l0!$C$55,'F(RxorK)'!$D50,1))+VALUE('k1-16'!O154),2) -> 0 | V55: =MOD(VALUE(MID(r0_l0!$C$56,'F(RxorK)'!$D50,1))+VALUE('k1-16'!P154),2) -> 1 | W55: =MOD(VALUE(MID(r0_l0!$C$57,'F(RxorK)'!$D50,1))+VALUE('k1-16'!Q154),2) -> 0 | X55: =MOD(VALUE(MID(r0_l0!$C$58,'F(RxorK)'!$D50,1))+VALUE('k1-16'!R154),2) -> 0
A56: 53 | B56: 29 | C56: =MID($E$1,B56,1) -> 0 | E56: 50 | G56: 48 | H56: =MOD(VALUE(MID($O$4,D51,1)) + VALUE('k1-16'!B155),2) -> 0 | I56: =MOD(VALUE(MID(r0_l0!$C$43,'F(RxorK)'!D51,1))+VALUE('k1-16'!C155),2) -> 0 | J56: =MOD(VALUE(MID(r0_l0!$C$44,'F(RxorK)'!$D51,1))+VALUE('k1-16'!D155),2) -> 0 | K56: =MOD(VALUE(MID(r0_l0!$C$45,'F(RxorK)'!D51,1))+VALUE('k1-16'!E155),2) -> 0 | L56: =MOD(VALUE(MID(r0_l0!$C$46,'F(RxorK)'!D51,1))+VALUE('k1-16'!F155),2) -> 1 | M56: =MOD(VALUE(MID(r0_l0!$C$47,'F(RxorK)'!$D51,1))+VALUE('k1-16'!G155),2) -> 1 | N56: =MOD(VALUE(MID(r0_l0!$C$48,'F(RxorK)'!$D51,1))+VALUE('k1-16'!H155),2) -> 0 | O56: =MOD(VALUE(MID(r0_l0!$C$49,'F(RxorK)'!$D51,1))+VALUE('k1-16'!I155),2) -> 1 | P56: =MOD(VALUE(MID(r0_l0!$C$50,'F(RxorK)'!$D51,1))+VALUE('k1-16'!J155),2) -> 1 | Q56: =MOD(VALUE(MID(r0_l0!$C$51,'F(RxorK)'!$D51,1))+VALUE('k1-16'!K155),2) -> 1 | R56: =MOD(VALUE(MID(r0_l0!$C$52,'F(RxorK)'!$D51,1))+VALUE('k1-16'!L155),2) -> 1 | S56: =MOD(VALUE(MID(r0_l0!$C$53,'F(RxorK)'!$D51,1))+VALUE('k1-16'!M155),2) -> 1 | T56: =MOD(VALUE(MID(r0_l0!$C$54,'F(RxorK)'!$D51,1))+VALUE('k1-16'!N155),2) -> 0 | U56: =MOD(VALUE(MID(r0_l0!$C$55,'F(RxorK)'!$D51,1))+VALUE('k1-16'!O155),2) -> 1 | V56: =MOD(VALUE(MID(r0_l0!$C$56,'F(RxorK)'!$D51,1))+VALUE('k1-16'!P155),2) -> 0 | W56: =MOD(VALUE(MID(r0_l0!$C$57,'F(RxorK)'!$D51,1))+VALUE('k1-16'!Q155),2) -> 0 | X56: =MOD(VALUE(MID(r0_l0!$C$58,'F(RxorK)'!$D51,1))+VALUE('k1-16'!R155),2) -> 0
A57: 54 | B57: 21 | C57: =MID($E$1,B57,1) -> 0 | E57: 18
A58: 55 | B58: 13 | C58: =MID($E$1,B58,1) -> 0 | E58: 58
A59: 56 | B59: 5 | C59: =MID($E$1,B59,1) -> 0 | E59: 26 | G59: * Chia thành các kí tự 6 bit
A60: 57 | B60: 63 | C60: =MID($E$1,B60,1) -> 1 | E60: 33
A61: 58 | B61: 55 | C61: =MID($E$1,B61,1) -> 0 | E61: 1 | G61: i | H61: 1 | I61: 2 | J61: 3 | K61: 4 | L61: 5 | M61: 6 | N61: 7 | O61: 8 | P61: 9 | Q61: 10 | R61: 11 | S61: 12 | T61: 13 | U61: 14 | V61: 15 | W61: 16
A62: 59 | B62: 47 | C62: =MID($E$1,B62,1) -> 1 | E62: 41 | G62: 1 | H62: =MID(_xlfn.TEXTJOIN("",TRUE,H$9:H$56), 1 + 6*($G62-1), 6) -> 011010 | I62: =MID(_xlfn.TEXTJOIN("",TRUE,I$9:I$56), 1 + 6*($G62-1), 6) -> 011011 | J62: =MID(_xlfn.TEXTJOIN("",TRUE,J$9:J$56), 1 + 6*($G62-1), 6) -> 111000 | K62: =MID(_xlfn.TEXTJOIN("",TRUE,K$9:K$56), 1 + 6*($G62-1), 6) -> 000110 | L62: =MID(_xlfn.TEXTJOIN("",TRUE,L$9:L$56), 1 + 6*($G62-1), 6) -> 101100 | M62: =MID(_xlfn.TEXTJOIN("",TRUE,M$9:M$56), 1 + 6*($G62-1), 6) -> 111001 | N62: =MID(_xlfn.TEXTJOIN("",TRUE,N$9:N$56), 1 + 6*($G62-1), 6) -> 011101 | O62: =MID(_xlfn.TEXTJOIN("",TRUE,O$9:O$56), 1 + 6*($G62-1), 6) -> 010101 | ... W62: =MID(_xlfn.TEXTJOIN("",TRUE,W$9:W$56), 1 + 6*($G62-1), 6) -> 011111
A63: 60 | B63: 39 | C63: =MID($E$1,B63,1) -> 0 | E63: 9 | G63: 2 | H63: =MID(_xlfn.TEXTJOIN("",TRUE,H$9:H$56), 1 + 6*($G63-1), 6) -> 110000 | I63: =MID(_xlfn.TEXTJOIN("",TRUE,I$9:I$56), 1 + 6*($G63-1), 6) -> 000100 | J63: =MID(_xlfn.TEXTJOIN("",TRUE,J$9:J$56), 1 + 6*($G63-1), 6) -> 001111 | K63: =MID(_xlfn.TEXTJOIN("",TRUE,K$9:K$56), 1 + 6*($G63-1), 6) -> 000000 | L63: =MID(_xlfn.TEXTJOIN("",TRUE,L$9:L$56), 1 + 6*($G63-1), 6) -> 110110 | M63: =MID(_xlfn.TEXTJOIN("",TRUE,M$9:M$56), 1 + 6*($G63-1), 6) -> 100000 | N63: =MID(_xlfn.TEXTJOIN("",TRUE,N$9:N$56), 1 + 6*($G63-1), 6) -> 101111 | O63: =MID(_xlfn.TEXTJOIN("",TRUE,O$9:O$56), 1 + 6*($G63-1), 6) -> 111110 | ... W63: =MID(_xlfn.TEXTJOIN("",TRUE,W$9:W$56), 1 + 6*($G63-1), 6) -> 101111
A64: 61 | B64: 31 | C64: =MID($E$1,B64,1) -> 1 | E64: 49 | G64: 3 | H64: =MID(_xlfn.TEXTJOIN("",TRUE,H$9:H$56), 1 + 6*($G64-1), 6) -> 000001 | I64: =MID(_xlfn.TEXTJOIN("",TRUE,I$9:I$56), 1 + 6*($G64-1), 6) -> 011110 | J64: =MID(_xlfn.TEXTJOIN("",TRUE,J$9:J$56), 1 + 6*($G64-1), 6) -> 110001 | K64: =MID(_xlfn.TEXTJOIN("",TRUE,K$9:K$56), 1 + 6*($G64-1), 6) -> 010101 | L64: =MID(_xlfn.TEXTJOIN("",TRUE,L$9:L$56), 1 + 6*($G64-1), 6) -> 111010 | M64: =MID(_xlfn.TEXTJOIN("",TRUE,M$9:M$56), 1 + 6*($G64-1), 6) -> 110000 | N64: =MID(_xlfn.TEXTJOIN("",TRUE,N$9:N$56), 1 + 6*($G64-1), 6) -> 100000 | O64: =MID(_xlfn.TEXTJOIN("",TRUE,O$9:O$56), 1 + 6*($G64-1), 6) -> 001110 | ... W64: =MID(_xlfn.TEXTJOIN("",TRUE,W$9:W$56), 1 + 6*($G64-1), 6) -> 111100
A65: 62 | B65: 23 | C65: =MID($E$1,B65,1) -> 0 | E65: 17 | G65: 4 | H65: =MID(_xlfn.TEXTJOIN("",TRUE,H$9:H$56), 1 + 6*($G65-1), 6) -> 000110 | I65: =MID(_xlfn.TEXTJOIN("",TRUE,I$9:I$56), 1 + 6*($G65-1), 6) -> 000110 | J65: =MID(_xlfn.TEXTJOIN("",TRUE,J$9:J$56), 1 + 6*($G65-1), 6) -> 110010 | K65: =MID(_xlfn.TEXTJOIN("",TRUE,K$9:K$56), 1 + 6*($G65-1), 6) -> 111011 | L65: =MID(_xlfn.TEXTJOIN("",TRUE,L$9:L$56), 1 + 6*($G65-1), 6) -> 101101 | M65: =MID(_xlfn.TEXTJOIN("",TRUE,M$9:M$56), 1 + 6*($G65-1), 6) -> 010011 | N65: =MID(_xlfn.TEXTJOIN("",TRUE,N$9:N$56), 1 + 6*($G65-1), 6) -> 010101 | O65: =MID(_xlfn.TEXTJOIN("",TRUE,O$9:O$56), 1 + 6*($G65-1), 6) -> 010101 | ... W65: =MID(_xlfn.TEXTJOIN("",TRUE,W$9:W$56), 1 + 6*($G65-1), 6) -> 000110
A66: 63 | B66: 15 | C66: =MID($E$1,B66,1) -> 1 | E66: 57 | G66: 5 | H66: =MID(_xlfn.TEXTJOIN("",TRUE,H$9:H$56), 1 + 6*($G66-1), 6) -> 101000 | I66: =MID(_xlfn.TEXTJOIN("",TRUE,I$9:I$56), 1 + 6*($G66-1), 6) -> 111100 | J66: =MID(_xlfn.TEXTJOIN("",TRUE,J$9:J$56), 1 + 6*($G66-1), 6) -> 100010 | K66: =MID(_xlfn.TEXTJOIN("",TRUE,K$9:K$56), 1 + 6*($G66-1), 6) -> 111010 | L66: =MID(_xlfn.TEXTJOIN("",TRUE,L$9:L$56), 1 + 6*($G66-1), 6) -> 100010 | M66: =MID(_xlfn.TEXTJOIN("",TRUE,M$9:M$56), 1 + 6*($G66-1), 6) -> 011000 | N66: =MID(_xlfn.TEXTJOIN("",TRUE,N$9:N$56), 1 + 6*($G66-1), 6) -> 000000 | O66: =MID(_xlfn.TEXTJOIN("",TRUE,O$9:O$56), 1 + 6*($G66-1), 6) -> 001000 | ... W66: =MID(_xlfn.TEXTJOIN("",TRUE,W$9:W$56), 1 + 6*($G66-1), 6) -> 110100
A67: 64 | B67: 7 | C67: =MID($E$1,B67,1) -> 0 | E67: 25 | G67: 6 | H67: =MID(_xlfn.TEXTJOIN("",TRUE,H$9:H$56), 1 + 6*($G67-1), 6) -> 010101 | I67: =MID(_xlfn.TEXTJOIN("",TRUE,I$9:I$56), 1 + 6*($G67-1), 6) -> 000101 | J67: =MID(_xlfn.TEXTJOIN("",TRUE,J$9:J$56), 1 + 6*($G67-1), 6) -> 110001 | K67: =MID(_xlfn.TEXTJOIN("",TRUE,K$9:K$56), 1 + 6*($G67-1), 6) -> 001110 | L67: =MID(_xlfn.TEXTJOIN("",TRUE,L$9:L$56), 1 + 6*($G67-1), 6) -> 100100 | M67: =MID(_xlfn.TEXTJOIN("",TRUE,M$9:M$56), 1 + 6*($G67-1), 6) -> 110101 | N67: =MID(_xlfn.TEXTJOIN("",TRUE,N$9:N$56), 1 + 6*($G67-1), 6) -> 000010 | O67: =MID(_xlfn.TEXTJOIN("",TRUE,O$9:O$56), 1 + 6*($G67-1), 6) -> 110000 | ... W67: =MID(_xlfn.TEXTJOIN("",TRUE,W$9:W$56), 1 + 6*($G67-1), 6) -> 110000
G68: 7 | H68: =MID(_xlfn.TEXTJOIN("",TRUE,H$9:H$56), 1 + 6*($G68-1), 6) -> 110011 | I68: =MID(_xlfn.TEXTJOIN("",TRUE,I$9:I$56), 1 + 6*($G68-1), 6) -> 011010 | J68: =MID(_xlfn.TEXTJOIN("",TRUE,J$9:J$56), 1 + 6*($G68-1), 6) -> 000111 | K68: =MID(_xlfn.TEXTJOIN("",TRUE,K$9:K$56), 1 + 6*($G68-1), 6) -> 111000 | L68: =MID(_xlfn.TEXTJOIN("",TRUE,L$9:L$56), 1 + 6*($G68-1), 6) -> 111001 | M68: =MID(_xlfn.TEXTJOIN("",TRUE,M$9:M$56), 1 + 6*($G68-1), 6) -> 001011 | N68: =MID(_xlfn.TEXTJOIN("",TRUE,N$9:N$56), 1 + 6*($G68-1), 6) -> 010101 | O68: =MID(_xlfn.TEXTJOIN("",TRUE,O$9:O$56), 1 + 6*($G68-1), 6) -> 110100 | ... W68: =MID(_xlfn.TEXTJOIN("",TRUE,W$9:W$56), 1 + 6*($G68-1), 6) -> 110111
G69: 8 | H69: =MID(_xlfn.TEXTJOIN("",TRUE,H$9:H$56), 1 + 6*($G69-1), 6) -> 110000 | I69: =MID(_xlfn.TEXTJOIN("",TRUE,I$9:I$56), 1 + 6*($G69-1), 6) -> 010010 | J69: =MID(_xlfn.TEXTJOIN("",TRUE,J$9:J$56), 1 + 6*($G69-1), 6) -> 010000 | K69: =MID(_xlfn.TEXTJOIN("",TRUE,K$9:K$56), 1 + 6*($G69-1), 6) -> 000110 | L69: =MID(_xlfn.TEXTJOIN("",TRUE,L$9:L$56), 1 + 6*($G69-1), 6) -> 100101 | M69: =MID(_xlfn.TEXTJOIN("",TRUE,M$9:M$56), 1 + 6*($G69-1), 6) -> 101111 | N69: =MID(_xlfn.TEXTJOIN("",TRUE,N$9:N$56), 1 + 6*($G69-1), 6) -> 101010 | O69: =MID(_xlfn.TEXTJOIN("",TRUE,O$9:O$56), 1 + 6*($G69-1), 6) -> 101111 | ... W69: =MID(_xlfn.TEXTJOIN("",TRUE,W$9:W$56), 1 + 6*($G69-1), 6) -> 011100
B71: * Sau khi đi qua S_BOX thì được kết quả
U72: * S(E(R0) XOR k1)
...

Sheet r0_l0
A1: IP(M) = | B1: ='F(RxorK)'!O1 -> 1001100011111110110011000000000011100000010101001111000010101010
A3: L0 = | B3: =LEFT(B1,32) -> 10011000111111101100110000000000 | G3: R0 = | H3: =RIGHT(B1,32) -> 11100000010101001111000010101010
A5: STT | B5: L0 | C5: L1 | D5: L2 | E5: L3 | F5: L4 | G5: L5 | H5: L6 | I5: L7 | J5: L8 | K5: L9 | L5: L10 | M5: L11 | N5: L12 | O5: L13 | P5: L14 | Q5: L15 | R5: L16 | U5: stt | V5: R0 | W5: R1 | X5: R2 | Y5: R3 | Z5: R4 | AA5: R5 | AB5: R6 | AC5: R7 | AD5: R8 | AE5: R9 | AF5: R10 | AG5: R11 | AH5: R12 | AI5: R13 | AJ5: R14 | AK5: R15 | AL5: R16
A6: 1 | B6: =MID($B$3,ROW(A1),1) -> 1 | C6: =V6 -> 1 | D6: =W6 -> 0 | E6: =X6 -> 0 | F6: =Y6 -> 1 | G6: =Z6 -> 1 | H6: =AA6 -> 0 | I6: =AB6 -> 0 | J6: =AC6 -> 0 | ... R6: =AK6 -> 0 | U6: 1 | V6: =MID($H$3, ROW(A1),1) -> 1 | W6: =MOD(B6 + MID('F(RxorK)'!$V$74, ROW(r0_l0!A1),1),2) -> 0 | X6: =MOD(C6+MID('F(RxorK)'!$V$75,ROW(r0_l0!$A1),1),2) -> 0 | Y6: =MOD(D6+MID('F(RxorK)'!$V$76,ROW(r0_l0!A1),1),2) -> 1 | Z6: =MOD(E6+MID('F(RxorK)'!$V$77,ROW(r0_l0!A1),1),2) -> 1 | AA6: =MOD(F6+MID('F(RxorK)'!$V$78,ROW(r0_l0!$A1),1),2) -> 0 | AB6: =MOD(G6+MID('F(RxorK)'!$V$79,ROW(r0_l0!$A1),1),2) -> 0 | AC6: =MOD(H6+MID('F(RxorK)'!$V$80,ROW(r0_l0!$A1),1),2) -> 0 | AD6: =MOD(I6+MID('F(RxorK)'!$V$81,ROW(r0_l0!$A1),1),2) -> 0 | AE6: =MOD(J6+MID('F(RxorK)'!$V$82,ROW(r0_l0!$A1),1),2) -> 1 | AF6: =MOD(K6+MID('F(RxorK)'!$V$83,ROW(r0_l0!$A1),1),2) -> 1 | AG6: =MOD(L6+MID('F(RxorK)'!$V$84,ROW(r0_l0!$A1),1),2) -> 0 | AH6: =MOD(M6+MID('F(RxorK)'!$V$85,ROW(r0_l0!$A1),1),2) -> 1 | AI6: =MOD(N6+MID('F(RxorK)'!$V$86,ROW(r0_l0!$A1),1),2) -> 0 | AJ6: =MOD(O6+MID('F(RxorK)'!$V$87,ROW(r0_l0!$A1),1),2) -> 1 | AK6: =MOD(P6+MID('F(RxorK)'!$V$88,ROW(r0_l0!$A1),1),2) -> 0 | AL6: =MOD(Q6+MID('F(RxorK)'!$V$89,ROW(r0_l0!$A1),1),2) -> 0
A7: 2 | B7: =MID($B$3,ROW(A2),1) -> 0 | C7: =V7 -> 1 | D7: =W7 -> 0 | E7: =X7 -> 1 | F7: =Y7 -> 1 | G7: =Z7 -> 0 | H7: =AA7 -> 0 | I7: =AB7 -> 0 | J7: =AC7 -> 1 | ... R7: =AK7 -> 1 | U7: 2 | V7: =MID($H$3, ROW(A2),1) -> 1 | W7: =MOD(B7 + MID('F(RxorK)'!$V$74, ROW(r0_l0!A2),1),2) -> 0 | X7: =MOD(C7+MID('F(RxorK)'!$V$75,ROW(r0_l0!$A2),1),2) -> 1 | Y7: =MOD(D7+MID('F(RxorK)'!$V$76,ROW(r0_l0!A2),1),2) -> 1 | Z7: =MOD(E7+MID('F(RxorK)'!$V$77,ROW(r0_l0!A2),1),2) -> 0 | AA7: =MOD(F7+MID('F(RxorK)'!$V$78,ROW(r0_l0!$A2),1),2) -> 0 | AB7: =MOD(G7+MID('F(RxorK)'!$V$79,ROW(r0_l0!$A2),1),2) -> 0 | AC7: =MOD(H7+MID('F(RxorK)'!$V$80,ROW(r0_l0!$A2),1),2) -> 1 | AD7: =MOD(I7+MID('F(RxorK)'!$V$81,ROW(r0_l0!$A2),1),2) -> 1 | AE7: =MOD(J7+MID('F(RxorK)'!$V$82,ROW(r0_l0!$A2),1),2) -> 0 | AF7: =MOD(K7+MID('F(RxorK)'!$V$83,ROW(r0_l0!$A2),1),2) -> 0 | AG7: =MOD(L7+MID('F(RxorK)'!$V$84,ROW(r0_l0!$A2),1),2) -> 1 | AH7: =MOD(M7+MID('F(RxorK)'!$V$85,ROW(r0_l0!$A2),1),2) -> 1 | AI7: =MOD(N7+MID('F(RxorK)'!$V$86,ROW(r0_l0!$A2),1),2) -> 0 | AJ7: =MOD(O7+MID('F(RxorK)'!$V$87,ROW(r0_l0!$A2),1),2) -> 0 | AK7: =MOD(P7+MID('F(RxorK)'!$V$88,ROW(r0_l0!$A2),1),2) -> 1 | AL7: =MOD(Q7+MID('F(RxorK)'!$V$89,ROW(r0_l0!$A2),1),2) -> 1
A8: 3 | B8: =MID($B$3,ROW(A3),1) -> 0 | C8: =V8 -> 1 | D8: =W8 -> 0 | E8: =X8 -> 1 | F8: =Y8 -> 0 | G8: =Z8 -> 0 | H8: =AA8 -> 0 | I8: =AB8 -> 1 | J8: =AC8 -> 0 | ... R8: =AK8 -> 1 | U8: 3 | V8: =MID($H$3, ROW(A3),1) -> 1 | W8: =MOD(B8 + MID('F(RxorK)'!$V$74, ROW(r0_l0!A3),1),2) -> 0 | X8: =MOD(C8+MID('F(RxorK)'!$V$75,ROW(r0_l0!$A3),1),2) -> 1 | Y8: =MOD(D8+MID('F(RxorK)'!$V$76,ROW(r0_l0!A3),1),2) -> 0 | Z8: =MOD(E8+MID('F(RxorK)'!$V$77,ROW(r0_l0!A3),1),2) -> 0 | AA8: =MOD(F8+MID('F(RxorK)'!$V$78,ROW(r0_l0!$A3),1),2) -> 0 | AB8: =MOD(G8+MID('F(RxorK)'!$V$79,ROW(r0_l0!$A3),1),2) -> 1 | AC8: =MOD(H8+MID('F(RxorK)'!$V$80,ROW(r0_l0!$A3),1),2) -> 0 | AD8: =MOD(I8+MID('F(RxorK)'!$V$81,ROW(r0_l0!$A3),1),2) -> 0 | AE8: =MOD(J8+MID('F(RxorK)'!$V$82,ROW(r0_l0!$A3),1),2) -> 1 | AF8: =MOD(K8+MID('F(RxorK)'!$V$83,ROW(r0_l0!$A3),1),2) -> 0 | AG8: =MOD(L8+MID('F(RxorK)'!$V$84,ROW(r0_l0!$A3),1),2) -> 0 | AH8: =MOD(M8+MID('F(RxorK)'!$V$85,ROW(r0_l0!$A3),1),2) -> 1 | AI8: =MOD(N8+MID('F(RxorK)'!$V$86,ROW(r0_l0!$A3),1),2) -> 1 | AJ8: =MOD(O8+MID('F(RxorK)'!$V$87,ROW(r0_l0!$A3),1),2) -> 0 | AK8: =MOD(P8+MID('F(RxorK)'!$V$88,ROW(r0_l0!$A3),1),2) -> 1 | AL8: =MOD(Q8+MID('F(RxorK)'!$V$89,ROW(r0_l0!$A3),1),2) -> 0
A9: 4 | B9: =MID($B$3,ROW(A4),1) -> 1 | C9: =V9 -> 0 | D9: =W9 -> 0 | E9: =X9 -> 0 | F9: =Y9 -> 1 | G9: =Z9 -> 1 | H9: =AA9 -> 0 | I9: =AB9 -> 1 | J9: =AC9 -> 0 | ... R9: =AK9 -> 0 | U9: 4 | V9: =MID($H$3, ROW(A4),1) -> 0 | W9: =MOD(B9 + MID('F(RxorK)'!$V$74, ROW(r0_l0!A4),1),2) -> 0 | X9: =MOD(C9+MID('F(RxorK)'!$V$75,ROW(r0_l0!$A4),1),2) -> 0 | Y9: =MOD(D9+MID('F(RxorK)'!$V$76,ROW(r0_l0!A4),1),2) -> 1 | Z9: =MOD(E9+MID('F(RxorK)'!$V$77,ROW(r0_l0!A4),1),2) -> 1 | AA9: =MOD(F9+MID('F(RxorK)'!$V$78,ROW(r0_l0!$A4),1),2) -> 0 | AB9: =MOD(G9+MID('F(RxorK)'!$V$79,ROW(r0_l0!$A4),1),2) -> 1 | AC9: =MOD(H9+MID('F(RxorK)'!$V$80,ROW(r0_l0!$A4),1),2) -> 0 | AD9: =MOD(I9+MID('F(RxorK)'!$V$81,ROW(r0_l0!$A4),1),2) -> 1 | AE9: =MOD(J9+MID('F(RxorK)'!$V$82,ROW(r0_l0!$A4),1),2) -> 1 | AF9: =MOD(K9+MID('F(RxorK)'!$V$83,ROW(r0_l0!$A4),1),2) -> 0 | AG9: =MOD(L9+MID('F(RxorK)'!$V$84,ROW(r0_l0!$A4),1),2) -> 0 | AH9: =MOD(M9+MID('F(RxorK)'!$V$85,ROW(r0_l0!$A4),1),2) -> 1 | AI9: =MOD(N9+MID('F(RxorK)'!$V$86,ROW(r0_l0!$A4),1),2) -> 1 | AJ9: =MOD(O9+MID('F(RxorK)'!$V$87,ROW(r0_l0!$A4),1),2) -> 1 | AK9: =MOD(P9+MID('F(RxorK)'!$V$88,ROW(r0_l0!$A4),1),2) -> 0 | AL9: =MOD(Q9+MID('F(RxorK)'!$V$89,ROW(r0_l0!$A4),1),2) -> 1
A10: 5 | B10: =MID($B$3,ROW(A5),1) -> 1 | C10: =V10 -> 0 | D10: =W10 -> 1 | E10: =X10 -> 1 | F10: =Y10 -> 0 | G10: =Z10 -> 1 | H10: =AA10 -> 1 | I10: =AB10 -> 0 | J10: =AC10 -> 0 | ... R10: =AK10 -> 1 | U10: 5 | V10: =MID($H$3, ROW(A5),1) -> 0 | W10: =MOD(B10 + MID('F(RxorK)'!$V$74, ROW(r0_l0!A5),1),2) -> 1 | X10: =MOD(C10+MID('F(RxorK)'!$V$75,ROW(r0_l0!$A5),1),2) -> 1 | Y10: =MOD(D10+MID('F(RxorK)'!$V$76,ROW(r0_l0!A5),1),2) -> 0 | Z10: =MOD(E10+MID('F(RxorK)'!$V$77,ROW(r0_l0!A5),1),2) -> 1 | AA10: =MOD(F10+MID('F(RxorK)'!$V$78,ROW(r0_l0!$A5),1),2) -> 1 | AB10: =MOD(G10+MID('F(RxorK)'!$V$79,ROW(r0_l0!$A5),1),2) -> 0 | AC10: =MOD(H10+MID('F(RxorK)'!$V$80,ROW(r0_l0!$A5),1),2) -> 0 | AD10: =MOD(I10+MID('F(RxorK)'!$V$81,ROW(r0_l0!$A5),1),2) -> 1 | AE10: =MOD(J10+MID('F(RxorK)'!$V$82,ROW(r0_l0!$A5),1),2) -> 1 | AF10: =MOD(K10+MID('F(RxorK)'!$V$83,ROW(r0_l0!$A5),1),2) -> 1 | AG10: =MOD(L10+MID('F(RxorK)'!$V$84,ROW(r0_l0!$A5),1),2) -> 0 | AH10: =MOD(M10+MID('F(RxorK)'!$V$85,ROW(r0_l0!$A5),1),2) -> 1 | AI10: =MOD(N10+MID('F(RxorK)'!$V$86,ROW(r0_l0!$A5),1),2) -> 1 | AJ10: =MOD(O10+MID('F(RxorK)'!$V$87,ROW(r0_l0!$A5),1),2) -> 1 | AK10: =MOD(P10+MID('F(RxorK)'!$V$88,ROW(r0_l0!$A5),1),2) -> 1 | AL10: =MOD(Q10+MID('F(RxorK)'!$V$89,ROW(r0_l0!$A5),1),2) -> 0
A11: 6 | B11: =MID($B$3,ROW(A6),1) -> 0 | C11: =V11 -> 0 | D11: =W11 -> 1 | E11: =X11 -> 0 | F11: =Y11 -> 1 | G11: =Z11 -> 1 | H11: =AA11 -> 1 | I11: =AB11 -> 0 | J11: =AC11 -> 0 | ... R11: =AK11 -> 1 | U11: 6 | V11: =MID($H$3, ROW(A6),1) -> 0 | W11: =MOD(B11 + MID('F(RxorK)'!$V$74, ROW(r0_l0!A6),1),2) -> 1 | X11: =MOD(C11+MID('F(RxorK)'!$V$75,ROW(r0_l0!$A6),1),2) -> 0 | Y11: =MOD(D11+MID('F(RxorK)'!$V$76,ROW(r0_l0!A6),1),2) -> 1 | Z11: =MOD(E11+MID('F(RxorK)'!$V$77,ROW(r0_l0!A6),1),2) -> 1 | AA11: =MOD(F11+MID('F(RxorK)'!$V$78,ROW(r0_l0!$A6),1),2) -> 1 | AB11: =MOD(G11+MID('F(RxorK)'!$V$79,ROW(r0_l0!$A6),1),2) -> 0 | AC11: =MOD(H11+MID('F(RxorK)'!$V$80,ROW(r0_l0!$A6),1),2) -> 0 | AD11: =MOD(I11+MID('F(RxorK)'!$V$81,ROW(r0_l0!$A6),1),2) -> 1 | AE11: =MOD(J11+MID('F(RxorK)'!$V$82,ROW(r0_l0!$A6),1),2) -> 0 | AF11: =MOD(K11+MID('F(RxorK)'!$V$83,ROW(r0_l0!$A6),1),2) -> 0 | AG11: =MOD(L11+MID('F(RxorK)'!$V$84,ROW(r0_l0!$A6),1),2) -> 1 | AH11: =MOD(M11+MID('F(RxorK)'!$V$85,ROW(r0_l0!$A6),1),2) -> 0 | AI11: =MOD(N11+MID('F(RxorK)'!$V$86,ROW(r0_l0!$A6),1),2) -> 1 | AJ11: =MOD(O11+MID('F(RxorK)'!$V$87,ROW(r0_l0!$A6),1),2) -> 1 | AK11: =MOD(P11+MID('F(RxorK)'!$V$88,ROW(r0_l0!$A6),1),2) -> 1 | AL11: =MOD(Q11+MID('F(RxorK)'!$V$89,ROW(r0_l0!$A6),1),2) -> 1
A12: 7 | B12: =MID($B$3,ROW(A7),1) -> 0 | C12: =V12 -> 0 | D12: =W12 -> 1 | E12: =X12 -> 0 | F12: =Y12 -> 0 | G12: =Z12 -> 0 | H12: =AA12 -> 0 | I12: =AB12 -> 1 | J12: =AC12 -> 1 | ... R12: =AK12 -> 1 | U12: 7 | V12: =MID($H$3, ROW(A7),1) -> 0 | W12: =MOD(B12 + MID('F(RxorK)'!$V$74, ROW(r0_l0!A7),1),2) -> 1 | X12: =MOD(C12+MID('F(RxorK)'!$V$75,ROW(r0_l0!$A7),1),2) -> 0 | Y12: =MOD(D12+MID('F(RxorK)'!$V$76,ROW(r0_l0!A7),1),2) -> 0 | Z12: =MOD(E12+MID('F(RxorK)'!$V$77,ROW(r0_l0!A7),1),2) -> 0 | AA12: =MOD(F12+MID('F(RxorK)'!$V$78,ROW(r0_l0!$A7),1),2) -> 0 | AB12: =MOD(G12+MID('F(RxorK)'!$V$79,ROW(r0_l0!$A7),1),2) -> 1 | AC12: =MOD(H12+MID('F(RxorK)'!$V$80,ROW(r0_l0!$A7),1),2) -> 1 | AD12: =MOD(I12+MID('F(RxorK)'!$V$81,ROW(r0_l0!$A7),1),2) -> 1 | AE12: =MOD(J12+MID('F(RxorK)'!$V$82,ROW(r0_l0!$A7),1),2) -> 0 | AF12: =MOD(K12+MID('F(RxorK)'!$V$83,ROW(r0_l0!$A7),1),2) -> 1 | AG12: =MOD(L12+MID('F(RxorK)'!$V$84,ROW(r0_l0!$A7),1),2) -> 0 | AH12: =MOD(M12+MID('F(RxorK)'!$V$85,ROW(r0_l0!$A7),1),2) -> 1 | AI12: =MOD(N12+MID('F(RxorK)'!$V$86,ROW(r0_l0!$A7),1),2) -> 1 | AJ12: =MOD(O12+MID('F(RxorK)'!$V$87,ROW(r0_l0!$A7),1),2) -> 1 | AK12: =MOD(P12+MID('F(RxorK)'!$V$88,ROW(r0_l0!$A7),1),2) -> 1 | AL12: =MOD(Q12+MID('F(RxorK)'!$V$89,ROW(r0_l0!$A7),1),2) -> 0
A13: 8 | B13: =MID($B$3,ROW(A8),1) -> 0 | C13: =V13 -> 0 | D13: =W13 -> 1 | E13: =X13 -> 0 | F13: =Y13 -> 1 | G13: =Z13 -> 0 | H13: =AA13 -> 1 | I13: =AB13 -> 1 | J13: =AC13 -> 1 | ... R13: =AK13 -> 0 | U13: 8 | V13: =MID($H$3, ROW(A8),1) -> 0 | W13: =MOD(B13 + MID('F(RxorK)'!$V$74, ROW(r0_l0!A8),1),2) -> 1 | X13: =MOD(C13+MID('F(RxorK)'!$V$75,ROW(r0_l0!$A8),1),2) -> 0 | Y13: =MOD(D13+MID('F(RxorK)'!$V$76,ROW(r0_l0!A8),1),2) -> 1 | Z13: =MOD(E13+MID('F(RxorK)'!$V$77,ROW(r0_l0!A8),1),2) -> 0 | AA13: =MOD(F13+MID('F(RxorK)'!$V$78,ROW(r0_l0!$A8),1),2) -> 1 | AB13: =MOD(G13+MID('F(RxorK)'!$V$79,ROW(r0_l0!$A8),1),2) -> 1 | AC13: =MOD(H13+MID('F(RxorK)'!$V$80,ROW(r0_l0!$A8),1),2) -> 1 | AD13: =MOD(I13+MID('F(RxorK)'!$V$81,ROW(r0_l0!$A8),1),2) -> 1 | AE13: =MOD(J13+MID('F(RxorK)'!$V$82,ROW(r0_l0!$A8),1),2) -> 0 | AF13: =MOD(K13+MID('F(RxorK)'!$V$83,ROW(r0_l0!$A8),1),2) -> 0 | AG13: =MOD(L13+MID('F(RxorK)'!$V$84,ROW(r0_l0!$A8),1),2) -> 0 | AH13: =MOD(M13+MID('F(RxorK)'!$V$85,ROW(r0_l0!$A8),1),2) -> 0 | AI13: =MOD(N13+MID('F(RxorK)'!$V$86,ROW(r0_l0!$A8),1),2) -> 1 | AJ13: =MOD(O13+MID('F(RxorK)'!$V$87,ROW(r0_l0!$A8),1),2) -> 1 | AK13: =MOD(P13+MID('F(RxorK)'!$V$88,ROW(r0_l0!$A8),1),2) -> 0 | AL13: =MOD(Q13+MID('F(RxorK)'!$V$89,ROW(r0_l0!$A8),1),2) -> 0
A14: 9 | B14: =MID($B$3,ROW(A9),1) -> 1 | C14: =V14 -> 0 | D14: =W14 -> 0 | E14: =X14 -> 0 | F14: =Y14 -> 0 | G14: =Z14 -> 0 | H14: =AA14 -> 0 | I14: =AB14 -> 1 | J14: =AC14 -> 0 | ... R14: =AK14 -> 0 | U14: 9 | V14: =MID($H$3, ROW(A9),1) -> 0 | W14: =MOD(B14 + MID('F(RxorK)'!$V$74, ROW(r0_l0!A9),1),2) -> 0 | X14: =MOD(C14+MID('F(RxorK)'!$V$75,ROW(r0_l0!$A9),1),2) -> 0 | Y14: =MOD(D14+MID('F(RxorK)'!$V$76,ROW(r0_l0!A9),1),2) -> 0 | Z14: =MOD(E14+MID('F(RxorK)'!$V$77,ROW(r0_l0!A9),1),2) -> 0 | AA14: =MOD(F14+MID('F(RxorK)'!$V$78,ROW(r0_l0!$A9),1),2) -> 0 | AB14: =MOD(G14+MID('F(RxorK)'!$V$79,ROW(r0_l0!$A9),1),2) -> 1 | AC14: =MOD(H14+MID('F(RxorK)'!$V$80,ROW(r0_l0!$A9),1),2) -> 0 | AD14: =MOD(I14+MID('F(RxorK)'!$V$81,ROW(r0_l0!$A9),1),2) -> 0 | AE14: =MOD(J14+MID('F(RxorK)'!$V$82,ROW(r0_l0!$A9),1),2) -> 0 | AF14: =MOD(K14+MID('F(RxorK)'!$V$83,ROW(r0_l0!$A9),1),2) -> 0 | AG14: =MOD(L14+MID('F(RxorK)'!$V$84,ROW(r0_l0!$A9),1),2) -> 1 | AH14: =MOD(M14+MID('F(RxorK)'!$V$85,ROW(r0_l0!$A9),1),2) -> 0 | AI14: =MOD(N14+MID('F(RxorK)'!$V$86,ROW(r0_l0!$A9),1),2) -> 0 | AJ14: =MOD(O14+MID('F(RxorK)'!$V$87,ROW(r0_l0!$A9),1),2) -> 1 | AK14: =MOD(P14+MID('F(RxorK)'!$V$88,ROW(r0_l0!$A9),1),2) -> 0 | AL14: =MOD(Q14+MID('F(RxorK)'!$V$89,ROW(r0_l0!$A9),1),2) -> 0
A15: 10 | B15: =MID($B$3,ROW(A10),1) -> 1 | C15: =V15 -> 1 | D15: =W15 -> 0 | E15: =X15 -> 0 | F15: =Y15 -> 0 | G15: =Z15 -> 1 | H15: =AA15 -> 0 | I15: =AB15 -> 0 | J15: =AC15 -> 1 | ... R15: =AK15 -> 1 | U15: 10 | V15: =MID($H$3, ROW(A10),1) -> 1 | W15: =MOD(B15 + MID('F(RxorK)'!$V$74, ROW(r0_l0!A10),1),2) -> 0 | X15: =MOD(C15+MID('F(RxorK)'!$V$75,ROW(r0_l0!$A10),1),2) -> 0 | Y15: =MOD(D15+MID('F(RxorK)'!$V$76,ROW(r0_l0!A10),1),2) -> 0 | Z15: =MOD(E15+MID('F(RxorK)'!$V$77,ROW(r0_l0!A10),1),2) -> 1 | AA15: =MOD(F15+MID('F(RxorK)'!$V$78,ROW(r0_l0!$A10),1),2) -> 0 | AB15: =MOD(G15+MID('F(RxorK)'!$V$79,ROW(r0_l0!$A10),1),2) -> 0 | AC15: =MOD(H15+MID('F(RxorK)'!$V$80,ROW(r0_l0!$A10),1),2) -> 1 | AD15: =MOD(I15+MID('F(RxorK)'!$V$81,ROW(r0_l0!$A10),1),2) -> 1 | AE15: =MOD(J15+MID('F(RxorK)'!$V$82,ROW(r0_l0!$A10),1),2) -> 1 | AF15: =MOD(K15+MID('F(RxorK)'!$V$83,ROW(r0_l0!$A10),1),2) -> 1 | AG15: =MOD(L15+MID('F(RxorK)'!$V$84,ROW(r0_l0!$A10),1),2) -> 0 | AH15: =MOD(M15+MID('F(RxorK)'!$V$85,ROW(r0_l0!$A10),1),2) -> 0 | AI15: =MOD(N15+MID('F(RxorK)'!$V$86,ROW(r0_l0!$A10),1),2) -> 1 | AJ15: =MOD(O15+MID('F(RxorK)'!$V$87,ROW(r0_l0!$A10),1),2) -> 1 | AK15: =MOD(P15+MID('F(RxorK)'!$V$88,ROW(r0_l0!$A10),1),2) -> 1 | AL15: =MOD(Q15+MID('F(RxorK)'!$V$89,ROW(r0_l0!$A10),1),2) -> 0
A16: 11 | B16: =MID($B$3,ROW(A11),1) -> 1 | C16: =V16 -> 0 | D16: =W16 -> 1 | E16: =X16 -> 0 | F16: =Y16 -> 0 | G16: =Z16 -> 0 | H16: =AA16 -> 1 | I16: =AB16 -> 0 | J16: =AC16 -> 1 | ... R16: =AK16 -> 0 | U16: 11 | V16: =MID($H$3, ROW(A11),1) -> 0 | W16: =MOD(B16 + MID('F(RxorK)'!$V$74, ROW(r0_l0!A11),1),2) -> 1 | X16: =MOD(C16+MID('F(RxorK)'!$V$75,ROW(r0_l0!$A11),1),2) -> 0 | Y16: =MOD(D16+MID('F(RxorK)'!$V$76,ROW(r0_l0!A11),1),2) -> 0 | Z16: =MOD(E16+MID('F(RxorK)'!$V$77,ROW(r0_l0!A11),1),2) -> 0 | AA16: =MOD(F16+MID('F(RxorK)'!$V$78,ROW(r0_l0!$A11),1),2) -> 1 | AB16: =MOD(G16+MID('F(RxorK)'!$V$79,ROW(r0_l0!$A11),1),2) -> 0 | AC16: =MOD(H16+MID('F(RxorK)'!$V$80,ROW(r0_l0!$A11),1),2) -> 1 | AD16: =MOD(I16+MID('F(RxorK)'!$V$81,ROW(r0_l0!$A11),1),2) -> 1 | AE16: =MOD(J16+MID('F(RxorK)'!$V$82,ROW(r0_l0!$A11),1),2) -> 1 | AF16: =MOD(K16+MID('F(RxorK)'!$V$83,ROW(r0_l0!$A11),1),2) -> 1 | AG16: =MOD(L16+MID('F(RxorK)'!$V$84,ROW(r0_l0!$A11),1),2) -> 0 | AH16: =MOD(M16+MID('F(RxorK)'!$V$85,ROW(r0_l0!$A11),1),2) -> 1 | AI16: =MOD(N16+MID('F(RxorK)'!$V$86,ROW(r0_l0!$A11),1),2) -> 1 | AJ16: =MOD(O16+MID('F(RxorK)'!$V$87,ROW(r0_l0!$A11),1),2) -> 0 | AK16: =MOD(P16+MID('F(RxorK)'!$V$88,ROW(r0_l0!$A11),1),2) -> 0 | AL16: =MOD(Q16+MID('F(RxorK)'!$V$89,ROW(r0_l0!$A11),1),2) -> 1
