Workbook

Sheet Đề bài
A1: Họ tên: Lã Minh Khánh | E1: Dựa trên thông tin trong ảnh, bài toán mã hóa và giải mã DES có các giá trị như sau: Input: Bản tin M = 00123456789abcde Khóa K = 0133457799bbcdff Output: Bản mã C = 1abf69d5a93e80b
A2: Lớp: 67CS
A3: Bài tập An toàn Bảo mật Thông tin
A4: Mã hóa DES

Sheet Permutations
A1: IP | B1: FP | C1: E-box | D1: P-box | E1: PC-1 | F1: PC-2 | G1: Left Shifts Schedule
A2: 58 | B2: 40 | C2: 32 | D2: 16 | E2: 57 | F2: 14 | G2: 1
A3: 50 | B3: 8 | C3: 1 | D3: 7 | E3: 49 | F3: 17 | G3: 1
A4: 42 | B4: 48 | C4: 2 | D4: 20 | E4: 41 | F4: 11 | G4: 2
A5: 34 | B5: 16 | C5: 3 | D5: 21 | E5: 33 | F5: 24 | G5: 2
A6: 26 | B6: 56 | C6: 4 | D6: 29 | E6: 25 | F6: 1 | G6: 2
A7: 18 | B7: 24 | C7: 5 | D7: 12 | E7: 17 | F7: 5 | G7: 2
A8: 10 | B8: 64 | C8: 4 | D8: 28 | E8: 9 | F8: 3 | G8: 2
A9: 2 | B9: 32 | C9: 5 | D9: 17 | E9: 1 | F9: 28 | G9: 2
A10: 60 | B10: 39 | C10: 6 | D10: 1 | E10: 58 | F10: 15 | G10: 1
A11: 52 | B11: 7 | C11: 7 | D11: 15 | E11: 50 | F11: 6 | G11: 2
A12: 44 | B12: 47 | C12: 8 | D12: 23 | E12: 42 | F12: 21 | G12: 2
A13: 36 | B13: 15 | C13: 9 | D13: 26 | E13: 34 | F13: 10 | G13: 2
... A17: 4 | B17: 31 | C17: 11 | D17: 10 | E17: 2 | F17: 4 | G17: 1
A18: 62 | B18: 38 | C18: 12 | D18: 2 | E18: 59 | F18: 26
A19: 54 | B19: 6 | C19: 13 | D19: 8 | E19: 51 | F19: 8
A20: 46 | B20: 46 | C20: 12 | D20: 24 | E20: 43 | F20: 16
A21: 38 | B21: 14 | C21: 13 | D21: 14 | E21: 35 | F21: 7
A22: 30 | B22: 54 | C22: 14 | D22: 32 | E22: 27 | F22: 27
A23: 22 | B23: 22 | C23: 15 | D23: 27 | E23: 19 | F23: 20
A24: 14 | B24: 62 | C24: 16 | D24: 3 | E24: 11 | F24: 13
A25: 6 | B25: 30 | C25: 17 | D25: 9 | E25: 3 | F25: 2
A26: 64 | B26: 37 | C26: 16 | D26: 19 | E26: 60 | F26: 41
A27: 56 | B27: 5 | C27: 17 | D27: 13 | E27: 52 | F27: 52
A28: 48 | B28: 45 | C28: 18 | D28: 30 | E28: 44 | F28: 31
A29: 40 | B29: 13 | C29: 19 | D29: 6 | E29: 36 | F29: 37
... A33: 8 | B33: 29 | C33: 21 | D33: 25 | E33: 39 | F33: 40
A34: 57 | B34: 36 | C34: 22 | E34: 31 | F34: 51
A35: 49 | B35: 4 | C35: 23 | E35: 23 | F35: 45
A36: 41 | B36: 44 | C36: 24 | E36: 15 | F36: 33
A37: 33 | B37: 12 | C37: 25 | E37: 7 | F37: 48
A38: 25 | B38: 52 | C38: 24 | E38: 62 | F38: 44
A39: 17 | B39: 20 | C39: 25 | E39: 54 | F39: 49
A40: 9 | B40: 60 | C40: 26 | E40: 46 | F40: 39
A41: 1 | B41: 28 | C41: 27 | E41: 38 | F41: 56
A42: 59 | B42: 35 | C42: 28 | E42: 30 | F42: 34
A43: 51 | B43: 3 | C43: 29 | E43: 22 | F43: 53
A44: 43 | B44: 43 | C44: 28 | E44: 14 | F44: 46
A45: 35 | B45: 11 | C45: 29 | E45: 6 | F45: 42
... A49: 3 | B49: 27 | C49: 1 | E49: 37 | F49: 32
...

Sheet S-boxes
A1: Input | B1: S-box 8 | F1: S-box 7 | J1: S-box 6 | N1: S-box 5 | R1: S-box 4 | V1: S-box 3 | Z1: S-box 2 | AD1: S-box 1
A2: 000000 | B2: 1 | C2: 1 | D2: 1 | E2: 0 | F2: 1 | G2: 1 | H2: 1 | I2: 1 | J2: 1 | K2: 0 | L2: 1 | M2: 0 | N2: 0 | O2: 1 | P2: 1 | Q2: 1 | R2: 0 | S2: 0 | T2: 1 | U2: 0 | V2: 1 | W2: 1 | X2: 0 | Y2: 0 | Z2: 0 | AA2: 1 | AB2: 0 | AC2: 0 | AD2: 1 | AE2: 1 | AF2: 0 | AG2: 1
A3: 000001 | B3: 0 | C3: 0 | D3: 0 | E3: 0 | F3: 0 | G3: 0 | H3: 1 | I3: 1 | J3: 1 | K3: 1 | L3: 0 | M3: 1 | N3: 1 | O3: 1 | P3: 0 | Q3: 1 | R3: 1 | S3: 1 | T3: 1 | U3: 0 | V3: 1 | W3: 0 | X3: 1 | Y3: 0 | Z3: 1 | AA3: 1 | AB3: 0 | AC3: 1 | AD3: 0 | AE3: 0 | AF3: 0 | AG3: 1
A4: 000010 | B4: 0 | C4: 1 | D4: 0 | E4: 0 | F4: 0 | G4: 0 | H4: 0 | I4: 1 | J4: 0 | K4: 0 | L4: 0 | M4: 0 | N4: 1 | O4: 1 | P4: 0 | Q4: 1 | R4: 1 | S4: 1 | T4: 0 | U4: 0 | V4: 0 | W4: 0 | X4: 0 | Y4: 1 | Z4: 1 | AA4: 0 | AB4: 1 | AC4: 1 | AD4: 0 | AE4: 0 | AF4: 1 | AG4: 0
A5: 000011 | B5: 1 | C5: 1 | D5: 1 | E5: 1 | F5: 1 | G5: 1 | H5: 0 | I5: 1 | J5: 0 | K5: 1 | L5: 1 | M5: 1 | N5: 1 | O5: 0 | P5: 0 | Q5: 0 | R5: 1 | S5: 0 | T5: 1 | U5: 1 | V5: 1 | W5: 1 | X5: 1 | Y5: 1 | Z5: 0 | AA5: 0 | AB5: 0 | AC5: 0 | AD5: 1 | AE5: 1 | AF5: 1 | AG5: 1
A6: 000100 | B6: 1 | C6: 1 | D6: 0 | E6: 1 | F6: 1 | G6: 0 | H6: 0 | I6: 0 | J6: 1 | K6: 0 | L6: 0 | M6: 1 | N6: 1 | O6: 1 | P6: 1 | Q6: 0 | R6: 0 | S6: 1 | T6: 0 | U6: 0 | V6: 1 | W6: 0 | X6: 1 | Y6: 0 | Z6: 0 | AA6: 0 | AB6: 1 | AC6: 0 | AD6: 1 | AE6: 0 | AF6: 0 | AG6: 0
A7: 000101 | B7: 0 | C7: 1 | D7: 1 | E7: 1 | F7: 0 | G7: 1 | H7: 0 | I7: 0 | J7: 0 | K7: 0 | L7: 0 | M7: 0 | N7: 1 | O7: 0 | P7: 1 | Q7: 1 | R7: 0 | S7: 0 | T7: 1 | U7: 0 | V7: 0 | W7: 1 | X7: 0 | Y7: 0 | Z7: 1 | AA7: 0 | AB7: 1 | AC7: 1 | AD7: 1 | AE7: 1 | AF7: 0 | AG7: 1
A8: 000110 | B8: 0 | C8: 0 | D8: 0 | E8: 1 | F8: 1 | G8: 1 | H8: 1 | I8: 0 | J8: 1 | K8: 1 | L8: 1 | M8: 0 | N8: 0 | O8: 0 | P8: 1 | Q8: 1 | R8: 0 | S8: 0 | T8: 0 | U8: 1 | V8: 1 | W8: 1 | X8: 1 | Y8: 1 | Z8: 1 | AA8: 1 | AB8: 1 | AC8: 0 | AD8: 0 | AE8: 1 | AF8: 0 | AG8: 0
A9: 000111 | B9: 0 | C9: 1 | D9: 0 | E9: 0 | F9: 0 | G9: 1 | H9: 1 | I9: 1 | J9: 1 | K9: 0 | L9: 0 | M9: 1 | N9: 0 | O9: 1 | P9: 0 | Q9: 1 | R9: 1 | S9: 1 | T9: 0 | U9: 0 | V9: 0 | W9: 0 | X9: 1 | Y9: 0 | Z9: 0 | AA9: 1 | AB9: 1 | AC9: 1 | AD9: 1 | AE9: 0 | AF9: 0 | AG9: 0
A10: 001000 | B10: 0 | C10: 0 | D10: 1 | E10: 0 | F10: 0 | G10: 1 | H10: 1 | I10: 0 | J10: 0 | K10: 1 | L10: 1 | M10: 0 | N10: 0 | O10: 0 | P10: 0 | Q10: 0 | R10: 0 | S10: 1 | T10: 1 | U10: 1 | V10: 1 | W10: 0 | X10: 0 | Y10: 1 | Z10: 1 | AA10: 1 | AB10: 1 | AC10: 1 | AD10: 0 | AE10: 1 | AF10: 1 | AG10: 0
A11: 001001 | B11: 1 | C11: 1 | D11: 1 | E11: 0 | F11: 1 | G11: 1 | H11: 1 | I11: 1 | J11: 0 | K11: 0 | L11: 1 | M11: 1 | N11: 0 | O11: 1 | P11: 1 | Q11: 0 | R11: 0 | S11: 1 | T11: 0 | U11: 0 | V11: 0 | W11: 1 | X11: 1 | Y11: 1 | Z11: 0 | AA11: 1 | AB11: 0 | AC11: 0 | AD11: 1 | AE11: 0 | AF11: 1 | AG11: 0
A12: 001010 | B12: 1 | C12: 1 | D12: 1 | E12: 1 | F12: 1 | G12: 0 | H12: 1 | I12: 1 | J12: 0 | K12: 0 | L12: 1 | M12: 1 | N12: 0 | O12: 1 | P12: 1 | Q12: 0 | R12: 1 | S12: 0 | T12: 1 | U12: 0 | V12: 0 | W12: 0 | X12: 1 | Y12: 0 | Z12: 0 | AA12: 0 | AB12: 0 | AC12: 0 | AD12: 1 | AE12: 1 | AF12: 1 | AG12: 1
A13: 001011 | B13: 0 | C13: 0 | D13: 1 | E13: 0 | F13: 0 | G13: 0 | H13: 1 | I13: 0 | J13: 0 | K13: 1 | L13: 0 | M13: 0 | N13: 1 | O13: 1 | P13: 1 | Q13: 1 | R13: 0 | S13: 1 | T13: 1 | U13: 1 | V13: 1 | W13: 1 | X13: 0 | Y13: 0 | Z13: 1 | AA13: 0 | AB13: 0 | AC13: 1 | AD13: 0 | AE13: 0 | AF13: 1 | AG13: 1
... A65: 111111 | B65: 1 | C65: 1 | D65: 0 | E65: 1 | F65: 1 | G65: 0 | H65: 0 | I65: 1 | J65: 1 | K65: 1 | L65: 0 | M65: 0 | N65: 1 | O65: 1 | P65: 1 | Q65: 0 | R65: 0 | S65: 0 | T65: 1 | U65: 1 | V65: 1 | W65: 1 | X65: 0 | Y65: 1 | Z65: 1 | AA65: 1 | AB65: 0 | AC65: 0 | AD65: 1 | AE65: 0 | AF65: 1 | AG65: 1

Sheet Giải nén khóa K
A1: Khóa K | C1: 0133457799bbcdff
A2: Convert to bits | C2: =CONCATENATE(DEC2BIN(HEX2DEC(MID(C$1,1,2)),8), DEC2BIN(HEX2DEC(MID(C$1,3,2)),8), DEC2BIN(HEX2DEC(MID(C$1,5,2)),8), DEC2BIN(HEX2DEC(MID(C$1,7,2)),8), DEC2BIN(HEX2DEC(MID(C$1,9,2)),8), DEC2BIN(HEX2DEC(MID(C$1,11,2)),8), DEC2BIN(HEX2DEC(MID(C$1,13,2)),8), DEC2BIN(HEX2DEC(MID(C$1,15,2)),8)) -> 0000000100110011010001010111011110011001101110111100110111111111
A4: Initial permutation (PC-1) | D4: {=_xlfn.TEXTJOIN("",TRUE, MID(C$2, INDEX(Permutations!$E$2:$E$57, _xlfn.SEQUENCE(1,56)), 1))} -> 11110000110011001010101010111010101011001100111100001010
I5: Round 1 | J5: =CONCATENATE(RIGHT($B$7,28-Permutations!G2),LEFT($B$7,Permutations!G2)) -> 1110000110011001010101010111 | K5: =CONCATENATE(RIGHT($B$9,28-Permutations!G2),LEFT($B$9,Permutations!G2)) -> 0101010110011001111000010101 | L5: {=_xlfn.TEXTJOIN("",TRUE,INDEX(MID(CONCATENATE(J5,K5),_xlfn.SEQUENCE(1,56,1,1),1),Permutations!$F$2:$F$49))} -> 000110110000001011101111110110110100100110100101
I6: Round 2 | J6: =CONCATENATE(RIGHT($B$7,28-Permutations!G3),LEFT($B$7,Permutations!G3)) -> 1110000110011001010101010111 | K6: =CONCATENATE(RIGHT($B$9,28-Permutations!G3),LEFT($B$9,Permutations!G3)) -> 0101010110011001111000010101 | L6: {=_xlfn.TEXTJOIN("",TRUE,INDEX(MID(CONCATENATE(J6,K6),_xlfn.SEQUENCE(1,56,1,1),1),Permutations!$F$2:$F$49))} -> 000110110000001011101111110110110100100110100101
A7: C0 | B7: =LEFT(D4,28) -> 1111000011001100101010101011 | I7: Round 3 | J7: =CONCATENATE(RIGHT($B$7,28-Permutations!G4),LEFT($B$7,Permutations!G4)) -> 1100001100110010101010101111 | K7: =CONCATENATE(RIGHT($B$9,28-Permutations!G4),LEFT($B$9,Permutations!G4)) -> 1010101100110011110000101010 | L7: {=_xlfn.TEXTJOIN("",TRUE,INDEX(MID(CONCATENATE(J7,K7),_xlfn.SEQUENCE(1,56,1,1),1),Permutations!$F$2:$F$49))} -> 011010011010111011011001001001011110101001100110
I8: Round 4 | J8: =CONCATENATE(RIGHT($B$7,28-Permutations!G5),LEFT($B$7,Permutations!G5)) -> 1100001100110010101010101111 | K8: =CONCATENATE(RIGHT($B$9,28-Permutations!G5),LEFT($B$9,Permutations!G5)) -> 1010101100110011110000101010 | L8: {=_xlfn.TEXTJOIN("",TRUE,INDEX(MID(CONCATENATE(J8,K8),_xlfn.SEQUENCE(1,56,1,1),1),Permutations!$F$2:$F$49))} -> 011010011010111011011001001001011110101001100110
A9: D0 | B9: =RIGHT(D4,28) -> 1010101011001100111100001010 | I9: Round 5 | J9: =CONCATENATE(RIGHT($B$7,28-Permutations!G6),LEFT($B$7,Permutations!G6)) -> 1100001100110010101010101111 | K9: =CONCATENATE(RIGHT($B$9,28-Permutations!G6),LEFT($B$9,Permutations!G6)) -> 1010101100110011110000101010 | L9: {=_xlfn.TEXTJOIN("",TRUE,INDEX(MID(CONCATENATE(J9,K9),_xlfn.SEQUENCE(1,56,1,1),1),Permutations!$F$2:$F$49))} -> 011010011010111011011001001001011110101001100110
I10: Round 6 | J10: =CONCATENATE(RIGHT($B$7,28-Permutations!G7),LEFT($B$7,Permutations!G7)) -> 1100001100110010101010101111 | K10: =CONCATENATE(RIGHT($B$9,28-Permutations!G7),LEFT($B$9,Permutations!G7)) -> 1010101100110011110000101010 | L10: {=_xlfn.TEXTJOIN("",TRUE,INDEX(MID(CONCATENATE(J10,K10),_xlfn.SEQUENCE(1,56,1,1),1),Permutations!$F$2:$F$49))} -> 011010011010111011011001001001011110101001100110
I11: Round 7 | J11: =CONCATENATE(RIGHT($B$7,28-Permutations!G8),LEFT($B$7,Permutations!G8)) -> 1100001100110010101010101111 | K11: =CONCATENATE(RIGHT($B$9,28-Permutations!G8),LEFT($B$9,Permutations!G8)) -> 1010101100110011110000101010 | L11: {=_xlfn.TEXTJOIN("",TRUE,INDEX(MID(CONCATENATE(J11,K11),_xlfn.SEQUENCE(1,56,1,1),1),Permutations!$F$2:$F$49))} -> 011010011010111011011001001001011110101001100110
I12: Round 8 | J12: =CONCATENATE(RIGHT($B$7,28-Permutations!G9),LEFT($B$7,Permutations!G9)) -> 1100001100110010101010101111 | K12: =CONCATENATE(RIGHT($B$9,28-Permutations!G9),LEFT($B$9,Permutations!G9)) -> 1010101100110011110000101010 | L12: {=_xlfn.TEXTJOIN("",TRUE,INDEX(MID(CONCATENATE(J12,K12),_xlfn.SEQUENCE(1,56,1,1),1),Permutations!$F$2:$F$49))} -> 011010011010111011011001001001011110101001100110
I13: Round 9 | J13: =CONCATENATE(RIGHT($B$7,28-Permutations!G10),LEFT($B$7,Permutations!G10)) -> 1110000110011001010101010111 | K13: =CONCATENATE(RIGHT($B$9,28-Permutations!G10),LEFT($B$9,Permutations!G10)) -> 0101010110011001111000010101 | L13: {=_xlfn.TEXTJOIN("",TRUE,INDEX(MID(CONCATENATE(J13,K13),_xlfn.SEQUENCE(1,56,1,1),1),Permutations!$F$2:$F$49))} -> 000110110000001011101111110110110100100110100101
I14: Round 10 | J14: =CONCATENATE(RIGHT($B$7,28-Permutations!G11),LEFT($B$7,Permutations!G11)) -> 1100001100110010101010101111 | K14: =CONCATENATE(RIGHT($B$9,28-Permutations!G11),LEFT($B$9,Permutations!G11)) -> 1010101100110011110000101010 | L14: {=_xlfn.TEXTJOIN("",TRUE,INDEX(MID(CONCATENATE(J14,K14),_xlfn.SEQUENCE(1,56,1,1),1),Permutations!$F$2:$F$49))} -> 011010011010111011011001001001011110101001100110
I15: Round 11 | J15: =CONCATENATE(RIGHT($B$7,28-Permutations!G12),LEFT($B$7,Permutations!G12)) -> 1100001100110010101010101111 | K15: =CONCATENATE(RIGHT($B$9,28-Permutations!G12),LEFT($B$9,Permutations!G12)) -> 1010101100110011110000101010 | L15: {=_xlfn.TEXTJOIN("",TRUE,INDEX(MID(CONCATENATE(J15,K15),_xlfn.SEQUENCE(1,56,1,1),1),Permutations!$F$2:$F$49))} -> 011010011010111011011001001001011110101001100110
I16: Round 12 | J16: =CONCATENATE(RIGHT($B$7,28-Permutations!G13),LEFT($B$7,Permutations!G13)) -> 1100001100110010101010101111 | K16: =CONCATENATE(RIGHT($B$9,28-Permutations!G13),LEFT($B$9,Permutations!G13)) -> 1010101100110011110000101010 | L16: {=_xlfn.TEXTJOIN("",TRUE,INDEX(MID(CONCATENATE(J16,K16),_xlfn.SEQUENCE(1,56,1,1),1),Permutations!$F$2:$F$49))} -> 011010011010111011011001001001011110101001100110
I17: Round 13 | J17: =CONCATENATE(RIGHT($B$7,28-Permutations!G14),LEFT($B$7,Permutations!G14)) -> 1100001100110010101010101111 | K17: =CONCATENATE(RIGHT($B$9,28-Permutations!G14),LEFT($B$9,Permutations!G14)) -> 1010101100110011110000101010 | L17: {=_xlfn.TEXTJOIN("",TRUE,INDEX(MID(CONCATENATE(J17,K17),_xlfn.SEQUENCE(1,56,1,1),1),Permutations!$F$2:$F$49))} -> 011010011010111011011001001001011110101001100110
I18: Round 14 | J18: =CONCATENATE(RIGHT($B$7,28-Permutations!G15),LEFT($B$7,Permutations!G15)) -> 1100001100110010101010101111 | K18: =CONCATENATE(RIGHT($B$9,28-Permutations!G15),LEFT($B$9,Permutations!G15)) -> 1010101100110011110000101010 | L18: {=_xlfn.TEXTJOIN("",TRUE,INDEX(MID(CONCATENATE(J18,K18),_xlfn.SEQUENCE(1,56,1,1),1),Permutations!$F$2:$F$49))} -> 011010011010111011011001001001011110101001100110
I19: Round 15 | J19: =CONCATENATE(RIGHT($B$7,28-Permutations!G16),LEFT($B$7,Permutations!G16)) -> 1100001100110010101010101111 | K19: =CONCATENATE(RIGHT($B$9,28-Permutations!G16),LEFT($B$9,Permutations!G16)) -> 1010101100110011110000101010 | L19: {=_xlfn.TEXTJOIN("",TRUE,INDEX(MID(CONCATENATE(J19,K19),_xlfn.SEQUENCE(1,56,1,1),1),Permutations!$F$2:$F$49))} -> 011010011010111011011001001001011110101001100110
I20: Round 16 | J20: =CONCATENATE(RIGHT($B$7,28-Permutations!G17),LEFT($B$7,Permutations!G17)) -> 1110000110011001010101010111 | K20: =CONCATENATE(RIGHT($B$9,28-Permutations!G17),LEFT($B$9,Permutations!G17)) -> 0101010110011001111000010101 | L20: {=_xlfn.TEXTJOIN("",TRUE,INDEX(MID(CONCATENATE(J20,K20),_xlfn.SEQUENCE(1,56,1,1),1),Permutations!$F$2:$F$49))} -> 000110110000001011101111110110110100100110100101

Sheet Mã hóa M sang C
A1: Bản tin M | C1: 00123456789abcde
A2: Convert to bits | C2: =CONCATENATE(DEC2BIN(HEX2DEC(MID(C$1,1,2)),8), DEC2BIN(HEX2DEC(MID(C$1,3,2)),8), DEC2BIN(HEX2DEC(MID(C$1,5,2)),8), DEC2BIN(HEX2DEC(MID(C$1,7,2)),8), DEC2BIN(HEX2DEC(MID(C$1,9,2)),8), DEC2BIN(HEX2DEC(MID(C$1,11,2)),8), DEC2BIN(HEX2DEC(MID(C$1,13,2)),8), DEC2BIN(HEX2DEC(MID(C$1,15,2)),8)) -> 0000000000010010001101000101011001111000100110101011110011011110
J5: Round 1 | K5: {=_xlfn.TEXTJOIN("",TRUE,INDEX(MID($B$17,_xlfn.SEQUENCE(1,32,1,1),1),Permutations!$C$2:$C$49))} -> 011100000000001010101001011110100001010101010101 | L5: ='Giải nén khóa K'!L5 -> 000110110000001011101111110110110100100110100101 | M5: {=_xlfn.TEXTJOIN("",TRUE,IF(MID(K5,_xlfn.SEQUENCE(1,48,1,1),1)=MID(L5,_xlfn.SEQUENCE(1,48,1,1),1),"0","1"))} -> 011010110000000001000110101000010101110011110000 | N5: =LEFT(M5,6) -> 011010 | O5: =MID(M5,7,6) -> 110000 | P5: =MID(M5,13,6) -> 000001 | Q5: =MID(M5,19,6) -> 000110 | R5: =MID(M5,25,6) -> 101000 | S5: =MID(M5,31,6) -> 010101 | T5: =MID(M5,37,6) -> 110011 | U5: =MID(M5,43,6) -> 110000 | V5: =_xlfn.TEXTJOIN("", TRUE, INDEX('S-boxes'!$B$2:$E$65, MATCH(N5, 'S-boxes'!$A$2:$A$65, 0), 0)) -> 1001 | W5: =_xlfn.TEXTJOIN("", TRUE, INDEX('S-boxes'!$F$2:$I$65, MATCH(O5, 'S-boxes'!$A$2:$A$65, 0), 0)) -> 0101 | X5: =_xlfn.TEXTJOIN("", TRUE, INDEX('S-boxes'!$J$2:$M$65, MATCH(P5, 'S-boxes'!$A$2:$A$65, 0), 0)) -> 1101 | Y5: =_xlfn.TEXTJOIN("", TRUE, INDEX('S-boxes'!$N$2:$Q$65, MATCH(Q5, 'S-boxes'!$A$2:$A$65, 0), 0)) -> 0011 | Z5: =_xlfn.TEXTJOIN("", TRUE, INDEX('S-boxes'!$R$2:$U$65, MATCH(R5, 'S-boxes'!$A$2:$A$65, 0), 0)) -> 1010 | AA5: =_xlfn.TEXTJOIN("", TRUE, INDEX('S-boxes'!$V$2:$Y$65, MATCH(S5, 'S-boxes'!$A$2:$A$65, 0), 0)) -> 1101 | AB5: =_xlfn.TEXTJOIN("", TRUE, INDEX('S-boxes'!$Z$2:$AC$65, MATCH(T5, 'S-boxes'!$A$2:$A$65, 0), 0)) -> 0101 | AC5: =_xlfn.TEXTJOIN("", TRUE, INDEX('S-boxes'!$AD$2:$AG$65, MATCH(U5, 'S-boxes'!$A$2:$A$65, 0), 0)) -> 0000 | AD5: =V5&W5&X5&Y5&Z5&AA5&AB5&AC5 -> 10010101110100111010110101010000 | AE5: {=_xlfn.TEXTJOIN("",TRUE,INDEX(MID(AD5,_xlfn.SEQUENCE(1,32,1,1),1),Permutations!$D$2:$D$33))} -> 10010111110100010110000110011010 | AF5: {=_xlfn.TEXTJOIN("",TRUE,IF(MID($B$11,_xlfn.SEQUENCE(1,32,1,1),1)=MID(AE5,_xlfn.SEQUENCE(1,32,1,1),1),"0","1"))} -> 00001111001011111010110110011010 | AG5: =$B$17 -> 11100000010101001111000010101010
A6: Initial Permutation (IP) | C6: {=_xlfn.TEXTJOIN("",TRUE, MID(C$2, INDEX(Permutations!$A$2:$A$65, _xlfn.SEQUENCE(1,64)), 1))} -> 1001100011111110110011000000000011100000010101001111000010101010 | J6: Round 2 | K6: {=_xlfn.TEXTJOIN("",TRUE,INDEX(MID(AF5,_xlfn.SEQUENCE(1,32,1,1),1),Permutations!$C$2:$C$49))} -> 000001011110100101011111110101011011110011110100 | L6: ='Giải nén khóa K'!L6 -> 000110110000001011101111110110110100100110100101 | M6: {=_xlfn.TEXTJOIN("",TRUE,IF(MID(K6,_xlfn.SEQUENCE(1,48,1,1),1)=MID(L6,_xlfn.SEQUENCE(1,48,1,1),1),"0","1"))} -> 000111101110101110110000000011101111010101010001 | N6: =LEFT(M6,6) -> 000111 | O6: =MID(M6,7,6) -> 101110 | P6: =MID(M6,13,6) -> 101110 | Q6: =MID(M6,19,6) -> 110000 | R6: =MID(M6,25,6) -> 000011 | S6: =MID(M6,31,6) -> 101111 | T6: =MID(M6,37,6) -> 010101 | U6: =MID(M6,43,6) -> 010001 | V6: =_xlfn.TEXTJOIN("", TRUE, INDEX('S-boxes'!$B$2:$E$65, MATCH(N6, 'S-boxes'!$A$2:$A$65, 0), 0)) -> 0100 | W6: =_xlfn.TEXTJOIN("", TRUE, INDEX('S-boxes'!$F$2:$I$65, MATCH(O6, 'S-boxes'!$A$2:$A$65, 0), 0)) -> 0001 | X6: =_xlfn.TEXTJOIN("", TRUE, INDEX('S-boxes'!$J$2:$M$65, MATCH(P6, 'S-boxes'!$A$2:$A$65, 0), 0)) -> 0000 | Y6: =_xlfn.TEXTJOIN("", TRUE, INDEX('S-boxes'!$N$2:$Q$65, MATCH(Q6, 'S-boxes'!$A$2:$A$65, 0), 0)) -> 1111 | Z6: =_xlfn.TEXTJOIN("", TRUE, INDEX('S-boxes'!$R$2:$U$65, MATCH(R6, 'S-boxes'!$A$2:$A$65, 0), 0)) -> 1011 | AA6: =_xlfn.TEXTJOIN("", TRUE, INDEX('S-boxes'!$V$2:$Y$65, MATCH(S6, 'S-boxes'!$A$2:$A$65, 0), 0)) -> 1010 | AB6: =_xlfn.TEXTJOIN("", TRUE, INDEX('S-boxes'!$Z$2:$AC$65, MATCH(T6, 'S-boxes'!$A$2:$A$65, 0), 0)) -> 0101 | AC6: =_xlfn.TEXTJOIN("", TRUE, INDEX('S-boxes'!$AD$2:$AG$65, MATCH(U6, 'S-boxes'!$A$2:$A$65, 0), 0)) -> 1100 | AD6: =V6&W6&X6&Y6&Z6&AA6&AB6&AC6 -> 01000001000011111011101001011100 | AE6: {=_xlfn.TEXTJOIN("",TRUE,INDEX(MID(AD6,_xlfn.SEQUENCE(1,32,1,1),1),Permutations!$D$2:$D$33))} -> 10111011011100001101000011100000 | AF6: {=_xlfn.TEXTJOIN("",TRUE,IF(MID(AF5,_xlfn.SEQUENCE(1,32,1,1),1)=MID(AE6,_xlfn.SEQUENCE(1,32,1,1),1),"0","1"))} -> 10110100010111110111110101111010 | AG6: =AF5 -> 00001111001011111010110110011010
J7: Round 3 | K7: {=_xlfn.TEXTJOIN("",TRUE,INDEX(MID(AF6,_xlfn.SEQUENCE(1,32,1,1),1),Permutations!$C$2:$C$49))} -> 010110101000001011111110101111111010101111110101 | L7: ='Giải nén khóa K'!L7 -> 011010011010111011011001001001011110101001100110 | M7: {=_xlfn.TEXTJOIN("",TRUE,IF(MID(K7,_xlfn.SEQUENCE(1,48,1,1),1)=MID(L7,_xlfn.SEQUENCE(1,48,1,1),1),"0","1"))} -> 001100110010110000100111100110100100000110010011 | N7: =LEFT(M7,6) -> 001100 | O7: =MID(M7,7,6) -> 110010 | P7: =MID(M7,13,6) -> 110000 | Q7: =MID(M7,19,6) -> 100111 | R7: =MID(M7,25,6) -> 100110 | S7: =MID(M7,31,6) -> 100100 | T7: =MID(M7,37,6) -> 000110 | U7: =MID(M7,43,6) -> 010011 | V7: =_xlfn.TEXTJOIN("", TRUE, INDEX('S-boxes'!$B$2:$E$65, MATCH(N7, 'S-boxes'!$A$2:$A$65, 0), 0)) -> 1011 | W7: =_xlfn.TEXTJOIN("", TRUE, INDEX('S-boxes'!$F$2:$I$65, MATCH(O7, 'S-boxes'!$A$2:$A$65, 0), 0)) -> 1000 | X7: =_xlfn.TEXTJOIN("", TRUE, INDEX('S-boxes'!$J$2:$M$65, MATCH(P7, 'S-boxes'!$A$2:$A$65, 0), 0)) -> 1011 | Y7: =_xlfn.TEXTJOIN("", TRUE, INDEX('S-boxes'!$N$2:$Q$65, MATCH(Q7, 'S-boxes'!$A$2:$A$65, 0), 0)) -> 0110 | Z7: =_xlfn.TEXTJOIN("", TRUE, INDEX('S-boxes'!$R$2:$U$65, MATCH(R7, 'S-boxes'!$A$2:$A$65, 0), 0)) -> 1011 | AA7: =_xlfn.TEXTJOIN("", TRUE, INDEX('S-boxes'!$V$2:$Y$65, MATCH(S7, 'S-boxes'!$A$2:$A$65, 0), 0)) -> 1111 | AB7: =_xlfn.TEXTJOIN("", TRUE, INDEX('S-boxes'!$Z$2:$AC$65, MATCH(T7, 'S-boxes'!$A$2:$A$65, 0), 0)) -> 1110 | AC7: =_xlfn.TEXTJOIN("", TRUE, INDEX('S-boxes'!$AD$2:$AG$65, MATCH(U7, 'S-boxes'!$A$2:$A$65, 0), 0)) -> 0101 | AD7: =V7&W7&X7&Y7&Z7&AA7&AB7&AC7 -> 10111000101101101011111111100101 | AE7: {=_xlfn.TEXTJOIN("",TRUE,INDEX(MID(AD7,_xlfn.SEQUENCE(1,32,1,1),1),Permutations!$D$2:$D$33))} -> 00110101111110000011111110101111 | AF7: {=_xlfn.TEXTJOIN("",TRUE,IF(MID(AF6,_xlfn.SEQUENCE(1,32,1,1),1)=MID(AE7,_xlfn.SEQUENCE(1,32,1,1),1),"0","1"))} -> 10000001101001110100001011010101 | AG7: =AF6 -> 10110100010111110111110101111010
J8: Round 4 | K8: {=_xlfn.TEXTJOIN("",TRUE,INDEX(MID(AF7,_xlfn.SEQUENCE(1,32,1,1),1),Permutations!$C$2:$C$49))} -> 110000000011110100001110101000000101011010101011 | L8: ='Giải nén khóa K'!L8 -> 011010011010111011011001001001011110101001100110 | M8: {=_xlfn.TEXTJOIN("",TRUE,IF(MID(K8,_xlfn.SEQUENCE(1,48,1,1),1)=MID(L8,_xlfn.SEQUENCE(1,48,1,1),1),"0","1"))} -> 101010011001001111010111100001011011110011001101 | N8: =LEFT(M8,6) -> 101010 | O8: =MID(M8,7,6) -> 011001 | P8: =MID(M8,13,6) -> 001111 | Q8: =MID(M8,19,6) -> 010111 | R8: =MID(M8,25,6) -> 100001 | S8: =MID(M8,31,6) -> 011011 | T8: =MID(M8,37,6) -> 110011 | U8: =MID(M8,43,6) -> 001101 | V8: =_xlfn.TEXTJOIN("", TRUE, INDEX('S-boxes'!$B$2:$E$65, MATCH(N8, 'S-boxes'!$A$2:$A$65, 0), 0)) -> 0110 | W8: =_xlfn.TEXTJOIN("", TRUE, INDEX('S-boxes'!$F$2:$I$65, MATCH(O8, 'S-boxes'!$A$2:$A$65, 0), 0)) -> 0110 | X8: =_xlfn.TEXTJOIN("", TRUE, INDEX('S-boxes'!$J$2:$M$65, MATCH(P8, 'S-boxes'!$A$2:$A$65, 0), 0)) -> 1010 | Y8: =_xlfn.TEXTJOIN("", TRUE, INDEX('S-boxes'!$N$2:$Q$65, MATCH(Q8, 'S-boxes'!$A$2:$A$65, 0), 0)) -> 1100 | Z8: =_xlfn.TEXTJOIN("", TRUE, INDEX('S-boxes'!$R$2:$U$65, MATCH(R8, 'S-boxes'!$A$2:$A$65, 0), 0)) -> 1011 | AA8: =_xlfn.TEXTJOIN("", TRUE, INDEX('S-boxes'!$V$2:$Y$65, MATCH(S8, 'S-boxes'!$A$2:$A$65, 0), 0)) -> 1011 | AB8: =_xlfn.TEXTJOIN("", TRUE, INDEX('S-boxes'!$Z$2:$AC$65, MATCH(T8, 'S-boxes'!$A$2:$A$65, 0), 0)) -> 0101 | AC8: =_xlfn.TEXTJOIN("", TRUE, INDEX('S-boxes'!$AD$2:$AG$65, MATCH(U8, 'S-boxes'!$A$2:$A$65, 0), 0)) -> 0111 | AD8: =V8&W8&X8&Y8&Z8&AA8&AB8&AC8 -> 01100110101011001011101101010111 | AE8: {=_xlfn.TEXTJOIN("",TRUE,INDEX(MID(AD8,_xlfn.SEQUENCE(1,32,1,1),1),Permutations!$D$2:$D$33))} -> 01110011001100101011101111110100 | AF8: {=_xlfn.TEXTJOIN("",TRUE,IF(MID(AF7,_xlfn.SEQUENCE(1,32,1,1),1)=MID(AE8,_xlfn.SEQUENCE(1,32,1,1),1),"0","1"))} -> 11110010100101011111100100100001 | AG8: =AF7 -> 10000001101001110100001011010101
J9: Round 5 | K9: {=_xlfn.TEXTJOIN("",TRUE,INDEX(MID(AF8,_xlfn.SEQUENCE(1,32,1,1),1),Permutations!$C$2:$C$49))} -> 111110100101010010101011111111110010100100000011 | L9: ='Giải nén khóa K'!L9 -> 011010011010111011011001001001011110101001100110 | M9: {=_xlfn.TEXTJOIN("",TRUE,IF(MID(K9,_xlfn.SEQUENCE(1,48,1,1),1)=MID(L9,_xlfn.SEQUENCE(1,48,1,1),1),"0","1"))} -> 100100111111101001110010110110101100001101100101 | N9: =LEFT(M9,6) -> 100100 | O9: =MID(M9,7,6) -> 111111 | P9: =MID(M9,13,6) -> 101001 | Q9: =MID(M9,19,6) -> 110010 | R9: =MID(M9,25,6) -> 110110 | S9: =MID(M9,31,6) -> 101100 | T9: =MID(M9,37,6) -> 001101 | U9: =MID(M9,43,6) -> 100101 | V9: =_xlfn.TEXTJOIN("", TRUE, INDEX('S-boxes'!$B$2:$E$65, MATCH(N9, 'S-boxes'!$A$2:$A$65, 0), 0)) -> 1110 | W9: =_xlfn.TEXTJOIN("", TRUE, INDEX('S-boxes'!$F$2:$I$65, MATCH(O9, 'S-boxes'!$A$2:$A$65, 0), 0)) -> 1001 | X9: =_xlfn.TEXTJOIN("", TRUE, INDEX('S-boxes'!$J$2:$M$65, MATCH(P9, 'S-boxes'!$A$2:$A$65, 0), 0)) -> 0110 | Y9: =_xlfn.TEXTJOIN("", TRUE, INDEX('S-boxes'!$N$2:$Q$65, MATCH(Q9, 'S-boxes'!$A$2:$A$65, 0), 0)) -> 0001 | Z9: =_xlfn.TEXTJOIN("", TRUE, INDEX('S-boxes'!$R$2:$U$65, MATCH(R9, 'S-boxes'!$A$2:$A$65, 0), 0)) -> 0101 | AA9: =_xlfn.TEXTJOIN("", TRUE, INDEX('S-boxes'!$V$2:$Y$65, MATCH(S9, 'S-boxes'!$A$2:$A$65, 0), 0)) -> 1100 | AB9: =_xlfn.TEXTJOIN("", TRUE, INDEX('S-boxes'!$Z$2:$AC$65, MATCH(T9, 'S-boxes'!$A$2:$A$65, 0), 0)) -> 0001 | AC9: =_xlfn.TEXTJOIN("", TRUE, INDEX('S-boxes'!$AD$2:$AG$65, MATCH(U9, 'S-boxes'!$A$2:$A$65, 0), 0)) -> 1110 | AD9: =V9&W9&X9&Y9&Z9&AA9&AB9&AC9 -> 11101001011000010101110000011110 | AE9: {=_xlfn.TEXTJOIN("",TRUE,INDEX(MID(AD9,_xlfn.SEQUENCE(1,32,1,1),1),Permutations!$D$2:$D$33))} -> 10111010100011111100001000101100 | AF9: {=_xlfn.TEXTJOIN("",TRUE,IF(MID(AF8,_xlfn.SEQUENCE(1,32,1,1),1)=MID(AE9,_xlfn.SEQUENCE(1,32,1,1),1),"0","1"))} -> 01001000000110100011101100001101 | AG9: =AF8 -> 11110010100101011111100100100001
J10: Round 6 | K10: {=_xlfn.TEXTJOIN("",TRUE,INDEX(MID(AF9,_xlfn.SEQUENCE(1,32,1,1),1),Permutations!$C$2:$C$49))} -> 101001010000000011110100000111110110100001011010 | L10: ='Giải nén khóa K'!L10 -> 011010011010111011011001001001011110101001100110 | M10: {=_xlfn.TEXTJOIN("",TRUE,IF(MID(K10,_xlfn.SEQUENCE(1,48,1,1),1)=MID(L10,_xlfn.SEQUENCE(1,48,1,1),1),"0","1"))} -> 110011001010111000101101001110101000001000111100 | N10: =LEFT(M10,6) -> 110011 | O10: =MID(M10,7,6) -> 001010 | P10: =MID(M10,13,6) -> 111000 | Q10: =MID(M10,19,6) -> 101101 | R10: =MID(M10,25,6) -> 001110 | S10: =MID(M10,31,6) -> 101000 | T10: =MID(M10,37,6) -> 001000 | U10: =MID(M10,43,6) -> 111100 | V10: =_xlfn.TEXTJOIN("", TRUE, INDEX('S-boxes'!$B$2:$E$65, MATCH(N10, 'S-boxes'!$A$2:$A$65, 0), 0)) -> 1011 | W10: =_xlfn.TEXTJOIN("", TRUE, INDEX('S-boxes'!$F$2:$I$65, MATCH(O10, 'S-boxes'!$A$2:$A$65, 0), 0)) -> 1011 | X10: =_xlfn.TEXTJOIN("", TRUE, INDEX('S-boxes'!$J$2:$M$65, MATCH(P10, 'S-boxes'!$A$2:$A$65, 0), 0)) -> 0101 | Y10: =_xlfn.TEXTJOIN("", TRUE, INDEX('S-boxes'!$N$2:$Q$65, MATCH(Q10, 'S-boxes'!$A$2:$A$65, 0), 0)) -> 1101 | Z10: =_xlfn.TEXTJOIN("", TRUE, INDEX('S-boxes'!$R$2:$U$65, MATCH(R10, 'S-boxes'!$A$2:$A$65, 0), 0)) -> 0110 | AA10: =_xlfn.TEXTJOIN("", TRUE, INDEX('S-boxes'!$V$2:$Y$65, MATCH(S10, 'S-boxes'!$A$2:$A$65, 0), 0)) -> 0010 | AB10: =_xlfn.TEXTJOIN("", TRUE, INDEX('S-boxes'!$Z$2:$AC$65, MATCH(T10, 'S-boxes'!$A$2:$A$65, 0), 0)) -> 1111 | AC10: =_xlfn.TEXTJOIN("", TRUE, INDEX('S-boxes'!$AD$2:$AG$65, MATCH(U10, 'S-boxes'!$A$2:$A$65, 0), 0)) -> 0101 | AD10: =V10&W10&X10&Y10&Z10&AA10&AB10&AC10 -> 10111011010111010110001011110101 | AE10: {=_xlfn.TEXTJOIN("",TRUE,INDEX(MID(AD10,_xlfn.SEQUENCE(1,32,1,1),1),Permutations!$D$2:$D$33))} -> 11000110101111010101111011100011 | AF10: {=_xlfn.TEXTJOIN("",TRUE,IF(MID(AF9,_xlfn.SEQUENCE(1,32,1,1),1)=MID(AE10,_xlfn.SEQUENCE(1,32,1,1),1),"0","1"))} -> 10001110101001110110010111101110 | AG10: =AF9 -> 01001000000110100011101100001101
A11: L0 | B11: =LEFT(C6,32) -> 10011000111111101100110000000000 | J11: Round 7 | K11: {=_xlfn.TEXTJOIN("",TRUE,INDEX(MID(AF10,_xlfn.SEQUENCE(1,32,1,1),1),Permutations!$C$2:$C$49))} -> 010001011101010100001110101100001011111101011101 | L11: ='Giải nén khóa K'!L11 -> 011010011010111011011001001001011110101001100110 | M11: {=_xlfn.TEXTJOIN("",TRUE,IF(MID(K11,_xlfn.SEQUENCE(1,48,1,1),1)=MID(L11,_xlfn.SEQUENCE(1,48,1,1),1),"0","1"))} -> 001011000111101111010111100101010101010100111011 | N11: =LEFT(M11,6) -> 001011 | O11: =MID(M11,7,6) -> 000111 | P11: =MID(M11,13,6) -> 101111 | Q11: =MID(M11,19,6) -> 010111 | R11: =MID(M11,25,6) -> 100101 | S11: =MID(M11,31,6) -> 010101 | T11: =MID(M11,37,6) -> 010100 | U11: =MID(M11,43,6) -> 111011 | V11: =_xlfn.TEXTJOIN("", TRUE, INDEX('S-boxes'!$B$2:$E$65, MATCH(N11, 'S-boxes'!$A$2:$A$65, 0), 0)) -> 0010 | W11: =_xlfn.TEXTJOIN("", TRUE, INDEX('S-boxes'!$F$2:$I$65, MATCH(O11, 'S-boxes'!$A$2:$A$65, 0), 0)) -> 0111 | X11: =_xlfn.TEXTJOIN("", TRUE, INDEX('S-boxes'!$J$2:$M$65, MATCH(P11, 'S-boxes'!$A$2:$A$65, 0), 0)) -> 0111 | Y11: =_xlfn.TEXTJOIN("", TRUE, INDEX('S-boxes'!$N$2:$Q$65, MATCH(Q11, 'S-boxes'!$A$2:$A$65, 0), 0)) -> 1100 | Z11: =_xlfn.TEXTJOIN("", TRUE, INDEX('S-boxes'!$R$2:$U$65, MATCH(R11, 'S-boxes'!$A$2:$A$65, 0), 0)) -> 1100 | AA11: =_xlfn.TEXTJOIN("", TRUE, INDEX('S-boxes'!$V$2:$Y$65, MATCH(S11, 'S-boxes'!$A$2:$A$65, 0), 0)) -> 1101 | AB11: =_xlfn.TEXTJOIN("", TRUE, INDEX('S-boxes'!$Z$2:$AC$65, MATCH(T11, 'S-boxes'!$A$2:$A$65, 0), 0)) -> 1001 | AC11: =_xlfn.TEXTJOIN("", TRUE, INDEX('S-boxes'!$AD$2:$AG$65, MATCH(U11, 'S-boxes'!$A$2:$A$65, 0), 0)) -> 0101 | AD11: =V11&W11&X11&Y11&Z11&AA11&AB11&AC11 -> 00100111011111001100110110010101 | AE11: {=_xlfn.TEXTJOIN("",TRUE,INDEX(MID(AD11,_xlfn.SEQUENCE(1,32,1,1),1),Permutations!$D$2:$D$33))} -> 01010111000001010111101001111101 | AF11: {=_xlfn.TEXTJOIN("",TRUE,IF(MID(AF10,_xlfn.SEQUENCE(1,32,1,1),1)=MID(AE11,_xlfn.SEQUENCE(1,32,1,1),1),"0","1"))} -> 11011001101000100001111110010011 | AG11: =AF10 -> 10001110101001110110010111101110
J12: Round 8 | K12: {=_xlfn.TEXTJOIN("",TRUE,INDEX(MID(AF11,_xlfn.SEQUENCE(1,32,1,1),1),Permutations!$C$2:$C$49))} -> 111011110011110100000100000011111111110010100111 | L12: ='Giải nén khóa K'!L12 -> 011010011010111011011001001001011110101001100110 | M12: {=_xlfn.TEXTJOIN("",TRUE,IF(MID(K12,_xlfn.SEQUENCE(1,48,1,1),1)=MID(L12,_xlfn.SEQUENCE(1,48,1,1),1),"0","1"))} -> 100001101001001111011101001010100001011011000001 | N12: =LEFT(M12,6) -> 100001 | O12: =MID(M12,7,6) -> 101001 | P12: =MID(M12,13,6) -> 001111 | Q12: =MID(M12,19,6) -> 011101 | R12: =MID(M12,25,6) -> 001010 | S12: =MID(M12,31,6) -> 100001 | T12: =MID(M12,37,6) -> 011011 | U12: =MID(M12,43,6) -> 000001 | V12: =_xlfn.TEXTJOIN("", TRUE, INDEX('S-boxes'!$B$2:$E$65, MATCH(N12, 'S-boxes'!$A$2:$A$65, 0), 0)) -> 1111 | W12: =_xlfn.TEXTJOIN("", TRUE, INDEX('S-boxes'!$F$2:$I$65, MATCH(O12, 'S-boxes'!$A$2:$A$65, 0), 0)) -> 0011 | X12: =_xlfn.TEXTJOIN("", TRUE, INDEX('S-boxes'!$J$2:$M$65, MATCH(P12, 'S-boxes'!$A$2:$A$65, 0), 0)) -> 1010 | Y12: =_xlfn.TEXTJOIN("", TRUE, INDEX('S-boxes'!$N$2:$Q$65, MATCH(Q12, 'S-boxes'!$A$2:$A$65, 0), 0)) -> 1110 | Z12: =_xlfn.TEXTJOIN("", TRUE, INDEX('S-boxes'!$R$2:$U$65, MATCH(R12, 'S-boxes'!$A$2:$A$65, 0), 0)) -> 1010 | AA12: =_xlfn.TEXTJOIN("", TRUE, INDEX('S-boxes'!$V$2:$Y$65, MATCH(S12, 'S-boxes'!$A$2:$A$65, 0), 0)) -> 0100 | AB12: =_xlfn.TEXTJOIN("", TRUE, INDEX('S-boxes'!$Z$2:$AC$65, MATCH(T12, 'S-boxes'!$A$2:$A$65, 0), 0)) -> 1111 | AC12: =_xlfn.TEXTJOIN("", TRUE, INDEX('S-boxes'!$AD$2:$AG$65, MATCH(U12, 'S-boxes'!$A$2:$A$65, 0), 0)) -> 0001 | AD12: =V12&W12&X12&Y12&Z12&AA12&AB12&AC12 -> 11110011101011101010010011110001 | AE12: {=_xlfn.TEXTJOIN("",TRUE,INDEX(MID(AD12,_xlfn.SEQUENCE(1,32,1,1),1),Permutations!$D$2:$D$33))} -> 01000011110100001101111111001111 | AF12: {=_xlfn.TEXTJOIN("",TRUE,IF(MID(AF11,_xlfn.SEQUENCE(1,32,1,1),1)=MID(AE12,_xlfn.SEQUENCE(1,32,1,1),1),"0","1"))} -> 10011010011100101100000001011100 | AG12: =AF11 -> 11011001101000100001111110010011
J13: Round 9 | K13: {=_xlfn.TEXTJOIN("",TRUE,INDEX(MID(AF12,_xlfn.SEQUENCE(1,32,1,1),1),Permutations!$C$2:$C$49))} -> 010011110100001110100101011000000000001011111001 | L13: ='Giải nén khóa K'!L13 -> 000110110000001011101111110110110100100110100101 | M13: {=_xlfn.TEXTJOIN("",TRUE,IF(MID(K13,_xlfn.SEQUENCE(1,48,1,1),1)=MID(L13,_xlfn.SEQUENCE(1,48,1,1),1),"0","1"))} -> 010101000100000101001010101110110100101101011100 | N13: =LEFT(M13,6) -> 010101 | O13: =MID(M13,7,6) -> 000100 | P13: =MID(M13,13,6) -> 000101 | Q13: =MID(M13,19,6) -> 001010 | R13: =MID(M13,25,6) -> 101110 | S13: =MID(M13,31,6) -> 110100 | T13: =MID(M13,37,6) -> 101101 | U13: =MID(M13,43,6) -> 011100 | V13: =_xlfn.TEXTJOIN("", TRUE, INDEX('S-boxes'!$B$2:$E$65, MATCH(N13, 'S-boxes'!$A$2:$A$65, 0), 0)) -> 1100 | W13: =_xlfn.TEXTJOIN("", TRUE, INDEX('S-boxes'!$F$2:$I$65, MATCH(O13, 'S-boxes'!$A$2:$A$65, 0), 0)) -> 1000 | X13: =_xlfn.TEXTJOIN("", TRUE, INDEX('S-boxes'!$J$2:$M$65, MATCH(P13, 'S-boxes'!$A$2:$A$65, 0), 0)) -> 0000 | Y13: =_xlfn.TEXTJOIN("", TRUE, INDEX('S-boxes'!$N$2:$Q$65, MATCH(Q13, 'S-boxes'!$A$2:$A$65, 0), 0)) -> 0110 | Z13: =_xlfn.TEXTJOIN("", TRUE, INDEX('S-boxes'!$R$2:$U$65, MATCH(R13, 'S-boxes'!$A$2:$A$65, 0), 0)) -> 1000 | AA13: =_xlfn.TEXTJOIN("", TRUE, INDEX('S-boxes'!$V$2:$Y$65, MATCH(S13, 'S-boxes'!$A$2:$A$65, 0), 0)) -> 0100 | AB13: =_xlfn.TEXTJOIN("", TRUE, INDEX('S-boxes'!$Z$2:$AC$65, MATCH(T13, 'S-boxes'!$A$2:$A$65, 0), 0)) -> 1010 | AC13: =_xlfn.TEXTJOIN("", TRUE, INDEX('S-boxes'!$AD$2:$AG$65, MATCH(U13, 'S-boxes'!$A$2:$A$65, 0), 0)) -> 1100 | AD13: =V13&W13&X13&Y13&Z13&AA13&AB13&AC13 -> 11001000000001101000010010101100 | AE13: {=_xlfn.TEXTJOIN("",TRUE,INDEX(MID(AD13,_xlfn.SEQUENCE(1,32,1,1),1),Permutations!$D$2:$D$33))} -> 00001001110010001001010000101001 | AF13: {=_xlfn.TEXTJOIN("",TRUE,IF(MID(AF12,_xlfn.SEQUENCE(1,32,1,1),1)=MID(AE13,_xlfn.SEQUENCE(1,32,1,1),1),"0","1"))} -> 10010011101110100101010001110101 | AG13: =AF12 -> 10011010011100101100000001011100
J14: Round 10 | K14: {=_xlfn.TEXTJOIN("",TRUE,INDEX(MID(AF13,_xlfn.SEQUENCE(1,32,1,1),1),Permutations!$C$2:$C$49))} -> 110010100111110111110100001010101000001110101011 | L14: ='Giải nén khóa K'!L14 -> 011010011010111011011001001001011110101001100110 | M14: {=_xlfn.TEXTJOIN("",TRUE,IF(MID(K14,_xlfn.SEQUENCE(1,48,1,1),1)=MID(L14,_xlfn.SEQUENCE(1,48,1,1),1),"0","1"))} -> 101000111101001100101101000011110110100111001101 | N14: =LEFT(M14,6) -> 101000 | O14: =MID(M14,7,6) -> 111101 | P14: =MID(M14,13,6) -> 001100 | Q14: =MID(M14,19,6) -> 101101 | R14: =MID(M14,25,6) -> 000011 | S14: =MID(M14,31,6) -> 110110 | T14: =MID(M14,37,6) -> 100111 | U14: =MID(M14,43,6) -> 001101 | V14: =_xlfn.TEXTJOIN("", TRUE, INDEX('S-boxes'!$B$2:$E$65, MATCH(N14, 'S-boxes'!$A$2:$A$65, 0), 0)) -> 1101 | W14: =_xlfn.TEXTJOIN("", TRUE, INDEX('S-boxes'!$F$2:$I$65, MATCH(O14, 'S-boxes'!$A$2:$A$65, 0), 0)) -> 1110 | X14: =_xlfn.TEXTJOIN("", TRUE, INDEX('S-boxes'!$J$2:$M$65, MATCH(P14, 'S-boxes'!$A$2:$A$65, 0), 0)) -> 1111 | Y14: =_xlfn.TEXTJOIN("", TRUE, INDEX('S-boxes'!$N$2:$Q$65, MATCH(Q14, 'S-boxes'!$A$2:$A$65, 0), 0)) -> 1101 | Z14: =_xlfn.TEXTJOIN("", TRUE, INDEX('S-boxes'!$R$2:$U$65, MATCH(R14, 'S-boxes'!$A$2:$A$65, 0), 0)) -> 1011 | AA14: =_xlfn.TEXTJOIN("", TRUE, INDEX('S-boxes'!$V$2:$Y$65, MATCH(S14, 'S-boxes'!$A$2:$A$65, 0), 0)) -> 1010 | AB14: =_xlfn.TEXTJOIN("", TRUE, INDEX('S-boxes'!$Z$2:$AC$65, MATCH(T14, 'S-boxes'!$A$2:$A$65, 0), 0)) -> 1000 | AC14: =_xlfn.TEXTJOIN("", TRUE, INDEX('S-boxes'!$AD$2:$AG$65, MATCH(U14, 'S-boxes'!$A$2:$A$65, 0), 0)) -> 0111 | AD14: =V14&W14&X14&Y14&Z14&AA14&AB14&AC14 -> 11011110111111011011101010000111 | AE14: {=_xlfn.TEXTJOIN("",TRUE,INDEX(MID(AD14,_xlfn.SEQUENCE(1,32,1,1),1),Permutations!$D$2:$D$33))} -> 11110101101010111001100111110111 | AF14: {=_xlfn.TEXTJOIN("",TRUE,IF(MID(AF13,_xlfn.SEQUENCE(1,32,1,1),1)=MID(AE14,_xlfn.SEQUENCE(1,32,1,1),1),"0","1"))} -> 01100110000100011100110110000010 | AG14: =AF13 -> 10010011101110100101010001110101
J15: Round 11 | K15: {=_xlfn.TEXTJOIN("",TRUE,INDEX(MID(AF14,_xlfn.SEQUENCE(1,32,1,1),1),Permutations!$C$2:$C$49))} -> 001100001100000010100011111001011011110000000100 | L15: ='Giải nén khóa K'!L15 -> 011010011010111011011001001001011110101001100110 | M15: {=_xlfn.TEXTJOIN("",TRUE,IF(MID(K15,_xlfn.SEQUENCE(1,48,1,1),1)=MID(L15,_xlfn.SEQUENCE(1,48,1,1),1),"0","1"))} -> 010110010110111001111010110000000101011001100010 | N15: =LEFT(M15,6) -> 010110 | O15: =MID(M15,7,6) -> 010110 | P15: =MID(M15,13,6) -> 111001 | Q15: =MID(M15,19,6) -> 111010 | R15: =MID(M15,25,6) -> 110000 | S15: =MID(M15,31,6) -> 000101 | T15: =MID(M15,37,6) -> 011001 | U15: =MID(M15,43,6) -> 100010 | V15: =_xlfn.TEXTJOIN("", TRUE, INDEX('S-boxes'!$B$2:$E$65, MATCH(N15, 'S-boxes'!$A$2:$A$65, 0), 0)) -> 1100 | W15: =_xlfn.TEXTJOIN("", TRUE, INDEX('S-boxes'!$F$2:$I$65, MATCH(O15, 'S-boxes'!$A$2:$A$65, 0), 0)) -> 1101 | X15: =_xlfn.TEXTJOIN("", TRUE, INDEX('S-boxes'!$J$2:$M$65, MATCH(P15, 'S-boxes'!$A$2:$A$65, 0), 0)) -> 1011 | Y15: =_xlfn.TEXTJOIN("", TRUE, INDEX('S-boxes'!$N$2:$Q$65, MATCH(Q15, 'S-boxes'!$A$2:$A$65, 0), 0)) -> 0010 | Z15: =_xlfn.TEXTJOIN("", TRUE, INDEX('S-boxes'!$R$2:$U$65, MATCH(R15, 'S-boxes'!$A$2:$A$65, 0), 0)) -> 1111 | AA15: =_xlfn.TEXTJOIN("", TRUE, INDEX('S-boxes'!$V$2:$Y$65, MATCH(S15, 'S-boxes'!$A$2:$A$65, 0), 0)) -> 0100 | AB15: =_xlfn.TEXTJOIN("", TRUE, INDEX('S-boxes'!$Z$2:$AC$65, MATCH(T15, 'S-boxes'!$A$2:$A$65, 0), 0)) -> 0010 | AC15: =_xlfn.TEXTJOIN("", TRUE, INDEX('S-boxes'!$AD$2:$AG$65, MATCH(U15, 'S-boxes'!$A$2:$A$65, 0), 0)) -> 1011 | AD15: =V15&W15&X15&Y15&Z15&AA15&AB15&AC15 -> 11001101101100101111010000101011 | AE15: {=_xlfn.TEXTJOIN("",TRUE,INDEX(MID(AD15,_xlfn.SEQUENCE(1,32,1,1),1),Permutations!$D$2:$D$33))} -> 00101101110011101100110110011100 | AF15: {=_xlfn.TEXTJOIN("",TRUE,IF(MID(AF14,_xlfn.SEQUENCE(1,32,1,1),1)=MID(AE15,_xlfn.SEQUENCE(1,32,1,1),1),"0","1"))} -> 01001011110111110000000000011110 | AG15: =AF14 -> 01100110000100011100110110000010
J16: Round 12 | K16: {=_xlfn.TEXTJOIN("",TRUE,INDEX(MID(AF15,_xlfn.SEQUENCE(1,32,1,1),1),Permutations!$C$2:$C$49))} -> 001001010111111011111110100000000000000011111100 | L16: ='Giải nén khóa K'!L16 -> 011010011010111011011001001001011110101001100110 | M16: {=_xlfn.TEXTJOIN("",TRUE,IF(MID(K16,_xlfn.SEQUENCE(1,48,1,1),1)=MID(L16,_xlfn.SEQUENCE(1,48,1,1),1),"0","1"))} -> 010011001101000000100111101001011110101010011010 | N16: =LEFT(M16,6) -> 010011 | O16: =MID(M16,7,6) -> 001101 | P16: =MID(M16,13,6) -> 000000 | Q16: =MID(M16,19,6) -> 100111 | R16: =MID(M16,25,6) -> 101001 | S16: =MID(M16,31,6) -> 011110 | T16: =MID(M16,37,6) -> 101010 | U16: =MID(M16,43,6) -> 011010 | V16: =_xlfn.TEXTJOIN("", TRUE, INDEX('S-boxes'!$B$2:$E$65, MATCH(N16, 'S-boxes'!$A$2:$A$65, 0), 0)) -> 0110 | W16: =_xlfn.TEXTJOIN("", TRUE, INDEX('S-boxes'!$F$2:$I$65, MATCH(O16, 'S-boxes'!$A$2:$A$65, 0), 0)) -> 1000 | X16: =_xlfn.TEXTJOIN("", TRUE, INDEX('S-boxes'!$J$2:$M$65, MATCH(P16, 'S-boxes'!$A$2:$A$65, 0), 0)) -> 1010 | Y16: =_xlfn.TEXTJOIN("", TRUE, INDEX('S-boxes'!$N$2:$Q$65, MATCH(Q16, 'S-boxes'!$A$2:$A$65, 0), 0)) -> 0110 | Z16: =_xlfn.TEXTJOIN("", TRUE, INDEX('S-boxes'!$R$2:$U$65, MATCH(R16, 'S-boxes'!$A$2:$A$65, 0), 0)) -> 0001 | AA16: =_xlfn.TEXTJOIN("", TRUE, INDEX('S-boxes'!$V$2:$Y$65, MATCH(S16, 'S-boxes'!$A$2:$A$65, 0), 0)) -> 1011 | AB16: =_xlfn.TEXTJOIN("", TRUE, INDEX('S-boxes'!$Z$2:$AC$65, MATCH(T16, 'S-boxes'!$A$2:$A$65, 0), 0)) -> 0011 | AC16: =_xlfn.TEXTJOIN("", TRUE, INDEX('S-boxes'!$AD$2:$AG$65, MATCH(U16, 'S-boxes'!$A$2:$A$65, 0), 0)) -> 0000 | AD16: =V16&W16&X16&Y16&Z16&AA16&AB16&AC16 -> 01101000101001100001101100110000 | AE16: {=_xlfn.TEXTJOIN("",TRUE,INDEX(MID(AD16,_xlfn.SEQUENCE(1,32,1,1),1),Permutations!$D$2:$D$33))} -> 00110010011010001011011100000100 | AF16: {=_xlfn.TEXTJOIN("",TRUE,IF(MID(AF15,_xlfn.SEQUENCE(1,32,1,1),1)=MID(AE16,_xlfn.SEQUENCE(1,32,1,1),1),"0","1"))} -> 01111001101101111011011100011010 | AG16: =AF15 -> 01001011110111110000000000011110
A17: R0 | B17: =RIGHT(C6,32) -> 11100000010101001111000010101010 | J17: Round 13 | K17: {=_xlfn.TEXTJOIN("",TRUE,INDEX(MID(AF16,_xlfn.SEQUENCE(1,32,1,1),1),Permutations!$C$2:$C$49))} -> 001111110011110110101111110110101110100011110100 | L17: ='Giải nén khóa K'!L17 -> 011010011010111011011001001001011110101001100110 | M17: {=_xlfn.TEXTJOIN("",TRUE,IF(MID(K17,_xlfn.SEQUENCE(1,48,1,1),1)=MID(L17,_xlfn.SEQUENCE(1,48,1,1),1),"0","1"))} -> 010101101001001101110110111111110000001010010010 | N17: =LEFT(M17,6) -> 010101 | O17: =MID(M17,7,6) -> 101001 | P17: =MID(M17,13,6) -> 001101 | Q17: =MID(M17,19,6) -> 110110 | R17: =MID(M17,25,6) -> 111111 | S17: =MID(M17,31,6) -> 110000 | T17: =MID(M17,37,6) -> 001010 | U17: =MID(M17,43,6) -> 010010 | V17: =_xlfn.TEXTJOIN("", TRUE, INDEX('S-boxes'!$B$2:$E$65, MATCH(N17, 'S-boxes'!$A$2:$A$65, 0), 0)) -> 1100 | W17: =_xlfn.TEXTJOIN("", TRUE, INDEX('S-boxes'!$F$2:$I$65, MATCH(O17, 'S-boxes'!$A$2:$A$65, 0), 0)) -> 0011 | X17: =_xlfn.TEXTJOIN("", TRUE, INDEX('S-boxes'!$J$2:$M$65, MATCH(P17, 'S-boxes'!$A$2:$A$65, 0), 0)) -> 0110 | Y17: =_xlfn.TEXTJOIN("", TRUE, INDEX('S-boxes'!$N$2:$Q$65, MATCH(Q17, 'S-boxes'!$A$2:$A$65, 0), 0)) -> 1110 | Z17: =_xlfn.TEXTJOIN("", TRUE, INDEX('S-boxes'!$R$2:$U$65, MATCH(R17, 'S-boxes'!$A$2:$A$65, 0), 0)) -> 0011 | AA17: =_xlfn.TEXTJOIN("", TRUE, INDEX('S-boxes'!$V$2:$Y$65, MATCH(S17, 'S-boxes'!$A$2:$A$65, 0), 0)) -> 0111 | AB17: =_xlfn.TEXTJOIN("", TRUE, INDEX('S-boxes'!$Z$2:$AC$65, MATCH(T17, 'S-boxes'!$A$2:$A$65, 0), 0)) -> 0000 | AC17: =_xlfn.TEXTJOIN("", TRUE, INDEX('S-boxes'!$AD$2:$AG$65, MATCH(U17, 'S-boxes'!$A$2:$A$65, 0), 0)) -> 1001 | AD17: =V17&W17&X17&Y17&Z17&AA17&AB17&AC17 -> 11000011011011100011011100001001 | AE17: {=_xlfn.TEXTJOIN("",TRUE,INDEX(MID(AD17,_xlfn.SEQUENCE(1,32,1,1),1),Permutations!$D$2:$D$33))} -> 01101000111000011111100011001100 | AF17: {=_xlfn.TEXTJOIN("",TRUE,IF(MID(AF16,_xlfn.SEQUENCE(1,32,1,1),1)=MID(AE17,_xlfn.SEQUENCE(1,32,1,1),1),"0","1"))} -> 00010001010101100100111111010110 | AG17: =AF16 -> 01111001101101111011011100011010
J18: Round 14 | K18: {=_xlfn.TEXTJOIN("",TRUE,INDEX(MID(AF17,_xlfn.SEQUENCE(1,32,1,1),1),Permutations!$C$2:$C$49))} -> 000010100010101010101100001001011111111010101100 | L18: ='Giải nén khóa K'!L18 -> 011010011010111011011001001001011110101001100110 | M18: {=_xlfn.TEXTJOIN("",TRUE,IF(MID(K18,_xlfn.SEQUENCE(1,48,1,1),1)=MID(L18,_xlfn.SEQUENCE(1,48,1,1),1),"0","1"))} -> 011000111000010001110101000000000001010011001010 | N18: =LEFT(M18,6) -> 011000 | O18: =MID(M18,7,6) -> 111000 | P18: =MID(M18,13,6) -> 010001 | Q18: =MID(M18,19,6) -> 110101 | R18: =MID(M18,25,6) -> 000000 | S18: =MID(M18,31,6) -> 000001 | T18: =MID(M18,37,6) -> 010011 | U18: =MID(M18,43,6) -> 001010 | V18: =_xlfn.TEXTJOIN("", TRUE, INDEX('S-boxes'!$B$2:$E$65, MATCH(N18, 'S-boxes'!$A$2:$A$65, 0), 0)) -> 0101 | W18: =_xlfn.TEXTJOIN("", TRUE, INDEX('S-boxes'!$F$2:$I$65, MATCH(O18, 'S-boxes'!$A$2:$A$65, 0), 0)) -> 1001 | X18: =_xlfn.TEXTJOIN("", TRUE, INDEX('S-boxes'!$J$2:$M$65, MATCH(P18, 'S-boxes'!$A$2:$A$65, 0), 0)) -> 0010 | Y18: =_xlfn.TEXTJOIN("", TRUE, INDEX('S-boxes'!$N$2:$Q$65, MATCH(Q18, 'S-boxes'!$A$2:$A$65, 0), 0)) -> 0101 | Z18: =_xlfn.TEXTJOIN("", TRUE, INDEX('S-boxes'!$R$2:$U$65, MATCH(R18, 'S-boxes'!$A$2:$A$65, 0), 0)) -> 0010 | AA18: =_xlfn.TEXTJOIN("", TRUE, INDEX('S-boxes'!$V$2:$Y$65, MATCH(S18, 'S-boxes'!$A$2:$A$65, 0), 0)) -> 1010 | AB18: =_xlfn.TEXTJOIN("", TRUE, INDEX('S-boxes'!$Z$2:$AC$65, MATCH(T18, 'S-boxes'!$A$2:$A$65, 0), 0)) -> 0011 | AC18: =_xlfn.TEXTJOIN("", TRUE, INDEX('S-boxes'!$AD$2:$AG$65, MATCH(U18, 'S-boxes'!$A$2:$A$65, 0), 0)) -> 1111 | AD18: =V18&W18&X18&Y18&Z18&AA18&AB18&AC18 -> 01011001001001010010101000111111 | AE18: {=_xlfn.TEXTJOIN("",TRUE,INDEX(MID(AD18,_xlfn.SEQUENCE(1,32,1,1),1),Permutations!$D$2:$D$33))} -> 10011010001010101101110010100110 | AF18: {=_xlfn.TEXTJOIN("",TRUE,IF(MID(AF17,_xlfn.SEQUENCE(1,32,1,1),1)=MID(AE18,_xlfn.SEQUENCE(1,32,1,1),1),"0","1"))} -> 10001011011111001001001101110000 | AG18: =AF17 -> 00010001010101100100111111010110
J19: Round 15 | K19: {=_xlfn.TEXTJOIN("",TRUE,INDEX(MID(AF18,_xlfn.SEQUENCE(1,32,1,1),1),Permutations!$C$2:$C$49))} -> 010001010110101111111001010010100110101110100001 | L19: ='Giải nén khóa K'!L19 -> 011010011010111011011001001001011110101001100110 | M19: {=_xlfn.TEXTJOIN("",TRUE,IF(MID(K19,_xlfn.SEQUENCE(1,48,1,1),1)=MID(L19,_xlfn.SEQUENCE(1,48,1,1),1),"0","1"))} -> 001011001100010100100000011011111000000111000111 | N19: =LEFT(M19,6) -> 001011 | O19: =MID(M19,7,6) -> 001100 | P19: =MID(M19,13,6) -> 010100 | Q19: =MID(M19,19,6) -> 100000 | R19: =MID(M19,25,6) -> 011011 | S19: =MID(M19,31,6) -> 111000 | T19: =MID(M19,37,6) -> 000111 | U19: =MID(M19,43,6) -> 000111 | V19: =_xlfn.TEXTJOIN("", TRUE, INDEX('S-boxes'!$B$2:$E$65, MATCH(N19, 'S-boxes'!$A$2:$A$65, 0), 0)) -> 0010 | W19: =_xlfn.TEXTJOIN("", TRUE, INDEX('S-boxes'!$F$2:$I$65, MATCH(O19, 'S-boxes'!$A$2:$A$65, 0), 0)) -> 0011 | X19: =_xlfn.TEXTJOIN("", TRUE, INDEX('S-boxes'!$J$2:$M$65, MATCH(P19, 'S-boxes'!$A$2:$A$65, 0), 0)) -> 1100 | Y19: =_xlfn.TEXTJOIN("", TRUE, INDEX('S-boxes'!$N$2:$Q$65, MATCH(Q19, 'S-boxes'!$A$2:$A$65, 0), 0)) -> 1010 | Z19: =_xlfn.TEXTJOIN("", TRUE, INDEX('S-boxes'!$R$2:$U$65, MATCH(R19, 'S-boxes'!$A$2:$A$65, 0), 0)) -> 1001 | AA19: =_xlfn.TEXTJOIN("", TRUE, INDEX('S-boxes'!$V$2:$Y$65, MATCH(S19, 'S-boxes'!$A$2:$A$65, 0), 0)) -> 0001 | AB19: =_xlfn.TEXTJOIN("", TRUE, INDEX('S-boxes'!$Z$2:$AC$65, MATCH(T19, 'S-boxes'!$A$2:$A$65, 0), 0)) -> 0111 | AC19: =_xlfn.TEXTJOIN("", TRUE, INDEX('S-boxes'!$AD$2:$AG$65, MATCH(U19, 'S-boxes'!$A$2:$A$65, 0), 0)) -> 1000 | AD19: =V19&W19&X19&Y19&Z19&AA19&AB19&AC19 -> 00100011110010101001000101111000 | AE19: {=_xlfn.TEXTJOIN("",TRUE,INDEX(MID(AD19,_xlfn.SEQUENCE(1,32,1,1),1),Permutations!$D$2:$D$33))} -> 01101011010100010110011101000000 | AF19: {=_xlfn.TEXTJOIN("",TRUE,IF(MID(AF18,_xlfn.SEQUENCE(1,32,1,1),1)=MID(AE19,_xlfn.SEQUENCE(1,32,1,1),1),"0","1"))} -> 11100000001011011111010000110000 | AG19: =AF18 -> 10001011011111001001001101110000
J20: Round 16 | K20: {=_xlfn.TEXTJOIN("",TRUE,INDEX(MID(AF19,_xlfn.SEQUENCE(1,32,1,1),1),Permutations!$C$2:$C$49))} -> 011100000000000101011011111110101000000110100001 | L20: ='Giải nén khóa K'!L20 -> 000110110000001011101111110110110100100110100101 | M20: {=_xlfn.TEXTJOIN("",TRUE,IF(MID(K20,_xlfn.SEQUENCE(1,48,1,1),1)=MID(L20,_xlfn.SEQUENCE(1,48,1,1),1),"0","1"))} -> 011010110000001110110100001000011100100000000100 | N20: =LEFT(M20,6) -> 011010 | O20: =MID(M20,7,6) -> 110000 | P20: =MID(M20,13,6) -> 001110 | Q20: =MID(M20,19,6) -> 110100 | R20: =MID(M20,25,6) -> 001000 | S20: =MID(M20,31,6) -> 011100 | T20: =MID(M20,37,6) -> 100000 | U20: =MID(M20,43,6) -> 000100 | V20: =_xlfn.TEXTJOIN("", TRUE, INDEX('S-boxes'!$B$2:$E$65, MATCH(N20, 'S-boxes'!$A$2:$A$65, 0), 0)) -> 1001 | W20: =_xlfn.TEXTJOIN("", TRUE, INDEX('S-boxes'!$F$2:$I$65, MATCH(O20, 'S-boxes'!$A$2:$A$65, 0), 0)) -> 0101 | X20: =_xlfn.TEXTJOIN("", TRUE, INDEX('S-boxes'!$J$2:$M$65, MATCH(P20, 'S-boxes'!$A$2:$A$65, 0), 0)) -> 0101 | Y20: =_xlfn.TEXTJOIN("", TRUE, INDEX('S-boxes'!$N$2:$Q$65, MATCH(Q20, 'S-boxes'!$A$2:$A$65, 0), 0)) -> 0011 | Z20: =_xlfn.TEXTJOIN("", TRUE, INDEX('S-boxes'!$R$2:$U$65, MATCH(R20, 'S-boxes'!$A$2:$A$65, 0), 0)) -> 0111 | AA20: =_xlfn.TEXTJOIN("", TRUE, INDEX('S-boxes'!$V$2:$Y$65, MATCH(S20, 'S-boxes'!$A$2:$A$65, 0), 0)) -> 0101 | AB20: =_xlfn.TEXTJOIN("", TRUE, INDEX('S-boxes'!$Z$2:$AC$65, MATCH(T20, 'S-boxes'!$A$2:$A$65, 0), 0)) -> 0001 | AC20: =_xlfn.TEXTJOIN("", TRUE, INDEX('S-boxes'!$AD$2:$AG$65, MATCH(U20, 'S-boxes'!$A$2:$A$65, 0), 0)) -> 1000 | AD20: =V20&W20&X20&Y20&Z20&AA20&AB20&AC20 -> 10010101010100110111010100011000 | AE20: {=_xlfn.TEXTJOIN("",TRUE,INDEX(MID(AD20,_xlfn.SEQUENCE(1,32,1,1),1),Permutations!$D$2:$D$33))} -> 10101110110001010110000010011010 | AF20: {=_xlfn.TEXTJOIN("",TRUE,IF(MID(AF19,_xlfn.SEQUENCE(1,32,1,1),1)=MID(AE20,_xlfn.SEQUENCE(1,32,1,1),1),"0","1"))} -> 01001110111010001001010010101010 | AG20: =AG19 -> 10001011011111001001001101110000
A22: Final Permutation (FP) | C22: =CONCATENATE(AF20,AG20) -> 0100111011101000100101001010101010001011011111001001001101110000
C26: {=_xlfn.TEXTJOIN("",TRUE,INDEX(MID(C22,_xlfn.SEQUENCE(1,64,1,1),1),Permutations!B2:B65))} -> 1000100011001001011001001111000100101110001100110111001010011101
A29: Bản mã C | C29: {=_xlfn.TEXTJOIN("",TRUE,DEC2HEX(BIN2DEC(MID(C26,_xlfn.SEQUENCE(LEN(C26)/4)*4-3,4)),1))} -> 88C964F12E33729D

Sheet Giải mã C về M
