Workbook
Name S_1: SBox!$B$4:$Q$7
Name S_2: SBox!$B$11:$Q$14
Name S_3: SBox!$B$18:$Q$21
Name S_4: SBox!$B$25:$Q$28

Sheet SBox
A3: S_1 | B3: 0 | C3: 1 | D3: 2 | E3: 3 | F3: 4 | G3: 5 | H3: 6 | I3: 7 | J3: 8 | K3: 9 | L3: 10 | M3: 11 | N3: 12 | O3: 13 | P3: 14 | Q3: 15
A4: 0 | B4: 14 | C4: 4 | D4: 13 | E4: 1 | F4: 2 | G4: 15 | H4: 11 | I4: 8 | J4: 3 | K4: 10 | L4: 6 | M4: 12 | N4: 5 | O4: 9 | P4: 0 | Q4: 7
A5: 1 | B5: 0 | C5: 15 | D5: 7 | E5: 4 | F5: 14 | G5: 2 | H5: 13 | I5: 1 | J5: 10 | K5: 6 | L5: 12 | M5: 11 | N5: 9 | O5: 5 | P5: 3 | Q5: 8
A6: 2 | B6: 4 | C6: 1 | D6: 14 | E6: 8 | F6: 13 | G6: 6 | H6: 2 | I6: 11 | J6: 15 | K6: 12 | L6: 9 | M6: 7 | N6: 3 | O6: 10 | P6: 5 | Q6: 0
A7: 3 | B7: 15 | C7: 12 | D7: 8 | E7: 2 | F7: 4 | G7: 9 | H7: 1 | I7: 7 | J7: 5 | K7: 11 | L7: 3 | M7: 14 | N7: 10 | O7: 0 | P7: 6 | Q7: 13
A10: S_2 | B10: 0 | C10: 1 | D10: 2 | E10: 3 | F10: 4 | G10: 5 | H10: 6 | I10: 7 | J10: 8 | K10: 9 | L10: 10 | M10: 11 | N10: 12 | O10: 13 | P10: 14 | Q10: 15
A11: 0 | B11: 15 | C11: 1 | D11: 8 | E11: 14 | F11: 6 | G11: 11 | H11: 3 | I11: 4 | J11: 9 | K11: 7 | L11: 2 | M11: 13 | N11: 12 | O11: 0 | P11: 5 | Q11: 10
A12: 1 | B12: 3 | C12: 13 | D12: 4 | E12: 7 | F12: 15 | G12: 2 | H12: 8 | I12: 14 | J12: 12 | K12: 0 | L12: 1 | M12: 10 | N12: 6 | O12: 9 | P12: 11 | Q12: 5
A13: 2 | B13: 0 | C13: 14 | D13: 7 | E13: 11 | F13: 10 | G13: 4 | H13: 13 | I13: 1 | J13: 5 | K13: 8 | L13: 12 | M13: 6 | N13: 9 | O13: 3 | P13: 2 | Q13: 15
A14: 3 | B14: 13 | C14: 8 | D14: 10 | E14: 1 | F14: 3 | G14: 15 | H14: 4 | I14: 2 | J14: 11 | K14: 6 | L14: 7 | M14: 12 | N14: 0 | O14: 5 | P14: 14 | Q14: 9
A17: S_3 | B17: 0 | C17: 1 | D17: 2 | E17: 3 | F17: 4 | G17: 5 | H17: 6 | I17: 7 | J17: 8 | K17: 9 | L17: 10 | M17: 11 | N17: 12 | O17: 13 | P17: 14 | Q17: 15
A18: 0 | B18: 10 | C18: 0 | D18: 9 | E18: 14 | F18: 6 | G18: 3 | H18: 15 | I18: 5 | J18: 1 | K18: 13 | L18: 12 | M18: 7 | N18: 11 | O18: 4 | P18: 2 | Q18: 8
A19: 1 | B19: 13 | C19: 7 | D19: 0 | E19: 9 | F19: 3 | G19: 4 | H19: 6 | I19: 10 | J19: 2 | K19: 8 | L19: 5 | M19: 14 | N19: 12 | O19: 11 | P19: 15 | Q19: 1
A20: 2 | B20: 13 | C20: 6 | D20: 4 | E20: 9 | F20: 8 | G20: 15 | H20: 3 | I20: 0 | J20: 11 | K20: 1 | L20: 2 | M20: 12 | N20: 5 | O20: 10 | P20: 14 | Q20: 7
A21: 3 | B21: 1 | C21: 10 | D21: 13 | E21: 0 | F21: 6 | G21: 9 | H21: 8 | I21: 7 | J21: 4 | K21: 15 | L21: 14 | M21: 3 | N21: 11 | O21: 5 | P21: 2 | Q21: 12
A24: S_4 | B24: 0 | C24: 1 | D24: 2 | E24: 3 | F24: 4 | G24: 5 | H24: 6 | I24: 7 | J24: 8 | K24: 9 | L24: 10 | M24: 11 | N24: 12 | O24: 13 | P24: 14 | Q24: 15
A25: 0 | B25: 7 | C25: 13 | D25: 14 | E25: 3 | F25: 0 | G25: 6 | H25: 9 | I25: 10 | J25: 1 | K25: 2 | L25: 8 | M25: 5 | N25: 11 | O25: 12 | P25: 4 | Q25: 15
A26: 1 | B26: 13 | C26: 8 | D26: 11 | E26: 5 | F26: 6 | G26: 15 | H26: 0 | I26: 3 | J26: 4 | K26: 7 | L26: 2 | M26: 12 | N26: 1 | O26: 10 | P26: 14 | Q26: 9
A27: 2 | B27: 10 | C27: 6 | D27: 9 | E27: 0 | F27: 12 | G27: 11 | H27: 7 | I27: 13 | J27: 15 | K27: 1 | L27: 3 | M27: 14 | N27: 5 | O27: 2 | P27: 8 | Q27: 4
A28: 3 | B28: 3 | C28: 15 | D28: 0 | E28: 6 | F28: 10 | G28: 1 | H28: 13 | I28: 8 | J28: 9 | K28: 4 | L28: 5 | M28: 11 | N28: 12 | O28: 7 | P28: 2 | Q28: 14
A31: S_5 | B31: 0 | C31: 1 | D31: 2 | E31: 3 | F31: 4 | G31: 5 | H31: 6 | I31: 7 | J31: 8 | K31: 9 | L31: 10 | M31: 11 | N31: 12 | O31: 13 | P31: 14 | Q31: 15
A32: 0 | B32: 2 | C32: 12 | D32: 4 | E32: 1 | F32: 7 | G32: 10 | H32: 11 | I32: 6 | J32: 8 | K32: 5 | L32: 3 | M32: 15 | N32: 13 | O32: 0 | P32: 14 | Q32: 9
A33: 1 | B33: 14 | C33: 11 | D33: 2 | E33: 12 | F33: 4 | G33: 7 | H33: 13 | I33: 1 | J33: 5 | K33: 0 | L33: 15 | M33: 10 | N33: 3 | O33: 9 | P33: 8 | Q33: 6
A34: 2 | B34: 4 | C34: 2 | D34: 1 | E34: 11 | F34: 10 | G34: 13 | H34: 7 | I34: 8 | J34: 15 | K34: 9 | L34: 12 | M34: 5 | N34: 6 | O34: 3 | P34: 0 | Q34: 14
A35: 3 | B35: 11 | C35: 8 | D35: 12 | E35: 7 | F35: 1 | G35: 14 | H35: 2 | I35: 13 | J35: 6 | K35: 15 | L35: 0 | M35: 9 | N35: 10 | O35: 4 | P35: 5 | Q35: 3
A38: S_6 | B38: 0 | C38: 1 | D38: 2 | E38: 3 | F38: 4 | G38: 5 | H38: 6 | I38: 7 | J38: 8 | K38: 9 | L38: 10 | M38: 11 | N38: 12 | O38: 13 | P38: 14 | Q38: 15
A39: 0 | B39: 12 | C39: 1 | D39: 10 | E39: 15 | F39: 9 | G39: 2 | H39: 6 | I39: 8 | J39: 0 | K39: 13 | L39: 3 | M39: 4 | N39: 14 | O39: 7 | P39: 5 | Q39: 11
A40: 1 | B40: 10 | C40: 15 | D40: 4 | E40: 2 | F40: 7 | G40: 12 | H40: 9 | I40: 5 | J40: 6 | K40: 1 | L40: 13 | M40: 14 | N40: 0 | O40: 11 | P40: 3 | Q40: 8
A41: 2 | B41: 9 | C41: 14 | D41: 15 | E41: 5 | F41: 2 | G41: 8 | H41: 12 | I41: 3 | J41: 7 | K41: 0 | L41: 4 | M41: 10 | N41: 1 | O41: 13 | P41: 11 | Q41: 6
A42: 3 | B42: 4 | C42: 3 | D42: 2 | E42: 12 | F42: 9 | G42: 5 | H42: 15 | I42: 10 | J42: 11 | K42: 14 | L42: 1 | M42: 7 | N42: 6 | O42: 0 | P42: 8 | Q42: 13
A45: S_7 | B45: 0 | C45: 1 | D45: 2 | E45: 3 | F45: 4 | G45: 5 | H45: 6 | I45: 7 | J45: 8 | K45: 9 | L45: 10 | M45: 11 | N45: 12 | O45: 13 | P45: 14 | Q45: 15
A46: 0 | B46: 4 | C46: 11 | D46: 2 | E46: 14 | F46: 15 | G46: 0 | H46: 8 | I46: 13 | J46: 3 | K46: 12 | L46: 9 | M46: 7 | N46: 5 | O46: 10 | P46: 6 | Q46: 1
A47: 1 | B47: 13 | C47: 0 | D47: 11 | E47: 7 | F47: 4 | G47: 9 | H47: 1 | I47: 10 | J47: 14 | K47: 3 | L47: 5 | M47: 12 | N47: 2 | O47: 15 | P47: 8 | Q47: 6
A48: 2 | B48: 1 | C48: 4 | D48: 11 | E48: 13 | F48: 12 | G48: 3 | H48: 7 | I48: 14 | J48: 10 | K48: 15 | L48: 6 | M48: 8 | N48: 0 | O48: 5 | P48: 9 | Q48: 2
A49: 3 | B49: 6 | C49: 11 | D49: 13 | E49: 8 | F49: 1 | G49: 4 | H49: 10 | I49: 7 | J49: 9 | K49: 5 | L49: 0 | M49: 15 | N49: 14 | O49: 2 | P49: 3 | Q49: 12
A52: S_8 | B52: 0 | C52: 1 | D52: 2 | E52: 3 | F52: 4 | G52: 5 | H52: 6 | I52: 7 | J52: 8 | K52: 9 | L52: 10 | M52: 11 | N52: 12 | O52: 13 | P52: 14 | Q52: 15
A53: 0 | B53: 13 | C53: 2 | D53: 8 | E53: 4 | F53: 6 | G53: 15 | H53: 11 | I53: 1 | J53: 10 | K53: 9 | L53: 3 | M53: 14 | N53: 5 | O53: 0 | P53: 12 | Q53: 7
A54: 1 | B54: 1 | C54: 15 | D54: 13 | E54: 8 | F54: 10 | G54: 3 | H54: 7 | I54: 4 | J54: 12 | K54: 5 | L54: 6 | M54: 11 | N54: 0 | O54: 14 | P54: 9 | Q54: 2
A55: 2 | B55: 7 | C55: 11 | D55: 4 | E55: 1 | F55: 9 | G55: 12 | H55: 14 | I55: 2 | J55: 0 | K55: 6 | L55: 10 | M55: 13 | N55: 15 | O55: 3 | P55: 5 | Q55: 8
A56: 3 | B56: 2 | C56: 1 | D56: 14 | E56: 7 | F56: 4 | G56: 10 | H56: 8 | I56: 13 | J56: 15 | K56: 12 | L56: 9 | M56: 0 | N56: 3 | O56: 5 | P56: 6 | Q56: 11

Sheet K1_16
A1: Khóa- k = | B1: 0133457799bbcdff = | D1: 0000000100110011010001010111011110011001101110111100110111111111
A3: stt k | B3: PC - 1 | C3: k0
A4: 1 | B4: 57 | C4: =MID($D$1,B4,1) -> 1 | D4: =C4&D5 -> 11110000110011001010101010111010101011001100111100001010
A5: =A4+1 -> 2 | B5: 49 | C5: =MID($D$1,B5,1) -> 1 | D5: =C5&D6 -> 1110000110011001010101010111010101011001100111100001010
A6: =A5+1 -> 3 | B6: 41 | C6: =MID($D$1,B6,1) -> 1 | D6: =C6&D7 -> 110000110011001010101010111010101011001100111100001010
A7: =A6+1 -> 4 | B7: 33 | C7: =MID($D$1,B7,1) -> 1 | D7: =C7&D8 -> 10000110011001010101010111010101011001100111100001010
A8: =A7+1 -> 5 | B8: 25 | C8: =MID($D$1,B8,1) -> 0 | D8: =C8&D9 -> 0000110011001010101010111010101011001100111100001010
A9: =A8+1 -> 6 | B9: 17 | C9: =MID($D$1,B9,1) -> 0 | D9: =C9&D10 -> 000110011001010101010111010101011001100111100001010
A10: =A9+1 -> 7 | B10: 9 | C10: =MID($D$1,B10,1) -> 0 | D10: =C10&D11 -> 00110011001010101010111010101011001100111100001010
A11: =A10+1 -> 8 | B11: 1 | C11: =MID($D$1,B11,1) -> 0 | D11: =C11&D12 -> 0110011001010101010111010101011001100111100001010
A12: =A11+1 -> 9 | B12: 58 | C12: =MID($D$1,B12,1) -> 1 | D12: =C12&D13 -> 110011001010101010111010101011001100111100001010
A13: =A12+1 -> 10 | B13: 50 | C13: =MID($D$1,B13,1) -> 1 | D13: =C13&D14 -> 10011001010101010111010101011001100111100001010
A14: =A13+1 -> 11 | B14: 42 | C14: =MID($D$1,B14,1) -> 0 | D14: =C14&D15 -> 0011001010101010111010101011001100111100001010
A15: =A14+1 -> 12 | B15: 34 | C15: =MID($D$1,B15,1) -> 0 | D15: =C15&D16 -> 011001010101010111010101011001100111100001010
A16: =A15+1 -> 13 | B16: 26 | C16: =MID($D$1,B16,1) -> 1 | D16: =C16&D17 -> 11001010101010111010101011001100111100001010
... A57: =A56+1 -> 54 | B57: 20 | C57: =MID($D$1,B57,1) -> 0 | D57: =C57&D58 -> 010
A58: =A57+1 -> 55 | B58: 12 | C58: =MID($D$1,B58,1) -> 1 | D58: =C58&C59 -> 10
A59: =A58+1 -> 56 | B59: 4 | C59: =MID($D$1,B59,1) -> 0
A64: Sau PC-1 có k0 = | C64: =_xlfn.TEXTJOIN("",TRUE,C4:C59) -> 11110000110011001010101010111010101011001100111100001010
M67: Bảng dịch trái
A68: C0 = | B68: =LEFT(C64,28) -> 1111000011001100101010101011 | G68: D0 = | H68: =RIGHT(C64,28) -> 1010101011001100111100001010 | M68: 1 | N68: 1
A69: C1 = | B69: =MID(B68, N68+1, LEN(B68)-N68) & LEFT(B68, N68) -> 1110000110011001010101010111 | G69: D1 = | H69: =MID(H68, N68+1, LEN(H68)-N68) & LEFT(H68, N68) -> 0101010110011001111000010101 | M69: 2 | N69: 1
A70: C2 = | B70: =MID(B69, N69+1, LEN(B69)-N69) & LEFT(B69, N69) -> 1100001100110010101010101111 | G70: D2= | H70: =MID(H69, N69+1, LEN(H69)-N69) & LEFT(H69, N69) -> 1010101100110011110000101010 | M70: 3 | N70: 2
A71: C3 = | B71: =MID(B70, N70+1, LEN(B70)-N70) & LEFT(B70, N70) -> 0000110011001010101010111111 | G71: D3 = | H71: =MID(H70, N70+1, LEN(H70)-N70) & LEFT(H70, N70) -> 1010110011001111000010101010 | M71: 4 | N71: 2
A72: C4 = | B72: =MID(B71, N71+1, LEN(B71)-N71) & LEFT(B71, N71) -> 0011001100101010101011111100 | G72: D4 = | H72: =MID(H71, N71+1, LEN(H71)-N71) & LEFT(H71, N71) -> 1011001100111100001010101010 | M72: 5 | N72: 2
A73: C5 = | B73: =MID(B72, N72+1, LEN(B72)-N72) & LEFT(B72, N72) -> 1100110010101010101111110000 | G73: D5 = | H73: =MID(H72, N72+1, LEN(H72)-N72) & LEFT(H72, N72) -> 1100110011110000101010101010 | M73: 6 | N73: 2
A74: C6 = | B74: =MID(B73, N73+1, LEN(B73)-N73) & LEFT(B73, N73) -> 0011001010101010111111000011 | G74: D6 = | H74: =MID(H73, N73+1, LEN(H73)-N73) & LEFT(H73, N73) -> 0011001111000010101010101011 | M74: 7 | N74: 2
A75: C7 = | B75: =MID(B74, N74+1, LEN(B74)-N74) & LEFT(B74, N74) -> 1100101010101011111100001100 | G75: D7 = | H75: =MID(H74, N74+1, LEN(H74)-N74) & LEFT(H74, N74) -> 1100111100001010101010101100 | M75: 8 | N75: 2
A76: C8 = | B76: =MID(B75, N75+1, LEN(B75)-N75) & LEFT(B75, N75) -> 0010101010101111110000110011 | G76: D8 = | H76: =MID(H75, N75+1, LEN(H75)-N75) & LEFT(H75, N75) -> 0011110000101010101010110011 | M76: 9 | N76: 1
A77: C9 = | B77: =MID(B76, N76+1, LEN(B76)-N76) & LEFT(B76, N76) -> 0101010101011111100001100110 | G77: D9 = | H77: =MID(H76, N76+1, LEN(H76)-N76) & LEFT(H76, N76) -> 0111100001010101010101100110 | M77: 10 | N77: 2
A78: C10 = | B78: =MID(B77, N77+1, LEN(B77)-N77) & LEFT(B77, N77) -> 0101010101111110000110011001 | G78: D10 = | H78: =MID(H77, N77+1, LEN(H77)-N77) & LEFT(H77, N77) -> 1110000101010101010110011001 | M78: 11 | N78: 2
A79: C11 = | B79: =MID(B78, N78+1, LEN(B78)-N78) & LEFT(B78, N78) -> 0101010111111000011001100101 | G79: D11 = | H79: =MID(H78, N78+1, LEN(H78)-N78) & LEFT(H78, N78) -> 1000010101010101011001100111 | M79: 12 | N79: 2
A80: C12 = | B80: =MID(B79, N79+1, LEN(B79)-N79) & LEFT(B79, N79) -> 0101011111100001100110010101 | G80: D12 = | H80: =MID(H79, N79+1, LEN(H79)-N79) & LEFT(H79, N79) -> 0001010101010101100110011110 | M80: 13 | N80: 2
... A83: C15 = | B83: =MID(B82, N82+1, LEN(B82)-N82) & LEFT(B82, N82) -> 1111100001100110010101010101 | G83: D15 = | H83: =MID(H82, N82+1, LEN(H82)-N82) & LEFT(H82, N82) -> 0101010101100110011110000101 | M83: 16 | N83: 1
A84: C16 = | B84: =MID(B83, N83+1, LEN(B83)-N83) & LEFT(B83, N83) -> 1111000011001100101010101011 | G84: D16 = | H84: =MID(H83, N83+1, LEN(H83)-N83) & LEFT(H83, N83) -> 1010101011001100111100001010
A88: Khóa K Khi dịch trái
A89: 1 | B89: =B69&H69 -> 11100001100110010101010101110101010110011001111000010101
A90: 2 | B90: =B70&H70 -> 11000011001100101010101011111010101100110011110000101010
A91: 3 | B91: =B71&H71 -> 00001100110010101010101111111010110011001111000010101010
A92: 4 | B92: =B72&H72 -> 00110011001010101010111111001011001100111100001010101010
...

Sheet Ham_f(RxorK)
A1: bản rõ | B1: Input M = 00123456789abcde = | E1: 0000000000010010001101000101011001111000100110101011110011011110
A5: stt | B5: IP | C5: IP(M) | D5: Ma trận E | E5: IP^-1 | I5: Ip(M) = | J5: =_xlfn.TEXTJOIN("", TRUE,C6:C69) -> 1001100011111110110011000000000011100000010101001111000010101010
A6: 1 | B6: 58 | C6: =MID($E$1,B6,1) -> 1 | D6: 32 | E6: 40
A7: 2 | B7: 50 | C7: =MID($E$1,B7,1) -> 0 | D7: 1 | E7: 8
A8: 3 | B8: 42 | C8: =MID($E$1,B8,1) -> 0 | D8: 2 | E8: 48 | I8: L0 = | J8: =LEFT(J5,32) -> 10011000111111101100110000000000 | P8: R0 = | Q8: =RIGHT(J5,32) -> 11100000010101001111000010101010
A9: 4 | B9: 34 | C9: =MID($E$1,B9,1) -> 1 | D9: 3 | E9: 16 | H9: E(Ri) XOR Ki+1
A10: 5 | B10: 26 | C10: =MID($E$1,B10,1) -> 1 | D10: 4 | E10: 56 | G10: i= | H10: 0 | I10: 1 | J10: 2 | K10: 3 | L10: 4 | M10: 5 | N10: 6 | O10: 7 | P10: 8 | Q10: 9 | R10: 10 | S10: 11 | T10: 12 | U10: 13 | V10: 14 | W10: 15
A11: 6 | B11: 18 | C11: =MID($E$1,B11,1) -> 0 | D11: 5 | E11: 24 | H11: =MOD(VALUE(MID($Q$8,D6,1)) + VALUE(K1_16!$B108), 2) -> 0 | I11: =MOD(VALUE(MID(R0_L0!$C$79,D6,1)) + VALUE(K1_16!$C108), 2) -> 0 | J11: =MOD(VALUE(MID(R0_L0!$C$80,$D6,1)) + VALUE(K1_16!D108), 2) -> 1 | K11: =MOD(VALUE(MID(R0_L0!$C$81,$D6,1)) + VALUE(K1_16!E108), 2) -> 0 | L11: =MOD(VALUE(MID(R0_L0!$C$82,$D6,1)) + VALUE(K1_16!F108), 2) -> 1 | M11: =MOD(VALUE(MID(R0_L0!$C$83,$D6,1)) + VALUE(K1_16!G108), 2) -> 1 | N11: =MOD(VALUE(MID(R0_L0!$C$84,$D6,1)) + VALUE(K1_16!H108), 2) -> 0 | O11: =MOD(VALUE(MID(R0_L0!$C$85,$D6,1)) + VALUE(K1_16!I108), 2) -> 0 | P11: =MOD(VALUE(MID(R0_L0!$C$86,$D6,1)) + VALUE(K1_16!J108), 2) -> 1 | Q11: =MOD(VALUE(MID(R0_L0!$C$87,$D6,1)) + VALUE(K1_16!K108), 2) -> 1 | R11: =MOD(VALUE(MID(R0_L0!$C$88,$D6,1)) + VALUE(K1_16!L108), 2) -> 0 | S11: =MOD(VALUE(MID(R0_L0!$C$89,$D6,1)) + VALUE(K1_16!M108), 2) -> 0 | T11: =MOD(VALUE(MID(R0_L0!$C$90,$D6,1)) + VALUE(K1_16!N108), 2) -> 0 | U11: =MOD(VALUE(MID(R0_L0!$C$91,$D6,1)) + VALUE(K1_16!O108), 2) -> 0 | V11: =MOD(VALUE(MID(R0_L0!$C$92,$D6,1)) + VALUE(K1_16!P108), 2) -> 0 | W11: =MOD(VALUE(MID(R0_L0!$C$93,$D6,1)) + VALUE(K1_16!Q108), 2) -> 0 | AA11: =MID($Q$8,D6,1) -> 0
A12: 7 | B12: 10 | C12: =MID($E$1,B12,1) -> 0 | D12: 4 | E12: 64 | H12: =MOD(VALUE(MID($Q$8,D7,1)) + VALUE(K1_16!$B109), 2) -> 1 | I12: =MOD(VALUE(MID(R0_L0!$C$79,D7,1)) + VALUE(K1_16!$C109), 2) -> 1 | J12: =MOD(VALUE(MID(R0_L0!$C$80,$D7,1)) + VALUE(K1_16!D109), 2) -> 1 | K12: =MOD(VALUE(MID(R0_L0!$C$81,$D7,1)) + VALUE(K1_16!E109), 2) -> 0 | L12: =MOD(VALUE(MID(R0_L0!$C$82,$D7,1)) + VALUE(K1_16!F109), 2) -> 0 | M12: =MOD(VALUE(MID(R0_L0!$C$83,$D7,1)) + VALUE(K1_16!G109), 2) -> 1 | N12: =MOD(VALUE(MID(R0_L0!$C$84,$D7,1)) + VALUE(K1_16!H109), 2) -> 1 | O12: =MOD(VALUE(MID(R0_L0!$C$85,$D7,1)) + VALUE(K1_16!I109), 2) -> 1 | P12: =MOD(VALUE(MID(R0_L0!$C$86,$D7,1)) + VALUE(K1_16!J109), 2) -> 1 | Q12: =MOD(VALUE(MID(R0_L0!$C$87,$D7,1)) + VALUE(K1_16!K109), 2) -> 1 | R12: =MOD(VALUE(MID(R0_L0!$C$88,$D7,1)) + VALUE(K1_16!L109), 2) -> 1 | S12: =MOD(VALUE(MID(R0_L0!$C$89,$D7,1)) + VALUE(K1_16!M109), 2) -> 1 | T12: =MOD(VALUE(MID(R0_L0!$C$90,$D7,1)) + VALUE(K1_16!N109), 2) -> 1 | U12: =MOD(VALUE(MID(R0_L0!$C$91,$D7,1)) + VALUE(K1_16!O109), 2) -> 1 | V12: =MOD(VALUE(MID(R0_L0!$C$92,$D7,1)) + VALUE(K1_16!P109), 2) -> 1 | W12: =MOD(VALUE(MID(R0_L0!$C$93,$D7,1)) + VALUE(K1_16!Q109), 2) -> 1 | AA12: =MID($Q$8,D7,1) -> 1
A13: 8 | B13: 2 | C13: =MID($E$1,B13,1) -> 0 | D13: 5 | E13: 32 | H13: =MOD(VALUE(MID($Q$8,D8,1)) + VALUE(K1_16!$B110), 2) -> 1 | I13: =MOD(VALUE(MID(R0_L0!$C$79,D8,1)) + VALUE(K1_16!$C110), 2) -> 1 | J13: =MOD(VALUE(MID(R0_L0!$C$80,$D8,1)) + VALUE(K1_16!D110), 2) -> 1 | K13: =MOD(VALUE(MID(R0_L0!$C$81,$D8,1)) + VALUE(K1_16!E110), 2) -> 0 | L13: =MOD(VALUE(MID(R0_L0!$C$82,$D8,1)) + VALUE(K1_16!F110), 2) -> 1 | M13: =MOD(VALUE(MID(R0_L0!$C$83,$D8,1)) + VALUE(K1_16!G110), 2) -> 1 | N13: =MOD(VALUE(MID(R0_L0!$C$84,$D8,1)) + VALUE(K1_16!H110), 2) -> 1 | O13: =MOD(VALUE(MID(R0_L0!$C$85,$D8,1)) + VALUE(K1_16!I110), 2) -> 0 | P13: =MOD(VALUE(MID(R0_L0!$C$86,$D8,1)) + VALUE(K1_16!J110), 2) -> 1 | Q13: =MOD(VALUE(MID(R0_L0!$C$87,$D8,1)) + VALUE(K1_16!K110), 2) -> 1 | R13: =MOD(VALUE(MID(R0_L0!$C$88,$D8,1)) + VALUE(K1_16!L110), 2) -> 1 | S13: =MOD(VALUE(MID(R0_L0!$C$89,$D8,1)) + VALUE(K1_16!M110), 2) -> 0 | T13: =MOD(VALUE(MID(R0_L0!$C$90,$D8,1)) + VALUE(K1_16!N110), 2) -> 1 | U13: =MOD(VALUE(MID(R0_L0!$C$91,$D8,1)) + VALUE(K1_16!O110), 2) -> 0 | V13: =MOD(VALUE(MID(R0_L0!$C$92,$D8,1)) + VALUE(K1_16!P110), 2) -> 1 | W13: =MOD(VALUE(MID(R0_L0!$C$93,$D8,1)) + VALUE(K1_16!Q110), 2) -> 1 | AA13: =MID($Q$8,D8,1) -> 1
A14: 9 | B14: 60 | C14: =MID($E$1,B14,1) -> 1 | D14: 6 | E14: 39 | H14: =MOD(VALUE(MID($Q$8,D9,1)) + VALUE(K1_16!$B111), 2) -> 0 | I14: =MOD(VALUE(MID(R0_L0!$C$79,D9,1)) + VALUE(K1_16!$C111), 2) -> 0 | J14: =MOD(VALUE(MID(R0_L0!$C$80,$D9,1)) + VALUE(K1_16!D111), 2) -> 0 | K14: =MOD(VALUE(MID(R0_L0!$C$81,$D9,1)) + VALUE(K1_16!E111), 2) -> 1 | L14: =MOD(VALUE(MID(R0_L0!$C$82,$D9,1)) + VALUE(K1_16!F111), 2) -> 1 | M14: =MOD(VALUE(MID(R0_L0!$C$83,$D9,1)) + VALUE(K1_16!G111), 2) -> 0 | N14: =MOD(VALUE(MID(R0_L0!$C$84,$D9,1)) + VALUE(K1_16!H111), 2) -> 1 | O14: =MOD(VALUE(MID(R0_L0!$C$85,$D9,1)) + VALUE(K1_16!I111), 2) -> 1 | P14: =MOD(VALUE(MID(R0_L0!$C$86,$D9,1)) + VALUE(K1_16!J111), 2) -> 0 | Q14: =MOD(VALUE(MID(R0_L0!$C$87,$D9,1)) + VALUE(K1_16!K111), 2) -> 0 | R14: =MOD(VALUE(MID(R0_L0!$C$88,$D9,1)) + VALUE(K1_16!L111), 2) -> 0 | S14: =MOD(VALUE(MID(R0_L0!$C$89,$D9,1)) + VALUE(K1_16!M111), 2) -> 1 | T14: =MOD(VALUE(MID(R0_L0!$C$90,$D9,1)) + VALUE(K1_16!N111), 2) -> 0 | U14: =MOD(VALUE(MID(R0_L0!$C$91,$D9,1)) + VALUE(K1_16!O111), 2) -> 0 | V14: =MOD(VALUE(MID(R0_L0!$C$92,$D9,1)) + VALUE(K1_16!P111), 2) -> 1 | W14: =MOD(VALUE(MID(R0_L0!$C$93,$D9,1)) + VALUE(K1_16!Q111), 2) -> 1 | AA14: =MID($Q$8,D9,1) -> 1
A15: 10 | B15: 52 | C15: =MID($E$1,B15,1) -> 1 | D15: 7 | E15: 7 | H15: =MOD(VALUE(MID($Q$8,D10,1)) + VALUE(K1_16!$B112), 2) -> 1 | I15: =MOD(VALUE(MID(R0_L0!$C$79,D10,1)) + VALUE(K1_16!$C112), 2) -> 1 | J15: =MOD(VALUE(MID(R0_L0!$C$80,$D10,1)) + VALUE(K1_16!D112), 2) -> 0 | K15: =MOD(VALUE(MID(R0_L0!$C$81,$D10,1)) + VALUE(K1_16!E112), 2) -> 1 | L15: =MOD(VALUE(MID(R0_L0!$C$82,$D10,1)) + VALUE(K1_16!F112), 2) -> 0 | M15: =MOD(VALUE(MID(R0_L0!$C$83,$D10,1)) + VALUE(K1_16!G112), 2) -> 0 | N15: =MOD(VALUE(MID(R0_L0!$C$84,$D10,1)) + VALUE(K1_16!H112), 2) -> 0 | O15: =MOD(VALUE(MID(R0_L0!$C$85,$D10,1)) + VALUE(K1_16!I112), 2) -> 0 | P15: =MOD(VALUE(MID(R0_L0!$C$86,$D10,1)) + VALUE(K1_16!J112), 2) -> 1 | Q15: =MOD(VALUE(MID(R0_L0!$C$87,$D10,1)) + VALUE(K1_16!K112), 2) -> 1 | R15: =MOD(VALUE(MID(R0_L0!$C$88,$D10,1)) + VALUE(K1_16!L112), 2) -> 0 | S15: =MOD(VALUE(MID(R0_L0!$C$89,$D10,1)) + VALUE(K1_16!M112), 2) -> 0 | T15: =MOD(VALUE(MID(R0_L0!$C$90,$D10,1)) + VALUE(K1_16!N112), 2) -> 1 | U15: =MOD(VALUE(MID(R0_L0!$C$91,$D10,1)) + VALUE(K1_16!O112), 2) -> 1 | V15: =MOD(VALUE(MID(R0_L0!$C$92,$D10,1)) + VALUE(K1_16!P112), 2) -> 0 | W15: =MOD(VALUE(MID(R0_L0!$C$93,$D10,1)) + VALUE(K1_16!Q112), 2) -> 1 | AA15: =MID($Q$8,D10,1) -> 0
A16: 11 | B16: 44 | C16: =MID($E$1,B16,1) -> 1 | D16: 8 | E16: 47 | H16: =MOD(VALUE(MID($Q$8,D11,1)) + VALUE(K1_16!$B113), 2) -> 0 | I16: =MOD(VALUE(MID(R0_L0!$C$79,D11,1)) + VALUE(K1_16!$C113), 2) -> 1 | J16: =MOD(VALUE(MID(R0_L0!$C$80,$D11,1)) + VALUE(K1_16!D113), 2) -> 0 | K16: =MOD(VALUE(MID(R0_L0!$C$81,$D11,1)) + VALUE(K1_16!E113), 2) -> 0 | L16: =MOD(VALUE(MID(R0_L0!$C$82,$D11,1)) + VALUE(K1_16!F113), 2) -> 0 | M16: =MOD(VALUE(MID(R0_L0!$C$83,$D11,1)) + VALUE(K1_16!G113), 2) -> 1 | N16: =MOD(VALUE(MID(R0_L0!$C$84,$D11,1)) + VALUE(K1_16!H113), 2) -> 1 | O16: =MOD(VALUE(MID(R0_L0!$C$85,$D11,1)) + VALUE(K1_16!I113), 2) -> 1 | P16: =MOD(VALUE(MID(R0_L0!$C$86,$D11,1)) + VALUE(K1_16!J113), 2) -> 1 | Q16: =MOD(VALUE(MID(R0_L0!$C$87,$D11,1)) + VALUE(K1_16!K113), 2) -> 1 | R16: =MOD(VALUE(MID(R0_L0!$C$88,$D11,1)) + VALUE(K1_16!L113), 2) -> 1 | S16: =MOD(VALUE(MID(R0_L0!$C$89,$D11,1)) + VALUE(K1_16!M113), 2) -> 0 | T16: =MOD(VALUE(MID(R0_L0!$C$90,$D11,1)) + VALUE(K1_16!N113), 2) -> 0 | U16: =MOD(VALUE(MID(R0_L0!$C$91,$D11,1)) + VALUE(K1_16!O113), 2) -> 0 | V16: =MOD(VALUE(MID(R0_L0!$C$92,$D11,1)) + VALUE(K1_16!P113), 2) -> 0 | W16: =MOD(VALUE(MID(R0_L0!$C$93,$D11,1)) + VALUE(K1_16!Q113), 2) -> 1 | Z16: 1 | AA16: =MID($Q$8,D11,1) -> 0
A17: 12 | B17: 36 | C17: =MID($E$1,B17,1) -> 1 | D17: 9 | E17: 15 | H17: =MOD(VALUE(MID($Q$8,D12,1)) + VALUE(K1_16!$B114), 2) -> 1 | I17: =MOD(VALUE(MID(R0_L0!$C$79,D12,1)) + VALUE(K1_16!$C114), 2) -> 0 | J17: =MOD(VALUE(MID(R0_L0!$C$80,$D12,1)) + VALUE(K1_16!D114), 2) -> 0 | K17: =MOD(VALUE(MID(R0_L0!$C$81,$D12,1)) + VALUE(K1_16!E114), 2) -> 0 | L17: =MOD(VALUE(MID(R0_L0!$C$82,$D12,1)) + VALUE(K1_16!F114), 2) -> 1 | M17: =MOD(VALUE(MID(R0_L0!$C$83,$D12,1)) + VALUE(K1_16!G114), 2) -> 1 | N17: =MOD(VALUE(MID(R0_L0!$C$84,$D12,1)) + VALUE(K1_16!H114), 2) -> 1 | O17: =MOD(VALUE(MID(R0_L0!$C$85,$D12,1)) + VALUE(K1_16!I114), 2) -> 1 | P17: =MOD(VALUE(MID(R0_L0!$C$86,$D12,1)) + VALUE(K1_16!J114), 2) -> 1 | Q17: =MOD(VALUE(MID(R0_L0!$C$87,$D12,1)) + VALUE(K1_16!K114), 2) -> 1 | R17: =MOD(VALUE(MID(R0_L0!$C$88,$D12,1)) + VALUE(K1_16!L114), 2) -> 0 | S17: =MOD(VALUE(MID(R0_L0!$C$89,$D12,1)) + VALUE(K1_16!M114), 2) -> 0 | T17: =MOD(VALUE(MID(R0_L0!$C$90,$D12,1)) + VALUE(K1_16!N114), 2) -> 1 | U17: =MOD(VALUE(MID(R0_L0!$C$91,$D12,1)) + VALUE(K1_16!O114), 2) -> 0 | V17: =MOD(VALUE(MID(R0_L0!$C$92,$D12,1)) + VALUE(K1_16!P114), 2) -> 0 | W17: =MOD(VALUE(MID(R0_L0!$C$93,$D12,1)) + VALUE(K1_16!Q114), 2) -> 1 | Z17: 1 | AA17: =MID($Q$8,D12,1) -> 0
A18: 13 | B18: 28 | C18: =MID($E$1,B18,1) -> 1 | D18: 8 | E18: 55 | H18: =MOD(VALUE(MID($Q$8,D13,1)) + VALUE(K1_16!$B115), 2) -> 1 | I18: =MOD(VALUE(MID(R0_L0!$C$79,D13,1)) + VALUE(K1_16!$C115), 2) -> 0 | J18: =MOD(VALUE(MID(R0_L0!$C$80,$D13,1)) + VALUE(K1_16!D115), 2) -> 0 | K18: =MOD(VALUE(MID(R0_L0!$C$81,$D13,1)) + VALUE(K1_16!E115), 2) -> 0 | L18: =MOD(VALUE(MID(R0_L0!$C$82,$D13,1)) + VALUE(K1_16!F115), 2) -> 1 | M18: =MOD(VALUE(MID(R0_L0!$C$83,$D13,1)) + VALUE(K1_16!G115), 2) -> 0 | N18: =MOD(VALUE(MID(R0_L0!$C$84,$D13,1)) + VALUE(K1_16!H115), 2) -> 0 | O18: =MOD(VALUE(MID(R0_L0!$C$85,$D13,1)) + VALUE(K1_16!I115), 2) -> 1 | P18: =MOD(VALUE(MID(R0_L0!$C$86,$D13,1)) + VALUE(K1_16!J115), 2) -> 1 | Q18: =MOD(VALUE(MID(R0_L0!$C$87,$D13,1)) + VALUE(K1_16!K115), 2) -> 0 | R18: =MOD(VALUE(MID(R0_L0!$C$88,$D13,1)) + VALUE(K1_16!L115), 2) -> 0 | S18: =MOD(VALUE(MID(R0_L0!$C$89,$D13,1)) + VALUE(K1_16!M115), 2) -> 1 | T18: =MOD(VALUE(MID(R0_L0!$C$90,$D13,1)) + VALUE(K1_16!N115), 2) -> 0 | U18: =MOD(VALUE(MID(R0_L0!$C$91,$D13,1)) + VALUE(K1_16!O115), 2) -> 0 | V18: =MOD(VALUE(MID(R0_L0!$C$92,$D13,1)) + VALUE(K1_16!P115), 2) -> 0 | W18: =MOD(VALUE(MID(R0_L0!$C$93,$D13,1)) + VALUE(K1_16!Q115), 2) -> 0 | Z18: 0 | AA18: =MID($Q$8,D13,1) -> 0
A19: 14 | B19: 20 | C19: =MID($E$1,B19,1) -> 1 | D19: 9 | E19: 23 | H19: =MOD(VALUE(MID($Q$8,D14,1)) + VALUE(K1_16!$B116), 2) -> 0 | I19: =MOD(VALUE(MID(R0_L0!$C$79,D14,1)) + VALUE(K1_16!$C116), 2) -> 0 | J19: =MOD(VALUE(MID(R0_L0!$C$80,$D14,1)) + VALUE(K1_16!D116), 2) -> 1 | K19: =MOD(VALUE(MID(R0_L0!$C$81,$D14,1)) + VALUE(K1_16!E116), 2) -> 0 | L19: =MOD(VALUE(MID(R0_L0!$C$82,$D14,1)) + VALUE(K1_16!F116), 2) -> 0 | M19: =MOD(VALUE(MID(R0_L0!$C$83,$D14,1)) + VALUE(K1_16!G116), 2) -> 0 | N19: =MOD(VALUE(MID(R0_L0!$C$84,$D14,1)) + VALUE(K1_16!H116), 2) -> 1 | O19: =MOD(VALUE(MID(R0_L0!$C$85,$D14,1)) + VALUE(K1_16!I116), 2) -> 1 | P19: =MOD(VALUE(MID(R0_L0!$C$86,$D14,1)) + VALUE(K1_16!J116), 2) -> 0 | Q19: =MOD(VALUE(MID(R0_L0!$C$87,$D14,1)) + VALUE(K1_16!K116), 2) -> 1 | R19: =MOD(VALUE(MID(R0_L0!$C$88,$D14,1)) + VALUE(K1_16!L116), 2) -> 0 | S19: =MOD(VALUE(MID(R0_L0!$C$89,$D14,1)) + VALUE(K1_16!M116), 2) -> 1 | T19: =MOD(VALUE(MID(R0_L0!$C$90,$D14,1)) + VALUE(K1_16!N116), 2) -> 1 | U19: =MOD(VALUE(MID(R0_L0!$C$91,$D14,1)) + VALUE(K1_16!O116), 2) -> 1 | V19: =MOD(VALUE(MID(R0_L0!$C$92,$D14,1)) + VALUE(K1_16!P116), 2) -> 0 | W19: =MOD(VALUE(MID(R0_L0!$C$93,$D14,1)) + VALUE(K1_16!Q116), 2) -> 1 | Z19: 0 | AA19: =MID($Q$8,D14,1) -> 0
A20: 15 | B20: 12 | C20: =MID($E$1,B20,1) -> 1 | D20: 10 | E20: 63 | H20: =MOD(VALUE(MID($Q$8,D15,1)) + VALUE(K1_16!$B117), 2) -> 0 | I20: =MOD(VALUE(MID(R0_L0!$C$79,D15,1)) + VALUE(K1_16!$C117), 2) -> 1 | J20: =MOD(VALUE(MID(R0_L0!$C$80,$D15,1)) + VALUE(K1_16!D117), 2) -> 1 | K20: =MOD(VALUE(MID(R0_L0!$C$81,$D15,1)) + VALUE(K1_16!E117), 2) -> 0 | L20: =MOD(VALUE(MID(R0_L0!$C$82,$D15,1)) + VALUE(K1_16!F117), 2) -> 1 | M20: =MOD(VALUE(MID(R0_L0!$C$83,$D15,1)) + VALUE(K1_16!G117), 2) -> 0 | N20: =MOD(VALUE(MID(R0_L0!$C$84,$D15,1)) + VALUE(K1_16!H117), 2) -> 1 | O20: =MOD(VALUE(MID(R0_L0!$C$85,$D15,1)) + VALUE(K1_16!I117), 2) -> 1 | P20: =MOD(VALUE(MID(R0_L0!$C$86,$D15,1)) + VALUE(K1_16!J117), 2) -> 0 | Q20: =MOD(VALUE(MID(R0_L0!$C$87,$D15,1)) + VALUE(K1_16!K117), 2) -> 1 | R20: =MOD(VALUE(MID(R0_L0!$C$88,$D15,1)) + VALUE(K1_16!L117), 2) -> 0 | S20: =MOD(VALUE(MID(R0_L0!$C$89,$D15,1)) + VALUE(K1_16!M117), 2) -> 1 | T20: =MOD(VALUE(MID(R0_L0!$C$90,$D15,1)) + VALUE(K1_16!N117), 2) -> 0 | U20: =MOD(VALUE(MID(R0_L0!$C$91,$D15,1)) + VALUE(K1_16!O117), 2) -> 0 | V20: =MOD(VALUE(MID(R0_L0!$C$92,$D15,1)) + VALUE(K1_16!P117), 2) -> 1 | W20: =MOD(VALUE(MID(R0_L0!$C$93,$D15,1)) + VALUE(K1_16!Q117), 2) -> 1 | Z20: 0 | AA20: =MID($Q$8,D15,1) -> 0
A21: 16 | B21: 4 | C21: =MID($E$1,B21,1) -> 0 | D21: 11 | E21: 31 | H21: =MOD(VALUE(MID($Q$8,D16,1)) + VALUE(K1_16!$B118), 2) -> 0 | I21: =MOD(VALUE(MID(R0_L0!$C$79,D16,1)) + VALUE(K1_16!$C118), 2) -> 0 | J21: =MOD(VALUE(MID(R0_L0!$C$80,$D16,1)) + VALUE(K1_16!D118), 2) -> 1 | K21: =MOD(VALUE(MID(R0_L0!$C$81,$D16,1)) + VALUE(K1_16!E118), 2) -> 0 | L21: =MOD(VALUE(MID(R0_L0!$C$82,$D16,1)) + VALUE(K1_16!F118), 2) -> 1 | M21: =MOD(VALUE(MID(R0_L0!$C$83,$D16,1)) + VALUE(K1_16!G118), 2) -> 0 | N21: =MOD(VALUE(MID(R0_L0!$C$84,$D16,1)) + VALUE(K1_16!H118), 2) -> 1 | O21: =MOD(VALUE(MID(R0_L0!$C$85,$D16,1)) + VALUE(K1_16!I118), 2) -> 1 | P21: =MOD(VALUE(MID(R0_L0!$C$86,$D16,1)) + VALUE(K1_16!J118), 2) -> 1 | Q21: =MOD(VALUE(MID(R0_L0!$C$87,$D16,1)) + VALUE(K1_16!K118), 2) -> 1 | R21: =MOD(VALUE(MID(R0_L0!$C$88,$D16,1)) + VALUE(K1_16!L118), 2) -> 0 | S21: =MOD(VALUE(MID(R0_L0!$C$89,$D16,1)) + VALUE(K1_16!M118), 2) -> 1 | T21: =MOD(VALUE(MID(R0_L0!$C$90,$D16,1)) + VALUE(K1_16!N118), 2) -> 0 | U21: =MOD(VALUE(MID(R0_L0!$C$91,$D16,1)) + VALUE(K1_16!O118), 2) -> 1 | V21: =MOD(VALUE(MID(R0_L0!$C$92,$D16,1)) + VALUE(K1_16!P118), 2) -> 1 | W21: =MOD(VALUE(MID(R0_L0!$C$93,$D16,1)) + VALUE(K1_16!Q118), 2) -> 1 | Z21: 0 | AA21: =MID($Q$8,D16,1) -> 0
A22: 17 | B22: 62 | C22: =MID($E$1,B22,1) -> 1 | D22: 12 | E22: 38 | H22: =MOD(VALUE(MID($Q$8,D17,1)) + VALUE(K1_16!$B119), 2) -> 0 | I22: =MOD(VALUE(MID(R0_L0!$C$79,D17,1)) + VALUE(K1_16!$C119), 2) -> 0 | J22: =MOD(VALUE(MID(R0_L0!$C$80,$D17,1)) + VALUE(K1_16!D119), 2) -> 1 | K22: =MOD(VALUE(MID(R0_L0!$C$81,$D17,1)) + VALUE(K1_16!E119), 2) -> 0 | L22: =MOD(VALUE(MID(R0_L0!$C$82,$D17,1)) + VALUE(K1_16!F119), 2) -> 0 | M22: =MOD(VALUE(MID(R0_L0!$C$83,$D17,1)) + VALUE(K1_16!G119), 2) -> 0 | N22: =MOD(VALUE(MID(R0_L0!$C$84,$D17,1)) + VALUE(K1_16!H119), 2) -> 1 | O22: =MOD(VALUE(MID(R0_L0!$C$85,$D17,1)) + VALUE(K1_16!I119), 2) -> 0 | P22: =MOD(VALUE(MID(R0_L0!$C$86,$D17,1)) + VALUE(K1_16!J119), 2) -> 1 | Q22: =MOD(VALUE(MID(R0_L0!$C$87,$D17,1)) + VALUE(K1_16!K119), 2) -> 1 | R22: =MOD(VALUE(MID(R0_L0!$C$88,$D17,1)) + VALUE(K1_16!L119), 2) -> 1 | S22: =MOD(VALUE(MID(R0_L0!$C$89,$D17,1)) + VALUE(K1_16!M119), 2) -> 0 | T22: =MOD(VALUE(MID(R0_L0!$C$90,$D17,1)) + VALUE(K1_16!N119), 2) -> 0 | U22: =MOD(VALUE(MID(R0_L0!$C$91,$D17,1)) + VALUE(K1_16!O119), 2) -> 0 | V22: =MOD(VALUE(MID(R0_L0!$C$92,$D17,1)) + VALUE(K1_16!P119), 2) -> 0 | W22: =MOD(VALUE(MID(R0_L0!$C$93,$D17,1)) + VALUE(K1_16!Q119), 2) -> 1 | Z22: 0 | AA22: =MID($Q$8,D17,1) -> 0
A23: 18 | B23: 54 | C23: =MID($E$1,B23,1) -> 1 | D23: 13 | E23: 6 | H23: =MOD(VALUE(MID($Q$8,D18,1)) + VALUE(K1_16!$B120), 2) -> 0 | I23: =MOD(VALUE(MID(R0_L0!$C$79,D18,1)) + VALUE(K1_16!$C120), 2) -> 0 | J23: =MOD(VALUE(MID(R0_L0!$C$80,$D18,1)) + VALUE(K1_16!D120), 2) -> 1 | K23: =MOD(VALUE(MID(R0_L0!$C$81,$D18,1)) + VALUE(K1_16!E120), 2) -> 0 | L23: =MOD(VALUE(MID(R0_L0!$C$82,$D18,1)) + VALUE(K1_16!F120), 2) -> 1 | M23: =MOD(VALUE(MID(R0_L0!$C$83,$D18,1)) + VALUE(K1_16!G120), 2) -> 1 | N23: =MOD(VALUE(MID(R0_L0!$C$84,$D18,1)) + VALUE(K1_16!H120), 2) -> 1 | O23: =MOD(VALUE(MID(R0_L0!$C$85,$D18,1)) + VALUE(K1_16!I120), 2) -> 0 | P23: =MOD(VALUE(MID(R0_L0!$C$86,$D18,1)) + VALUE(K1_16!J120), 2) -> 0 | Q23: =MOD(VALUE(MID(R0_L0!$C$87,$D18,1)) + VALUE(K1_16!K120), 2) -> 0 | R23: =MOD(VALUE(MID(R0_L0!$C$88,$D18,1)) + VALUE(K1_16!L120), 2) -> 1 | S23: =MOD(VALUE(MID(R0_L0!$C$89,$D18,1)) + VALUE(K1_16!M120), 2) -> 0 | T23: =MOD(VALUE(MID(R0_L0!$C$90,$D18,1)) + VALUE(K1_16!N120), 2) -> 0 | U23: =MOD(VALUE(MID(R0_L0!$C$91,$D18,1)) + VALUE(K1_16!O120), 2) -> 1 | V23: =MOD(VALUE(MID(R0_L0!$C$92,$D18,1)) + VALUE(K1_16!P120), 2) -> 1 | W23: =MOD(VALUE(MID(R0_L0!$C$93,$D18,1)) + VALUE(K1_16!Q120), 2) -> 1 | Z23: 0 | AA23: =MID($Q$8,D18,1) -> 0
A24: 19 | B24: 46 | C24: =MID($E$1,B24,1) -> 0 | D24: 12 | E24: 46 | H24: =MOD(VALUE(MID($Q$8,D19,1)) + VALUE(K1_16!$B121), 2) -> 0 | I24: =MOD(VALUE(MID(R0_L0!$C$79,D19,1)) + VALUE(K1_16!$C121), 2) -> 1 | J24: =MOD(VALUE(MID(R0_L0!$C$80,$D19,1)) + VALUE(K1_16!D121), 2) -> 1 | K24: =MOD(VALUE(MID(R0_L0!$C$81,$D19,1)) + VALUE(K1_16!E121), 2) -> 1 | L24: =MOD(VALUE(MID(R0_L0!$C$82,$D19,1)) + VALUE(K1_16!F121), 2) -> 1 | M24: =MOD(VALUE(MID(R0_L0!$C$83,$D19,1)) + VALUE(K1_16!G121), 2) -> 1 | N24: =MOD(VALUE(MID(R0_L0!$C$84,$D19,1)) + VALUE(K1_16!H121), 2) -> 0 | O24: =MOD(VALUE(MID(R0_L0!$C$85,$D19,1)) + VALUE(K1_16!I121), 2) -> 0 | P24: =MOD(VALUE(MID(R0_L0!$C$86,$D19,1)) + VALUE(K1_16!J121), 2) -> 0 | Q24: =MOD(VALUE(MID(R0_L0!$C$87,$D19,1)) + VALUE(K1_16!K121), 2) -> 0 | R24: =MOD(VALUE(MID(R0_L0!$C$88,$D19,1)) + VALUE(K1_16!L121), 2) -> 1 | S24: =MOD(VALUE(MID(R0_L0!$C$89,$D19,1)) + VALUE(K1_16!M121), 2) -> 1 | T24: =MOD(VALUE(MID(R0_L0!$C$90,$D19,1)) + VALUE(K1_16!N121), 2) -> 1 | U24: =MOD(VALUE(MID(R0_L0!$C$91,$D19,1)) + VALUE(K1_16!O121), 2) -> 0 | V24: =MOD(VALUE(MID(R0_L0!$C$92,$D19,1)) + VALUE(K1_16!P121), 2) -> 1 | W24: =MOD(VALUE(MID(R0_L0!$C$93,$D19,1)) + VALUE(K1_16!Q121), 2) -> 1 | Z24: 1 | AA24: =MID($Q$8,D19,1) -> 0
A25: 20 | B25: 38 | C25: =MID($E$1,B25,1) -> 0 | D25: 13 | E25: 14 | H25: =MOD(VALUE(MID($Q$8,D20,1)) + VALUE(K1_16!$B122), 2) -> 0 | I25: =MOD(VALUE(MID(R0_L0!$C$79,D20,1)) + VALUE(K1_16!$C122), 2) -> 1 | J25: =MOD(VALUE(MID(R0_L0!$C$80,$D20,1)) + VALUE(K1_16!D122), 2) -> 0 | K25: =MOD(VALUE(MID(R0_L0!$C$81,$D20,1)) + VALUE(K1_16!E122), 2) -> 0 | L25: =MOD(VALUE(MID(R0_L0!$C$82,$D20,1)) + VALUE(K1_16!F122), 2) -> 1 | M25: =MOD(VALUE(MID(R0_L0!$C$83,$D20,1)) + VALUE(K1_16!G122), 2) -> 0 | N25: =MOD(VALUE(MID(R0_L0!$C$84,$D20,1)) + VALUE(K1_16!H122), 2) -> 0 | O25: =MOD(VALUE(MID(R0_L0!$C$85,$D20,1)) + VALUE(K1_16!I122), 2) -> 1 | P25: =MOD(VALUE(MID(R0_L0!$C$86,$D20,1)) + VALUE(K1_16!J122), 2) -> 0 | Q25: =MOD(VALUE(MID(R0_L0!$C$87,$D20,1)) + VALUE(K1_16!K122), 2) -> 0 | R25: =MOD(VALUE(MID(R0_L0!$C$88,$D20,1)) + VALUE(K1_16!L122), 2) -> 0 | S25: =MOD(VALUE(MID(R0_L0!$C$89,$D20,1)) + VALUE(K1_16!M122), 2) -> 0 | T25: =MOD(VALUE(MID(R0_L0!$C$90,$D20,1)) + VALUE(K1_16!N122), 2) -> 0 | U25: =MOD(VALUE(MID(R0_L0!$C$91,$D20,1)) + VALUE(K1_16!O122), 2) -> 0 | V25: =MOD(VALUE(MID(R0_L0!$C$92,$D20,1)) + VALUE(K1_16!P122), 2) -> 1 | W25: =MOD(VALUE(MID(R0_L0!$C$93,$D20,1)) + VALUE(K1_16!Q122), 2) -> 1 | Z25: 0 | AA25: =MID($Q$8,D20,1) -> 1
A26: 21 | B26: 30 | C26: =MID($E$1,B26,1) -> 1 | D26: 14 | E26: 54 | H26: =MOD(VALUE(MID($Q$8,D21,1)) + VALUE(K1_16!$B123), 2) -> 0 | I26: =MOD(VALUE(MID(R0_L0!$C$79,D21,1)) + VALUE(K1_16!$C123), 2) -> 1 | J26: =MOD(VALUE(MID(R0_L0!$C$80,$D21,1)) + VALUE(K1_16!D123), 2) -> 0 | K26: =MOD(VALUE(MID(R0_L0!$C$81,$D21,1)) + VALUE(K1_16!E123), 2) -> 1 | L26: =MOD(VALUE(MID(R0_L0!$C$82,$D21,1)) + VALUE(K1_16!F123), 2) -> 0 | M26: =MOD(VALUE(MID(R0_L0!$C$83,$D21,1)) + VALUE(K1_16!G123), 2) -> 0 | N26: =MOD(VALUE(MID(R0_L0!$C$84,$D21,1)) + VALUE(K1_16!H123), 2) -> 0 | O26: =MOD(VALUE(MID(R0_L0!$C$85,$D21,1)) + VALUE(K1_16!I123), 2) -> 1 | P26: =MOD(VALUE(MID(R0_L0!$C$86,$D21,1)) + VALUE(K1_16!J123), 2) -> 0 | Q26: =MOD(VALUE(MID(R0_L0!$C$87,$D21,1)) + VALUE(K1_16!K123), 2) -> 0 | R26: =MOD(VALUE(MID(R0_L0!$C$88,$D21,1)) + VALUE(K1_16!L123), 2) -> 0 | S26: =MOD(VALUE(MID(R0_L0!$C$89,$D21,1)) + VALUE(K1_16!M123), 2) -> 1 | T26: =MOD(VALUE(MID(R0_L0!$C$90,$D21,1)) + VALUE(K1_16!N123), 2) -> 0 | U26: =MOD(VALUE(MID(R0_L0!$C$91,$D21,1)) + VALUE(K1_16!O123), 2) -> 0 | V26: =MOD(VALUE(MID(R0_L0!$C$92,$D21,1)) + VALUE(K1_16!P123), 2) -> 1 | W26: =MOD(VALUE(MID(R0_L0!$C$93,$D21,1)) + VALUE(K1_16!Q123), 2) -> 1 | Z26: 1 | AA26: =MID($Q$8,D21,1) -> 0
A27: 22 | B27: 22 | C27: =MID($E$1,B27,1) -> 1 | D27: 15 | E27: 22 | H27: =MOD(VALUE(MID($Q$8,D22,1)) + VALUE(K1_16!$B124), 2) -> 0 | I27: =MOD(VALUE(MID(R0_L0!$C$79,D22,1)) + VALUE(K1_16!$C124), 2) -> 1 | J27: =MOD(VALUE(MID(R0_L0!$C$80,$D22,1)) + VALUE(K1_16!D124), 2) -> 0 | K27: =MOD(VALUE(MID(R0_L0!$C$81,$D22,1)) + VALUE(K1_16!E124), 2) -> 0 | L27: =MOD(VALUE(MID(R0_L0!$C$82,$D22,1)) + VALUE(K1_16!F124), 2) -> 1 | M27: =MOD(VALUE(MID(R0_L0!$C$83,$D22,1)) + VALUE(K1_16!G124), 2) -> 0 | N27: =MOD(VALUE(MID(R0_L0!$C$84,$D22,1)) + VALUE(K1_16!H124), 2) -> 0 | O27: =MOD(VALUE(MID(R0_L0!$C$85,$D22,1)) + VALUE(K1_16!I124), 2) -> 1 | P27: =MOD(VALUE(MID(R0_L0!$C$86,$D22,1)) + VALUE(K1_16!J124), 2) -> 1 | Q27: =MOD(VALUE(MID(R0_L0!$C$87,$D22,1)) + VALUE(K1_16!K124), 2) -> 1 | R27: =MOD(VALUE(MID(R0_L0!$C$88,$D22,1)) + VALUE(K1_16!L124), 2) -> 0 | S27: =MOD(VALUE(MID(R0_L0!$C$89,$D22,1)) + VALUE(K1_16!M124), 2) -> 1 | T27: =MOD(VALUE(MID(R0_L0!$C$90,$D22,1)) + VALUE(K1_16!N124), 2) -> 0 | U27: =MOD(VALUE(MID(R0_L0!$C$91,$D22,1)) + VALUE(K1_16!O124), 2) -> 0 | V27: =MOD(VALUE(MID(R0_L0!$C$92,$D22,1)) + VALUE(K1_16!P124), 2) -> 1 | W27: =MOD(VALUE(MID(R0_L0!$C$93,$D22,1)) + VALUE(K1_16!Q124), 2) -> 0 | Z27: 1 | AA27: =MID($Q$8,D22,1) -> 1
... A53: 48 | B53: 3 | C53: =MID($E$1,B53,1) -> 0 | D53: 1 | E53: 27 | H53: =MOD(VALUE(MID($Q$8,D48,1)) + VALUE(K1_16!$B150), 2) -> 1 | I53: =MOD(VALUE(MID(R0_L0!$C$79,D48,1)) + VALUE(K1_16!$C150), 2) -> 0 | J53: =MOD(VALUE(MID(R0_L0!$C$80,$D48,1)) + VALUE(K1_16!D150), 2) -> 0 | K53: =MOD(VALUE(MID(R0_L0!$C$81,$D48,1)) + VALUE(K1_16!E150), 2) -> 0 | L53: =MOD(VALUE(MID(R0_L0!$C$82,$D48,1)) + VALUE(K1_16!F150), 2) -> 1 | M53: =MOD(VALUE(MID(R0_L0!$C$83,$D48,1)) + VALUE(K1_16!G150), 2) -> 1 | N53: =MOD(VALUE(MID(R0_L0!$C$84,$D48,1)) + VALUE(K1_16!H150), 2) -> 1 | O53: =MOD(VALUE(MID(R0_L0!$C$85,$D48,1)) + VALUE(K1_16!I150), 2) -> 1 | P53: =MOD(VALUE(MID(R0_L0!$C$86,$D48,1)) + VALUE(K1_16!J150), 2) -> 1 | Q53: =MOD(VALUE(MID(R0_L0!$C$87,$D48,1)) + VALUE(K1_16!K150), 2) -> 1 | R53: =MOD(VALUE(MID(R0_L0!$C$88,$D48,1)) + VALUE(K1_16!L150), 2) -> 1 | S53: =MOD(VALUE(MID(R0_L0!$C$89,$D48,1)) + VALUE(K1_16!M150), 2) -> 0 | T53: =MOD(VALUE(MID(R0_L0!$C$90,$D48,1)) + VALUE(K1_16!N150), 2) -> 1 | U53: =MOD(VALUE(MID(R0_L0!$C$91,$D48,1)) + VALUE(K1_16!O150), 2) -> 0 | V53: =MOD(VALUE(MID(R0_L0!$C$92,$D48,1)) + VALUE(K1_16!P150), 2) -> 1 | W53: =MOD(VALUE(MID(R0_L0!$C$93,$D48,1)) + VALUE(K1_16!Q150), 2) -> 0 | Z53: 0 | AA53: =MID($Q$8,D48,1) -> 0
A54: 49 | B54: 61 | C54: =MID($E$1,B54,1) -> 1 | E54: 34 | H54: =MOD(VALUE(MID($Q$8,D49,1)) + VALUE(K1_16!$B151), 2) -> 1 | I54: =MOD(VALUE(MID(R0_L0!$C$79,D49,1)) + VALUE(K1_16!$C151), 2) -> 1 | J54: =MOD(VALUE(MID(R0_L0!$C$80,$D49,1)) + VALUE(K1_16!D151), 2) -> 1 | K54: =MOD(VALUE(MID(R0_L0!$C$81,$D49,1)) + VALUE(K1_16!E151), 2) -> 0 | L54: =MOD(VALUE(MID(R0_L0!$C$82,$D49,1)) + VALUE(K1_16!F151), 2) -> 0 | M54: =MOD(VALUE(MID(R0_L0!$C$83,$D49,1)) + VALUE(K1_16!G151), 2) -> 0 | N54: =MOD(VALUE(MID(R0_L0!$C$84,$D49,1)) + VALUE(K1_16!H151), 2) -> 0 | O54: =MOD(VALUE(MID(R0_L0!$C$85,$D49,1)) + VALUE(K1_16!I151), 2) -> 0 | P54: =MOD(VALUE(MID(R0_L0!$C$86,$D49,1)) + VALUE(K1_16!J151), 2) -> 0 | Q54: =MOD(VALUE(MID(R0_L0!$C$87,$D49,1)) + VALUE(K1_16!K151), 2) -> 1 | R54: =MOD(VALUE(MID(R0_L0!$C$88,$D49,1)) + VALUE(K1_16!L151), 2) -> 0 | S54: =MOD(VALUE(MID(R0_L0!$C$89,$D49,1)) + VALUE(K1_16!M151), 2) -> 1 | T54: =MOD(VALUE(MID(R0_L0!$C$90,$D49,1)) + VALUE(K1_16!N151), 2) -> 0 | U54: =MOD(VALUE(MID(R0_L0!$C$91,$D49,1)) + VALUE(K1_16!O151), 2) -> 0 | V54: =MOD(VALUE(MID(R0_L0!$C$92,$D49,1)) + VALUE(K1_16!P151), 2) -> 1 | W54: =MOD(VALUE(MID(R0_L0!$C$93,$D49,1)) + VALUE(K1_16!Q151), 2) -> 1 | Z54: 0 | AA54: =MID($Q$8,D49,1) -> 1
A55: 50 | B55: 53 | C55: =MID($E$1,B55,1) -> 1 | E55: 2 | H55: =MOD(VALUE(MID($Q$8,D50,1)) + VALUE(K1_16!$B152), 2) -> 0 | I55: =MOD(VALUE(MID(R0_L0!$C$79,D50,1)) + VALUE(K1_16!$C152), 2) -> 0 | J55: =MOD(VALUE(MID(R0_L0!$C$80,$D50,1)) + VALUE(K1_16!D152), 2) -> 0 | K55: =MOD(VALUE(MID(R0_L0!$C$81,$D50,1)) + VALUE(K1_16!E152), 2) -> 0 | L55: =MOD(VALUE(MID(R0_L0!$C$82,$D50,1)) + VALUE(K1_16!F152), 2) -> 0 | M55: =MOD(VALUE(MID(R0_L0!$C$83,$D50,1)) + VALUE(K1_16!G152), 2) -> 1 | N55: =MOD(VALUE(MID(R0_L0!$C$84,$D50,1)) + VALUE(K1_16!H152), 2) -> 1 | O55: =MOD(VALUE(MID(R0_L0!$C$85,$D50,1)) + VALUE(K1_16!I152), 2) -> 1 | P55: =MOD(VALUE(MID(R0_L0!$C$86,$D50,1)) + VALUE(K1_16!J152), 2) -> 0 | Q55: =MOD(VALUE(MID(R0_L0!$C$87,$D50,1)) + VALUE(K1_16!K152), 2) -> 1 | R55: =MOD(VALUE(MID(R0_L0!$C$88,$D50,1)) + VALUE(K1_16!L152), 2) -> 1 | S55: =MOD(VALUE(MID(R0_L0!$C$89,$D50,1)) + VALUE(K1_16!M152), 2) -> 0 | T55: =MOD(VALUE(MID(R0_L0!$C$90,$D50,1)) + VALUE(K1_16!N152), 2) -> 0 | U55: =MOD(VALUE(MID(R0_L0!$C$91,$D50,1)) + VALUE(K1_16!O152), 2) -> 0 | V55: =MOD(VALUE(MID(R0_L0!$C$92,$D50,1)) + VALUE(K1_16!P152), 2) -> 1 | W55: =MOD(VALUE(MID(R0_L0!$C$93,$D50,1)) + VALUE(K1_16!Q152), 2) -> 1 | Z55: 1 | AA55: =MID($Q$8,D50,1) -> 0
A56: 51 | B56: 45 | C56: =MID($E$1,B56,1) -> 1 | E56: 42 | H56: =MOD(VALUE(MID($Q$8,D51,1)) + VALUE(K1_16!$B153), 2) -> 0 | I56: =MOD(VALUE(MID(R0_L0!$C$79,D51,1)) + VALUE(K1_16!$C153), 2) -> 0 | J56: =MOD(VALUE(MID(R0_L0!$C$80,$D51,1)) + VALUE(K1_16!D153), 2) -> 0 | K56: =MOD(VALUE(MID(R0_L0!$C$81,$D51,1)) + VALUE(K1_16!E153), 2) -> 1 | L56: =MOD(VALUE(MID(R0_L0!$C$82,$D51,1)) + VALUE(K1_16!F153), 2) -> 1 | M56: =MOD(VALUE(MID(R0_L0!$C$83,$D51,1)) + VALUE(K1_16!G153), 2) -> 1 | N56: =MOD(VALUE(MID(R0_L0!$C$84,$D51,1)) + VALUE(K1_16!H153), 2) -> 0 | O56: =MOD(VALUE(MID(R0_L0!$C$85,$D51,1)) + VALUE(K1_16!I153), 2) -> 1 | P56: =MOD(VALUE(MID(R0_L0!$C$86,$D51,1)) + VALUE(K1_16!J153), 2) -> 1 | Q56: =MOD(VALUE(MID(R0_L0!$C$87,$D51,1)) + VALUE(K1_16!K153), 2) -> 0 | R56: =MOD(VALUE(MID(R0_L0!$C$88,$D51,1)) + VALUE(K1_16!L153), 2) -> 0 | S56: =MOD(VALUE(MID(R0_L0!$C$89,$D51,1)) + VALUE(K1_16!M153), 2) -> 1 | T56: =MOD(VALUE(MID(R0_L0!$C$90,$D51,1)) + VALUE(K1_16!N153), 2) -> 0 | U56: =MOD(VALUE(MID(R0_L0!$C$91,$D51,1)) + VALUE(K1_16!O153), 2) -> 0 | V56: =MOD(VALUE(MID(R0_L0!$C$92,$D51,1)) + VALUE(K1_16!P153), 2) -> 0 | W56: =MOD(VALUE(MID(R0_L0!$C$93,$D51,1)) + VALUE(K1_16!Q153), 2) -> 1 | Z56: 0 | AA56: =MID($Q$8,D51,1) -> 1
A57: 52 | B57: 37 | C57: =MID($E$1,B57,1) -> 1 | E57: 10 | H57: =MOD(VALUE(MID($Q$8,D52,1)) + VALUE(K1_16!$B154), 2) -> 0 | I57: =MOD(VALUE(MID(R0_L0!$C$79,D52,1)) + VALUE(K1_16!$C154), 2) -> 1 | J57: =MOD(VALUE(MID(R0_L0!$C$80,$D52,1)) + VALUE(K1_16!D154), 2) -> 0 | K57: =MOD(VALUE(MID(R0_L0!$C$81,$D52,1)) + VALUE(K1_16!E154), 2) -> 1 | L57: =MOD(VALUE(MID(R0_L0!$C$82,$D52,1)) + VALUE(K1_16!F154), 2) -> 0 | M57: =MOD(VALUE(MID(R0_L0!$C$83,$D52,1)) + VALUE(K1_16!G154), 2) -> 1 | N57: =MOD(VALUE(MID(R0_L0!$C$84,$D52,1)) + VALUE(K1_16!H154), 2) -> 1 | O57: =MOD(VALUE(MID(R0_L0!$C$85,$D52,1)) + VALUE(K1_16!I154), 2) -> 1 | P57: =MOD(VALUE(MID(R0_L0!$C$86,$D52,1)) + VALUE(K1_16!J154), 2) -> 0 | Q57: =MOD(VALUE(MID(R0_L0!$C$87,$D52,1)) + VALUE(K1_16!K154), 2) -> 1 | R57: =MOD(VALUE(MID(R0_L0!$C$88,$D52,1)) + VALUE(K1_16!L154), 2) -> 1 | S57: =MOD(VALUE(MID(R0_L0!$C$89,$D52,1)) + VALUE(K1_16!M154), 2) -> 0 | T57: =MOD(VALUE(MID(R0_L0!$C$90,$D52,1)) + VALUE(K1_16!N154), 2) -> 1 | U57: =MOD(VALUE(MID(R0_L0!$C$91,$D52,1)) + VALUE(K1_16!O154), 2) -> 0 | V57: =MOD(VALUE(MID(R0_L0!$C$92,$D52,1)) + VALUE(K1_16!P154), 2) -> 1 | W57: =MOD(VALUE(MID(R0_L0!$C$93,$D52,1)) + VALUE(K1_16!Q154), 2) -> 0 | Z57: 1 | AA57: =MID($Q$8,D52,1) -> 0
A58: 53 | B58: 29 | C58: =MID($E$1,B58,1) -> 0 | E58: 50 | H58: =MOD(VALUE(MID($Q$8,D53,1)) + VALUE(K1_16!$B155), 2) -> 0 | I58: =MOD(VALUE(MID(R0_L0!$C$79,D53,1)) + VALUE(K1_16!$C155), 2) -> 0 | J58: =MOD(VALUE(MID(R0_L0!$C$80,$D53,1)) + VALUE(K1_16!D155), 2) -> 0 | K58: =MOD(VALUE(MID(R0_L0!$C$81,$D53,1)) + VALUE(K1_16!E155), 2) -> 0 | L58: =MOD(VALUE(MID(R0_L0!$C$82,$D53,1)) + VALUE(K1_16!F155), 2) -> 1 | M58: =MOD(VALUE(MID(R0_L0!$C$83,$D53,1)) + VALUE(K1_16!G155), 2) -> 1 | N58: =MOD(VALUE(MID(R0_L0!$C$84,$D53,1)) + VALUE(K1_16!H155), 2) -> 0 | O58: =MOD(VALUE(MID(R0_L0!$C$85,$D53,1)) + VALUE(K1_16!I155), 2) -> 1 | P58: =MOD(VALUE(MID(R0_L0!$C$86,$D53,1)) + VALUE(K1_16!J155), 2) -> 1 | Q58: =MOD(VALUE(MID(R0_L0!$C$87,$D53,1)) + VALUE(K1_16!K155), 2) -> 1 | R58: =MOD(VALUE(MID(R0_L0!$C$88,$D53,1)) + VALUE(K1_16!L155), 2) -> 1 | S58: =MOD(VALUE(MID(R0_L0!$C$89,$D53,1)) + VALUE(K1_16!M155), 2) -> 1 | T58: =MOD(VALUE(MID(R0_L0!$C$90,$D53,1)) + VALUE(K1_16!N155), 2) -> 0 | U58: =MOD(VALUE(MID(R0_L0!$C$91,$D53,1)) + VALUE(K1_16!O155), 2) -> 1 | V58: =MOD(VALUE(MID(R0_L0!$C$92,$D53,1)) + VALUE(K1_16!P155), 2) -> 0 | W58: =MOD(VALUE(MID(R0_L0!$C$93,$D53,1)) + VALUE(K1_16!Q155), 2) -> 0 | AA58: =MID($Q$8,D53,1) -> 1
A59: 54 | B59: 21 | C59: =MID($E$1,B59,1) -> 0 | E59: 18
A60: 55 | B60: 13 | C60: =MID($E$1,B60,1) -> 0 | E60: 58
A61: 56 | B61: 5 | C61: =MID($E$1,B61,1) -> 0 | E61: 26
A62: 57 | B62: 63 | C62: =MID($E$1,B62,1) -> 1 | E62: 33
A63: 58 | B63: 55 | C63: =MID($E$1,B63,1) -> 0 | E63: 1 | H63: CHIA THÀNH CÁC KÍ TỰ 6 Bit
A64: 59 | B64: 47 | C64: =MID($E$1,B64,1) -> 1 | E64: 41
A65: 60 | B65: 39 | C65: =MID($E$1,B65,1) -> 0 | E65: 9 | G65: i= | H65: 1 | I65: 2 | J65: 3 | K65: 4 | L65: 5 | M65: 6 | N65: 7 | O65: 8 | P65: 9 | Q65: 10 | R65: 11 | S65: 12 | T65: 13 | U65: 14 | V65: 15 | W65: 16
A66: 61 | B66: 31 | C66: =MID($E$1,B66,1) -> 1 | E66: 49 | G66: 1 | H66: =MID(_xlfn.TEXTJOIN("",TRUE,H$11:H$58), 1 + 6*($G66-1), 6) -> 011010 | I66: =MID(_xlfn.TEXTJOIN("",TRUE,I$11:I$58), 1 + 6*($G66-1), 6) -> 011011 | J66: =MID(_xlfn.TEXTJOIN("",TRUE,J$11:J$58), 1 + 6*($G66-1), 6) -> 111000 | K66: =MID(_xlfn.TEXTJOIN("",TRUE,K$11:K$58), 1 + 6*($G66-1), 6) -> 000110 | L66: =MID(_xlfn.TEXTJOIN("",TRUE,L$11:L$58), 1 + 6*($G66-1), 6) -> 101100 | M66: =MID(_xlfn.TEXTJOIN("",TRUE,M$11:M$58), 1 + 6*($G66-1), 6) -> 111001 | N66: =MID(_xlfn.TEXTJOIN("",TRUE,N$11:N$58), 1 + 6*($G66-1), 6) -> 011101 | O66: =MID(_xlfn.TEXTJOIN("",TRUE,O$11:O$58), 1 + 6*($G66-1), 6) -> 010101 | ... W66: =MID(_xlfn.TEXTJOIN("",TRUE,W$11:W$58), 1 + 6*($G66-1), 6) -> 011111
A67: 62 | B67: 23 | C67: =MID($E$1,B67,1) -> 0 | E67: 17 | G67: 2 | H67: =MID(_xlfn.TEXTJOIN("",TRUE,$H$11:$H$58), 1 + 6*(G67-1), 6) -> 110000 | I67: =MID(_xlfn.TEXTJOIN("",TRUE,I$11:I$58), 1 + 6*($G67-1), 6) -> 000100 | J67: =MID(_xlfn.TEXTJOIN("",TRUE,J$11:J$58), 1 + 6*($G67-1), 6) -> 001111 | K67: =MID(_xlfn.TEXTJOIN("",TRUE,K$11:K$58), 1 + 6*($G67-1), 6) -> 000000 | L67: =MID(_xlfn.TEXTJOIN("",TRUE,L$11:L$58), 1 + 6*($G67-1), 6) -> 110110 | M67: =MID(_xlfn.TEXTJOIN("",TRUE,M$11:M$58), 1 + 6*($G67-1), 6) -> 100000 | N67: =MID(_xlfn.TEXTJOIN("",TRUE,N$11:N$58), 1 + 6*($G67-1), 6) -> 101111 | O67: =MID(_xlfn.TEXTJOIN("",TRUE,O$11:O$58), 1 + 6*($G67-1), 6) -> 111110 | P67: =MID(_xlfn.TEXTJOIN("",TRUE,P$11:P$58), 1 + 6*($G67-1), 6) -> 110011 | ... W67: =MID(_xlfn.TEXTJOIN("",TRUE,W$11:W$58), 1 + 6*($G67-1), 6) -> 101111
A68: 63 | B68: 15 | C68: =MID($E$1,B68,1) -> 1 | E68: 57 | G68: 3 | H68: =MID(_xlfn.TEXTJOIN("",TRUE,$H$11:$H$58), 1 + 6*(G68-1), 6) -> 000001 | I68: =MID(_xlfn.TEXTJOIN("",TRUE,I$11:I$58), 1 + 6*($G68-1), 6) -> 011110 | J68: =MID(_xlfn.TEXTJOIN("",TRUE,J$11:J$58), 1 + 6*($G68-1), 6) -> 110001 | K68: =MID(_xlfn.TEXTJOIN("",TRUE,K$11:K$58), 1 + 6*($G68-1), 6) -> 010101 | L68: =MID(_xlfn.TEXTJOIN("",TRUE,L$11:L$58), 1 + 6*($G68-1), 6) -> 111010 | M68: =MID(_xlfn.TEXTJOIN("",TRUE,M$11:M$58), 1 + 6*($G68-1), 6) -> 110000 | N68: =MID(_xlfn.TEXTJOIN("",TRUE,N$11:N$58), 1 + 6*($G68-1), 6) -> 100000 | O68: =MID(_xlfn.TEXTJOIN("",TRUE,O$11:O$58), 1 + 6*($G68-1), 6) -> 001110 | P68: =MID(_xlfn.TEXTJOIN("",TRUE,P$11:P$58), 1 + 6*($G68-1), 6) -> 000010 | ... W68: =MID(_xlfn.TEXTJOIN("",TRUE,W$11:W$58), 1 + 6*($G68-1), 6) -> 111100
...

Sheet R0_L0
A1: Ip(M) = | B1: ='Ham_f(RxorK)'!J5 -> 1001100011111110110011000000000011100000010101001111000010101010
A2: L0 = | B2: =LEFT(B1,32) -> 10011000111111101100110000000000 | H2: R0 = | I2: =RIGHT(B1,32) -> 11100000010101001111000010101010
A8: L0 | B8: L1 | C8: L2 | D8: L3 | E8: L4 | F8: L5 | G8: L6 | H8: L7 | I8: L8 | J8: L9 | K8: L10 | L8: L11 | M8: L12 | N8: L13 | O8: L14 | P8: L15 | Q8: L16
A9: =MID($B$2,ROW(A1),1) -> 1 | B9: =A44 -> 1 | C9: =B44 -> 0 | D9: =C44 -> 0 | E9: =D44 -> 1 | F9: =E44 -> 1 | G9: =F44 -> 0 | H9: =G44 -> 0 | I9: =H44 -> 0 | ... Q9: =P44 -> 0
A10: =MID($B$2,ROW(A2),1) -> 0 | B10: =A45 -> 1 | C10: =B45 -> 0 | D10: =C45 -> 1 | E10: =D45 -> 1 | F10: =E45 -> 0 | G10: =F45 -> 0 | H10: =G45 -> 0 | I10: =H45 -> 1 | ... Q10: =P45 -> 1
A11: =MID($B$2,ROW(A3),1) -> 0 | B11: =A46 -> 1 | C11: =B46 -> 0 | D11: =C46 -> 1 | E11: =D46 -> 0 | F11: =E46 -> 0 | G11: =F46 -> 0 | H11: =G46 -> 1 | I11: =H46 -> 0 | ... Q11: =P46 -> 1
A12: =MID($B$2,ROW(A4),1) -> 1 | B12: =A47 -> 0 | C12: =B47 -> 0 | D12: =C47 -> 0 | E12: =D47 -> 1 | F12: =E47 -> 1 | G12: =F47 -> 0 | H12: =G47 -> 1 | I12: =H47 -> 0 | ... Q12: =P47 -> 0
A13: =MID($B$2,ROW(A5),1) -> 1 | B13: =A48 -> 0 | C13: =B48 -> 1 | D13: =C48 -> 1 | E13: =D48 -> 0 | F13: =E48 -> 1 | G13: =F48 -> 1 | H13: =G48 -> 0 | I13: =H48 -> 0 | ... Q13: =P48 -> 1
A14: =MID($B$2,ROW(A6),1) -> 0 | B14: =A49 -> 0 | C14: =B49 -> 1 | D14: =C49 -> 0 | E14: =D49 -> 1 | F14: =E49 -> 1 | G14: =F49 -> 1 | H14: =G49 -> 0 | I14: =H49 -> 0 | ... Q14: =P49 -> 1
A15: =MID($B$2,ROW(A7),1) -> 0 | B15: =A50 -> 0 | C15: =B50 -> 1 | D15: =C50 -> 0 | E15: =D50 -> 0 | F15: =E50 -> 0 | G15: =F50 -> 0 | H15: =G50 -> 1 | I15: =H50 -> 1 | ... Q15: =P50 -> 1
A16: =MID($B$2,ROW(A8),1) -> 0 | B16: =A51 -> 0 | C16: =B51 -> 1 | D16: =C51 -> 0 | E16: =D51 -> 1 | F16: =E51 -> 0 | G16: =F51 -> 1 | H16: =G51 -> 1 | I16: =H51 -> 1 | ... Q16: =P51 -> 0
A17: =MID($B$2,ROW(A9),1) -> 1 | B17: =A52 -> 0 | C17: =B52 -> 0 | D17: =C52 -> 0 | E17: =D52 -> 0 | F17: =E52 -> 0 | G17: =F52 -> 0 | H17: =G52 -> 1 | I17: =H52 -> 0 | ... Q17: =P52 -> 0
A18: =MID($B$2,ROW(A10),1) -> 1 | B18: =A53 -> 1 | C18: =B53 -> 0 | D18: =C53 -> 0 | E18: =D53 -> 0 | F18: =E53 -> 1 | G18: =F53 -> 0 | H18: =G53 -> 0 | I18: =H53 -> 1 | ... Q18: =P53 -> 1
A19: =MID($B$2,ROW(A11),1) -> 1 | B19: =A54 -> 0 | C19: =B54 -> 1 | D19: =C54 -> 0 | E19: =D54 -> 0 | F19: =E54 -> 0 | G19: =F54 -> 1 | H19: =G54 -> 0 | I19: =H54 -> 1 | ... Q19: =P54 -> 0
A20: =MID($B$2,ROW(A12),1) -> 1 | B20: =A55 -> 1 | C20: =B55 -> 0 | D20: =C55 -> 1 | E20: =D55 -> 1 | F20: =E55 -> 1 | G20: =F55 -> 0 | H20: =G55 -> 1 | I20: =H55 -> 1 | ... Q20: =P55 -> 0
... A40: =MID($B$2,ROW(A32),1) -> 0 | B40: =A75 -> 0 | C40: =B75 -> 0 | D40: =C75 -> 1 | E40: =D75 -> 0 | F40: =E75 -> 1 | G40: =F75 -> 1 | H40: =G75 -> 0 | I40: =H75 -> 1 | ... Q40: =P75 -> 1
A43: R0 | B43: R1 | C43: R2 | D43: R3 | E43: R4 | F43: R5 | G43: R6 | H43: R7 | I43: R8 | J43: R9 | K43: R10 | L43: R11 | M43: R12 | N43: R13 | O43: R14 | P43: R15 | Q43: R16
A44: =MID($I$2,ROW(A1),1) -> 1 | B44: =MOD(A9 + MID('Ham_f(RxorK)'!$I$88, ROW(A1), 1), 2) -> 0 | C44: =MOD(B9 + MID('Ham_f(RxorK)'!$I$89, ROW($A1), 1), 2) -> 0 | D44: =MOD(C9 + MID('Ham_f(RxorK)'!$I$90, ROW($A1), 1), 2) -> 1 | E44: =MOD(D9 + MID('Ham_f(RxorK)'!$I$91, ROW($A1), 1), 2) -> 1 | F44: =MOD(E9 + MID('Ham_f(RxorK)'!$I$92, ROW($A1), 1), 2) -> 0 | G44: =MOD(F9 + MID('Ham_f(RxorK)'!$I$93, ROW($A1), 1), 2) -> 0 | H44: =MOD(G9 + MID('Ham_f(RxorK)'!$I$94, ROW($A1), 1), 2) -> 0 | I44: =MOD(H9 + MID('Ham_f(RxorK)'!$I$95, ROW($A1), 1), 2) -> 0 | J44: =MOD(I9 + MID('Ham_f(RxorK)'!$I$96, ROW($A1), 1), 2) -> 1 | K44: =MOD(J9 + MID('Ham_f(RxorK)'!$I$97, ROW($A1), 1), 2) -> 1 | L44: =MOD(K9 + MID('Ham_f(RxorK)'!$I$98, ROW($A1), 1), 2) -> 0 | M44: =MOD(L9 + MID('Ham_f(RxorK)'!$I$99, ROW($A1), 1), 2) -> 1 | N44: =MOD(M9 + MID('Ham_f(RxorK)'!$I$100, ROW($A1), 1), 2) -> 0 | O44: =MOD(N9 + MID('Ham_f(RxorK)'!$I$101, ROW($A1), 1), 2) -> 1 | P44: =MOD(O9 + MID('Ham_f(RxorK)'!$I$102, ROW($A1), 1), 2) -> 0 | Q44: =MOD(P9 + MID('Ham_f(RxorK)'!$I$103, ROW($A1), 1), 2) -> 0
A45: =MID($I$2,ROW(A2),1) -> 1 | B45: =MOD(A10 + MID('Ham_f(RxorK)'!$I$88, ROW(A2), 1), 2) -> 0 | C45: =MOD(B10 + MID('Ham_f(RxorK)'!$I$89, ROW($A2), 1), 2) -> 1 | D45: =MOD(C10 + MID('Ham_f(RxorK)'!$I$90, ROW($A2), 1), 2) -> 1 | E45: =MOD(D10 + MID('Ham_f(RxorK)'!$I$91, ROW($A2), 1), 2) -> 0 | F45: =MOD(E10 + MID('Ham_f(RxorK)'!$I$92, ROW($A2), 1), 2) -> 0 | G45: =MOD(F10 + MID('Ham_f(RxorK)'!$I$93, ROW($A2), 1), 2) -> 0 | H45: =MOD(G10 + MID('Ham_f(RxorK)'!$I$94, ROW($A2), 1), 2) -> 1 | I45: =MOD(H10 + MID('Ham_f(RxorK)'!$I$95, ROW($A2), 1), 2) -> 1 | J45: =MOD(I10 + MID('Ham_f(RxorK)'!$I$96, ROW($A2), 1), 2) -> 0 | K45: =MOD(J10 + MID('Ham_f(RxorK)'!$I$97, ROW($A2), 1), 2) -> 0 | L45: =MOD(K10 + MID('Ham_f(RxorK)'!$I$98, ROW($A2), 1), 2) -> 1 | M45: =MOD(L10 + MID('Ham_f(RxorK)'!$I$99, ROW($A2), 1), 2) -> 1 | N45: =MOD(M10 + MID('Ham_f(RxorK)'!$I$100, ROW($A2), 1), 2) -> 0 | O45: =MOD(N10 + MID('Ham_f(RxorK)'!$I$101, ROW($A2), 1), 2) -> 0 | P45: =MOD(O10 + MID('Ham_f(RxorK)'!$I$102, ROW($A2), 1), 2) -> 1 | Q45: =MOD(P10 + MID('Ham_f(RxorK)'!$I$103, ROW($A2), 1), 2) -> 1
A46: =MID($I$2,ROW(A3),1) -> 1 | B46: =MOD(A11 + MID('Ham_f(RxorK)'!$I$88, ROW(A3), 1), 2) -> 0 | C46: =MOD(B11 + MID('Ham_f(RxorK)'!$I$89, ROW($A3), 1), 2) -> 1 | D46: =MOD(C11 + MID('Ham_f(RxorK)'!$I$90, ROW($A3), 1), 2) -> 0 | E46: =MOD(D11 + MID('Ham_f(RxorK)'!$I$91, ROW($A3), 1), 2) -> 0 | F46: =MOD(E11 + MID('Ham_f(RxorK)'!$I$92, ROW($A3), 1), 2) -> 0 | G46: =MOD(F11 + MID('Ham_f(RxorK)'!$I$93, ROW($A3), 1), 2) -> 1 | H46: =MOD(G11 + MID('Ham_f(RxorK)'!$I$94, ROW($A3), 1), 2) -> 0 | I46: =MOD(H11 + MID('Ham_f(RxorK)'!$I$95, ROW($A3), 1), 2) -> 0 | J46: =MOD(I11 + MID('Ham_f(RxorK)'!$I$96, ROW($A3), 1), 2) -> 1 | K46: =MOD(J11 + MID('Ham_f(RxorK)'!$I$97, ROW($A3), 1), 2) -> 0 | L46: =MOD(K11 + MID('Ham_f(RxorK)'!$I$98, ROW($A3), 1), 2) -> 0 | M46: =MOD(L11 + MID('Ham_f(RxorK)'!$I$99, ROW($A3), 1), 2) -> 1 | N46: =MOD(M11 + MID('Ham_f(RxorK)'!$I$100, ROW($A3), 1), 2) -> 1 | O46: =MOD(N11 + MID('Ham_f(RxorK)'!$I$101, ROW($A3), 1), 2) -> 0 | P46: =MOD(O11 + MID('Ham_f(RxorK)'!$I$102, ROW($A3), 1), 2) -> 1 | Q46: =MOD(P11 + MID('Ham_f(RxorK)'!$I$103, ROW($A3), 1), 2) -> 0
A47: =MID($I$2,ROW(A4),1) -> 0 | B47: =MOD(A12 + MID('Ham_f(RxorK)'!$I$88, ROW(A4), 1), 2) -> 0 | C47: =MOD(B12 + MID('Ham_f(RxorK)'!$I$89, ROW($A4), 1), 2) -> 0 | D47: =MOD(C12 + MID('Ham_f(RxorK)'!$I$90, ROW($A4), 1), 2) -> 1 | E47: =MOD(D12 + MID('Ham_f(RxorK)'!$I$91, ROW($A4), 1), 2) -> 1 | F47: =MOD(E12 + MID('Ham_f(RxorK)'!$I$92, ROW($A4), 1), 2) -> 0 | G47: =MOD(F12 + MID('Ham_f(RxorK)'!$I$93, ROW($A4), 1), 2) -> 1 | H47: =MOD(G12 + MID('Ham_f(RxorK)'!$I$94, ROW($A4), 1), 2) -> 0 | I47: =MOD(H12 + MID('Ham_f(RxorK)'!$I$95, ROW($A4), 1), 2) -> 1 | J47: =MOD(I12 + MID('Ham_f(RxorK)'!$I$96, ROW($A4), 1), 2) -> 1 | K47: =MOD(J12 + MID('Ham_f(RxorK)'!$I$97, ROW($A4), 1), 2) -> 0 | L47: =MOD(K12 + MID('Ham_f(RxorK)'!$I$98, ROW($A4), 1), 2) -> 0 | M47: =MOD(L12 + MID('Ham_f(RxorK)'!$I$99, ROW($A4), 1), 2) -> 1 | N47: =MOD(M12 + MID('Ham_f(RxorK)'!$I$100, ROW($A4), 1), 2) -> 1 | O47: =MOD(N12 + MID('Ham_f(RxorK)'!$I$101, ROW($A4), 1), 2) -> 1 | P47: =MOD(O12 + MID('Ham_f(RxorK)'!$I$102, ROW($A4), 1), 2) -> 0 | Q47: =MOD(P12 + MID('Ham_f(RxorK)'!$I$103, ROW($A4), 1), 2) -> 1
A48: =MID($I$2,ROW(A5),1) -> 0 | B48: =MOD(A13 + MID('Ham_f(RxorK)'!$I$88, ROW(A5), 1), 2) -> 1 | C48: =MOD(B13 + MID('Ham_f(RxorK)'!$I$89, ROW($A5), 1), 2) -> 1 | D48: =MOD(C13 + MID('Ham_f(RxorK)'!$I$90, ROW($A5), 1), 2) -> 0 | E48: =MOD(D13 + MID('Ham_f(RxorK)'!$I$91, ROW($A5), 1), 2) -> 1 | F48: =MOD(E13 + MID('Ham_f(RxorK)'!$I$92, ROW($A5), 1), 2) -> 1 | G48: =MOD(F13 + MID('Ham_f(RxorK)'!$I$93, ROW($A5), 1), 2) -> 0 | H48: =MOD(G13 + MID('Ham_f(RxorK)'!$I$94, ROW($A5), 1), 2) -> 0 | I48: =MOD(H13 + MID('Ham_f(RxorK)'!$I$95, ROW($A5), 1), 2) -> 1 | J48: =MOD(I13 + MID('Ham_f(RxorK)'!$I$96, ROW($A5), 1), 2) -> 1 | K48: =MOD(J13 + MID('Ham_f(RxorK)'!$I$97, ROW($A5), 1), 2) -> 1 | L48: =MOD(K13 + MID('Ham_f(RxorK)'!$I$98, ROW($A5), 1), 2) -> 0 | M48: =MOD(L13 + MID('Ham_f(RxorK)'!$I$99, ROW($A5), 1), 2) -> 1 | N48: =MOD(M13 + MID('Ham_f(RxorK)'!$I$100, ROW($A5), 1), 2) -> 1 | O48: =MOD(N13 + MID('Ham_f(RxorK)'!$I$101, ROW($A5), 1), 2) -> 1 | P48: =MOD(O13 + MID('Ham_f(RxorK)'!$I$102, ROW($A5), 1), 2) -> 1 | Q48: =MOD(P13 + MID('Ham_f(RxorK)'!$I$103, ROW($A5), 1), 2) -> 0
A49: =MID($I$2,ROW(A6),1) -> 0 | B49: =MOD(A14 + MID('Ham_f(RxorK)'!$I$88, ROW(A6), 1), 2) -> 1 | C49: =MOD(B14 + MID('Ham_f(RxorK)'!$I$89, ROW($A6), 1), 2) -> 0 | D49: =MOD(C14 + MID('Ham_f(RxorK)'!$I$90, ROW($A6), 1), 2) -> 1 | E49: =MOD(D14 + MID('Ham_f(RxorK)'!$I$91, ROW($A6), 1), 2) -> 1 | F49: =MOD(E14 + MID('Ham_f(RxorK)'!$I$92, ROW($A6), 1), 2) -> 1 | G49: =MOD(F14 + MID('Ham_f(RxorK)'!$I$93, ROW($A6), 1), 2) -> 0 | H49: =MOD(G14 + MID('Ham_f(RxorK)'!$I$94, ROW($A6), 1), 2) -> 0 | I49: =MOD(H14 + MID('Ham_f(RxorK)'!$I$95, ROW($A6), 1), 2) -> 1 | J49: =MOD(I14 + MID('Ham_f(RxorK)'!$I$96, ROW($A6), 1), 2) -> 0 | K49: =MOD(J14 + MID('Ham_f(RxorK)'!$I$97, ROW($A6), 1), 2) -> 0 | L49: =MOD(K14 + MID('Ham_f(RxorK)'!$I$98, ROW($A6), 1), 2) -> 1 | M49: =MOD(L14 + MID('Ham_f(RxorK)'!$I$99, ROW($A6), 1), 2) -> 0 | N49: =MOD(M14 + MID('Ham_f(RxorK)'!$I$100, ROW($A6), 1), 2) -> 1 | O49: =MOD(N14 + MID('Ham_f(RxorK)'!$I$101, ROW($A6), 1), 2) -> 1 | P49: =MOD(O14 + MID('Ham_f(RxorK)'!$I$102, ROW($A6), 1), 2) -> 1 | Q49: =MOD(P14 + MID('Ham_f(RxorK)'!$I$103, ROW($A6), 1), 2) -> 1
A50: =MID($I$2,ROW(A7),1) -> 0 | B50: =MOD(A15 + MID('Ham_f(RxorK)'!$I$88, ROW(A7), 1), 2) -> 1 | C50: =MOD(B15 + MID('Ham_f(RxorK)'!$I$89, ROW($A7), 1), 2) -> 0 | D50: =MOD(C15 + MID('Ham_f(RxorK)'!$I$90, ROW($A7), 1), 2) -> 0 | E50: =MOD(D15 + MID('Ham_f(RxorK)'!$I$91, ROW($A7), 1), 2) -> 0 | F50: =MOD(E15 + MID('Ham_f(RxorK)'!$I$92, ROW($A7), 1), 2) -> 0 | G50: =MOD(F15 + MID('Ham_f(RxorK)'!$I$93, ROW($A7), 1), 2) -> 1 | H50: =MOD(G15 + MID('Ham_f(RxorK)'!$I$94, ROW($A7), 1), 2) -> 1 | I50: =MOD(H15 + MID('Ham_f(RxorK)'!$I$95, ROW($A7), 1), 2) -> 1 | J50: =MOD(I15 + MID('Ham_f(RxorK)'!$I$96, ROW($A7), 1), 2) -> 0 | K50: =MOD(J15 + MID('Ham_f(RxorK)'!$I$97, ROW($A7), 1), 2) -> 1 | L50: =MOD(K15 + MID('Ham_f(RxorK)'!$I$98, ROW($A7), 1), 2) -> 0 | M50: =MOD(L15 + MID('Ham_f(RxorK)'!$I$99, ROW($A7), 1), 2) -> 1 | N50: =MOD(M15 + MID('Ham_f(RxorK)'!$I$100, ROW($A7), 1), 2) -> 1 | O50: =MOD(N15 + MID('Ham_f(RxorK)'!$I$101, ROW($A7), 1), 2) -> 1 | P50: =MOD(O15 + MID('Ham_f(RxorK)'!$I$102, ROW($A7), 1), 2) -> 1 | Q50: =MOD(P15 + MID('Ham_f(RxorK)'!$I$103, ROW($A7), 1), 2) -> 0
A51: =MID($I$2,ROW(A8),1) -> 0 | B51: =MOD(A16 + MID('Ham_f(RxorK)'!$I$88, ROW(A8), 1), 2) -> 1 | C51: =MOD(B16 + MID('Ham_f(RxorK)'!$I$89, ROW($A8), 1), 2) -> 0 | D51: =MOD(C16 + MID('Ham_f(RxorK)'!$I$90, ROW($A8), 1), 2) -> 1 | E51: =MOD(D16 + MID('Ham_f(RxorK)'!$I$91, ROW($A8), 1), 2) -> 0 | F51: =MOD(E16 + MID('Ham_f(RxorK)'!$I$92, ROW($A8), 1), 2) -> 1 | G51: =MOD(F16 + MID('Ham_f(RxorK)'!$I$93, ROW($A8), 1), 2) -> 1 | H51: =MOD(G16 + MID('Ham_f(RxorK)'!$I$94, ROW($A8), 1), 2) -> 1 | I51: =MOD(H16 + MID('Ham_f(RxorK)'!$I$95, ROW($A8), 1), 2) -> 1 | J51: =MOD(I16 + MID('Ham_f(RxorK)'!$I$96, ROW($A8), 1), 2) -> 0 | K51: =MOD(J16 + MID('Ham_f(RxorK)'!$I$97, ROW($A8), 1), 2) -> 0 | L51: =MOD(K16 + MID('Ham_f(RxorK)'!$I$98, ROW($A8), 1), 2) -> 0 | M51: =MOD(L16 + MID('Ham_f(RxorK)'!$I$99, ROW($A8), 1), 2) -> 0 | N51: =MOD(M16 + MID('Ham_f(RxorK)'!$I$100, ROW($A8), 1), 2) -> 1 | O51: =MOD(N16 + MID('Ham_f(RxorK)'!$I$101, ROW($A8), 1), 2) -> 1 | P51: =MOD(O16 + MID('Ham_f(RxorK)'!$I$102, ROW($A8), 1), 2) -> 0 | Q51: =MOD(P16 + MID('Ham_f(RxorK)'!$I$103, ROW($A8), 1), 2) -> 0
A52: =MID($I$2,ROW(A9),1) -> 0 | B52: =MOD(A17 + MID('Ham_f(RxorK)'!$I$88, ROW(A9), 1), 2) -> 0 | C52: =MOD(B17 + MID('Ham_f(RxorK)'!$I$89, ROW($A9), 1), 2) -> 0 | D52: =MOD(C17 + MID('Ham_f(RxorK)'!$I$90, ROW($A9), 1), 2) -> 0 | E52: =MOD(D17 + MID('Ham_f(RxorK)'!$I$91, ROW($A9), 1), 2) -> 0 | F52: =MOD(E17 + MID('Ham_f(RxorK)'!$I$92, ROW($A9), 1), 2) -> 0 | G52: =MOD(F17 + MID('Ham_f(RxorK)'!$I$93, ROW($A9), 1), 2) -> 1 | H52: =MOD(G17 + MID('Ham_f(RxorK)'!$I$94, ROW($A9), 1), 2) -> 0 | I52: =MOD(H17 + MID('Ham_f(RxorK)'!$I$95, ROW($A9), 1), 2) -> 0 | J52: =MOD(I17 + MID('Ham_f(RxorK)'!$I$96, ROW($A9), 1), 2) -> 0 | K52: =MOD(J17 + MID('Ham_f(RxorK)'!$I$97, ROW($A9), 1), 2) -> 0 | L52: =MOD(K17 + MID('Ham_f(RxorK)'!$I$98, ROW($A9), 1), 2) -> 1 | M52: =MOD(L17 + MID('Ham_f(RxorK)'!$I$99, ROW($A9), 1), 2) -> 0 | N52: =MOD(M17 + MID('Ham_f(RxorK)'!$I$100, ROW($A9), 1), 2) -> 0 | O52: =MOD(N17 + MID('Ham_f(RxorK)'!$I$101, ROW($A9), 1), 2) -> 1 | P52: =MOD(O17 + MID('Ham_f(RxorK)'!$I$102, ROW($A9), 1), 2) -> 0 | Q52: =MOD(P17 + MID('Ham_f(RxorK)'!$I$103, ROW($A9), 1), 2) -> 0
A53: =MID($I$2,ROW(A10),1) -> 1 | B53: =MOD(A18 + MID('Ham_f(RxorK)'!$I$88, ROW(A10), 1), 2) -> 0 | C53: =MOD(B18 + MID('Ham_f(RxorK)'!$I$89, ROW($A10), 1), 2) -> 0 | D53: =MOD(C18 + MID('Ham_f(RxorK)'!$I$90, ROW($A10), 1), 2) -> 0 | E53: =MOD(D18 + MID('Ham_f(RxorK)'!$I$91, ROW($A10), 1), 2) -> 1 | F53: =MOD(E18 + MID('Ham_f(RxorK)'!$I$92, ROW($A10), 1), 2) -> 0 | G53: =MOD(F18 + MID('Ham_f(RxorK)'!$I$93, ROW($A10), 1), 2) -> 0 | H53: =MOD(G18 + MID('Ham_f(RxorK)'!$I$94, ROW($A10), 1), 2) -> 1 | I53: =MOD(H18 + MID('Ham_f(RxorK)'!$I$95, ROW($A10), 1), 2) -> 1 | J53: =MOD(I18 + MID('Ham_f(RxorK)'!$I$96, ROW($A10), 1), 2) -> 1 | K53: =MOD(J18 + MID('Ham_f(RxorK)'!$I$97, ROW($A10), 1), 2) -> 1 | L53: =MOD(K18 + MID('Ham_f(RxorK)'!$I$98, ROW($A10), 1), 2) -> 0 | M53: =MOD(L18 + MID('Ham_f(RxorK)'!$I$99, ROW($A10), 1), 2) -> 0 | N53: =MOD(M18 + MID('Ham_f(RxorK)'!$I$100, ROW($A10), 1), 2) -> 1 | O53: =MOD(N18 + MID('Ham_f(RxorK)'!$I$101, ROW($A10), 1), 2) -> 1 | P53: =MOD(O18 + MID('Ham_f(RxorK)'!$I$102, ROW($A10), 1), 2) -> 1 | Q53: =MOD(P18 + MID('Ham_f(RxorK)'!$I$103, ROW($A10), 1), 2) -> 0
A54: =MID($I$2,ROW(A11),1) -> 0 | B54: =MOD(A19 + MID('Ham_f(RxorK)'!$I$88, ROW(A11), 1), 2) -> 1 | C54: =MOD(B19 + MID('Ham_f(RxorK)'!$I$89, ROW($A11), 1), 2) -> 0 | D54: =MOD(C19 + MID('Ham_f(RxorK)'!$I$90, ROW($A11), 1), 2) -> 0 | E54: =MOD(D19 + MID('Ham_f(RxorK)'!$I$91, ROW($A11), 1), 2) -> 0 | F54: =MOD(E19 + MID('Ham_f(RxorK)'!$I$92, ROW($A11), 1), 2) -> 1 | G54: =MOD(F19 + MID('Ham_f(RxorK)'!$I$93, ROW($A11), 1), 2) -> 0 | H54: =MOD(G19 + MID('Ham_f(RxorK)'!$I$94, ROW($A11), 1), 2) -> 1 | I54: =MOD(H19 + MID('Ham_f(RxorK)'!$I$95, ROW($A11), 1), 2) -> 1 | J54: =MOD(I19 + MID('Ham_f(RxorK)'!$I$96, ROW($A11), 1), 2) -> 1 | K54: =MOD(J19 + MID('Ham_f(RxorK)'!$I$97, ROW($A11), 1), 2) -> 1 | L54: =MOD(K19 + MID('Ham_f(RxorK)'!$I$98, ROW($A11), 1), 2) -> 0 | M54: =MOD(L19 + MID('Ham_f(RxorK)'!$I$99, ROW($A11), 1), 2) -> 1 | N54: =MOD(M19 + MID('Ham_f(RxorK)'!$I$100, ROW($A11), 1), 2) -> 1 | O54: =MOD(N19 + MID('Ham_f(RxorK)'!$I$101, ROW($A11), 1), 2) -> 0 | P54: =MOD(O19 + MID('Ham_f(RxorK)'!$I$102, ROW($A11), 1), 2) -> 0 | Q54: =MOD(P19 + MID('Ham_f(RxorK)'!$I$103, ROW($A11), 1), 2) -> 1
