Workbook
Name C_0: Key!$B$8:$AC$8
Name D_0: Key!$AD$8:$BE$8
Name E_TBL: Tables!$E$2:$E$49
Name FB_TBL: Tables!$C$2:$C$65
Name IP_TBL: Tables!$A$2:$A$65
Name K_1: Key!$B$14:$AW$14
Name K_10BITS: Key!$B$60:$AW$60
Name K_11BITS: Key!$B$65:$AW$65
Name K_12BITS: Key!$B$70:$AW$70
Name K_14BITS: Key!$B$80:$AW$80
Name K_15BITS: Key!$B$85:$AW$85
Name K_16BITS: Key!$B$90:$AW$90
Name K_1BITS: Key!$B$14:$AW$14
Name K_2: Key!$B$19:$AW$19
Name K_2BITS: Key!$B$19:$AW$19
Name K_3BITS: Key!$B$24:$AW$24
Name K_4BITS: Key!$B$29:$AW$29
Name K_6BITS: Key!$B$40:$AW$40
Name K_7BITS: Key!$B$45:$AW$45
Name K_8BITS: Key!$B$50:$AW$50
Name K_9BITS: Key!$B$55:$AW$55
Name K_BITS: Inputs!$C$8:$BN$8
Name K1_BITS: Key!$B$14:$AW$14
Name K13_BITS: Key!$B$75:$AW$75
Name K5_BITS: Key!$B$35:$AW$35
Name M_BITS: Inputs!$C$7:$BN$7
Name P_TBL: Tables!$G$2:$G$33
Name PC1_TBL: Tables!$I$2:$I$57
Name PC2_TBL: Tables!$K$2:$K$49
Name S_1: Tables!$M$20:$AB$23
Name S_2: Tables!$M$25:$AB$28
Name S_3: Tables!$M$30:$AB$33
Name S_4: Tables!$M$35:$AB$38
Name S_5: Tables!$M$40:$AB$43
Name S_6: Tables!$M$45:$AB$48
Name S_7: Tables!$M$50:$AB$53
Name S_8: Tables!$M$55:$AB$58
Name SHIFT_TBL: Tables!$M$2:$AB$2

Sheet Inputs
B2: 00123456789abcde
B3: 0133457799bbcdff
C6: 1 | D6: =C6+1 -> 2 | E6: =D6+1 -> 3 | F6: =E6+1 -> 4 | G6: =F6+1 -> 5 | H6: =G6+1 -> 6 | I6: =H6+1 -> 7 | J6: =I6+1 -> 8 | K6: =J6+1 -> 9 | ... BN6: =BM6+1 -> 64
B7: M | C7: =MOD(QUOTIENT(HEX2DEC(MID($B$2,INT((C$6-1)/4)+1,1)),2^(3-MOD(C$6-1,4))),2) -> 0 | D7: =MOD(QUOTIENT(HEX2DEC(MID($B$2,INT((D$6-1)/4)+1,1)),2^(3-MOD(D$6-1,4))),2) -> 0 | E7: =MOD(QUOTIENT(HEX2DEC(MID($B$2,INT((E$6-1)/4)+1,1)),2^(3-MOD(E$6-1,4))),2) -> 0 | F7: =MOD(QUOTIENT(HEX2DEC(MID($B$2,INT((F$6-1)/4)+1,1)),2^(3-MOD(F$6-1,4))),2) -> 0 | G7: =MOD(QUOTIENT(HEX2DEC(MID($B$2,INT((G$6-1)/4)+1,1)),2^(3-MOD(G$6-1,4))),2) -> 0 | H7: =MOD(QUOTIENT(HEX2DEC(MID($B$2,INT((H$6-1)/4)+1,1)),2^(3-MOD(H$6-1,4))),2) -> 0 | I7: =MOD(QUOTIENT(HEX2DEC(MID($B$2,INT((I$6-1)/4)+1,1)),2^(3-MOD(I$6-1,4))),2) -> 0 | J7: =MOD(QUOTIENT(HEX2DEC(MID($B$2,INT((J$6-1)/4)+1,1)),2^(3-MOD(J$6-1,4))),2) -> 0 | ... BN7: =MOD(QUOTIENT(HEX2DEC(MID($B$2,INT((BN$6-1)/4)+1,1)),2^(3-MOD(BN$6-1,4))),2) -> 0
B8: K | C8: =MOD( QUOTIENT( HEX2DEC( MID($B$3, INT((C$6-1)/4)+1, 1) ), 2^(3-MOD(C$6-1,4)) ), 2 ) -> 0 | D8: =MOD( QUOTIENT( HEX2DEC( MID($B$3, INT((D$6-1)/4)+1, 1) ), 2^(3-MOD(D$6-1,4)) ), 2 ) -> 0 | E8: =MOD( QUOTIENT( HEX2DEC( MID($B$3, INT((E$6-1)/4)+1, 1) ), 2^(3-MOD(E$6-1,4)) ), 2 ) -> 0 | F8: =MOD( QUOTIENT( HEX2DEC( MID($B$3, INT((F$6-1)/4)+1, 1) ), 2^(3-MOD(F$6-1,4)) ), 2 ) -> 0 | G8: =MOD( QUOTIENT( HEX2DEC( MID($B$3, INT((G$6-1)/4)+1, 1) ), 2^(3-MOD(G$6-1,4)) ), 2 ) -> 0 | H8: =MOD( QUOTIENT( HEX2DEC( MID($B$3, INT((H$6-1)/4)+1, 1) ), 2^(3-MOD(H$6-1,4)) ), 2 ) -> 0 | I8: =MOD( QUOTIENT( HEX2DEC( MID($B$3, INT((I$6-1)/4)+1, 1) ), 2^(3-MOD(I$6-1,4)) ), 2 ) -> 0 | J8: =MOD( QUOTIENT( HEX2DEC( MID($B$3, INT((J$6-1)/4)+1, 1) ), 2^(3-MOD(J$6-1,4)) ), 2 ) -> 1 | ... BN8: =MOD( QUOTIENT( HEX2DEC( MID($B$3, INT((BN$6-1)/4)+1, 1) ), 2^(3-MOD(BN$6-1,4)) ), 2 ) -> 1

Sheet Tables
A1: IP | C1: FB | E1: E | G1: P | I1: PC_1 | K1: PC_2
A2: 58 | C2: 40 | E2: 32 | G2: 16 | I2: 57 | K2: 14 | M2: 1 | N2: 1 | O2: 2 | P2: 2 | Q2: 2 | R2: 2 | S2: 2 | T2: 2 | U2: 1 | V2: 2 | W2: 2 | X2: 2 | Y2: 2 | Z2: 2 | AA2: 2 | AB2: 1
A3: 50 | C3: 8 | E3: 1 | G3: 7 | I3: 49 | K3: 17
A4: 42 | C4: 48 | E4: 2 | G4: 20 | I4: 41 | K4: 11
A5: 34 | C5: 16 | E5: 3 | G5: 21 | I5: 33 | K5: 24
A6: 26 | C6: 56 | E6: 4 | G6: 29 | I6: 25 | K6: 1
A7: 18 | C7: 24 | E7: 5 | G7: 12 | I7: 17 | K7: 5
A8: 10 | C8: 64 | E8: 4 | G8: 28 | I8: 9 | K8: 3
A9: 2 | C9: 32 | E9: 5 | G9: 17 | I9: 1 | K9: 28
A10: 60 | C10: 39 | E10: 6 | G10: 1 | I10: 58 | K10: 15
A11: 52 | C11: 7 | E11: 7 | G11: 15 | I11: 50 | K11: 6
A12: 44 | C12: 47 | E12: 8 | G12: 23 | I12: 42 | K12: 21
A13: 36 | C13: 15 | E13: 9 | G13: 26 | I13: 34 | K13: 10
A14: 28 | C14: 55 | E14: 8 | G14: 5 | I14: 26 | K14: 23
... A17: 4 | C17: 31 | E17: 11 | G17: 10 | I17: 2 | K17: 4
A18: 62 | C18: 38 | E18: 12 | G18: 2 | I18: 59 | K18: 26 | M18: S1
A19: 54 | C19: 6 | E19: 13 | G19: 8 | I19: 51 | K19: 8
A20: 46 | C20: 46 | E20: 12 | G20: 24 | I20: 43 | K20: 16 | M20: 14 | N20: 4 | O20: 13 | P20: 1 | Q20: 2 | R20: 15 | S20: 11 | T20: 8 | U20: 3 | V20: 10 | W20: 6 | X20: 12 | Y20: 5 | Z20: 9 | AA20: 0 | AB20: 7
A21: 38 | C21: 14 | E21: 13 | G21: 14 | I21: 35 | K21: 7 | M21: 0 | N21: 15 | O21: 7 | P21: 4 | Q21: 14 | R21: 2 | S21: 13 | T21: 1 | U21: 10 | V21: 6 | W21: 12 | X21: 11 | Y21: 9 | Z21: 5 | AA21: 3 | AB21: 8
A22: 30 | C22: 54 | E22: 14 | G22: 32 | I22: 27 | K22: 27 | M22: 4 | N22: 1 | O22: 14 | P22: 8 | Q22: 13 | R22: 6 | S22: 2 | T22: 11 | U22: 15 | V22: 12 | W22: 9 | X22: 7 | Y22: 3 | Z22: 10 | AA22: 5 | AB22: 0
A23: 22 | C23: 22 | E23: 15 | G23: 27 | I23: 19 | K23: 20 | M23: 15 | N23: 12 | O23: 8 | P23: 2 | Q23: 4 | R23: 9 | S23: 1 | T23: 7 | U23: 5 | V23: 11 | W23: 3 | X23: 14 | Y23: 10 | Z23: 0 | AA23: 6 | AB23: 13
A24: 14 | C24: 62 | E24: 16 | G24: 3 | I24: 11 | K24: 13 | M24: S2
A25: 6 | C25: 30 | E25: 17 | G25: 9 | I25: 3 | K25: 2 | M25: 15 | N25: 1 | O25: 8 | P25: 14 | Q25: 6 | R25: 11 | S25: 3 | T25: 4 | U25: 9 | V25: 7 | W25: 2 | X25: 13 | Y25: 12 | Z25: 0 | AA25: 5 | AB25: 10
A26: 64 | C26: 37 | E26: 16 | G26: 19 | I26: 60 | K26: 41 | M26: 3 | N26: 13 | O26: 4 | P26: 7 | Q26: 15 | R26: 2 | S26: 8 | T26: 14 | U26: 12 | V26: 0 | W26: 1 | X26: 10 | Y26: 6 | Z26: 9 | AA26: 11 | AB26: 5
A27: 56 | C27: 5 | E27: 17 | G27: 13 | I27: 52 | K27: 52 | M27: 0 | N27: 14 | O27: 7 | P27: 11 | Q27: 10 | R27: 4 | S27: 13 | T27: 1 | U27: 5 | V27: 8 | W27: 12 | X27: 6 | Y27: 9 | Z27: 3 | AA27: 2 | AB27: 15
A28: 48 | C28: 45 | E28: 18 | G28: 30 | I28: 44 | K28: 31 | M28: 13 | N28: 8 | O28: 10 | P28: 1 | Q28: 3 | R28: 15 | S28: 4 | T28: 2 | U28: 11 | V28: 6 | W28: 7 | X28: 12 | Y28: 0 | Z28: 5 | AA28: 14 | AB28: 9
A29: 40 | C29: 13 | E29: 19 | G29: 6 | I29: 36 | K29: 37 | M29: S3
A30: 32 | C30: 53 | E30: 20 | G30: 22 | I30: 63 | K30: 47 | M30: 10 | N30: 0 | O30: 9 | P30: 14 | Q30: 6 | R30: 3 | S30: 15 | T30: 5 | U30: 1 | V30: 13 | W30: 12 | X30: 7 | Y30: 11 | Z30: 4 | AA30: 2 | AB30: 8
A31: 24 | C31: 21 | E31: 21 | G31: 11 | I31: 55 | K31: 55 | M31: 13 | N31: 7 | O31: 0 | P31: 9 | Q31: 3 | R31: 4 | S31: 6 | T31: 10 | U31: 2 | V31: 8 | W31: 5 | X31: 12 | Y31: 14 | Z31: 11 | AA31: 15 | AB31: 1
A32: 16 | C32: 61 | E32: 20 | G32: 4 | I32: 47 | K32: 30 | M32: 13 | N32: 6 | O32: 4 | P32: 9 | Q32: 8 | R32: 15 | S32: 3 | T32: 0 | U32: 11 | V32: 1 | W32: 2 | X32: 12 | Y32: 5 | Z32: 10 | AA32: 14 | AB32: 7
A33: 8 | C33: 29 | E33: 21 | G33: 25 | I33: 39 | K33: 40 | M33: 1 | N33: 10 | O33: 13 | P33: 0 | Q33: 6 | R33: 9 | S33: 8 | T33: 7 | U33: 4 | V33: 15 | W33: 14 | X33: 3 | Y33: 11 | Z33: 5 | AA33: 2 | AB33: 12
A34: 57 | C34: 36 | E34: 22 | I34: 31 | K34: 51 | M34: S4
A35: 49 | C35: 4 | E35: 23 | I35: 23 | K35: 45 | M35: 7 | N35: 13 | O35: 14 | P35: 3 | Q35: 0 | R35: 6 | S35: 9 | T35: 10 | U35: 1 | V35: 2 | W35: 8 | X35: 5 | Y35: 11 | Z35: 12 | AA35: 4 | AB35: 15
A36: 41 | C36: 44 | E36: 24 | I36: 15 | K36: 33 | M36: 13 | N36: 8 | O36: 11 | P36: 5 | Q36: 6 | R36: 15 | S36: 0 | T36: 3 | U36: 4 | V36: 7 | W36: 2 | X36: 12 | Y36: 1 | Z36: 10 | AA36: 14 | AB36: 9
A37: 33 | C37: 12 | E37: 25 | I37: 7 | K37: 48 | M37: 10 | N37: 6 | O37: 9 | P37: 0 | Q37: 12 | R37: 11 | S37: 7 | T37: 13 | U37: 15 | V37: 1 | W37: 3 | X37: 14 | Y37: 5 | Z37: 2 | AA37: 8 | AB37: 4
A38: 25 | C38: 52 | E38: 24 | I38: 62 | K38: 44 | M38: 3 | N38: 15 | O38: 0 | P38: 6 | Q38: 10 | R38: 1 | S38: 13 | T38: 8 | U38: 9 | V38: 4 | W38: 5 | X38: 11 | Y38: 12 | Z38: 7 | AA38: 2 | AB38: 14
A39: 17 | C39: 20 | E39: 25 | I39: 54 | K39: 49 | M39: S5
A40: 9 | C40: 60 | E40: 26 | I40: 46 | K40: 39 | M40: 2 | N40: 12 | O40: 4 | P40: 1 | Q40: 7 | R40: 10 | S40: 11 | T40: 6 | U40: 8 | V40: 5 | W40: 3 | X40: 15 | Y40: 13 | Z40: 0 | AA40: 14 | AB40: 9
A41: 1 | C41: 28 | E41: 27 | I41: 38 | K41: 56 | M41: 14 | N41: 11 | O41: 2 | P41: 12 | Q41: 4 | R41: 7 | S41: 13 | T41: 1 | U41: 5 | V41: 0 | W41: 15 | X41: 10 | Y41: 3 | Z41: 9 | AA41: 8 | AB41: 6
A42: 59 | C42: 35 | E42: 28 | I42: 30 | K42: 34 | M42: 4 | N42: 2 | O42: 1 | P42: 11 | Q42: 10 | R42: 13 | S42: 7 | T42: 8 | U42: 15 | V42: 9 | W42: 12 | X42: 5 | Y42: 6 | Z42: 3 | AA42: 0 | AB42: 14
...

Sheet Key
B5: K-PC-1
B6: {=INDEX(K_BITS, 1, INDEX(PC1_TBL, COLUMNS($B$6:B6)))} -> 1 | C6: {=INDEX(K_BITS, 1, INDEX(PC1_TBL, COLUMNS($B$6:C6)))} -> 1 | D6: {=INDEX(K_BITS, 1, INDEX(PC1_TBL, COLUMNS($B$6:D6)))} -> 1 | E6: {=INDEX(K_BITS, 1, INDEX(PC1_TBL, COLUMNS($B$6:E6)))} -> 1 | F6: {=INDEX(K_BITS, 1, INDEX(PC1_TBL, COLUMNS($B$6:F6)))} -> 0 | G6: {=INDEX(K_BITS, 1, INDEX(PC1_TBL, COLUMNS($B$6:G6)))} -> 0 | H6: {=INDEX(K_BITS, 1, INDEX(PC1_TBL, COLUMNS($B$6:H6)))} -> 0 | I6: {=INDEX(K_BITS, 1, INDEX(PC1_TBL, COLUMNS($B$6:I6)))} -> 0 | ... BE6: {=INDEX(K_BITS, 1, INDEX(PC1_TBL, COLUMNS($B$6:BE6)))} -> 0
B7: C0 | AD7: D0
B8: =B6 -> 1 | C8: =C6 -> 1 | D8: =D6 -> 1 | E8: =E6 -> 1 | F8: =F6 -> 0 | G8: =G6 -> 0 | H8: =H6 -> 0 | I8: =I6 -> 0 | ... BE8: =BE6 -> 0
A11: Round 1: | AD11: D1
A12: C1 | B12: {=INDEX($B$8:$AC$8, 1, MOD(COLUMNS($B$12:B12)-1 + INDEX(SHIFT_TBL,1,1), 28) + 1)} -> 1 | C12: {=INDEX($B$8:$AC$8, 1, MOD(COLUMNS($B$12:C12)-1 + INDEX(SHIFT_TBL,1,1), 28) + 1)} -> 1 | D12: {=INDEX($B$8:$AC$8, 1, MOD(COLUMNS($B$12:D12)-1 + INDEX(SHIFT_TBL,1,1), 28) + 1)} -> 1 | E12: {=INDEX($B$8:$AC$8, 1, MOD(COLUMNS($B$12:E12)-1 + INDEX(SHIFT_TBL,1,1), 28) + 1)} -> 0 | F12: {=INDEX($B$8:$AC$8, 1, MOD(COLUMNS($B$12:F12)-1 + INDEX(SHIFT_TBL,1,1), 28) + 1)} -> 0 | G12: {=INDEX($B$8:$AC$8, 1, MOD(COLUMNS($B$12:G12)-1 + INDEX(SHIFT_TBL,1,1), 28) + 1)} -> 0 | H12: {=INDEX($B$8:$AC$8, 1, MOD(COLUMNS($B$12:H12)-1 + INDEX(SHIFT_TBL,1,1), 28) + 1)} -> 0 | I12: {=INDEX($B$8:$AC$8, 1, MOD(COLUMNS($B$12:I12)-1 + INDEX(SHIFT_TBL,1,1), 28) + 1)} -> 1 | J12: {=INDEX($B$8:$AC$8, 1, MOD(COLUMNS($B$12:I12)-1 + INDEX(SHIFT_TBL,1,1), 28) + 1)} -> 1 | K12: {=INDEX($B$8:$AC$8, 1, MOD(COLUMNS($B$12:K12)-1 + INDEX(SHIFT_TBL,1,1), 28) + 1)} -> 0 | L12: {=INDEX($B$8:$AC$8, 1, MOD(COLUMNS($B$12:L12)-1 + INDEX(SHIFT_TBL,1,1), 28) + 1)} -> 0 | M12: {=INDEX($B$8:$AC$8, 1, MOD(COLUMNS($B$12:M12)-1 + INDEX(SHIFT_TBL,1,1), 28) + 1)} -> 1 | N12: {=INDEX($B$8:$AC$8, 1, MOD(COLUMNS($B$12:N12)-1 + INDEX(SHIFT_TBL,1,1), 28) + 1)} -> 1 | O12: {=INDEX($B$8:$AC$8, 1, MOD(COLUMNS($B$12:O12)-1 + INDEX(SHIFT_TBL,1,1), 28) + 1)} -> 0 | P12: {=INDEX($B$8:$AC$8, 1, MOD(COLUMNS($B$12:P12)-1 + INDEX(SHIFT_TBL,1,1), 28) + 1)} -> 0 | Q12: {=INDEX($B$8:$AC$8, 1, MOD(COLUMNS($B$12:Q12)-1 + INDEX(SHIFT_TBL,1,1), 28) + 1)} -> 1 | R12: {=INDEX($B$8:$AC$8, 1, MOD(COLUMNS($B$12:R12)-1 + INDEX(SHIFT_TBL,1,1), 28) + 1)} -> 0 | ... AC12: {=INDEX($B$8:$AC$8, 1, MOD(COLUMNS($B$12:AC12)-1 + INDEX(SHIFT_TBL,1,1), 28) + 1)} -> 1 | AD12: {=INDEX($AD$8:$BE$8, 1, MOD(COLUMNS($AD$12:AD12)-1 + INDEX(SHIFT_TBL,1,2), 28) + 1)} -> 0 | AE12: {=INDEX($AD$8:$BE$8, 1, MOD(COLUMNS($AD$12:AE12)-1 + INDEX(SHIFT_TBL,1,2), 28) + 1)} -> 1 | AF12: {=INDEX($AD$8:$BE$8, 1, MOD(COLUMNS($AD$12:AF12)-1 + INDEX(SHIFT_TBL,1,2), 28) + 1)} -> 0 | AG12: {=INDEX($AD$8:$BE$8, 1, MOD(COLUMNS($AD$12:AG12)-1 + INDEX(SHIFT_TBL,1,2), 28) + 1)} -> 1 | AH12: {=INDEX($AD$8:$BE$8, 1, MOD(COLUMNS($AD$12:AH12)-1 + INDEX(SHIFT_TBL,1,2), 28) + 1)} -> 0 | AI12: {=INDEX($AD$8:$BE$8, 1, MOD(COLUMNS($AD$12:AI12)-1 + INDEX(SHIFT_TBL,1,2), 28) + 1)} -> 1 | AJ12: {=INDEX($AD$8:$BE$8, 1, MOD(COLUMNS($AD$12:AJ12)-1 + INDEX(SHIFT_TBL,1,2), 28) + 1)} -> 0 | AK12: {=INDEX($AD$8:$BE$8, 1, MOD(COLUMNS($AD$12:AK12)-1 + INDEX(SHIFT_TBL,1,2), 28) + 1)} -> 1 | ... BE12: {=INDEX($AD$8:$BE$8, 1, MOD(COLUMNS($AD$12:BE12)-1 + INDEX(SHIFT_TBL,1,2), 28) + 1)} -> 1
A13: C1||D1 | B13: {=INDEX($B$8:$AC$8, 1, MOD(COLUMNS($B$12:B13)-1 + INDEX(SHIFT_TBL,1,1), 28) + 1)} -> 1 | C13: {=INDEX($B$8:$AC$8, 1, MOD(COLUMNS($B$12:C13)-1 + INDEX(SHIFT_TBL,1,1), 28) + 1)} -> 1 | D13: {=INDEX($B$8:$AC$8, 1, MOD(COLUMNS($B$12:D13)-1 + INDEX(SHIFT_TBL,1,1), 28) + 1)} -> 1 | E13: {=INDEX($B$8:$AC$8, 1, MOD(COLUMNS($B$12:E13)-1 + INDEX(SHIFT_TBL,1,1), 28) + 1)} -> 0 | F13: {=INDEX($B$8:$AC$8, 1, MOD(COLUMNS($B$12:F13)-1 + INDEX(SHIFT_TBL,1,1), 28) + 1)} -> 0 | G13: {=INDEX($B$8:$AC$8, 1, MOD(COLUMNS($B$12:G13)-1 + INDEX(SHIFT_TBL,1,1), 28) + 1)} -> 0 | H13: {=INDEX($B$8:$AC$8, 1, MOD(COLUMNS($B$12:H13)-1 + INDEX(SHIFT_TBL,1,1), 28) + 1)} -> 0 | I13: {=INDEX($B$8:$AC$8, 1, MOD(COLUMNS($B$12:I13)-1 + INDEX(SHIFT_TBL,1,1), 28) + 1)} -> 1 | ... AC13: {=INDEX($B$8:$AC$8, 1, MOD(COLUMNS($B$12:AC13)-1 + INDEX(SHIFT_TBL,1,1), 28) + 1)} -> 1 | AD13: {=INDEX($AD$8:$BE$8, 1, MOD(COLUMNS($AD$12:AD13)-1 + INDEX(SHIFT_TBL,1,1), 28) + 1)} -> 0 | AE13: {=INDEX($AD$8:$BE$8, 1, MOD(COLUMNS($AD$12:AE13)-1 + INDEX(SHIFT_TBL,1,1), 28) + 1)} -> 1 | AF13: {=INDEX($AD$8:$BE$8, 1, MOD(COLUMNS($AD$12:AF13)-1 + INDEX(SHIFT_TBL,1,1), 28) + 1)} -> 0 | AG13: {=INDEX($AD$8:$BE$8, 1, MOD(COLUMNS($AD$12:AG13)-1 + INDEX(SHIFT_TBL,1,1), 28) + 1)} -> 1 | AH13: {=INDEX($AD$8:$BE$8, 1, MOD(COLUMNS($AD$12:AH13)-1 + INDEX(SHIFT_TBL,1,1), 28) + 1)} -> 0 | AI13: {=INDEX($AD$8:$BE$8, 1, MOD(COLUMNS($AD$12:AI13)-1 + INDEX(SHIFT_TBL,1,1), 28) + 1)} -> 1 | AJ13: {=INDEX($AD$8:$BE$8, 1, MOD(COLUMNS($AD$12:AJ13)-1 + INDEX(SHIFT_TBL,1,1), 28) + 1)} -> 0 | AK13: {=INDEX($AD$8:$BE$8, 1, MOD(COLUMNS($AD$12:AK13)-1 + INDEX(SHIFT_TBL,1,1), 28) + 1)} -> 1 | ... BE13: {=INDEX($AD$8:$BE$8, 1, MOD(COLUMNS($AD$12:BE13)-1 + INDEX(SHIFT_TBL,1,1), 28) + 1)} -> 1
A14: K1 | B14: {=INDEX($B$13:$BE$13, 1, INDEX(PC2_TBL, COLUMNS($B$14:B14)))} -> 0 | C14: {=INDEX($B$13:$BE$13, 1, INDEX(PC2_TBL, COLUMNS($B$14:C14)))} -> 0 | D14: {=INDEX($B$13:$BE$13, 1, INDEX(PC2_TBL, COLUMNS($B$14:D14)))} -> 0 | E14: {=INDEX($B$13:$BE$13, 1, INDEX(PC2_TBL, COLUMNS($B$14:E14)))} -> 1 | F14: {=INDEX($B$13:$BE$13, 1, INDEX(PC2_TBL, COLUMNS($B$14:F14)))} -> 1 | G14: {=INDEX($B$13:$BE$13, 1, INDEX(PC2_TBL, COLUMNS($B$14:G14)))} -> 0 | H14: {=INDEX($B$13:$BE$13, 1, INDEX(PC2_TBL, COLUMNS($B$14:H14)))} -> 1 | I14: {=INDEX($B$13:$BE$13, 1, INDEX(PC2_TBL, COLUMNS($B$14:I14)))} -> 1 | ... AW14: {=INDEX($B$13:$BE$13, 1, INDEX(PC2_TBL, COLUMNS($B$14:AW14)))} -> 1
A16: Round2: | AD16: D2
A17: C2 | B17: {=INDEX($B$12:$AC$12, 1, MOD(COLUMNS($B$17:B17)-1 + INDEX(SHIFT_TBL,1,1), 28) + 1)} -> 1 | C17: {=INDEX($B$12:$AC$12, 1, MOD(COLUMNS($B$17:C17)-1 + INDEX(SHIFT_TBL,1,1), 28) + 1)} -> 1 | D17: {=INDEX($B$12:$AC$12, 1, MOD(COLUMNS($B$17:D17)-1 + INDEX(SHIFT_TBL,1,1), 28) + 1)} -> 0 | E17: {=INDEX($B$12:$AC$12, 1, MOD(COLUMNS($B$17:E17)-1 + INDEX(SHIFT_TBL,1,1), 28) + 1)} -> 0 | F17: {=INDEX($B$12:$AC$12, 1, MOD(COLUMNS($B$17:F17)-1 + INDEX(SHIFT_TBL,1,1), 28) + 1)} -> 0 | G17: {=INDEX($B$12:$AC$12, 1, MOD(COLUMNS($B$17:G17)-1 + INDEX(SHIFT_TBL,1,1), 28) + 1)} -> 0 | H17: {=INDEX($B$12:$AC$12, 1, MOD(COLUMNS($B$17:H17)-1 + INDEX(SHIFT_TBL,1,1), 28) + 1)} -> 1 | I17: {=INDEX($B$12:$AC$12, 1, MOD(COLUMNS($B$17:I17)-1 + INDEX(SHIFT_TBL,1,1), 28) + 1)} -> 1 | ... AC17: {=INDEX($B$12:$AC$12, 1, MOD(COLUMNS($B$17:AC17)-1 + INDEX(SHIFT_TBL,1,1), 28) + 1)} -> 1 | AD17: {=INDEX($AD$12:$BE$12, 1, MOD(COLUMNS($AD$17:AD17)-1 + INDEX(SHIFT_TBL,1,1), 28) + 1)} -> 1 | AE17: {=INDEX($AD$12:$BE$12, 1, MOD(COLUMNS($AD$17:AE17)-1 + INDEX(SHIFT_TBL,1,1), 28) + 1)} -> 0 | AF17: {=INDEX($AD$12:$BE$12, 1, MOD(COLUMNS($AD$17:AF17)-1 + INDEX(SHIFT_TBL,1,1), 28) + 1)} -> 1 | AG17: {=INDEX($AD$12:$BE$12, 1, MOD(COLUMNS($AD$17:AG17)-1 + INDEX(SHIFT_TBL,1,1), 28) + 1)} -> 0 | AH17: {=INDEX($AD$12:$BE$12, 1, MOD(COLUMNS($AD$17:AH17)-1 + INDEX(SHIFT_TBL,1,1), 28) + 1)} -> 1 | AI17: {=INDEX($AD$12:$BE$12, 1, MOD(COLUMNS($AD$17:AI17)-1 + INDEX(SHIFT_TBL,1,1), 28) + 1)} -> 0 | AJ17: {=INDEX($AD$12:$BE$12, 1, MOD(COLUMNS($AD$17:AJ17)-1 + INDEX(SHIFT_TBL,1,1), 28) + 1)} -> 1 | AK17: {=INDEX($AD$12:$BE$12, 1, MOD(COLUMNS($AD$17:AK17)-1 + INDEX(SHIFT_TBL,1,1), 28) + 1)} -> 1 | ... BE17: {=INDEX($AD$12:$BE$12, 1, MOD(COLUMNS($AD$17:BE17)-1 + INDEX(SHIFT_TBL,1,1), 28) + 1)} -> 0
A18: C2||D2 | B18: {=INDEX($B$12:$AC$12, 1, MOD(COLUMNS($B$17:B18)-1 + INDEX(SHIFT_TBL,1,2), 28) + 1)} -> 1 | C18: {=INDEX($B$12:$AC$12, 1, MOD(COLUMNS($B$17:C18)-1 + INDEX(SHIFT_TBL,1,2), 28) + 1)} -> 1 | D18: {=INDEX($B$12:$AC$12, 1, MOD(COLUMNS($B$17:D18)-1 + INDEX(SHIFT_TBL,1,2), 28) + 1)} -> 0 | E18: {=INDEX($B$12:$AC$12, 1, MOD(COLUMNS($B$17:E18)-1 + INDEX(SHIFT_TBL,1,2), 28) + 1)} -> 0 | F18: {=INDEX($B$12:$AC$12, 1, MOD(COLUMNS($B$17:F18)-1 + INDEX(SHIFT_TBL,1,2), 28) + 1)} -> 0 | G18: {=INDEX($B$12:$AC$12, 1, MOD(COLUMNS($B$17:G18)-1 + INDEX(SHIFT_TBL,1,2), 28) + 1)} -> 0 | H18: {=INDEX($B$12:$AC$12, 1, MOD(COLUMNS($B$17:H18)-1 + INDEX(SHIFT_TBL,1,2), 28) + 1)} -> 1 | I18: {=INDEX($B$12:$AC$12, 1, MOD(COLUMNS($B$17:I18)-1 + INDEX(SHIFT_TBL,1,2), 28) + 1)} -> 1 | ... AC18: {=INDEX($B$12:$AC$12, 1, MOD(COLUMNS($B$17:AC18)-1 + INDEX(SHIFT_TBL,1,2), 28) + 1)} -> 1 | AD18: {=INDEX($AD$12:$BE$12, 1, MOD(COLUMNS($AD$17:AD18)-1 + INDEX(SHIFT_TBL,1,2), 28) + 1)} -> 1 | AE18: {=INDEX($AD$12:$BE$12, 1, MOD(COLUMNS($AD$17:AE18)-1 + INDEX(SHIFT_TBL,1,2), 28) + 1)} -> 0 | AF18: {=INDEX($AD$12:$BE$12, 1, MOD(COLUMNS($AD$17:AF18)-1 + INDEX(SHIFT_TBL,1,2), 28) + 1)} -> 1 | AG18: {=INDEX($AD$12:$BE$12, 1, MOD(COLUMNS($AD$17:AG18)-1 + INDEX(SHIFT_TBL,1,2), 28) + 1)} -> 0 | AH18: {=INDEX($AD$12:$BE$12, 1, MOD(COLUMNS($AD$17:AH18)-1 + INDEX(SHIFT_TBL,1,2), 28) + 1)} -> 1 | AI18: {=INDEX($AD$12:$BE$12, 1, MOD(COLUMNS($AD$17:AI18)-1 + INDEX(SHIFT_TBL,1,2), 28) + 1)} -> 0 | AJ18: {=INDEX($AD$12:$BE$12, 1, MOD(COLUMNS($AD$17:AJ18)-1 + INDEX(SHIFT_TBL,1,2), 28) + 1)} -> 1 | AK18: {=INDEX($AD$12:$BE$12, 1, MOD(COLUMNS($AD$17:AK18)-1 + INDEX(SHIFT_TBL,1,2), 28) + 1)} -> 1 | ... BE18: {=INDEX($AD$12:$BE$12, 1, MOD(COLUMNS($AD$17:BE18)-1 + INDEX(SHIFT_TBL,1,2), 28) + 1)} -> 0
A19: K2 | B19: {=INDEX($B$18:$BE$18, 1, INDEX(PC2_TBL, COLUMNS($B$19:B19)))} -> 0 | C19: {=INDEX($B$18:$BE$18, 1, INDEX(PC2_TBL, COLUMNS($B$19:C19)))} -> 1 | D19: {=INDEX($B$18:$BE$18, 1, INDEX(PC2_TBL, COLUMNS($B$19:D19)))} -> 1 | E19: {=INDEX($B$18:$BE$18, 1, INDEX(PC2_TBL, COLUMNS($B$19:E19)))} -> 0 | F19: {=INDEX($B$18:$BE$18, 1, INDEX(PC2_TBL, COLUMNS($B$19:F19)))} -> 1 | G19: {=INDEX($B$18:$BE$18, 1, INDEX(PC2_TBL, COLUMNS($B$19:G19)))} -> 0 | H19: {=INDEX($B$18:$BE$18, 1, INDEX(PC2_TBL, COLUMNS($B$19:H19)))} -> 0 | I19: {=INDEX($B$18:$BE$18, 1, INDEX(PC2_TBL, COLUMNS($B$19:I19)))} -> 1 | ... AW19: {=INDEX($B$18:$BE$18, 1, INDEX(PC2_TBL, COLUMNS($B$19:AW19)))} -> 0
A21: Round3: | AD21: D3
A22: C3 | B22: {=INDEX($B$17:$AC$17, 1, MOD(COLUMNS($B$22:B22)-1 + INDEX(SHIFT_TBL,1,3), 28) + 1)} -> 0 | C22: {=INDEX($B$17:$AC$17, 1, MOD(COLUMNS($B$22:C22)-1 + INDEX(SHIFT_TBL,1,3), 28) + 1)} -> 0 | D22: {=INDEX($B$17:$AC$17, 1, MOD(COLUMNS($B$22:D22)-1 + INDEX(SHIFT_TBL,1,3), 28) + 1)} -> 0 | E22: {=INDEX($B$17:$AC$17, 1, MOD(COLUMNS($B$22:E22)-1 + INDEX(SHIFT_TBL,1,3), 28) + 1)} -> 0 | F22: {=INDEX($B$17:$AC$17, 1, MOD(COLUMNS($B$22:F22)-1 + INDEX(SHIFT_TBL,1,3), 28) + 1)} -> 1 | G22: {=INDEX($B$17:$AC$17, 1, MOD(COLUMNS($B$22:G22)-1 + INDEX(SHIFT_TBL,1,3), 28) + 1)} -> 1 | H22: {=INDEX($B$17:$AC$17, 1, MOD(COLUMNS($B$22:H22)-1 + INDEX(SHIFT_TBL,1,3), 28) + 1)} -> 0 | I22: {=INDEX($B$17:$AC$17, 1, MOD(COLUMNS($B$22:I22)-1 + INDEX(SHIFT_TBL,1,3), 28) + 1)} -> 0 | ... AC22: {=INDEX($B$17:$AC$17, 1, MOD(COLUMNS($B$22:AC22)-1 + INDEX(SHIFT_TBL,1,3), 28) + 1)} -> 1 | AD22: {=INDEX($AD$17:$BE$17, 1, MOD(COLUMNS($AD$22:AD22)-1 + INDEX(SHIFT_TBL,1,3), 28) + 1)} -> 1 | AE22: {=INDEX($AD$17:$BE$17, 1, MOD(COLUMNS($AD$22:AE22)-1 + INDEX(SHIFT_TBL,1,3), 28) + 1)} -> 0 | AF22: {=INDEX($AD$17:$BE$17, 1, MOD(COLUMNS($AD$22:AF22)-1 + INDEX(SHIFT_TBL,1,3), 28) + 1)} -> 1 | AG22: {=INDEX($AD$17:$BE$17, 1, MOD(COLUMNS($AD$22:AG22)-1 + INDEX(SHIFT_TBL,1,3), 28) + 1)} -> 0 | AH22: {=INDEX($AD$17:$BE$17, 1, MOD(COLUMNS($AD$22:AH22)-1 + INDEX(SHIFT_TBL,1,3), 28) + 1)} -> 1 | AI22: {=INDEX($AD$17:$BE$17, 1, MOD(COLUMNS($AD$22:AI22)-1 + INDEX(SHIFT_TBL,1,3), 28) + 1)} -> 1 | AJ22: {=INDEX($AD$17:$BE$17, 1, MOD(COLUMNS($AD$22:AJ22)-1 + INDEX(SHIFT_TBL,1,3), 28) + 1)} -> 0 | AK22: {=INDEX($AD$17:$BE$17, 1, MOD(COLUMNS($AD$22:AK22)-1 + INDEX(SHIFT_TBL,1,3), 28) + 1)} -> 0 | ... BE22: {=INDEX($AD$17:$BE$17, 1, MOD(COLUMNS($AD$22:BE22)-1 + INDEX(SHIFT_TBL,1,3), 28) + 1)} -> 0
A23: C3||D3 | B23: {=INDEX($B$17:$AC$17, 1, MOD(COLUMNS($B$22:B23)-1 + INDEX(SHIFT_TBL,1,3), 28) + 1)} -> 0 | C23: {=INDEX($B$17:$AC$17, 1, MOD(COLUMNS($B$22:C23)-1 + INDEX(SHIFT_TBL,1,3), 28) + 1)} -> 0 | D23: {=INDEX($B$17:$AC$17, 1, MOD(COLUMNS($B$22:D23)-1 + INDEX(SHIFT_TBL,1,3), 28) + 1)} -> 0 | E23: {=INDEX($B$17:$AC$17, 1, MOD(COLUMNS($B$22:E23)-1 + INDEX(SHIFT_TBL,1,3), 28) + 1)} -> 0 | F23: {=INDEX($B$17:$AC$17, 1, MOD(COLUMNS($B$22:F23)-1 + INDEX(SHIFT_TBL,1,3), 28) + 1)} -> 1 | G23: {=INDEX($B$17:$AC$17, 1, MOD(COLUMNS($B$22:G23)-1 + INDEX(SHIFT_TBL,1,3), 28) + 1)} -> 1 | H23: {=INDEX($B$17:$AC$17, 1, MOD(COLUMNS($B$22:H23)-1 + INDEX(SHIFT_TBL,1,3), 28) + 1)} -> 0 | I23: {=INDEX($B$17:$AC$17, 1, MOD(COLUMNS($B$22:I23)-1 + INDEX(SHIFT_TBL,1,3), 28) + 1)} -> 0 | ... AC23: {=INDEX($B$17:$AC$17, 1, MOD(COLUMNS($B$22:AC23)-1 + INDEX(SHIFT_TBL,1,3), 28) + 1)} -> 1 | AD23: {=INDEX($AD$17:$BE$17, 1, MOD(COLUMNS($AD$22:AD23)-1 + INDEX(SHIFT_TBL,1,3), 28) + 1)} -> 1 | AE23: {=INDEX($AD$17:$BE$17, 1, MOD(COLUMNS($AD$22:AE23)-1 + INDEX(SHIFT_TBL,1,3), 28) + 1)} -> 0 | AF23: {=INDEX($AD$17:$BE$17, 1, MOD(COLUMNS($AD$22:AF23)-1 + INDEX(SHIFT_TBL,1,3), 28) + 1)} -> 1 | AG23: {=INDEX($AD$17:$BE$17, 1, MOD(COLUMNS($AD$22:AG23)-1 + INDEX(SHIFT_TBL,1,3), 28) + 1)} -> 0 | AH23: {=INDEX($AD$17:$BE$17, 1, MOD(COLUMNS($AD$22:AH23)-1 + INDEX(SHIFT_TBL,1,3), 28) + 1)} -> 1 | AI23: {=INDEX($AD$17:$BE$17, 1, MOD(COLUMNS($AD$22:AI23)-1 + INDEX(SHIFT_TBL,1,3), 28) + 1)} -> 1 | AJ23: {=INDEX($AD$17:$BE$17, 1, MOD(COLUMNS($AD$22:AJ23)-1 + INDEX(SHIFT_TBL,1,3), 28) + 1)} -> 0 | AK23: {=INDEX($AD$17:$BE$17, 1, MOD(COLUMNS($AD$22:AK23)-1 + INDEX(SHIFT_TBL,1,3), 28) + 1)} -> 0 | ... BE23: {=INDEX($AD$17:$BE$17, 1, MOD(COLUMNS($AD$22:BE23)-1 + INDEX(SHIFT_TBL,1,3), 28) + 1)} -> 0
A24: K3 | B24: {=B24:AE24=INDEX($B$22:$BE$22, 1, INDEX(PC2_TBL, COLUMNS($B$24:B24)))} -> 0 | C24: {=INDEX($B$22:$BE$22, 1, INDEX(PC2_TBL, COLUMNS($B$24:C24)))} -> 1 | D24: {=INDEX($B$22:$BE$22, 1, INDEX(PC2_TBL, COLUMNS($B$24:D24)))} -> 0 | E24: {=INDEX($B$22:$BE$22, 1, INDEX(PC2_TBL, COLUMNS($B$24:E24)))} -> 1 | F24: {=INDEX($B$22:$BE$22, 1, INDEX(PC2_TBL, COLUMNS($B$24:F24)))} -> 0 | G24: {=INDEX($B$22:$BE$22, 1, INDEX(PC2_TBL, COLUMNS($B$24:G24)))} -> 1 | H24: {=INDEX($B$22:$BE$22, 1, INDEX(PC2_TBL, COLUMNS($B$24:H24)))} -> 0 | I24: {=INDEX($B$22:$BE$22, 1, INDEX(PC2_TBL, COLUMNS($B$24:I24)))} -> 1 | J24: {=INDEX($B$22:$BE$22, 1, INDEX(PC2_TBL, COLUMNS($B$24:J24)))} -> 1 | ... AW24: {=INDEX($B$22:$BE$22, 1, INDEX(PC2_TBL, COLUMNS($B$24:AW24)))} -> 0
A26: Round4: | AD26: D4
A27: C4 | B27: {=INDEX($B$22:$AC$22, 1, MOD(COLUMNS($B$27:B27)-1 + INDEX(SHIFT_TBL,1,4), 28) + 1)} -> 0 | C27: {=INDEX($B$22:$AC$22, 1, MOD(COLUMNS($B$27:C27)-1 + INDEX(SHIFT_TBL,1,4), 28) + 1)} -> 0 | D27: {=INDEX($B$22:$AC$22, 1, MOD(COLUMNS($B$27:D27)-1 + INDEX(SHIFT_TBL,1,4), 28) + 1)} -> 1 | E27: {=INDEX($B$22:$AC$22, 1, MOD(COLUMNS($B$27:E27)-1 + INDEX(SHIFT_TBL,1,4), 28) + 1)} -> 1 | F27: {=INDEX($B$22:$AC$22, 1, MOD(COLUMNS($B$27:F27)-1 + INDEX(SHIFT_TBL,1,4), 28) + 1)} -> 0 | G27: {=INDEX($B$22:$AC$22, 1, MOD(COLUMNS($B$27:G27)-1 + INDEX(SHIFT_TBL,1,4), 28) + 1)} -> 0 | H27: {=INDEX($B$22:$AC$22, 1, MOD(COLUMNS($B$27:H27)-1 + INDEX(SHIFT_TBL,1,4), 28) + 1)} -> 1 | I27: {=INDEX($B$22:$AC$22, 1, MOD(COLUMNS($B$27:I27)-1 + INDEX(SHIFT_TBL,1,4), 28) + 1)} -> 1 | ... AC27: {=INDEX($B$22:$AC$22, 1, MOD(COLUMNS($B$27:AC27)-1 + INDEX(SHIFT_TBL,1,4), 28) + 1)} -> 0 | AD27: {=INDEX($AD$22:$BE$22, 1, MOD(COLUMNS($AD$27:AD27)-1 + INDEX(SHIFT_TBL,1,4), 28) + 1)} -> 1 | AE27: {=INDEX($AD$22:$BE$22, 1, MOD(COLUMNS($AD$27:AE27)-1 + INDEX(SHIFT_TBL,1,4), 28) + 1)} -> 0 | AF27: {=INDEX($AD$22:$BE$22, 1, MOD(COLUMNS($AD$27:AF27)-1 + INDEX(SHIFT_TBL,1,4), 28) + 1)} -> 1 | AG27: {=INDEX($AD$22:$BE$22, 1, MOD(COLUMNS($AD$27:AG27)-1 + INDEX(SHIFT_TBL,1,4), 28) + 1)} -> 1 | AH27: {=INDEX($AD$22:$BE$22, 1, MOD(COLUMNS($AD$27:AH27)-1 + INDEX(SHIFT_TBL,1,4), 28) + 1)} -> 0 | AI27: {=INDEX($AD$22:$BE$22, 1, MOD(COLUMNS($AD$27:AI27)-1 + INDEX(SHIFT_TBL,1,4), 28) + 1)} -> 0 | AJ27: {=INDEX($AD$22:$BE$22, 1, MOD(COLUMNS($AD$27:AJ27)-1 + INDEX(SHIFT_TBL,1,4), 28) + 1)} -> 1 | AK27: {=INDEX($AD$22:$BE$22, 1, MOD(COLUMNS($AD$27:AK27)-1 + INDEX(SHIFT_TBL,1,4), 28) + 1)} -> 1 | ... BE27: {=INDEX($AD$22:$BE$22, 1, MOD(COLUMNS($AD$27:BE27)-1 + INDEX(SHIFT_TBL,1,4), 28) + 1)} -> 0
A28: C4||D4 | B28: {=INDEX($B$22:$AC$22, 1, MOD(COLUMNS($B$27:B28)-1 + INDEX(SHIFT_TBL,1,4), 28) + 1)} -> 0 | C28: {=INDEX($B$22:$AC$22, 1, MOD(COLUMNS($B$27:C28)-1 + INDEX(SHIFT_TBL,1,4), 28) + 1)} -> 0 | D28: {=INDEX($B$22:$AC$22, 1, MOD(COLUMNS($B$27:D28)-1 + INDEX(SHIFT_TBL,1,4), 28) + 1)} -> 1 | E28: {=INDEX($B$22:$AC$22, 1, MOD(COLUMNS($B$27:E28)-1 + INDEX(SHIFT_TBL,1,4), 28) + 1)} -> 1 | F28: {=INDEX($B$22:$AC$22, 1, MOD(COLUMNS($B$27:F28)-1 + INDEX(SHIFT_TBL,1,4), 28) + 1)} -> 0 | G28: {=INDEX($B$22:$AC$22, 1, MOD(COLUMNS($B$27:G28)-1 + INDEX(SHIFT_TBL,1,4), 28) + 1)} -> 0 | H28: {=INDEX($B$22:$AC$22, 1, MOD(COLUMNS($B$27:H28)-1 + INDEX(SHIFT_TBL,1,4), 28) + 1)} -> 1 | I28: {=INDEX($B$22:$AC$22, 1, MOD(COLUMNS($B$27:I28)-1 + INDEX(SHIFT_TBL,1,4), 28) + 1)} -> 1 | ... AC28: {=INDEX($B$22:$AC$22, 1, MOD(COLUMNS($B$27:AC28)-1 + INDEX(SHIFT_TBL,1,4), 28) + 1)} -> 0 | AD28: {=INDEX($AD$22:$BE$22, 1, MOD(COLUMNS($AD$27:AD28)-1 + INDEX(SHIFT_TBL,1,4), 28) + 1)} -> 1 | AE28: {=INDEX($AD$22:$BE$22, 1, MOD(COLUMNS($AD$27:AE28)-1 + INDEX(SHIFT_TBL,1,4), 28) + 1)} -> 0 | AF28: {=INDEX($AD$22:$BE$22, 1, MOD(COLUMNS($AD$27:AF28)-1 + INDEX(SHIFT_TBL,1,4), 28) + 1)} -> 1 | AG28: {=INDEX($AD$22:$BE$22, 1, MOD(COLUMNS($AD$27:AG28)-1 + INDEX(SHIFT_TBL,1,4), 28) + 1)} -> 1 | AH28: {=INDEX($AD$22:$BE$22, 1, MOD(COLUMNS($AD$27:AH28)-1 + INDEX(SHIFT_TBL,1,4), 28) + 1)} -> 0 | AI28: {=INDEX($AD$22:$BE$22, 1, MOD(COLUMNS($AD$27:AI28)-1 + INDEX(SHIFT_TBL,1,4), 28) + 1)} -> 0 | AJ28: {=INDEX($AD$22:$BE$22, 1, MOD(COLUMNS($AD$27:AJ28)-1 + INDEX(SHIFT_TBL,1,4), 28) + 1)} -> 1 | AK28: {=INDEX($AD$22:$BE$22, 1, MOD(COLUMNS($AD$27:AK28)-1 + INDEX(SHIFT_TBL,1,4), 28) + 1)} -> 1 | ... BE28: {=INDEX($AD$22:$BE$22, 1, MOD(COLUMNS($AD$27:BE28)-1 + INDEX(SHIFT_TBL,1,4), 28) + 1)} -> 0
A29: K4 | B29: {=INDEX($B$28:$BE$28, 1, INDEX(PC2_TBL, COLUMNS($B$29:B29)))} -> 0 | C29: {=INDEX($B$28:$BE$28, 1, INDEX(PC2_TBL, COLUMNS($B$29:C29)))} -> 1 | D29: {=INDEX($B$28:$BE$28, 1, INDEX(PC2_TBL, COLUMNS($B$29:D29)))} -> 1 | E29: {=INDEX($B$28:$BE$28, 1, INDEX(PC2_TBL, COLUMNS($B$29:E29)))} -> 1 | F29: {=INDEX($B$28:$BE$28, 1, INDEX(PC2_TBL, COLUMNS($B$29:F29)))} -> 0 | G29: {=INDEX($B$28:$BE$28, 1, INDEX(PC2_TBL, COLUMNS($B$29:G29)))} -> 0 | H29: {=INDEX($B$28:$BE$28, 1, INDEX(PC2_TBL, COLUMNS($B$29:H29)))} -> 1 | I29: {=INDEX($B$28:$BE$28, 1, INDEX(PC2_TBL, COLUMNS($B$29:I29)))} -> 0 | ... AW29: {=INDEX($B$28:$BE$28, 1, INDEX(PC2_TBL, COLUMNS($B$29:AW29)))} -> 1
A31: Round5 | AD31: D5
A32: C5 | B32: {=INDEX($B$27:$AC$27, 1, MOD(COLUMNS($B$32:B32)-1 + INDEX(SHIFT_TBL,1,5), 28) + 1)} -> 1 | C32: {=INDEX($B$27:$AC$27, 1, MOD(COLUMNS($B$32:C32)-1 + INDEX(SHIFT_TBL,1,5), 28) + 1)} -> 1 | D32: {=INDEX($B$27:$AC$27, 1, MOD(COLUMNS($B$32:D32)-1 + INDEX(SHIFT_TBL,1,5), 28) + 1)} -> 0 | E32: {=INDEX($B$27:$AC$27, 1, MOD(COLUMNS($B$32:E32)-1 + INDEX(SHIFT_TBL,1,5), 28) + 1)} -> 0 | F32: {=INDEX($B$27:$AC$27, 1, MOD(COLUMNS($B$32:F32)-1 + INDEX(SHIFT_TBL,1,5), 28) + 1)} -> 1 | G32: {=INDEX($B$27:$AC$27, 1, MOD(COLUMNS($B$32:G32)-1 + INDEX(SHIFT_TBL,1,5), 28) + 1)} -> 1 | H32: {=INDEX($B$27:$AC$27, 1, MOD(COLUMNS($B$32:H32)-1 + INDEX(SHIFT_TBL,1,5), 28) + 1)} -> 0 | I32: {=INDEX($B$27:$AC$27, 1, MOD(COLUMNS($B$32:I32)-1 + INDEX(SHIFT_TBL,1,5), 28) + 1)} -> 0 | ... AC32: {=INDEX($B$27:$AC$27, 1, MOD(COLUMNS($B$32:AC32)-1 + INDEX(SHIFT_TBL,1,5), 28) + 1)} -> 0 | AD32: {=INDEX($AD$27:$BE$27, 1, MOD(COLUMNS($AD$32:AD32)-1 + INDEX(SHIFT_TBL,1,5), 28) + 1)} -> 1 | AE32: {=INDEX($AD$27:$BE$27, 1, MOD(COLUMNS($AD$32:AE32)-1 + INDEX(SHIFT_TBL,1,5), 28) + 1)} -> 1 | AF32: {=INDEX($AD$27:$BE$27, 1, MOD(COLUMNS($AD$32:AF32)-1 + INDEX(SHIFT_TBL,1,5), 28) + 1)} -> 0 | AG32: {=INDEX($AD$27:$BE$27, 1, MOD(COLUMNS($AD$32:AG32)-1 + INDEX(SHIFT_TBL,1,5), 28) + 1)} -> 0 | AH32: {=INDEX($AD$27:$BE$27, 1, MOD(COLUMNS($AD$32:AH32)-1 + INDEX(SHIFT_TBL,1,5), 28) + 1)} -> 1 | AI32: {=INDEX($AD$27:$BE$27, 1, MOD(COLUMNS($AD$32:AI32)-1 + INDEX(SHIFT_TBL,1,5), 28) + 1)} -> 1 | AJ32: {=INDEX($AD$27:$BE$27, 1, MOD(COLUMNS($AD$32:AJ32)-1 + INDEX(SHIFT_TBL,1,5), 28) + 1)} -> 0 | AK32: {=INDEX($AD$27:$BE$27, 1, MOD(COLUMNS($AD$32:AK32)-1 + INDEX(SHIFT_TBL,1,5), 28) + 1)} -> 0 | ... BE32: {=INDEX($AD$27:$BE$27, 1, MOD(COLUMNS($AD$32:BE32)-1 + INDEX(SHIFT_TBL,1,5), 28) + 1)} -> 0
A34: C5||D5 | B34: {=INDEX($B$27:$AC$27, 1, MOD(COLUMNS($B$32:B34)-1 + INDEX(SHIFT_TBL,1,5), 28) + 1)} -> 1 | C34: {=INDEX($B$27:$AC$27, 1, MOD(COLUMNS($B$32:C34)-1 + INDEX(SHIFT_TBL,1,5), 28) + 1)} -> 1 | D34: {=INDEX($B$27:$AC$27, 1, MOD(COLUMNS($B$32:D34)-1 + INDEX(SHIFT_TBL,1,5), 28) + 1)} -> 0 | E34: {=INDEX($B$27:$AC$27, 1, MOD(COLUMNS($B$32:E34)-1 + INDEX(SHIFT_TBL,1,5), 28) + 1)} -> 0 | F34: {=INDEX($B$27:$AC$27, 1, MOD(COLUMNS($B$32:F34)-1 + INDEX(SHIFT_TBL,1,5), 28) + 1)} -> 1 | G34: {=INDEX($B$27:$AC$27, 1, MOD(COLUMNS($B$32:G34)-1 + INDEX(SHIFT_TBL,1,5), 28) + 1)} -> 1 | H34: {=INDEX($B$27:$AC$27, 1, MOD(COLUMNS($B$32:H34)-1 + INDEX(SHIFT_TBL,1,5), 28) + 1)} -> 0 | I34: {=INDEX($B$27:$AC$27, 1, MOD(COLUMNS($B$32:I34)-1 + INDEX(SHIFT_TBL,1,5), 28) + 1)} -> 0 | ... AC34: {=INDEX($B$27:$AC$27, 1, MOD(COLUMNS($B$32:AC34)-1 + INDEX(SHIFT_TBL,1,5), 28) + 1)} -> 0 | AD34: {=INDEX($AD$27:$BE$27, 1, MOD(COLUMNS($AD$32:AD34)-1 + INDEX(SHIFT_TBL,1,5), 28) + 1)} -> 1 | AE34: {=INDEX($AD$27:$BE$27, 1, MOD(COLUMNS($AD$32:AE34)-1 + INDEX(SHIFT_TBL,1,5), 28) + 1)} -> 1 | AF34: {=INDEX($AD$27:$BE$27, 1, MOD(COLUMNS($AD$32:AF34)-1 + INDEX(SHIFT_TBL,1,5), 28) + 1)} -> 0 | AG34: {=INDEX($AD$27:$BE$27, 1, MOD(COLUMNS($AD$32:AG34)-1 + INDEX(SHIFT_TBL,1,5), 28) + 1)} -> 0 | AH34: {=INDEX($AD$27:$BE$27, 1, MOD(COLUMNS($AD$32:AH34)-1 + INDEX(SHIFT_TBL,1,5), 28) + 1)} -> 1 | AI34: {=INDEX($AD$27:$BE$27, 1, MOD(COLUMNS($AD$32:AI34)-1 + INDEX(SHIFT_TBL,1,5), 28) + 1)} -> 1 | AJ34: {=INDEX($AD$27:$BE$27, 1, MOD(COLUMNS($AD$32:AJ34)-1 + INDEX(SHIFT_TBL,1,5), 28) + 1)} -> 0 | AK34: {=INDEX($AD$27:$BE$27, 1, MOD(COLUMNS($AD$32:AK34)-1 + INDEX(SHIFT_TBL,1,5), 28) + 1)} -> 0 | ... BE34: {=INDEX($AD$27:$BE$27, 1, MOD(COLUMNS($AD$32:BE34)-1 + INDEX(SHIFT_TBL,1,5), 28) + 1)} -> 0
A35: K5 | B35: {=INDEX($B$32:$BE$32, 1, INDEX(PC2_TBL, COLUMNS($B$35:B45)))} -> 0 | C35: {=INDEX($B$32:$BE$32, 1, INDEX(PC2_TBL, COLUMNS($B$35:C45)))} -> 1 | D35: {=INDEX($B$32:$BE$32, 1, INDEX(PC2_TBL, COLUMNS($B$35:D45)))} -> 1 | E35: {=INDEX($B$32:$BE$32, 1, INDEX(PC2_TBL, COLUMNS($B$35:E45)))} -> 1 | F35: {=INDEX($B$32:$BE$32, 1, INDEX(PC2_TBL, COLUMNS($B$35:F45)))} -> 1 | G35: {=INDEX($B$32:$BE$32, 1, INDEX(PC2_TBL, COLUMNS($B$35:G45)))} -> 1 | H35: {=INDEX($B$32:$BE$32, 1, INDEX(PC2_TBL, COLUMNS($B$35:H45)))} -> 0 | I35: {=INDEX($B$32:$BE$32, 1, INDEX(PC2_TBL, COLUMNS($B$35:I45)))} -> 0 | ... AW35: {=INDEX($B$32:$BE$32, 1, INDEX(PC2_TBL, COLUMNS($B$35:AW45)))} -> 0
A37: Round 6 | AD37: D6
A38: C6 | B38: {=INDEX($B$32:$AC$32, 1, MOD(COLUMNS($B$38:B38)-1 + INDEX(SHIFT_TBL,1,6), 28) + 1)} -> 0 | C38: {=INDEX($B$32:$AC$32, 1, MOD(COLUMNS($B$38:C38)-1 + INDEX(SHIFT_TBL,1,6), 28) + 1)} -> 0 | D38: {=INDEX($B$32:$AC$32, 1, MOD(COLUMNS($B$38:D38)-1 + INDEX(SHIFT_TBL,1,6), 28) + 1)} -> 1 | E38: {=INDEX($B$32:$AC$32, 1, MOD(COLUMNS($B$38:E38)-1 + INDEX(SHIFT_TBL,1,6), 28) + 1)} -> 1 | F38: {=INDEX($B$32:$AC$32, 1, MOD(COLUMNS($B$38:F38)-1 + INDEX(SHIFT_TBL,1,6), 28) + 1)} -> 0 | G38: {=INDEX($B$32:$AC$32, 1, MOD(COLUMNS($B$38:G38)-1 + INDEX(SHIFT_TBL,1,6), 28) + 1)} -> 0 | H38: {=INDEX($B$32:$AC$32, 1, MOD(COLUMNS($B$38:H38)-1 + INDEX(SHIFT_TBL,1,6), 28) + 1)} -> 1 | I38: {=INDEX($B$32:$AC$32, 1, MOD(COLUMNS($B$38:I38)-1 + INDEX(SHIFT_TBL,1,6), 28) + 1)} -> 0 | ... AC38: {=INDEX($B$32:$AC$32, 1, MOD(COLUMNS($B$38:AC38)-1 + INDEX(SHIFT_TBL,1,6), 28) + 1)} -> 1 | AD38: {=INDEX($AD$32:$BE$32, 1, MOD(COLUMNS($AD$38:AD38)-1 + INDEX(SHIFT_TBL,1,6), 28) + 1)} -> 0 | AE38: {=INDEX($AD$32:$BE$32, 1, MOD(COLUMNS($AD$38:AE38)-1 + INDEX(SHIFT_TBL,1,6), 28) + 1)} -> 0 | AF38: {=INDEX($AD$32:$BE$32, 1, MOD(COLUMNS($AD$38:AF38)-1 + INDEX(SHIFT_TBL,1,6), 28) + 1)} -> 1 | AG38: {=INDEX($AD$32:$BE$32, 1, MOD(COLUMNS($AD$38:AG38)-1 + INDEX(SHIFT_TBL,1,6), 28) + 1)} -> 1 | AH38: {=INDEX($AD$32:$BE$32, 1, MOD(COLUMNS($AD$38:AH38)-1 + INDEX(SHIFT_TBL,1,6), 28) + 1)} -> 0 | AI38: {=INDEX($AD$32:$BE$32, 1, MOD(COLUMNS($AD$38:AI38)-1 + INDEX(SHIFT_TBL,1,6), 28) + 1)} -> 0 | AJ38: {=INDEX($AD$32:$BE$32, 1, MOD(COLUMNS($AD$38:AJ38)-1 + INDEX(SHIFT_TBL,1,6), 28) + 1)} -> 1 | AK38: {=INDEX($AD$32:$BE$32, 1, MOD(COLUMNS($AD$38:AK38)-1 + INDEX(SHIFT_TBL,1,6), 28) + 1)} -> 1 | ... BE38: {=INDEX($AD$32:$BE$32, 1, MOD(COLUMNS($AD$38:BE38)-1 + INDEX(SHIFT_TBL,1,6), 28) + 1)} -> 1
A39: C6||D6 | B39: {=INDEX($B$32:$AC$32, 1, MOD(COLUMNS($B$38:B39)-1 + INDEX(SHIFT_TBL,1,6), 28) + 1)} -> 0 | C39: {=INDEX($B$32:$AC$32, 1, MOD(COLUMNS($B$38:C39)-1 + INDEX(SHIFT_TBL,1,6), 28) + 1)} -> 0 | D39: {=INDEX($B$32:$AC$32, 1, MOD(COLUMNS($B$38:D39)-1 + INDEX(SHIFT_TBL,1,6), 28) + 1)} -> 1 | E39: {=INDEX($B$32:$AC$32, 1, MOD(COLUMNS($B$38:E39)-1 + INDEX(SHIFT_TBL,1,6), 28) + 1)} -> 1 | F39: {=INDEX($B$32:$AC$32, 1, MOD(COLUMNS($B$38:F39)-1 + INDEX(SHIFT_TBL,1,6), 28) + 1)} -> 0 | G39: {=INDEX($B$32:$AC$32, 1, MOD(COLUMNS($B$38:G39)-1 + INDEX(SHIFT_TBL,1,6), 28) + 1)} -> 0 | H39: {=INDEX($B$32:$AC$32, 1, MOD(COLUMNS($B$38:H39)-1 + INDEX(SHIFT_TBL,1,6), 28) + 1)} -> 1 | I39: {=INDEX($B$32:$AC$32, 1, MOD(COLUMNS($B$38:I39)-1 + INDEX(SHIFT_TBL,1,6), 28) + 1)} -> 0 | ... AC39: {=INDEX($B$32:$AC$32, 1, MOD(COLUMNS($B$38:AC39)-1 + INDEX(SHIFT_TBL,1,6), 28) + 1)} -> 1 | AD39: {=INDEX($AD$32:$BE$32, 1, MOD(COLUMNS($AD$38:AD39)-1 + INDEX(SHIFT_TBL,1,5), 28) + 1)} -> 0 | AE39: {=INDEX($AD$32:$BE$32, 1, MOD(COLUMNS($AD$38:AE39)-1 + INDEX(SHIFT_TBL,1,5), 28) + 1)} -> 0 | AF39: {=INDEX($AD$32:$BE$32, 1, MOD(COLUMNS($AD$38:AF39)-1 + INDEX(SHIFT_TBL,1,5), 28) + 1)} -> 1 | AG39: {=INDEX($AD$32:$BE$32, 1, MOD(COLUMNS($AD$38:AG39)-1 + INDEX(SHIFT_TBL,1,5), 28) + 1)} -> 1 | AH39: {=INDEX($AD$32:$BE$32, 1, MOD(COLUMNS($AD$38:AH39)-1 + INDEX(SHIFT_TBL,1,5), 28) + 1)} -> 0 | AI39: {=INDEX($AD$32:$BE$32, 1, MOD(COLUMNS($AD$38:AI39)-1 + INDEX(SHIFT_TBL,1,5), 28) + 1)} -> 0 | AJ39: {=INDEX($AD$32:$BE$32, 1, MOD(COLUMNS($AD$38:AJ39)-1 + INDEX(SHIFT_TBL,1,5), 28) + 1)} -> 1 | AK39: {=INDEX($AD$32:$BE$32, 1, MOD(COLUMNS($AD$38:AK39)-1 + INDEX(SHIFT_TBL,1,5), 28) + 1)} -> 1 | ... BE39: {=INDEX($AD$32:$BE$32, 1, MOD(COLUMNS($AD$38:BE39)-1 + INDEX(SHIFT_TBL,1,5), 28) + 1)} -> 1
A40: K6 | B40: {=INDEX($B$38:$BE$38, 1, INDEX(PC2_TBL, COLUMNS($B$40:B40)))} -> 0 | C40: {=INDEX($B$38:$BE$38, 1, INDEX(PC2_TBL, COLUMNS($B$40:C40)))} -> 1 | D40: {=INDEX($B$38:$BE$38, 1, INDEX(PC2_TBL, COLUMNS($B$40:D40)))} -> 1 | E40: {=INDEX($B$38:$BE$38, 1, INDEX(PC2_TBL, COLUMNS($B$40:E40)))} -> 0 | F40: {=INDEX($B$38:$BE$38, 1, INDEX(PC2_TBL, COLUMNS($B$40:F40)))} -> 0 | G40: {=INDEX($B$38:$BE$38, 1, INDEX(PC2_TBL, COLUMNS($B$40:G40)))} -> 0 | H40: {=INDEX($B$38:$BE$38, 1, INDEX(PC2_TBL, COLUMNS($B$40:H40)))} -> 1 | I40: {=INDEX($B$38:$BE$38, 1, INDEX(PC2_TBL, COLUMNS($B$40:I40)))} -> 1 | ... AW40: {=INDEX($B$38:$BE$38, 1, INDEX(PC2_TBL, COLUMNS($B$40:AW40)))} -> 1
A42: Round 7 | AD42: D7
A43: C7 | B43: {=INDEX($B$38:$AC$38, 1, MOD(COLUMNS($B$43:B43)-1 + INDEX(SHIFT_TBL,1,7), 28) + 1)} -> 1 | C43: {=INDEX($B$38:$AC$38, 1, MOD(COLUMNS($B$43:C43)-1 + INDEX(SHIFT_TBL,1,7), 28) + 1)} -> 1 | D43: {=INDEX($B$38:$AC$38, 1, MOD(COLUMNS($B$43:D43)-1 + INDEX(SHIFT_TBL,1,7), 28) + 1)} -> 0 | E43: {=INDEX($B$38:$AC$38, 1, MOD(COLUMNS($B$43:E43)-1 + INDEX(SHIFT_TBL,1,7), 28) + 1)} -> 0 | F43: {=INDEX($B$38:$AC$38, 1, MOD(COLUMNS($B$43:F43)-1 + INDEX(SHIFT_TBL,1,7), 28) + 1)} -> 1 | G43: {=INDEX($B$38:$AC$38, 1, MOD(COLUMNS($B$43:G43)-1 + INDEX(SHIFT_TBL,1,7), 28) + 1)} -> 0 | H43: {=INDEX($B$38:$AC$38, 1, MOD(COLUMNS($B$43:H43)-1 + INDEX(SHIFT_TBL,1,7), 28) + 1)} -> 1 | I43: {=INDEX($B$38:$AC$38, 1, MOD(COLUMNS($B$43:I43)-1 + INDEX(SHIFT_TBL,1,7), 28) + 1)} -> 0 | ... AC43: {=INDEX($B$38:$AC$38, 1, MOD(COLUMNS($B$43:AC43)-1 + INDEX(SHIFT_TBL,1,7), 28) + 1)} -> 0 | AD43: {=INDEX($AD$38:$BE$38, 1, MOD(COLUMNS($AD$43:AD43)-1 + INDEX(SHIFT_TBL,1,7), 28) + 1)} -> 1 | AE43: {=INDEX($AD$38:$BE$38, 1, MOD(COLUMNS($AD$43:AE43)-1 + INDEX(SHIFT_TBL,1,7), 28) + 1)} -> 1 | AF43: {=INDEX($AD$38:$BE$38, 1, MOD(COLUMNS($AD$43:AF43)-1 + INDEX(SHIFT_TBL,1,7), 28) + 1)} -> 0 | AG43: {=INDEX($AD$38:$BE$38, 1, MOD(COLUMNS($AD$43:AG43)-1 + INDEX(SHIFT_TBL,1,7), 28) + 1)} -> 0 | AH43: {=INDEX($AD$38:$BE$38, 1, MOD(COLUMNS($AD$43:AH43)-1 + INDEX(SHIFT_TBL,1,7), 28) + 1)} -> 1 | AI43: {=INDEX($AD$38:$BE$38, 1, MOD(COLUMNS($AD$43:AI43)-1 + INDEX(SHIFT_TBL,1,7), 28) + 1)} -> 1 | AJ43: {=INDEX($AD$38:$BE$38, 1, MOD(COLUMNS($AD$43:AJ43)-1 + INDEX(SHIFT_TBL,1,7), 28) + 1)} -> 1 | AK43: {=INDEX($AD$38:$BE$38, 1, MOD(COLUMNS($AD$43:AK43)-1 + INDEX(SHIFT_TBL,1,7), 28) + 1)} -> 1 | ... BE43: {=INDEX($AD$38:$BE$38, 1, MOD(COLUMNS($AD$43:BE43)-1 + INDEX(SHIFT_TBL,1,7), 28) + 1)} -> 0
A44: C7||D7 | B44: {=INDEX($B$38:$AC$38, 1, MOD(COLUMNS($B$43:B44)-1 + INDEX(SHIFT_TBL,1,7), 28) + 1)} -> 1 | C44: {=INDEX($B$38:$AC$38, 1, MOD(COLUMNS($B$43:C44)-1 + INDEX(SHIFT_TBL,1,7), 28) + 1)} -> 1 | D44: {=INDEX($B$38:$AC$38, 1, MOD(COLUMNS($B$43:D44)-1 + INDEX(SHIFT_TBL,1,7), 28) + 1)} -> 0 | E44: {=INDEX($B$38:$AC$38, 1, MOD(COLUMNS($B$43:E44)-1 + INDEX(SHIFT_TBL,1,7), 28) + 1)} -> 0 | F44: {=INDEX($B$38:$AC$38, 1, MOD(COLUMNS($B$43:F44)-1 + INDEX(SHIFT_TBL,1,7), 28) + 1)} -> 1 | G44: {=INDEX($B$38:$AC$38, 1, MOD(COLUMNS($B$43:G44)-1 + INDEX(SHIFT_TBL,1,7), 28) + 1)} -> 0 | H44: {=INDEX($B$38:$AC$38, 1, MOD(COLUMNS($B$43:H44)-1 + INDEX(SHIFT_TBL,1,7), 28) + 1)} -> 1 | I44: {=INDEX($B$38:$AC$38, 1, MOD(COLUMNS($B$43:I44)-1 + INDEX(SHIFT_TBL,1,7), 28) + 1)} -> 0 | ... AC44: {=INDEX($B$38:$AC$38, 1, MOD(COLUMNS($B$43:AC44)-1 + INDEX(SHIFT_TBL,1,7), 28) + 1)} -> 0 | AD44: {=INDEX($AD$38:$BE$38, 1, MOD(COLUMNS($AD$43:AD44)-1 + INDEX(SHIFT_TBL,1,7), 28) + 1)} -> 1 | AE44: {=INDEX($AD$38:$BE$38, 1, MOD(COLUMNS($AD$43:AE44)-1 + INDEX(SHIFT_TBL,1,7), 28) + 1)} -> 1 | AF44: {=INDEX($AD$38:$BE$38, 1, MOD(COLUMNS($AD$43:AF44)-1 + INDEX(SHIFT_TBL,1,7), 28) + 1)} -> 0 | AG44: {=INDEX($AD$38:$BE$38, 1, MOD(COLUMNS($AD$43:AG44)-1 + INDEX(SHIFT_TBL,1,7), 28) + 1)} -> 0 | AH44: {=INDEX($AD$38:$BE$38, 1, MOD(COLUMNS($AD$43:AH44)-1 + INDEX(SHIFT_TBL,1,7), 28) + 1)} -> 1 | AI44: {=INDEX($AD$38:$BE$38, 1, MOD(COLUMNS($AD$43:AI44)-1 + INDEX(SHIFT_TBL,1,7), 28) + 1)} -> 1 | AJ44: {=INDEX($AD$38:$BE$38, 1, MOD(COLUMNS($AD$43:AJ44)-1 + INDEX(SHIFT_TBL,1,7), 28) + 1)} -> 1 | AK44: {=INDEX($AD$38:$BE$38, 1, MOD(COLUMNS($AD$43:AK44)-1 + INDEX(SHIFT_TBL,1,7), 28) + 1)} -> 1 | ... BE44: {=INDEX($AD$38:$BE$38, 1, MOD(COLUMNS($AD$43:BE44)-1 + INDEX(SHIFT_TBL,1,7), 28) + 1)} -> 0
A45: K7 | B45: {=INDEX($B$43:$BE$43, 1, INDEX(PC2_TBL, COLUMNS($B$45:B45)))} -> 0 | C45: {=INDEX($B$43:$BE$43, 1, INDEX(PC2_TBL, COLUMNS($B$45:C45)))} -> 1 | D45: {=INDEX($B$43:$BE$43, 1, INDEX(PC2_TBL, COLUMNS($B$45:D45)))} -> 1 | E45: {=INDEX($B$43:$BE$43, 1, INDEX(PC2_TBL, COLUMNS($B$45:E45)))} -> 0 | F45: {=INDEX($B$43:$BE$43, 1, INDEX(PC2_TBL, COLUMNS($B$45:F45)))} -> 1 | G45: {=INDEX($B$43:$BE$43, 1, INDEX(PC2_TBL, COLUMNS($B$45:G45)))} -> 1 | H45: {=INDEX($B$43:$BE$43, 1, INDEX(PC2_TBL, COLUMNS($B$45:H45)))} -> 0 | I45: {=INDEX($B$43:$BE$43, 1, INDEX(PC2_TBL, COLUMNS($B$45:I45)))} -> 0 | ... AW45: {=INDEX($B$43:$BE$43, 1, INDEX(PC2_TBL, COLUMNS($B$45:AW45)))} -> 0
A47: Round 8 | AD47: D8
A48: C8 | B48: {=INDEX($B$43:$AC$43, 1, MOD(COLUMNS($B$48:B48)-1 + INDEX(SHIFT_TBL,1,8), 28) + 1)} -> 0 | C48: {=INDEX($B$43:$AC$43, 1, MOD(COLUMNS($B$48:C48)-1 + INDEX(SHIFT_TBL,1,8), 28) + 1)} -> 0 | D48: {=INDEX($B$43:$AC$43, 1, MOD(COLUMNS($B$48:D48)-1 + INDEX(SHIFT_TBL,1,8), 28) + 1)} -> 1 | E48: {=INDEX($B$43:$AC$43, 1, MOD(COLUMNS($B$48:E48)-1 + INDEX(SHIFT_TBL,1,8), 28) + 1)} -> 0 | F48: {=INDEX($B$43:$AC$43, 1, MOD(COLUMNS($B$48:F48)-1 + INDEX(SHIFT_TBL,1,8), 28) + 1)} -> 1 | G48: {=INDEX($B$43:$AC$43, 1, MOD(COLUMNS($B$48:G48)-1 + INDEX(SHIFT_TBL,1,8), 28) + 1)} -> 0 | H48: {=INDEX($B$43:$AC$43, 1, MOD(COLUMNS($B$48:H48)-1 + INDEX(SHIFT_TBL,1,8), 28) + 1)} -> 1 | I48: {=INDEX($B$43:$AC$43, 1, MOD(COLUMNS($B$48:I48)-1 + INDEX(SHIFT_TBL,1,8), 28) + 1)} -> 0 | ... AC48: {=INDEX($B$43:$AC$43, 1, MOD(COLUMNS($B$48:AC48)-1 + INDEX(SHIFT_TBL,1,8), 28) + 1)} -> 1 | AD48: {=INDEX($AD$43:$BE$43, 1, MOD(COLUMNS($AD$48:AD48)-1 + INDEX(SHIFT_TBL,1,8), 28) + 1)} -> 0 | AE48: {=INDEX($AD$43:$BE$43, 1, MOD(COLUMNS($AD$48:AE48)-1 + INDEX(SHIFT_TBL,1,8), 28) + 1)} -> 0 | AF48: {=INDEX($AD$43:$BE$43, 1, MOD(COLUMNS($AD$48:AF48)-1 + INDEX(SHIFT_TBL,1,8), 28) + 1)} -> 1 | AG48: {=INDEX($AD$43:$BE$43, 1, MOD(COLUMNS($AD$48:AG48)-1 + INDEX(SHIFT_TBL,1,8), 28) + 1)} -> 1 | AH48: {=INDEX($AD$43:$BE$43, 1, MOD(COLUMNS($AD$48:AH48)-1 + INDEX(SHIFT_TBL,1,8), 28) + 1)} -> 1 | AI48: {=INDEX($AD$43:$BE$43, 1, MOD(COLUMNS($AD$48:AI48)-1 + INDEX(SHIFT_TBL,1,8), 28) + 1)} -> 1 | AJ48: {=INDEX($AD$43:$BE$43, 1, MOD(COLUMNS($AD$48:AJ48)-1 + INDEX(SHIFT_TBL,1,8), 28) + 1)} -> 0 | AK48: {=INDEX($AD$43:$BE$43, 1, MOD(COLUMNS($AD$48:AK48)-1 + INDEX(SHIFT_TBL,1,8), 28) + 1)} -> 0 | ... BE48: {=INDEX($AD$43:$BE$43, 1, MOD(COLUMNS($AD$48:BE48)-1 + INDEX(SHIFT_TBL,1,8), 28) + 1)} -> 1
A49: C8||D8 | B49: {=INDEX($B$43:$AC$43, 1, MOD(COLUMNS($B$48:B49)-1 + INDEX(SHIFT_TBL,1,8), 28) + 1)} -> 0 | C49: {=INDEX($B$43:$AC$43, 1, MOD(COLUMNS($B$48:C49)-1 + INDEX(SHIFT_TBL,1,8), 28) + 1)} -> 0 | D49: {=INDEX($B$43:$AC$43, 1, MOD(COLUMNS($B$48:D49)-1 + INDEX(SHIFT_TBL,1,8), 28) + 1)} -> 1 | E49: {=INDEX($B$43:$AC$43, 1, MOD(COLUMNS($B$48:E49)-1 + INDEX(SHIFT_TBL,1,8), 28) + 1)} -> 0 | F49: {=INDEX($B$43:$AC$43, 1, MOD(COLUMNS($B$48:F49)-1 + INDEX(SHIFT_TBL,1,8), 28) + 1)} -> 1 | G49: {=INDEX($B$43:$AC$43, 1, MOD(COLUMNS($B$48:G49)-1 + INDEX(SHIFT_TBL,1,8), 28) + 1)} -> 0 | H49: {=INDEX($B$43:$AC$43, 1, MOD(COLUMNS($B$48:H49)-1 + INDEX(SHIFT_TBL,1,8), 28) + 1)} -> 1 | I49: {=INDEX($B$43:$AC$43, 1, MOD(COLUMNS($B$48:I49)-1 + INDEX(SHIFT_TBL,1,8), 28) + 1)} -> 0 | ... AC49: {=INDEX($B$43:$AC$43, 1, MOD(COLUMNS($B$48:AC49)-1 + INDEX(SHIFT_TBL,1,8), 28) + 1)} -> 1 | AD49: {=INDEX($AD$43:$BE$43, 1, MOD(COLUMNS($AD$48:AD49)-1 + INDEX(SHIFT_TBL,1,8), 28) + 1)} -> 0 | AE49: {=INDEX($AD$43:$BE$43, 1, MOD(COLUMNS($AD$48:AE49)-1 + INDEX(SHIFT_TBL,1,8), 28) + 1)} -> 0 | AF49: {=INDEX($AD$43:$BE$43, 1, MOD(COLUMNS($AD$48:AF49)-1 + INDEX(SHIFT_TBL,1,8), 28) + 1)} -> 1 | AG49: {=INDEX($AD$43:$BE$43, 1, MOD(COLUMNS($AD$48:AG49)-1 + INDEX(SHIFT_TBL,1,8), 28) + 1)} -> 1 | AH49: {=INDEX($AD$43:$BE$43, 1, MOD(COLUMNS($AD$48:AH49)-1 + INDEX(SHIFT_TBL,1,8), 28) + 1)} -> 1 | AI49: {=INDEX($AD$43:$BE$43, 1, MOD(COLUMNS($AD$48:AI49)-1 + INDEX(SHIFT_TBL,1,8), 28) + 1)} -> 1 | AJ49: {=INDEX($AD$43:$BE$43, 1, MOD(COLUMNS($AD$48:AJ49)-1 + INDEX(SHIFT_TBL,1,8), 28) + 1)} -> 0 | AK49: {=INDEX($AD$43:$BE$43, 1, MOD(COLUMNS($AD$48:AK49)-1 + INDEX(SHIFT_TBL,1,8), 28) + 1)} -> 0 | ... BE49: {=INDEX($AD$43:$BE$43, 1, MOD(COLUMNS($AD$48:BE49)-1 + INDEX(SHIFT_TBL,1,8), 28) + 1)} -> 1
A50: K8 | B50: {=INDEX($B$48:$BE$48, 1, INDEX(PC2_TBL, COLUMNS($B$50:B50)))} -> 1 | C50: {=INDEX($B$48:$BE$48, 1, INDEX(PC2_TBL, COLUMNS($B$50:C50)))} -> 1 | D50: {=INDEX($B$48:$BE$48, 1, INDEX(PC2_TBL, COLUMNS($B$50:D50)))} -> 1 | E50: {=INDEX($B$48:$BE$48, 1, INDEX(PC2_TBL, COLUMNS($B$50:E50)))} -> 1 | F50: {=INDEX($B$48:$BE$48, 1, INDEX(PC2_TBL, COLUMNS($B$50:F50)))} -> 0 | G50: {=INDEX($B$48:$BE$48, 1, INDEX(PC2_TBL, COLUMNS($B$50:G50)))} -> 1 | H50: {=INDEX($B$48:$BE$48, 1, INDEX(PC2_TBL, COLUMNS($B$50:H50)))} -> 1 | I50: {=INDEX($B$48:$BE$48, 1, INDEX(PC2_TBL, COLUMNS($B$50:I50)))} -> 1 | ... AW50: {=INDEX($B$48:$BE$48, 1, INDEX(PC2_TBL, COLUMNS($B$50:AW50)))} -> 1
A52: Round 9 | AD52: D10
A53: C9 | B53: {=INDEX($B$48:$AC$48, 1, MOD(COLUMNS($B$53:B53)-1 + INDEX(SHIFT_TBL,1,9), 28) + 1)} -> 0 | C53: {=INDEX($B$48:$AC$48, 1, MOD(COLUMNS($B$53:C53)-1 + INDEX(SHIFT_TBL,1,9), 28) + 1)} -> 1 | D53: {=INDEX($B$48:$AC$48, 1, MOD(COLUMNS($B$53:D53)-1 + INDEX(SHIFT_TBL,1,9), 28) + 1)} -> 0 | E53: {=INDEX($B$48:$AC$48, 1, MOD(COLUMNS($B$53:E53)-1 + INDEX(SHIFT_TBL,1,9), 28) + 1)} -> 1 | F53: {=INDEX($B$48:$AC$48, 1, MOD(COLUMNS($B$53:F53)-1 + INDEX(SHIFT_TBL,1,9), 28) + 1)} -> 0 | G53: {=INDEX($B$48:$AC$48, 1, MOD(COLUMNS($B$53:G53)-1 + INDEX(SHIFT_TBL,1,9), 28) + 1)} -> 1 | H53: {=INDEX($B$48:$AC$48, 1, MOD(COLUMNS($B$53:H53)-1 + INDEX(SHIFT_TBL,1,9), 28) + 1)} -> 0 | I53: {=INDEX($B$48:$AC$48, 1, MOD(COLUMNS($B$53:I53)-1 + INDEX(SHIFT_TBL,1,9), 28) + 1)} -> 1 | ... AC53: {=INDEX($B$48:$AC$48, 1, MOD(COLUMNS($B$53:AC53)-1 + INDEX(SHIFT_TBL,1,9), 28) + 1)} -> 0 | AD53: {=INDEX($AD$48:$BE$48, 1, MOD(COLUMNS($AD$53:AD53)-1 + INDEX(SHIFT_TBL,1,9), 28) + 1)} -> 0 | AE53: {=INDEX($AD$48:$BE$48, 1, MOD(COLUMNS($AD$53:AE53)-1 + INDEX(SHIFT_TBL,1,9), 28) + 1)} -> 1 | AF53: {=INDEX($AD$48:$BE$48, 1, MOD(COLUMNS($AD$53:AF53)-1 + INDEX(SHIFT_TBL,1,9), 28) + 1)} -> 1 | AG53: {=INDEX($AD$48:$BE$48, 1, MOD(COLUMNS($AD$53:AG53)-1 + INDEX(SHIFT_TBL,1,9), 28) + 1)} -> 1 | AH53: {=INDEX($AD$48:$BE$48, 1, MOD(COLUMNS($AD$53:AH53)-1 + INDEX(SHIFT_TBL,1,9), 28) + 1)} -> 1 | AI53: {=INDEX($AD$48:$BE$48, 1, MOD(COLUMNS($AD$53:AI53)-1 + INDEX(SHIFT_TBL,1,9), 28) + 1)} -> 0 | AJ53: {=INDEX($AD$48:$BE$48, 1, MOD(COLUMNS($AD$53:AJ53)-1 + INDEX(SHIFT_TBL,1,9), 28) + 1)} -> 0 | AK53: {=INDEX($AD$48:$BE$48, 1, MOD(COLUMNS($AD$53:AK53)-1 + INDEX(SHIFT_TBL,1,9), 28) + 1)} -> 0 | ... BE53: {=INDEX($AD$48:$BE$48, 1, MOD(COLUMNS($AD$53:BE53)-1 + INDEX(SHIFT_TBL,1,9), 28) + 1)} -> 0
A54: C9||D9 | B54: {=INDEX($B$48:$AC$48, 1, MOD(COLUMNS($B$53:B54)-1 + INDEX(SHIFT_TBL,1,9), 28) + 1)} -> 0 | C54: {=INDEX($B$48:$AC$48, 1, MOD(COLUMNS($B$53:C54)-1 + INDEX(SHIFT_TBL,1,9), 28) + 1)} -> 1 | D54: {=INDEX($B$48:$AC$48, 1, MOD(COLUMNS($B$53:D54)-1 + INDEX(SHIFT_TBL,1,9), 28) + 1)} -> 0 | E54: {=INDEX($B$48:$AC$48, 1, MOD(COLUMNS($B$53:E54)-1 + INDEX(SHIFT_TBL,1,9), 28) + 1)} -> 1 | F54: {=INDEX($B$48:$AC$48, 1, MOD(COLUMNS($B$53:F54)-1 + INDEX(SHIFT_TBL,1,9), 28) + 1)} -> 0 | G54: {=INDEX($B$48:$AC$48, 1, MOD(COLUMNS($B$53:G54)-1 + INDEX(SHIFT_TBL,1,9), 28) + 1)} -> 1 | H54: {=INDEX($B$48:$AC$48, 1, MOD(COLUMNS($B$53:H54)-1 + INDEX(SHIFT_TBL,1,9), 28) + 1)} -> 0 | I54: {=INDEX($B$48:$AC$48, 1, MOD(COLUMNS($B$53:I54)-1 + INDEX(SHIFT_TBL,1,9), 28) + 1)} -> 1 | ... AC54: {=INDEX($B$48:$AC$48, 1, MOD(COLUMNS($B$53:AC54)-1 + INDEX(SHIFT_TBL,1,9), 28) + 1)} -> 0 | AD54: {=INDEX($AD$48:$BE$48, 1, MOD(COLUMNS($AD$53:AD54)-1 + INDEX(SHIFT_TBL,1,9), 28) + 1)} -> 0 | AE54: {=INDEX($AD$48:$BE$48, 1, MOD(COLUMNS($AD$53:AE54)-1 + INDEX(SHIFT_TBL,1,9), 28) + 1)} -> 1 | AF54: {=INDEX($AD$48:$BE$48, 1, MOD(COLUMNS($AD$53:AF54)-1 + INDEX(SHIFT_TBL,1,9), 28) + 1)} -> 1 | AG54: {=INDEX($AD$48:$BE$48, 1, MOD(COLUMNS($AD$53:AG54)-1 + INDEX(SHIFT_TBL,1,9), 28) + 1)} -> 1 | AH54: {=INDEX($AD$48:$BE$48, 1, MOD(COLUMNS($AD$53:AH54)-1 + INDEX(SHIFT_TBL,1,9), 28) + 1)} -> 1 | AI54: {=INDEX($AD$48:$BE$48, 1, MOD(COLUMNS($AD$53:AI54)-1 + INDEX(SHIFT_TBL,1,9), 28) + 1)} -> 0 | AJ54: {=INDEX($AD$48:$BE$48, 1, MOD(COLUMNS($AD$53:AJ54)-1 + INDEX(SHIFT_TBL,1,9), 28) + 1)} -> 0 | AK54: {=INDEX($AD$48:$BE$48, 1, MOD(COLUMNS($AD$53:AK54)-1 + INDEX(SHIFT_TBL,1,9), 28) + 1)} -> 0 | ... BE54: {=INDEX($AD$48:$BE$48, 1, MOD(COLUMNS($AD$53:BE54)-1 + INDEX(SHIFT_TBL,1,9), 28) + 1)} -> 0
A55: K9 | B55: {=INDEX($B$53:$BE$53, 1, INDEX(PC2_TBL, COLUMNS($B$55:B55)))} -> 1 | C55: {=INDEX($B$53:$BE$53, 1, INDEX(PC2_TBL, COLUMNS($B$55:C55)))} -> 1 | D55: {=INDEX($B$53:$BE$53, 1, INDEX(PC2_TBL, COLUMNS($B$55:D55)))} -> 0 | E55: {=INDEX($B$53:$BE$53, 1, INDEX(PC2_TBL, COLUMNS($B$55:E55)))} -> 0 | F55: {=INDEX($B$53:$BE$53, 1, INDEX(PC2_TBL, COLUMNS($B$55:F55)))} -> 0 | G55: {=INDEX($B$53:$BE$53, 1, INDEX(PC2_TBL, COLUMNS($B$55:G55)))} -> 0 | H55: {=INDEX($B$53:$BE$53, 1, INDEX(PC2_TBL, COLUMNS($B$55:H55)))} -> 0 | I55: {=INDEX($B$53:$BE$53, 1, INDEX(PC2_TBL, COLUMNS($B$55:I55)))} -> 0 | ... AW55: {=INDEX($B$53:$BE$53, 1, INDEX(PC2_TBL, COLUMNS($B$55:AW55)))} -> 1
...

Sheet Rounds
B5: L0 | AH5: R0
B6: {=INDEX(M_BITS, 1, INDEX(IP_TBL, COLUMNS($B$6:B6)))} -> 1 | C6: {=INDEX(M_BITS, 1, INDEX(IP_TBL, COLUMNS($B$6:C6)))} -> 0 | D6: {=INDEX(M_BITS, 1, INDEX(IP_TBL, COLUMNS($B$6:D6)))} -> 0 | E6: {=INDEX(M_BITS, 1, INDEX(IP_TBL, COLUMNS($B$6:E6)))} -> 1 | F6: {=INDEX(M_BITS, 1, INDEX(IP_TBL, COLUMNS($B$6:F6)))} -> 1 | G6: {=INDEX(M_BITS, 1, INDEX(IP_TBL, COLUMNS($B$6:G6)))} -> 0 | H6: {=INDEX(M_BITS, 1, INDEX(IP_TBL, COLUMNS($B$6:H6)))} -> 0 | I6: {=INDEX(M_BITS, 1, INDEX(IP_TBL, COLUMNS($B$6:I6)))} -> 0 | ... BM6: {=INDEX(M_BITS, 1, INDEX(IP_TBL, COLUMNS($B$6:BM6)))} -> 0
A11: Round 1
A12: E(R0) | B12: {=INDEX($AH$6:$BM$6, 1, INDEX(E_TBL, COLUMNS($B$12:B12)))} -> 0 | C12: {=INDEX($AH$6:$BM$6, 1, INDEX(E_TBL, COLUMNS($B$12:C12)))} -> 1 | D12: {=INDEX($AH$6:$BM$6, 1, INDEX(E_TBL, COLUMNS($B$12:D12)))} -> 1 | E12: {=INDEX($AH$6:$BM$6, 1, INDEX(E_TBL, COLUMNS($B$12:E12)))} -> 1 | F12: {=INDEX($AH$6:$BM$6, 1, INDEX(E_TBL, COLUMNS($B$12:F12)))} -> 0 | G12: {=INDEX($AH$6:$BM$6, 1, INDEX(E_TBL, COLUMNS($B$12:G12)))} -> 0 | H12: {=INDEX($AH$6:$BM$6, 1, INDEX(E_TBL, COLUMNS($B$12:H12)))} -> 0 | I12: {=INDEX($AH$6:$BM$6, 1, INDEX(E_TBL, COLUMNS($B$12:I12)))} -> 0 | ... AW12: {=INDEX($AH$6:$BM$6, 1, INDEX(E_TBL, COLUMNS($B$12:AW12)))} -> 1
A13: XOR với K1 | B13: =MOD(B12 + Key!B14, 2) -> 0 | C13: =MOD(C12 + Key!C14, 2) -> 1 | D13: =MOD(D12 + Key!D14, 2) -> 1 | E13: =MOD(E12 + Key!E14, 2) -> 0 | F13: =MOD(F12 + Key!F14, 2) -> 1 | G13: =MOD(G12 + Key!G14, 2) -> 0 | H13: =MOD(H12 + Key!H14, 2) -> 1 | I13: =MOD(I12 + Key!I14, 2) -> 1 | ... AW13: =MOD(AW12 + Key!AW14, 2) -> 0
B14: S1 | H14: S2 | N14: S3 | T14: S4 | Z14: S5 | AF14: S6 | AL14: S7 | AR14: S8
B15: 1001 | H15: 0101 | N15: 1101 | T15: 0011 | Z15: 1010 | AF15: 1101 | AL15: 0101 | AR15: 0000
A16: Hoán vị | B16: 1001 | C16: 0111 | D16: 1101 | E16: 0001 | F16: 0110 | G16: 0001 | H16: 1001 | I16: 1010
A17: R1: | B17: 0000 | C17: 1111 | D17: 0010 | E17: 1111 | F17: 1010 | G17: 1101 | H17: 1001 | I17: 1010
A19: Round 2
A20: E(R1) | B20: 0 | C20: 0 | D20: 0 | E20: 0 | F20: 0 | G20: 1 | H20: 0 | I20: 1 | J20: 1 | K20: 1 | L20: 1 | M20: 0 | N20: 1 | O20: 0 | P20: 0 | Q20: 1 | R20: 0 | S20: 1 | T20: 0 | U20: 1 | V20: 1 | W20: 1 | X20: 1 | Y20: 1 | Z20: 1 | AA20: 1 | AB20: 0 | AC20: 1 | AD20: 0 | AE20: 1 | AF20: 0 | AG20: 1 | AH20: 1 | AI20: 0 | AJ20: 1 | AK20: 1 | AL20: 1 | AM20: 1 | AN20: 0 | AO20: 0 | AP20: 1 | AQ20: 1 | AR20: 1 | AS20: 1 | AT20: 0 | AU20: 1 | AV20: 0 | AW20: 0
A21: XOR | B21: =MOD(B20 + Key!B19, 2) -> 0 | C21: =MOD(C20 + Key!C19, 2) -> 1 | D21: =MOD(D20 + Key!D19, 2) -> 1 | E21: =MOD(E20 + Key!E19, 2) -> 0 | F21: =MOD(F20 + Key!F19, 2) -> 1 | G21: =MOD(G20 + Key!G19, 2) -> 1 | H21: =MOD(H20 + Key!H19, 2) -> 0 | I21: =MOD(I20 + Key!I19, 2) -> 0 | ... AW21: =MOD(AW20 + Key!AW19, 2) -> 0
A22: Hoán vị | B22: 0101 | C22: 1000 | D22: 1000 | E22: 0011 | F22: 0000 | G22: 0100 | H22: 0101 | I22: 1001
A23: R2 | B23: 0110 | C23: 1000 | D23: 0001 | E23: 1100 | F23: 0111 | G23: 1101 | H23: 1010 | I23: 0001
A25: Round 3
A26: E(R2) | B26: 1011 | C26: 0101 | D26: 0000 | E26: 0000 | F26: 1111 | G26: 1000 | H26: 0011 | I26: 1111 | J26: 1011 | K26: 1101 | L26: 0000 | M26: 0010
A27: XOR | B27: 1110 | C27: 0000 | D27: 1111 | E27: 1100 | F27: 0111 | G27: 0010 | H27: 1000 | I27: 1011 | J27: 0001 | K27: 0001 | L27: 1101 | M27: 0000
A28: Hoán vị | B28: 1101 | C28: 1010 | D28: 0011 | E28: 1011 | F28: 0010 | G28: 0110 | H28: 1001 | I28: 0010
A29: R3 | B29: 1101 | C29: 0101 | D29: 0001 | E29: 0100 | F29: 1000 | G29: 1011 | H29: 0000 | I29: 1000
A31: Round 4
A32: E(R3) | B32: 0110 1010 1010 0110 1000 1010 1000 1010 0100 1010 1001 1010 1000 1000 1010 0001
A33: XOR | B33: 0000 0011 0001 0000 0000 0001 0001 0011 0001 1110 0111 1001 1100 0000
A34: Hoán vị | B34: 1111 0010 1001 0001 0001 0100 1010 1010 0000 1010 0110 1110
A35: R4 | B35: 1001 1100 0110 0101 0011 0100 1010 0101 1001 0011 0010 0111
A37: Round 5
A38: E(R4) | B38: 1100 1111 1000 0010 1010 1010 1001 0101 1010 1000 1010 0111
A39: XOR | B39: 1011 0011 0110 1110 1010 111 100 1010 0100 1110 0110 0101
A40: Hoán vị | B40: 1101 1000 0011 0010 0011 0111 1111 1101
A41: R5 | B41: 0000 1101 0010 0110 1011 1100 1111 0101
A43: Round 6
A44: E(R5) | B44: 1000 0101 1010 1001 0001 0011 0110 0011 0101 0010 1110 1111
A45: XOR | B45: 1110 0110 0000 1100 0001 0011 0110 0011 0101 0010 1110 1111
A46: Hoán vị | B46: 1010 1111 1100 0100 0011 1011 0010 0101
A47: R6 | B47: 0011 0011 1001 0001 0001 0110 0011 0110
A49: Round 7
A50: E(R6) | B50: 0001 1010 0111 1100 1010 0010 1000 1010 1100 0001 1010 1100
A51: XOR | B51: 0111 0110 1111 1000 0001 0101 0000 0000 0010 0101 1010 1010
A52: Hoán vị | B52: 0100 1110 0101 0001 0010 0011 1010 0010
A53: R7 | B53: 0100 0011 0111 0111 1001 1111 0101 0111
A55: Round 8
...

Sheet Output
B4: Hoán vị | C4: 0 | D4: 0 | E4: 0 | F4: 1 | G4: 1 | H4: 0 | I4: 1 | J4: 0 | K4: 1 | L4: 0 | M4: 1 | N4: 1 | O4: 1 | P4: 1 | Q4: 1 | R4: 1 | S4: 1 | T4: 1 | U4: 1 | V4: 1 | W4: 0 | X4: 1 | Y4: 1 | Z4: 0 | AA4: 1 | AB4: 0 | AC4: 0 | AD4: 1 | AE4: 1 | AF4: 1 | AG4: 0 | AH4: 1 | AI4: 0 | AJ4: 1 | AK4: 0 | AL4: 1 | AM4: 1 | AN4: 0 | AO4: 1 | AP4: 0 | AQ4: 1 | AR4: 0 | AS4: 0 | AT4: 1 | AU4: 0 | AV4: 0 | AW4: 1 | AX4: 1 | AY4: 1 | AZ4: 1 | BA4: 1 | BB4: 0 | BC4: 1 | BD4: 0 | BE4: 0 | BF4: 0 | BG4: 0 | BH4: 0 | BI4: 0 | BJ4: 0 | BK4: 1 | BL4: 0 | BM4: 1 | BN4: 1
B6: Các nhóm hệ 4bit
B7: 0001 | C7: 1010 | D7: 1011 | E7: 1111 | F7: 1111 | G7: 0110 | H7: 1001 | I7: 1101 | J7: 0101 | K7: 1010 | L7: 1001 | M7: 0011 | N7: 1110 | O7: 1000 | P7: 0000 | Q7: 1011
B8: 1 | C8: A | D8: B | E8: F | F8: F | G8: 6 | H8: 9 | I8: D | J8: 5 | K8: A | L8: 9 | M8: 3 | N8: E | O8: 8 | P8: 0 | Q8: B
