Workbook

Sheet Tính toán
A1: M = 00123456789abcde
A2: K = 0133457799bbcdff
A4: Bản rõ ban đầu
A6: STT | B6: 1 | C6: 2 | D6: 3 | E6: 4 | F6: 5 | G6: 6 | H6: 7 | I6: 8 | J6: 9 | K6: 10 | L6: 11 | M6: 12 | N6: 13 | O6: 14 | P6: 15 | Q6: 16 | R6: 17 | S6: 18 | T6: 19 | U6: 20 | V6: 21 | W6: 22 | X6: 23 | Y6: 24 | Z6: 25 | AA6: 26 | AB6: 27 | AC6: 28 | AD6: 29 | AE6: 30 | AF6: 31 | AG6: 32 | AH6: 33 | AI6: 34 | AJ6: 35 | AK6: 36 | AL6: 37 | AM6: 38 | AN6: 39 | AO6: 40 | AP6: 41 | AQ6: 42 | AR6: 43 | AS6: 44 | AT6: 45 | AU6: 46 | AV6: 47 | AW6: 48 | AX6: 49 | AY6: 50 | AZ6: 51 | BA6: 52 | BB6: 53 | BC6: 54 | BD6: 55 | BE6: 56 | BF6: 57 | BG6: 58 | BH6: 59 | BI6: 60 | BJ6: 61 | BK6: 62 | BL6: 63 | BM6: 64
A7: M | B7: 0 | C7: 0 | D7: 0 | E7: 0 | F7: 0 | G7: 0 | H7: 0 | I7: 0 | J7: 0 | K7: 0 | L7: 0 | M7: 1 | N7: 0 | O7: 0 | P7: 1 | Q7: 0 | R7: 0 | S7: 0 | T7: 1 | U7: 1 | V7: 0 | W7: 1 | X7: 0 | Y7: 0 | Z7: 0 | AA7: 1 | AB7: 0 | AC7: 1 | AD7: 0 | AE7: 1 | AF7: 1 | AG7: 0 | AH7: 0 | AI7: 1 | AJ7: 1 | AK7: 1 | AL7: 1 | AM7: 0 | AN7: 0 | AO7: 0 | AP7: 1 | AQ7: 0 | AR7: 0 | AS7: 1 | AT7: 1 | AU7: 0 | AV7: 1 | AW7: 0 | AX7: 1 | AY7: 0 | AZ7: 1 | BA7: 1 | BB7: 1 | BC7: 1 | BD7: 0 | BE7: 0 | BF7: 1 | BG7: 1 | BH7: 0 | BI7: 1 | BJ7: 1 | BK7: 1 | BL7: 1 | BM7: 0 | BN7: =MID($D$1,COLUMN(BP1),1) | BO7: =MID($D$1,COLUMN(BQ1),1)
A9: Khóa ban đầu
A11: STT | B11: 1 | C11: 2 | D11: 3 | E11: 4 | F11: 5 | G11: 6 | H11: 7 | I11: 8 | J11: 9 | K11: 10 | L11: 11 | M11: 12 | N11: 13 | O11: 14 | P11: 15 | Q11: 16 | R11: 17 | S11: 18 | T11: 19 | U11: 20 | V11: 21 | W11: 22 | X11: 23 | Y11: 24 | Z11: 25 | AA11: 26 | AB11: 27 | AC11: 28 | AD11: 29 | AE11: 30 | AF11: 31 | AG11: 32 | AH11: 33 | AI11: 34 | AJ11: 35 | AK11: 36 | AL11: 37 | AM11: 38 | AN11: 39 | AO11: 40 | AP11: 41 | AQ11: 42 | AR11: 43 | AS11: 44 | AT11: 45 | AU11: 46 | AV11: 47 | AW11: 48 | AX11: 49 | AY11: 50 | AZ11: 51 | BA11: 52 | BB11: 53 | BC11: 54 | BD11: 55 | BE11: 56 | BF11: 57 | BG11: 58 | BH11: 59 | BI11: 60 | BJ11: 61 | BK11: 62 | BL11: 63 | BM11: 64
A12: K | B12: 0 | C12: 0 | D12: 0 | E12: 0 | F12: 0 | G12: 0 | H12: 0 | I12: 1 | J12: 0 | K12: 0 | L12: 1 | M12: 1 | N12: 0 | O12: 0 | P12: 1 | Q12: 1 | R12: 0 | S12: 1 | T12: 0 | U12: 0 | V12: 0 | W12: 1 | X12: 0 | Y12: 1 | Z12: 0 | AA12: 1 | AB12: 1 | AC12: 1 | AD12: 0 | AE12: 1 | AF12: 1 | AG12: 1 | AH12: 1 | AI12: 0 | AJ12: 0 | AK12: 1 | AL12: 1 | AM12: 0 | AN12: 0 | AO12: 1 | AP12: 1 | AQ12: 0 | AR12: 1 | AS12: 1 | AT12: 1 | AU12: 0 | AV12: 1 | AW12: 1 | AX12: 1 | AY12: 1 | AZ12: 0 | BA12: 0 | BB12: 1 | BC12: 1 | BD12: 0 | BE12: 1 | BF12: 1 | BG12: 1 | BH12: 1 | BI12: 1 | BJ12: 1 | BK12: 1 | BL12: 1 | BM12: 1
B14: BẢNG IP | K14: BẢNG IP-1 | T14: BẢNG P
B15: 58 | C15: 50 | D15: 42 | E15: 34 | F15: 26 | G15: 18 | H15: 10 | I15: 2 | K15: 40 | L15: 8 | M15: 48 | N15: 16 | O15: 56 | P15: 24 | Q15: 64 | R15: 32 | T15: 16 | U15: 7 | V15: 20 | W15: 21 | X15: 29 | Y15: 12 | Z15: 28 | AA15: 17
B16: 60 | C16: 52 | D16: 44 | E16: 36 | F16: 28 | G16: 20 | H16: 12 | I16: 4 | K16: 39 | L16: 7 | M16: 47 | N16: 15 | O16: 55 | P16: 23 | Q16: 63 | R16: 31 | T16: 1 | U16: 15 | V16: 23 | W16: 26 | X16: 5 | Y16: 18 | Z16: 31 | AA16: 10
B17: 62 | C17: 54 | D17: 46 | E17: 38 | F17: 30 | G17: 22 | H17: 14 | I17: 6 | K17: 38 | L17: 6 | M17: 46 | N17: 14 | O17: 54 | P17: 22 | Q17: 62 | R17: 30 | T17: 2 | U17: 8 | V17: 24 | W17: 14 | X17: 32 | Y17: 27 | Z17: 3 | AA17: 9
B18: 64 | C18: 56 | D18: 48 | E18: 40 | F18: 32 | G18: 24 | H18: 16 | I18: 8 | K18: 37 | L18: 5 | M18: 45 | N18: 13 | O18: 53 | P18: 21 | Q18: 61 | R18: 29 | T18: 19 | U18: 13 | V18: 30 | W18: 6 | X18: 22 | Y18: 11 | Z18: 4 | AA18: 25
B19: 57 | C19: 49 | D19: 41 | E19: 33 | F19: 25 | G19: 17 | H19: 9 | I19: 1 | K19: 36 | L19: 4 | M19: 44 | N19: 12 | O19: 52 | P19: 20 | Q19: 60 | R19: 28
B20: 59 | C20: 51 | D20: 43 | E20: 35 | F20: 27 | G20: 19 | H20: 11 | I20: 3 | K20: 35 | L20: 3 | M20: 43 | N20: 11 | O20: 51 | P20: 19 | Q20: 59 | R20: 27
B21: 61 | C21: 53 | D21: 45 | E21: 37 | F21: 29 | G21: 21 | H21: 13 | I21: 5 | K21: 34 | L21: 2 | M21: 42 | N21: 10 | O21: 50 | P21: 18 | Q21: 58 | R21: 26
B22: 63 | C22: 55 | D22: 47 | E22: 39 | F22: 31 | G22: 23 | H22: 15 | I22: 7 | K22: 33 | L22: 1 | M22: 41 | N22: 9 | O22: 49 | P22: 17 | Q22: 57 | R22: 25
B24: BẢNG PC-1 | K24: BẢNG PC-2 | T24: BẢNG E
B25: 57 | C25: 49 | D25: 41 | E25: 33 | F25: 25 | G25: 17 | H25: 9 | K25: 14 | L25: 17 | M25: 11 | N25: 24 | O25: 1 | P25: 5 | T25: 32 | U25: 1 | V25: 2 | W25: 3 | X25: 4 | Y25: 5
B26: 1 | C26: 58 | D26: 50 | E26: 42 | F26: 34 | G26: 26 | H26: 18 | K26: 3 | L26: 28 | M26: 15 | N26: 6 | O26: 21 | P26: 10 | T26: 4 | U26: 5 | V26: 6 | W26: 7 | X26: 8 | Y26: 9
B27: 10 | C27: 2 | D27: 59 | E27: 51 | F27: 43 | G27: 35 | H27: 27 | K27: 23 | L27: 19 | M27: 12 | N27: 4 | O27: 26 | P27: 8 | T27: 8 | U27: 9 | V27: 10 | W27: 11 | X27: 12 | Y27: 13
B28: 19 | C28: 11 | D28: 3 | E28: 60 | F28: 52 | G28: 44 | H28: 36 | K28: 16 | L28: 7 | M28: 27 | N28: 20 | O28: 13 | P28: 2 | T28: 12 | U28: 13 | V28: 14 | W28: 15 | X28: 16 | Y28: 17
B29: 63 | C29: 55 | D29: 47 | E29: 39 | F29: 31 | G29: 23 | H29: 15 | K29: 41 | L29: 52 | M29: 31 | N29: 37 | O29: 47 | P29: 55 | T29: 16 | U29: 17 | V29: 18 | W29: 19 | X29: 20 | Y29: 21
B30: 7 | C30: 62 | D30: 54 | E30: 46 | F30: 38 | G30: 30 | H30: 22 | K30: 30 | L30: 40 | M30: 51 | N30: 45 | O30: 33 | P30: 48 | T30: 20 | U30: 21 | V30: 22 | W30: 23 | X30: 24 | Y30: 25
B31: 14 | C31: 6 | D31: 61 | E31: 53 | F31: 45 | G31: 37 | H31: 29 | K31: 44 | L31: 49 | M31: 39 | N31: 56 | O31: 34 | P31: 53 | T31: 24 | U31: 25 | V31: 26 | W31: 27 | X31: 28 | Y31: 29
B32: 21 | C32: 13 | D32: 5 | E32: 28 | F32: 20 | G32: 12 | H32: 4 | K32: 46 | L32: 42 | M32: 50 | N32: 36 | O32: 29 | P32: 32 | T32: 28 | U32: 29 | V32: 30 | W32: 31 | X32: 32 | Y32: 1
A34: Sau khi hoán vị, ta được IP(M) như sau:
A36: IP(M) | B36: {=INDEX($B$7:$BS$7, B15)} -> 1 | C36: {=INDEX($B$7:$BS$7, C15)} -> 0 | D36: {=INDEX($B$7:$BS$7, D15)} -> 0 | E36: {=INDEX($B$7:$BS$7, E15)} -> 1 | F36: {=INDEX($B$7:$BS$7, F15)} -> 1 | G36: {=INDEX($B$7:$BS$7, G15)} -> 0 | H36: {=INDEX($B$7:$BS$7, H15)} -> 0 | I36: {=INDEX($B$7:$BS$7, I15)} -> 0
B37: {=INDEX($B$7:$BS$7, B16)} -> 1 | C37: {=INDEX($B$7:$BS$7, C16)} -> 1 | D37: {=INDEX($B$7:$BS$7, D16)} -> 1 | E37: {=INDEX($B$7:$BS$7, E16)} -> 1 | F37: {=INDEX($B$7:$BS$7, F16)} -> 1 | G37: {=INDEX($B$7:$BS$7, G16)} -> 1 | H37: {=INDEX($B$7:$BS$7, H16)} -> 1 | I37: {=INDEX($B$7:$BS$7, I16)} -> 0
B38: {=INDEX($B$7:$BS$7, B17)} -> 1 | C38: {=INDEX($B$7:$BS$7, C17)} -> 1 | D38: {=INDEX($B$7:$BS$7, D17)} -> 0 | E38: {=INDEX($B$7:$BS$7, E17)} -> 0 | F38: {=INDEX($B$7:$BS$7, F17)} -> 1 | G38: {=INDEX($B$7:$BS$7, G17)} -> 1 | H38: {=INDEX($B$7:$BS$7, H17)} -> 0 | I38: {=INDEX($B$7:$BS$7, I17)} -> 0
B39: {=INDEX($B$7:$BS$7, B18)} -> 0 | C39: {=INDEX($B$7:$BS$7, C18)} -> 0 | D39: {=INDEX($B$7:$BS$7, D18)} -> 0 | E39: {=INDEX($B$7:$BS$7, E18)} -> 0 | F39: {=INDEX($B$7:$BS$7, F18)} -> 0 | G39: {=INDEX($B$7:$BS$7, G18)} -> 0 | H39: {=INDEX($B$7:$BS$7, H18)} -> 0 | I39: {=INDEX($B$7:$BS$7, I18)} -> 0
B40: {=INDEX($B$7:$BS$7, B19)} -> 1 | C40: {=INDEX($B$7:$BS$7, C19)} -> 1 | D40: {=INDEX($B$7:$BS$7, D19)} -> 1 | E40: {=INDEX($B$7:$BS$7, E19)} -> 0 | F40: {=INDEX($B$7:$BS$7, F19)} -> 0 | G40: {=INDEX($B$7:$BS$7, G19)} -> 0 | H40: {=INDEX($B$7:$BS$7, H19)} -> 0 | I40: {=INDEX($B$7:$BS$7, I19)} -> 0
B41: {=INDEX($B$7:$BS$7, B20)} -> 0 | C41: {=INDEX($B$7:$BS$7, C20)} -> 1 | D41: {=INDEX($B$7:$BS$7, D20)} -> 0 | E41: {=INDEX($B$7:$BS$7, E20)} -> 1 | F41: {=INDEX($B$7:$BS$7, F20)} -> 0 | G41: {=INDEX($B$7:$BS$7, G20)} -> 1 | H41: {=INDEX($B$7:$BS$7, H20)} -> 0 | I41: {=INDEX($B$7:$BS$7, I20)} -> 0
B42: {=INDEX($B$7:$BS$7, B21)} -> 1 | C42: {=INDEX($B$7:$BS$7, C21)} -> 1 | D42: {=INDEX($B$7:$BS$7, D21)} -> 1 | E42: {=INDEX($B$7:$BS$7, E21)} -> 1 | F42: {=INDEX($B$7:$BS$7, F21)} -> 0 | G42: {=INDEX($B$7:$BS$7, G21)} -> 0 | H42: {=INDEX($B$7:$BS$7, H21)} -> 0 | I42: {=INDEX($B$7:$BS$7, I21)} -> 0
B43: {=INDEX($B$7:$BS$7, B22)} -> 1 | C43: {=INDEX($B$7:$BS$7, C22)} -> 0 | D43: {=INDEX($B$7:$BS$7, D22)} -> 1 | E43: {=INDEX($B$7:$BS$7, E22)} -> 0 | F43: {=INDEX($B$7:$BS$7, F22)} -> 1 | G43: {=INDEX($B$7:$BS$7, G22)} -> 0 | H43: {=INDEX($B$7:$BS$7, H22)} -> 1 | I43: {=INDEX($B$7:$BS$7, I22)} -> 0
A45: STT | B45: 1 | C45: 2 | D45: 3 | E45: 4 | F45: 5 | G45: 6 | H45: 7 | I45: 8 | J45: 9 | K45: 10 | L45: 11 | M45: 12 | N45: 13 | O45: 14 | P45: 15 | Q45: 16 | R45: 17 | S45: 18 | T45: 19 | U45: 20 | V45: 21 | W45: 22 | X45: 23 | Y45: 24 | Z45: 25 | AA45: 26 | AB45: 27 | AC45: 28 | AD45: 29 | AE45: 30 | AF45: 31 | AG45: 32 | AH45: 33 | AI45: 34 | AJ45: 35 | AK45: 36 | AL45: 37 | AM45: 38 | AN45: 39 | AO45: 40 | AP45: 41 | AQ45: 42 | AR45: 43 | AS45: 44 | AT45: 45 | AU45: 46 | AV45: 47 | AW45: 48 | AX45: 49 | AY45: 50 | AZ45: 51 | BA45: 52 | BB45: 53 | BC45: 54 | BD45: 55 | BE45: 56 | BF45: 57 | BG45: 58 | BH45: 59 | BI45: 60 | BJ45: 61 | BK45: 62 | BL45: 63 | BM45: 64
A46: IP(M) | B46: {=INDEX($B$36:$I$43, INT((COLUMN(A1)-1)/8)+1, MOD(COLUMN(A1)-1,8)+1)} -> 1 | C46: {=INDEX($B$36:$I$43, INT((COLUMN(B1)-1)/8)+1, MOD(COLUMN(B1)-1,8)+1)} -> 0 | D46: {=INDEX($B$36:$I$43, INT((COLUMN(C1)-1)/8)+1, MOD(COLUMN(C1)-1,8)+1)} -> 0 | E46: {=INDEX($B$36:$I$43, INT((COLUMN(D1)-1)/8)+1, MOD(COLUMN(D1)-1,8)+1)} -> 1 | F46: {=INDEX($B$36:$I$43, INT((COLUMN(E1)-1)/8)+1, MOD(COLUMN(E1)-1,8)+1)} -> 1 | G46: {=INDEX($B$36:$I$43, INT((COLUMN(F1)-1)/8)+1, MOD(COLUMN(F1)-1,8)+1)} -> 0 | H46: {=INDEX($B$36:$I$43, INT((COLUMN(G1)-1)/8)+1, MOD(COLUMN(G1)-1,8)+1)} -> 0 | I46: {=INDEX($B$36:$I$43, INT((COLUMN(H1)-1)/8)+1, MOD(COLUMN(H1)-1,8)+1)} -> 0 | ... BM46: {=INDEX($B$36:$I$43, INT((COLUMN(BL1)-1)/8)+1, MOD(COLUMN(BL1)-1,8)+1)} -> 0
A48: Tính toán các giá trị khóa vòng
A50: Bảng PC-1(K) | B50: {=INDEX($B$12:$BS$12, B25)} -> 1 | C50: {=INDEX($B$12:$BS$12, C25)} -> 1 | D50: {=INDEX($B$12:$BS$12, D25)} -> 1 | E50: {=INDEX($B$12:$BS$12, E25)} -> 1 | F50: {=INDEX($B$12:$BS$12, F25)} -> 0 | G50: {=INDEX($B$12:$BS$12, G25)} -> 0 | H50: {=INDEX($B$12:$BS$12, H25)} -> 0
B51: {=INDEX($B$12:$BS$12, B26)} -> 0 | C51: {=INDEX($B$12:$BS$12, C26)} -> 1 | D51: {=INDEX($B$12:$BS$12, D26)} -> 1 | E51: {=INDEX($B$12:$BS$12, E26)} -> 0 | F51: {=INDEX($B$12:$BS$12, F26)} -> 0 | G51: {=INDEX($B$12:$BS$12, G26)} -> 1 | H51: {=INDEX($B$12:$BS$12, H26)} -> 1
...

Sheet S-box
A1: BẢNG S1
A2: 14 | B2: 4 | C2: 13 | D2: 1 | E2: 2 | F2: 15 | G2: 11 | H2: 8 | I2: 3 | J2: 10 | K2: 6 | L2: 12 | M2: 5 | N2: 9 | O2: 0 | P2: 7
A3: 0 | B3: 15 | C3: 7 | D3: 4 | E3: 14 | F3: 2 | G3: 13 | H3: 1 | I3: 10 | J3: 6 | K3: 12 | L3: 11 | M3: 9 | N3: 5 | O3: 3 | P3: 8
A4: 4 | B4: 1 | C4: 14 | D4: 8 | E4: 13 | F4: 6 | G4: 2 | H4: 11 | I4: 15 | J4: 12 | K4: 9 | L4: 7 | M4: 3 | N4: 10 | O4: 5 | P4: 0
A5: 15 | B5: 12 | C5: 8 | D5: 2 | E5: 4 | F5: 9 | G5: 1 | H5: 7 | I5: 5 | J5: 11 | K5: 3 | L5: 14 | M5: 10 | N5: 0 | O5: 6 | P5: 13
A7: BẢNG S2
A8: 15 | B8: 1 | C8: 8 | D8: 14 | E8: 6 | F8: 11 | G8: 3 | H8: 4 | I8: 9 | J8: 7 | K8: 2 | L8: 13 | M8: 12 | N8: 0 | O8: 5 | P8: 10
A9: 3 | B9: 13 | C9: 4 | D9: 7 | E9: 15 | F9: 2 | G9: 8 | H9: 14 | I9: 12 | J9: 0 | K9: 1 | L9: 10 | M9: 6 | N9: 9 | O9: 11 | P9: 5
A10: 0 | B10: 14 | C10: 7 | D10: 11 | E10: 10 | F10: 4 | G10: 13 | H10: 1 | I10: 5 | J10: 8 | K10: 12 | L10: 6 | M10: 9 | N10: 3 | O10: 2 | P10: 15
A11: 13 | B11: 8 | C11: 10 | D11: 1 | E11: 3 | F11: 15 | G11: 4 | H11: 2 | I11: 11 | J11: 6 | K11: 7 | L11: 12 | M11: 0 | N11: 5 | O11: 14 | P11: 9
A13: BẢNG S3
A14: 10 | B14: 0 | C14: 9 | D14: 14 | E14: 6 | F14: 3 | G14: 15 | H14: 5 | I14: 1 | J14: 13 | K14: 12 | L14: 7 | M14: 11 | N14: 4 | O14: 2 | P14: 8
A15: 13 | B15: 7 | C15: 0 | D15: 9 | E15: 3 | F15: 4 | G15: 6 | H15: 10 | I15: 2 | J15: 8 | K15: 5 | L15: 14 | M15: 12 | N15: 11 | O15: 15 | P15: 1
A16: 13 | B16: 6 | C16: 4 | D16: 9 | E16: 8 | F16: 15 | G16: 3 | H16: 0 | I16: 11 | J16: 1 | K16: 2 | L16: 12 | M16: 5 | N16: 10 | O16: 14 | P16: 7
A17: 1 | B17: 10 | C17: 13 | D17: 0 | E17: 6 | F17: 9 | G17: 8 | H17: 7 | I17: 4 | J17: 15 | K17: 14 | L17: 3 | M17: 11 | N17: 5 | O17: 2 | P17: 12
A19: BẢNG S4
A20: 7 | B20: 13 | C20: 14 | D20: 3 | E20: 0 | F20: 6 | G20: 9 | H20: 10 | I20: 1 | J20: 2 | K20: 8 | L20: 5 | M20: 11 | N20: 12 | O20: 4 | P20: 15
A21: 13 | B21: 8 | C21: 11 | D21: 5 | E21: 6 | F21: 15 | G21: 0 | H21: 3 | I21: 4 | J21: 7 | K21: 2 | L21: 12 | M21: 1 | N21: 10 | O21: 14 | P21: 9
A22: 10 | B22: 6 | C22: 9 | D22: 0 | E22: 12 | F22: 11 | G22: 7 | H22: 13 | I22: 15 | J22: 1 | K22: 3 | L22: 14 | M22: 5 | N22: 2 | O22: 8 | P22: 4
A23: 3 | B23: 15 | C23: 0 | D23: 6 | E23: 10 | F23: 1 | G23: 13 | H23: 8 | I23: 9 | J23: 4 | K23: 5 | L23: 11 | M23: 12 | N23: 7 | O23: 2 | P23: 14
A25: BẢNG S5
A26: 2 | B26: 12 | C26: 4 | D26: 1 | E26: 7 | F26: 10 | G26: 11 | H26: 6 | I26: 8 | J26: 5 | K26: 3 | L26: 15 | M26: 13 | N26: 0 | O26: 14 | P26: 9
A27: 14 | B27: 11 | C27: 2 | D27: 12 | E27: 4 | F27: 7 | G27: 13 | H27: 1 | I27: 5 | J27: 0 | K27: 15 | L27: 10 | M27: 3 | N27: 9 | O27: 8 | P27: 6
A28: 4 | B28: 2 | C28: 1 | D28: 11 | E28: 10 | F28: 13 | G28: 7 | H28: 8 | I28: 15 | J28: 9 | K28: 12 | L28: 5 | M28: 6 | N28: 3 | O28: 0 | P28: 14
A29: 11 | B29: 8 | C29: 12 | D29: 7 | E29: 1 | F29: 14 | G29: 2 | H29: 13 | I29: 6 | J29: 15 | K29: 0 | L29: 9 | M29: 10 | N29: 4 | O29: 5 | P29: 3
A31: BẢNG S6
A32: 12 | B32: 1 | C32: 10 | D32: 15 | E32: 9 | F32: 2 | G32: 6 | H32: 8 | I32: 0 | J32: 13 | K32: 3 | L32: 4 | M32: 14 | N32: 7 | O32: 5 | P32: 11
A33: 10 | B33: 15 | C33: 4 | D33: 2 | E33: 7 | F33: 12 | G33: 9 | H33: 5 | I33: 6 | J33: 1 | K33: 13 | L33: 14 | M33: 0 | N33: 11 | O33: 3 | P33: 8
A34: 9 | B34: 14 | C34: 15 | D34: 5 | E34: 2 | F34: 8 | G34: 12 | H34: 3 | I34: 7 | J34: 0 | K34: 4 | L34: 10 | M34: 1 | N34: 13 | O34: 11 | P34: 6
A35: 4 | B35: 3 | C35: 2 | D35: 12 | E35: 9 | F35: 5 | G35: 15 | H35: 10 | I35: 11 | J35: 14 | K35: 1 | L35: 7 | M35: 6 | N35: 0 | O35: 8 | P35: 13
A37: BẢNG S7
A38: 4 | B38: 11 | C38: 2 | D38: 14 | E38: 15 | F38: 0 | G38: 8 | H38: 13 | I38: 3 | J38: 12 | K38: 9 | L38: 7 | M38: 5 | N38: 10 | O38: 6 | P38: 1
A39: 13 | B39: 0 | C39: 11 | D39: 7 | E39: 4 | F39: 9 | G39: 1 | H39: 10 | I39: 14 | J39: 3 | K39: 5 | L39: 12 | M39: 2 | N39: 15 | O39: 8 | P39: 6
A40: 1 | B40: 4 | C40: 11 | D40: 13 | E40: 12 | F40: 3 | G40: 7 | H40: 14 | I40: 10 | J40: 15 | K40: 6 | L40: 8 | M40: 0 | N40: 5 | O40: 9 | P40: 2
A41: 6 | B41: 11 | C41: 13 | D41: 8 | E41: 1 | F41: 4 | G41: 10 | H41: 7 | I41: 9 | J41: 5 | K41: 0 | L41: 15 | M41: 14 | N41: 2 | O41: 3 | P41: 12
A43: BẢNG S8
A44: 13 | B44: 2 | C44: 8 | D44: 4 | E44: 6 | F44: 15 | G44: 11 | H44: 1 | I44: 10 | J44: 9 | K44: 3 | L44: 14 | M44: 5 | N44: 0 | O44: 12 | P44: 7
A45: 1 | B45: 15 | C45: 13 | D45: 8 | E45: 10 | F45: 3 | G45: 7 | H45: 4 | I45: 12 | J45: 5 | K45: 6 | L45: 11 | M45: 0 | N45: 14 | O45: 9 | P45: 2
A46: 7 | B46: 11 | C46: 4 | D46: 1 | E46: 9 | F46: 12 | G46: 14 | H46: 2 | I46: 0 | J46: 6 | K46: 10 | L46: 13 | M46: 15 | N46: 3 | O46: 5 | P46: 8
A47: 2 | B47: 1 | C47: 14 | D47: 7 | E47: 4 | F47: 10 | G47: 8 | H47: 13 | I47: 15 | J47: 12 | K47: 9 | L47: 0 | M47: 3 | N47: 5 | O47: 6 | P47: 11
